Workbook

Sheet INC HS Data
A1: Name | B1: Site | C1: Name | D1: Tenure at Date of Injury | E1: Employment Type | F1: Nature of Injury | G1: Claim | H1: Claim Status
A2: DOUGLAS, KARIN | B2: 2032 | C2: Traralgon | D2: 2 | E2: PART TIME | F2: Residual soft tissue disorders due to trauma or unknown mechanisms
A3: MITCHELL, ANGELA | B3: 1005 | C3: Elizabeth | D3: 0 | E3: PART TIME | F3: Residual soft tissue disorders due to trauma or unknown mechanisms
A4: KNIGHT, REBEKAH | B4: 4045 | C4: Ulverstone | D4: 17 | E4: FULL TIME | F4: Residual soft tissue disorders due to trauma or unknown mechanisms
A5: PRIDMORE-JOHNSTON, REBECCA | B5: 4043 | C5: Launceston | D5: 2 | E5: PART TIME | F5: Contusion, bruising and superficial crushing
A6: ANDREWS, SIOBHAN | B6: 4044 | C6: Devonport | D6: 0 | E6: CASUAL | F6: Laceration or open wound not involving traumatic amputation
A7: DIMAKAKOS, MELISSA | B7: 2023 | C7: Epping | D7: 20 | E7: PART TIME | F7: Residual soft tissue disorders due to trauma or unknown mechanisms
A8: KOKKINOS, ANGELA | B8: 2020 | C8: Forest Hill | D8: 2 | E8: CASUAL | F8: Laceration or open wound not involving traumatic amputation | G8: Claim | H8: Accepted Claim
A9: CSIKOS, JAMISON | B9: 2028 | C9: Cranbourne Park | D9: 2 | E9: PART TIME | F9: Residual soft tissue disorders due to trauma or unknown mechanisms
A10: SANDHU, KULDEEP KAUR | B10: 9095 | C10: Chermside | D10: 1 | E10: PART TIME | F10: Residual soft tissue disorders due to trauma or unknown mechanisms | G10: Claim | H10: Accepted Claim
A11: THOMAS, LAUREN | B11: 1005 | C11: Elizabeth | D11: 0 | E11: CASUAL | F11: Foreign body on external eye, in ear or nose or in respiratory, digestive or reproductive tract
A12: DANILEUSKI, THOMAS | B12: 9095 | C12: Chermside | D12: 6 | E12: PART TIME | F12: Residual soft tissue disorders due to trauma or unknown mechanisms | G12: Claim | H12: Accepted Claim
A13: HENDY, KATE | B13: 1011 | C13: Marion | D13: 24 | E13: PART TIME | F13: Residual soft tissue disorders due to trauma or unknown mechanisms
A14: DOWSETT, TAMERA | B14: 6071 | C14: Tweed Heads | D14: 1 | E14: FULL TIME | F14: Residual soft tissue disorders due to trauma or unknown mechanisms
A15: ALLEN, SUSAN | B15: 1006 | C15: West Lakes | D15: 13 | E15: PART TIME | F15: Residual soft tissue disorders due to trauma or unknown mechanisms | G15: Claim | H15: Accepted Claim (MEO)
A16: KARYN, FALCO | B16: 9098 | C16: Carindale | D16: 0 | E16: FULL TIME | F16: Residual soft tissue disorders due to trauma or unknown mechanisms
A17: LAWSON, NIKKITA | B17: 4043 | C17: Launceston | D17: 7 | E17: PART TIME | F17: Laceration or open wound not involving traumatic amputation
A18: MCMULLEN, ALYSE | B18: 2042 | C18: Carnegie (Hs Home) | D18: 2 | E18: FULL TIME | F18: Laceration or open wound not involving traumatic amputation
A19: HUNTER, SARAH | B19: 1011 | C19: Marion | D19: 8 | E19: FULL TIME | F19: Residual soft tissue disorders due to trauma or unknown mechanisms
A20: NUTTALL, BELINDA | B20: 2021 | C20: Geelong | D20: 6 | E20: FULL TIME | F20: Residual soft tissue disorders due to trauma or unknown mechanisms
A21: MAVER, GEORGIE | B21: 2023 | C21: Epping | D21: 2 | E21: FULL TIME | F21: Residual soft tissue disorders due to trauma or unknown mechanisms
A22: ZIGOURAS, LOREDANA | B22: 2025 | C22: Southland | D22: 3 | E22: CASUAL | F22: Residual soft tissue disorders due to trauma or unknown mechanisms
A23: ARNOLD, MAKENZIE | B23: 4045 | C23: Ulverstone | D23: 1 | E23: CASUAL | F23: Other mental diseases, not elsewhere classified
A24: BYNION, FAY | B24: 2025 | C24: Southland | D24: 1 | E24: FULL TIME | F24: Residual soft tissue disorders due to trauma or unknown mechanisms
A25: ADDAMS, SAMANTHA | B25: 2019 | C25: Ballarat | D25: 0 | E25: PART TIME | F25: Reaction to stressors - other, multiple or not specified | G25: Claim | H25: Pending Claim
A26: GANGI, ALESSIA | B26: 2024 | C26: Highpoint | D26: 0 | E26: CASUAL
A27: SMITH, KIEREN | B27: 1011 | C27: Marion | D27: 10 | E27: PART TIME | F27: Laceration or open wound not involving traumatic amputation
A28: MEAD, SUSANNE | B28: 2029 | C28: Waurn Ponds (Hs Home) | D28: 0 | E28: PART TIME | F28: Laceration or open wound not involving traumatic amputation
A29: MORRISS, ASHLEY | B29: 6068 | C29: Wagga Wagga | D29: 0 | E29: CASUAL | F29: Laceration or open wound not involving traumatic amputation
A30: DE GENNARO, MADELINE | B30: 1011 | C30: Marion | D30: 2 | E30: CASUAL | F30: Laceration or open wound not involving traumatic amputation
A31: MCGURGAN, KAYLA | B31: 2026 | C31: Shepparton | D31: 1 | E31: CASUAL | F31: Residual soft tissue disorders due to trauma or unknown mechanisms
A32: ADAMS, CHRISTINE | B32: 2029 | C32: Waurn Ponds (Hs Home) | D32: 1 | E32: PART TIME | F32: Laceration or open wound not involving traumatic amputation
A33: BOURNE, MAREE | B33: 6068 | C33: Wagga Wagga | D33: 4 | E33: PART TIME | F33: Residual soft tissue disorders due to trauma or unknown mechanisms
A34: PENFOLD, ALANA | B34: 1005 | C34: Elizabeth | D34: 3 | E34: CASUAL | F34: Laceration or open wound not involving traumatic amputation
A35: RUSH, GEORGINA | B35: 4045 | C35: Ulverstone | D35: 2 | E35: PART TIME | F35: Reaction to stressors - other, multiple or not specified
A36: FORBES, LILLY MAY | B36: 6071 | C36: Tweed Heads | D36: 1 | E36: PART TIME | F36: Residual soft tissue disorders due to trauma or unknown mechanisms
A37: MCNAMARA, NEASHER | B37: 9095 | C37: Chermside | D37: 4 | E37: FULL TIME | F37: Residual soft tissue disorders due to trauma or unknown mechanisms | G37: Claim | H37: Accepted Claim
A38: MARINO, ANGELA | B38: 1010 | C38: Whyalla | D38: 2 | E38: PART TIME | F38: Laceration or open wound not involving traumatic amputation
A39: QUEEN, DECLAN | B39: 4042 | C39: Cambridge | D39: 1 | E39: PART TIME | F39: Residual soft tissue disorders due to trauma or unknown mechanisms
A40: HANSEN, LACHLAN | B40: 9097 | C40: Hervey Bay | D40: 0 | E40: PART TIME | F40: Foreign body on external eye, in ear or nose or in respiratory, digestive or reproductive tract
...

Sheet HS Graphs
E18: Figure 1 | F18: Total Incidents within 19-month period | S18: Figure 3 | T18: Total Incidents and Claims within 19-month period
E36: Figure 2 | F36: Total Claims within 19-month period | S36: Figure 4 | T36: Total Incidents and Claims within 19-month period by Age Groups
E54: Figure 4 | F54: Total Incidents and Claims within 19-month period by Tenure Groups | S54: Figure 5 | T54: Total Incidents and Claims between 1-5 Years Tenure from Date of Injury
M73: Figure 6 | N73: Total Incidents and Claims within 19-month period (NSW Only)

Sheet Group Graph

Sheet Pie Charts
A3: Incidents | B3: 270 | P3: Team Member Incidents | Q3: 300
A4: Claims | B4: 57 | P4: Non-Work Related | Q4: 27
F16: Figure 1 | G16: Incidents and Claims within 18-month period | U16: Figure 3 | V16: Non-Work Related incidents
A18: Accepted Claim | B18: 36 | P18: Non-Work Related | Q18: 23
A19: Pending Claim | B19: 13 | P19: Pending Claims | Q19: 1
A20: Accepted Claim (MEO) | B20: 5 | P20: Accepted Claims | Q20: 2
A21: Invalid Claim | B21: 2 | P21: Declined Claims | Q21: 1
A22: Declined Claim | B22: 1
F33: Figure 2 | G33: Claim Status within 18-month period | U33: Figure 4 | V33: Claim Status within Non-Work Related

Sheet Pivot
H1: Claim | I1: Claim | K1: Claim | L1: Claim | O1: Claim | P1: Claim
A2: HS Incidents Per Age Group and Region | D2: HS Incidents Per Tenure Group | H2: HS Claims Per Age Group and Region | K2: HS Claim Per Tenure Group | O2: Incident Correlation NWR_TMJ
A3: Row Labels | B3: Count of Grouping Level 2 | D3: Row Labels | E3: Count of Grouping Level 2 | H3: Row Labels | I3: Count of Age Bracket | K3: Row Labels | L3: Count of Grouping Level 2 | O3: Count of Incidents Correlation NWR_TMJ | P3: Column Labels
A4: Harris Scarfe - NSW/ACT | B4: 34 | D4: Under 1 Year | E4: 62 | H4: Harris Scarfe - NSW/ACT | I4: 4 | K4: Under 1 Year | L4: 8 | O4: Row Labels | P4: 20-24 Years | Q4: 25-34 Years | R4: 35-44 Years | S4: 45-54 Years | T4: More Than 55 Years | U4: Grand Total
A5: Less Than 20 Years | B5: 1 | D5: 1-5 Years | E5: 165 | H5: 20-24 Years | I5: 1 | K5: 1-5 Years | L5: 28 | O5: Accepted Claim | S5: 1 | T5: 1 | U5: 2
A6: 20-24 Years | B6: 5 | D6: 6-10 Years | E6: 47 | H6: 25-34 Years | I6: 1 | K6: 6-10 Years | L6: 9 | O6: Declined Claim | Q6: 1 | U6: 1
A7: 25-34 Years | B7: 8 | D7: 11-15 Years | E7: 17 | H7: 35-44 Years | I7: 1 | K7: 11-15 Years | L7: 8 | O7: Pending Claim | R7: 1 | U7: 1
A8: 35-44 Years | B8: 2 | D8: 16-20 Years | E8: 17 | H8: 45-54 Years | I8: 1 | K8: 16-20 Years | L8: 3 | O8: Grand Total | Q8: 1 | R8: 1 | S8: 1 | T8: 1 | U8: 4
A9: 45-54 Years | B9: 8 | D9: 21-25 Years | E9: 7 | H9: Harris Scarfe - QLD | I9: 17 | K9: 26-30 Years | L9: 1
A10: More Than 55 Years | B10: 10 | D10: 26-30 Years | E10: 7 | H10: 20-24 Years | I10: 4 | K10: Grand Total | L10: 57
A11: Harris Scarfe - QLD | B11: 74 | D11: More Than 30 Years | E11: 5 | H11: 25-34 Years | I11: 5
A12: Less Than 20 Years | B12: 6 | D12: Grand Total | E12: 327 | H12: 35-44 Years | I12: 2
A13: 20-24 Years | B13: 8 | H13: 45-54 Years | I13: 3
A14: 25-34 Years | B14: 22 | H14: More Than 55 Years | I14: 3
A15: 35-44 Years | B15: 8 | D15: Tenure Bracket at Date of Injury | E15: 1-5 Years | H15: Harris Scarfe - SA/TAS | I15: 12
A16: 45-54 Years | B16: 17 | D16: HS Incidents between 1-5 years Tenure | H16: 20-24 Years | I16: 2
A17: More Than 55 Years | B17: 13 | D17: Row Labels | E17: Count of Grouping Level 2 | H17: 25-34 Years | I17: 2
A18: Harris Scarfe - SA/TAS | B18: 103 | D18: 1 | E18: 72 | H18: 35-44 Years | I18: 2
A19: Less Than 20 Years | B19: 9 | D19: 2 | E19: 38 | H19: 45-54 Years | I19: 2
A20: 20-24 Years | B20: 15 | D20: 3 | E20: 23 | H20: More Than 55 Years | I20: 4
A21: 25-34 Years | B21: 16 | D21: 4 | E21: 20 | H21: Harris Scarfe - VIC | I21: 13
A22: 35-44 Years | B22: 14 | D22: 5 | E22: 12 | H22: 20-24 Years | I22: 3
A23: 45-54 Years | B23: 18 | D23: Grand Total | E23: 165 | H23: 25-34 Years | I23: 2
A24: More Than 55 Years | B24: 31 | H24: 35-44 Years | I24: 2
A25: Harris Scarfe - VIC | B25: 64 | H25: 45-54 Years | I25: 1
A26: Less Than 20 Years | B26: 4 | H26: More Than 55 Years | I26: 5
A27: 20-24 Years | B27: 14 | H27: Harris Scarfe - VIC & NSW | I27: 11
A28: 25-34 Years | B28: 9 | H28: 25-34 Years | I28: 1
A29: 35-44 Years | B29: 8 | H29: 35-44 Years | I29: 4
A30: 45-54 Years | B30: 15 | H30: 45-54 Years | I30: 1
A31: More Than 55 Years | B31: 14 | H31: More Than 55 Years | I31: 5
A32: Harris Scarfe - VIC & NSW | B32: 52 | H32: Grand Total | I32: 57
A33: Less Than 20 Years | B33: 1
A34: 20-24 Years | B34: 7 | H34: Tenure Bracket at Date of Injury | I34: 1-5 Years
A35: 25-34 Years | B35: 8 | H35: Claim | I35: Claim
A36: 35-44 Years | B36: 12 | H36: HS Claims between 1-5 years Tenure
A37: 45-54 Years | B37: 8 | H37: Row Labels | I37: Count of Claim
A38: More Than 55 Years | B38: 16 | H38: 1 | I38: 12
A39: Grand Total | B39: 327 | H39: 2 | I39: 8
H40: 3 | I40: 3
...

Sheet HS FEED
A1: Harris Scarfe | B1: FY24 | S1: FY25
A2: Incidents | B2: ="JUL, "&B1 -> JUL, FY24 | C2: ="AUG, "&B1 -> AUG, FY24 | D2: ="SEP, "&B1 -> SEP, FY24 | E2: ="Q1, "&B1 -> Q1, FY24 | F2: ="OCT, "&B1 -> OCT, FY24 | G2: ="NOV, "&B1 -> NOV, FY24 | H2: ="DEC, "&B1 -> DEC, FY24 | I2: ="Q2, "&B1 -> Q2, FY24 | J2: ="JAN, "&B1 -> JAN, FY24 | K2: ="FEB, "&B1 -> FEB, FY24 | L2: ="MAR, "&B1 -> MAR, FY24 | M2: ="Q3, "&B1 -> Q3, FY24 | N2: ="APR, "&B1 -> APR, FY24 | O2: ="MAY, "&B1 -> MAY, FY24 | P2: ="JUN, "&B1 -> JUN, FY24 | Q2: ="Q4, "&B1 -> Q4, FY24 | R2: ="Full Year, "&B1 -> Full Year, FY24 | S2: ="JUL, "&S1 -> JUL, FY25 | T2: ="AUG, "&S1 -> AUG, FY25 | U2: ="SEP, "&S1 -> SEP, FY25 | V2: ="Q1, "&S1 -> Q1, FY25 | W2: ="OCT, "&S1 -> OCT, FY25 | X2: ="NOV, "&S1 -> NOV, FY25 | Y2: ="DEC, "&S1 -> DEC, FY25 | Z2: ="Q2, "&S1 -> Q2, FY25 | AA2: ="JAN, "&S1 -> JAN, FY25 | AB2: ="FEB, "&S1 -> FEB, FY25 | AC2: ="MAR, "&S1 -> MAR, FY25 | AD2: ="Q3, "&S1 -> Q3, FY25 | AE2: ="APR, "&S1 -> APR, FY25 | AF2: ="MAY, "&S1 -> MAY, FY25 | AG2: ="JUN, "&S1 -> JUN, FY25 | AH2: ="Q4, "&S1 -> Q4, FY25 | AI2: ="Full Year, "&S1 -> Full Year, FY25
A3: Incidents | B3: =COUNTIFS('18-Month HS Incidents'!$AO:$AO,'HS FEED'!B$2) -> 0 | C3: =COUNTIFS('18-Month HS Incidents'!$AO:$AO,'HS FEED'!C$2) -> 0 | D3: =COUNTIFS('18-Month HS Incidents'!$AO:$AO,'HS FEED'!D$2) -> 0 | E3: =SUBTOTAL(9,B3:D3) -> 0 | F3: =COUNTIFS('18-Month HS Incidents'!$AO:$AO,'HS FEED'!F$2) -> 13 | G3: =COUNTIFS('18-Month HS Incidents'!$AO:$AO,'HS FEED'!G$2) -> 19 | H3: =COUNTIFS('18-Month HS Incidents'!$AO:$AO,'HS FEED'!H$2) -> 27 | I3: =SUBTOTAL(9,F3:H3) -> 59 | J3: =COUNTIFS('18-Month HS Incidents'!$AO:$AO,'HS FEED'!J$2) -> 17 | K3: =COUNTIFS('18-Month HS Incidents'!$AO:$AO,'HS FEED'!K$2) -> 20 | L3: =COUNTIFS('18-Month HS Incidents'!$AO:$AO,'HS FEED'!L$2) -> 17 | M3: =SUBTOTAL(9,J3:L3) -> 54 | N3: =COUNTIFS('18-Month HS Incidents'!$AO:$AO,'HS FEED'!N$2) -> 12 | O3: =COUNTIFS('18-Month HS Incidents'!$AO:$AO,'HS FEED'!O$2) -> 30 | P3: =COUNTIFS('18-Month HS Incidents'!$AO:$AO,'HS FEED'!P$2) -> 18 | Q3: =SUBTOTAL(9,N3:P3) -> 60 | R3: =SUBTOTAL(9,B3:Q3) -> 173 | S3: =COUNTIFS('18-Month HS Incidents'!$AO:$AO,'HS FEED'!S$2) -> 16 | T3: =COUNTIFS('18-Month HS Incidents'!$AO:$AO,'HS FEED'!T$2) -> 24 | U3: =COUNTIFS('18-Month HS Incidents'!$AO:$AO,'HS FEED'!U$2) -> 17 | V3: =SUBTOTAL(9,S3:U3) -> 57 | W3: =COUNTIFS('18-Month HS Incidents'!$AO:$AO,'HS FEED'!W$2) -> 16 | X3: =COUNTIFS('18-Month HS Incidents'!$AO:$AO,'HS FEED'!X$2) -> 18 | Y3: =COUNTIFS('18-Month HS Incidents'!$AO:$AO,'HS FEED'!Y$2) -> 17 | Z3: =SUBTOTAL(9,W3:Y3) -> 51 | AA3: =COUNTIFS('18-Month HS Incidents'!$AO:$AO,'HS FEED'!AA$2) -> 8 | AB3: =COUNTIFS('18-Month HS Incidents'!$AO:$AO,'HS FEED'!AB$2) -> 9 | AC3: =COUNTIFS('18-Month HS Incidents'!$AO:$AO,'HS FEED'!AC$2) -> 19 | AD3: =SUBTOTAL(9,AA3:AC3) -> 36 | AE3: =COUNTIFS('18-Month HS Incidents'!$AO:$AO,'HS FEED'!AE$2) -> 10 | AF3: =COUNTIFS('18-Month HS Incidents'!$AO:$AO,'HS FEED'!AF$2) -> 0 | AG3: =COUNTIFS('18-Month HS Incidents'!$AO:$AO,'HS FEED'!AG$2) -> 0 | AH3: =SUBTOTAL(9,AE3:AG3) -> 10 | AI3: =SUBTOTAL(9,S3:AH3) -> 154
A4: YTD Incident | B4: =SUBTOTAL(9,$B3:B3) -> 0 | C4: =SUBTOTAL(9,$B3:C3) -> 0 | D4: =SUBTOTAL(9,$B3:D3) -> 0 | E4: =SUBTOTAL(9,$B3:E3) -> 0 | F4: =SUBTOTAL(9,$B3:F3) -> 13 | G4: =SUBTOTAL(9,$B3:G3) -> 32 | H4: =SUBTOTAL(9,$B3:H3) -> 59 | I4: =SUBTOTAL(9,$B3:I3) -> 59 | ... R4: =SUBTOTAL(9,$B3:R3) -> 173 | S4: =SUBTOTAL(9,$S3:S3) -> 16 | T4: =SUBTOTAL(9,$S3:T3) -> 40 | U4: =SUBTOTAL(9,$S3:U3) -> 57 | V4: =SUBTOTAL(9,$S3:V3) -> 57 | W4: =SUBTOTAL(9,$S3:W3) -> 73 | X4: =SUBTOTAL(9,$S3:X3) -> 91 | Y4: =SUBTOTAL(9,$S3:Y3) -> 108 | Z4: =SUBTOTAL(9,$S3:Z3) -> 108 | ... AI4: =SUBTOTAL(9,$S3:AI3) -> 154
A6: Claims
A7: Claim | B7: =COUNTIFS('18-Month HS Incidents'!$AO:$AO,'HS FEED'!B$2,'18-Month HS Incidents'!$AR:$AR,"Claim") -> 0 | C7: =COUNTIFS('18-Month HS Incidents'!$AO:$AO,'HS FEED'!C$2,'18-Month HS Incidents'!$AR:$AR,"Claim") -> 0 | D7: =COUNTIFS('18-Month HS Incidents'!$AO:$AO,'HS FEED'!D$2,'18-Month HS Incidents'!$AR:$AR,"Claim") -> 0 | E7: =SUBTOTAL(9,B7:D7) -> 0 | F7: =COUNTIFS('18-Month HS Incidents'!$AO:$AO,'HS FEED'!F$2,'18-Month HS Incidents'!$AR:$AR,"Claim") -> 3 | G7: =COUNTIFS('18-Month HS Incidents'!$AO:$AO,'HS FEED'!G$2,'18-Month HS Incidents'!$AR:$AR,"Claim") -> 2 | H7: =COUNTIFS('18-Month HS Incidents'!$AO:$AO,'HS FEED'!H$2,'18-Month HS Incidents'!$AR:$AR,"Claim") -> 4 | I7: =SUBTOTAL(9,F7:H7) -> 9 | J7: =COUNTIFS('18-Month HS Incidents'!$AO:$AO,'HS FEED'!J$2,'18-Month HS Incidents'!$AR:$AR,"Claim") -> 1 | K7: =COUNTIFS('18-Month HS Incidents'!$AO:$AO,'HS FEED'!K$2,'18-Month HS Incidents'!$AR:$AR,"Claim") -> 3 | L7: =COUNTIFS('18-Month HS Incidents'!$AO:$AO,'HS FEED'!L$2,'18-Month HS Incidents'!$AR:$AR,"Claim") -> 2 | M7: =SUBTOTAL(9,J7:L7) -> 6 | N7: =COUNTIFS('18-Month HS Incidents'!$AO:$AO,'HS FEED'!N$2,'18-Month HS Incidents'!$AR:$AR,"Claim") -> 1 | O7: =COUNTIFS('18-Month HS Incidents'!$AO:$AO,'HS FEED'!O$2,'18-Month HS Incidents'!$AR:$AR,"Claim") -> 6 | P7: =COUNTIFS('18-Month HS Incidents'!$AO:$AO,'HS FEED'!P$2,'18-Month HS Incidents'!$AR:$AR,"Claim") -> 4 | Q7: =SUBTOTAL(9,N7:P7) -> 11 | R7: =SUBTOTAL(9,B7:Q7) -> 26 | S7: =COUNTIFS('18-Month HS Incidents'!$AO:$AO,'HS FEED'!S$2,'18-Month HS Incidents'!$AR:$AR,"Claim") -> 3 | T7: =COUNTIFS('18-Month HS Incidents'!$AO:$AO,'HS FEED'!T$2,'18-Month HS Incidents'!$AR:$AR,"Claim") -> 6 | U7: =COUNTIFS('18-Month HS Incidents'!$AO:$AO,'HS FEED'!U$2,'18-Month HS Incidents'!$AR:$AR,"Claim") -> 3 | V7: =SUBTOTAL(9,S7:U7) -> 12 | W7: =COUNTIFS('18-Month HS Incidents'!$AO:$AO,'HS FEED'!W$2,'18-Month HS Incidents'!$AR:$AR,"Claim") -> 3 | X7: =COUNTIFS('18-Month HS Incidents'!$AO:$AO,'HS FEED'!X$2,'18-Month HS Incidents'!$AR:$AR,"Claim") -> 5 | Y7: =COUNTIFS('18-Month HS Incidents'!$AO:$AO,'HS FEED'!Y$2,'18-Month HS Incidents'!$AR:$AR,"Claim") -> 3 | Z7: =SUBTOTAL(9,W7:Y7) -> 11 | AA7: =COUNTIFS('18-Month HS Incidents'!$AO:$AO,'HS FEED'!AA$2,'18-Month HS Incidents'!$AR:$AR,"Claim") -> 1 | AB7: =COUNTIFS('18-Month HS Incidents'!$AO:$AO,'HS FEED'!AB$2,'18-Month HS Incidents'!$AR:$AR,"Claim") -> 2 | AC7: =COUNTIFS('18-Month HS Incidents'!$AO:$AO,'HS FEED'!AC$2,'18-Month HS Incidents'!$AR:$AR,"Claim") -> 3 | AD7: =SUBTOTAL(9,AA7:AC7) -> 6 | AE7: =COUNTIFS('18-Month HS Incidents'!$AO:$AO,'HS FEED'!AE$2,'18-Month HS Incidents'!$AR:$AR,"Claim") -> 2 | AF7: =COUNTIFS('18-Month HS Incidents'!$AO:$AO,'HS FEED'!AF$2,'18-Month HS Incidents'!$AR:$AR,"Claim") -> 0 | AG7: =COUNTIFS('18-Month HS Incidents'!$AO:$AO,'HS FEED'!AG$2,'18-Month HS Incidents'!$AR:$AR,"Claim") -> 0 | AH7: =SUBTOTAL(9,AE7:AG7) -> 2 | AI7: =SUBTOTAL(9,S7:AH7) -> 31
A8: YTD Claim | B8: =SUBTOTAL(9,$B7:B7) -> 0 | C8: =SUBTOTAL(9,$B7:C7) -> 0 | D8: =SUBTOTAL(9,$B7:D7) -> 0 | E8: =SUBTOTAL(9,$B7:E7) -> 0 | F8: =SUBTOTAL(9,$B7:F7) -> 3 | G8: =SUBTOTAL(9,$B7:G7) -> 5 | H8: =SUBTOTAL(9,$B7:H7) -> 9 | I8: =SUBTOTAL(9,$B7:I7) -> 9 | ... R8: =SUBTOTAL(9,$B7:R7) -> 26 | S8: =SUBTOTAL(9,$S7:S7) -> 3 | T8: =SUBTOTAL(9,$S7:T7) -> 9 | U8: =SUBTOTAL(9,$S7:U7) -> 12 | V8: =SUBTOTAL(9,$S7:V7) -> 12 | W8: =SUBTOTAL(9,$S7:W7) -> 15 | X8: =SUBTOTAL(9,$S7:X7) -> 20 | Y8: =SUBTOTAL(9,$S7:Y7) -> 23 | Z8: =SUBTOTAL(9,$S7:Z7) -> 23 | ... AI8: =SUBTOTAL(9,$S7:AI7) -> 31
A11: NSW | AK11: Less Than 20 Years | AL11: 20-24 Years | AM11: 25-34 Years | AN11: 35-44 Years | AO11: 45-54 Years | AP11: More Than 55 Years
A12: Incidents | B12: =COUNTIFS('18-Month HS Incidents'!$AO:$AO,'HS FEED'!B$2,'18-Month HS Incidents'!$AW:$AW,'HS FEED'!$A$11) -> 0 | C12: =COUNTIFS('18-Month HS Incidents'!$AO:$AO,'HS FEED'!C$2,'18-Month HS Incidents'!$AW:$AW,'HS FEED'!$A$11) -> 0 | D12: =COUNTIFS('18-Month HS Incidents'!$AO:$AO,'HS FEED'!D$2,'18-Month HS Incidents'!$AW:$AW,'HS FEED'!$A$11) -> 0 | E12: =SUBTOTAL(9,B12:D12) -> 0 | F12: =COUNTIFS('18-Month HS Incidents'!$AO:$AO,'HS FEED'!F$2,'18-Month HS Incidents'!$AW:$AW,'HS FEED'!$A$11) -> 1 | G12: =COUNTIFS('18-Month HS Incidents'!$AO:$AO,'HS FEED'!G$2,'18-Month HS Incidents'!$AW:$AW,'HS FEED'!$A$11) -> 2 | H12: =COUNTIFS('18-Month HS Incidents'!$AO:$AO,'HS FEED'!H$2,'18-Month HS Incidents'!$AW:$AW,'HS FEED'!$A$11) -> 4 | I12: =SUBTOTAL(9,F12:H12) -> 7 | J12: =COUNTIFS('18-Month HS Incidents'!$AO:$AO,'HS FEED'!J$2,'18-Month HS Incidents'!$AW:$AW,'HS FEED'!$A$11) -> 2 | K12: =COUNTIFS('18-Month HS Incidents'!$AO:$AO,'HS FEED'!K$2,'18-Month HS Incidents'!$AW:$AW,'HS FEED'!$A$11) -> 4 | L12: =COUNTIFS('18-Month HS Incidents'!$AO:$AO,'HS FEED'!L$2,'18-Month HS Incidents'!$AW:$AW,'HS FEED'!$A$11) -> 5 | M12: =SUBTOTAL(9,J12:L12) -> 11 | N12: =COUNTIFS('18-Month HS Incidents'!$AO:$AO,'HS FEED'!N$2,'18-Month HS Incidents'!$AW:$AW,'HS FEED'!$A$11) -> 1 | O12: =COUNTIFS('18-Month HS Incidents'!$AO:$AO,'HS FEED'!O$2,'18-Month HS Incidents'!$AW:$AW,'HS FEED'!$A$11) -> 4 | P12: =COUNTIFS('18-Month HS Incidents'!$AO:$AO,'HS FEED'!P$2,'18-Month HS Incidents'!$AW:$AW,'HS FEED'!$A$11) -> 0 | Q12: =SUBTOTAL(9,N12:P12) -> 5 | R12: =SUBTOTAL(9,B12:Q12) -> 23 | S12: =COUNTIFS('18-Month HS Incidents'!$AO:$AO,'HS FEED'!S$2,'18-Month HS Incidents'!$AW:$AW,'HS FEED'!$A$11) -> 2 | T12: =COUNTIFS('18-Month HS Incidents'!$AO:$AO,'HS FEED'!T$2,'18-Month HS Incidents'!$AW:$AW,'HS FEED'!$A$11) -> 2 | U12: =COUNTIFS('18-Month HS Incidents'!$AO:$AO,'HS FEED'!U$2,'18-Month HS Incidents'!$AW:$AW,'HS FEED'!$A$11) -> 4 | V12: =SUBTOTAL(9,S12:U12) -> 8 | W12: =COUNTIFS('18-Month HS Incidents'!$AO:$AO,'HS FEED'!W$2,'18-Month HS Incidents'!$AW:$AW,'HS FEED'!$A$11) -> 3 | X12: =COUNTIFS('18-Month HS Incidents'!$AO:$AO,'HS FEED'!X$2,'18-Month HS Incidents'!$AW:$AW,'HS FEED'!$A$11) -> 3 | Y12: =COUNTIFS('18-Month HS Incidents'!$AO:$AO,'HS FEED'!Y$2,'18-Month HS Incidents'!$AW:$AW,'HS FEED'!$A$11) -> 2 | Z12: =SUBTOTAL(9,W12:Y12) -> 8 | AA12: =COUNTIFS('18-Month HS Incidents'!$AO:$AO,'HS FEED'!AA$2,'18-Month HS Incidents'!$AW:$AW,'HS FEED'!$A$11) -> 0 | AB12: =COUNTIFS('18-Month HS Incidents'!$AO:$AO,'HS FEED'!AB$2,'18-Month HS Incidents'!$AW:$AW,'HS FEED'!$A$11) -> 2 | AC12: =COUNTIFS('18-Month HS Incidents'!$AO:$AO,'HS FEED'!AC$2,'18-Month HS Incidents'!$AW:$AW,'HS FEED'!$A$11) -> 0 | AD12: =SUBTOTAL(9,AA12:AC12) -> 2 | AE12: =COUNTIFS('18-Month HS Incidents'!$AO:$AO,'HS FEED'!AE$2,'18-Month HS Incidents'!$AW:$AW,'HS FEED'!$A$11) -> 2 | AF12: =COUNTIFS('18-Month HS Incidents'!$AO:$AO,'HS FEED'!AF$2,'18-Month HS Incidents'!$AW:$AW,'HS FEED'!$A$11) -> 0 | AG12: =COUNTIFS('18-Month HS Incidents'!$AO:$AO,'HS FEED'!AG$2,'18-Month HS Incidents'!$AW:$AW,'HS FEED'!$A$11) -> 0 | AH12: =SUBTOTAL(9,AE12:AG12) -> 2 | AI12: =SUBTOTAL(9,S12:AH12) -> 20 | AJ12: Incidents | AK12: 21 | AL12: 49 | AM12: 63 | AN12: 44 | AO12: 66 | AP12: 84
A13: Claims | B13: =COUNTIFS('18-Month HS Incidents'!$AO:$AO,'HS FEED'!B$2,'18-Month HS Incidents'!$AR:$AR,"Claim",'18-Month HS Incidents'!$AW:$AW,'HS FEED'!$A$11) -> 0 | C13: =COUNTIFS('18-Month HS Incidents'!$AO:$AO,'HS FEED'!C$2,'18-Month HS Incidents'!$AR:$AR,"Claim",'18-Month HS Incidents'!$AW:$AW,'HS FEED'!$A$11) -> 0 | D13: =COUNTIFS('18-Month HS Incidents'!$AO:$AO,'HS FEED'!D$2,'18-Month HS Incidents'!$AR:$AR,"Claim",'18-Month HS Incidents'!$AW:$AW,'HS FEED'!$A$11) -> 0 | E13: =SUBTOTAL(9,B13:D13) -> 0 | F13: =COUNTIFS('18-Month HS Incidents'!$AO:$AO,'HS FEED'!F$2,'18-Month HS Incidents'!$AR:$AR,"Claim",'18-Month HS Incidents'!$AW:$AW,'HS FEED'!$A$11) -> 0 | G13: =COUNTIFS('18-Month HS Incidents'!$AO:$AO,'HS FEED'!G$2,'18-Month HS Incidents'!$AR:$AR,"Claim",'18-Month HS Incidents'!$AW:$AW,'HS FEED'!$A$11) -> 0 | H13: =COUNTIFS('18-Month HS Incidents'!$AO:$AO,'HS FEED'!H$2,'18-Month HS Incidents'!$AR:$AR,"Claim",'18-Month HS Incidents'!$AW:$AW,'HS FEED'!$A$11) -> 0 | I13: =SUBTOTAL(9,F13:H13) -> 0 | J13: =COUNTIFS('18-Month HS Incidents'!$AO:$AO,'HS FEED'!J$2,'18-Month HS Incidents'!$AR:$AR,"Claim",'18-Month HS Incidents'!$AW:$AW,'HS FEED'!$A$11) -> 0 | K13: =COUNTIFS('18-Month HS Incidents'!$AO:$AO,'HS FEED'!K$2,'18-Month HS Incidents'!$AR:$AR,"Claim",'18-Month HS Incidents'!$AW:$AW,'HS FEED'!$A$11) -> 1 | L13: =COUNTIFS('18-Month HS Incidents'!$AO:$AO,'HS FEED'!L$2,'18-Month HS Incidents'!$AR:$AR,"Claim",'18-Month HS Incidents'!$AW:$AW,'HS FEED'!$A$11) -> 0 | M13: =SUBTOTAL(9,J13:L13) -> 1 | N13: =COUNTIFS('18-Month HS Incidents'!$AO:$AO,'HS FEED'!N$2,'18-Month HS Incidents'!$AR:$AR,"Claim",'18-Month HS Incidents'!$AW:$AW,'HS FEED'!$A$11) -> 0 | O13: =COUNTIFS('18-Month HS Incidents'!$AO:$AO,'HS FEED'!O$2,'18-Month HS Incidents'!$AR:$AR,"Claim",'18-Month HS Incidents'!$AW:$AW,'HS FEED'!$A$11) -> 0 | P13: =COUNTIFS('18-Month HS Incidents'!$AO:$AO,'HS FEED'!P$2,'18-Month HS Incidents'!$AR:$AR,"Claim",'18-Month HS Incidents'!$AW:$AW,'HS FEED'!$A$11) -> 0 | Q13: =SUBTOTAL(9,N13:P13) -> 0 | R13: =SUBTOTAL(9,B13:Q13) -> 1 | S13: =COUNTIFS('18-Month HS Incidents'!$AO:$AO,'HS FEED'!S$2,'18-Month HS Incidents'!$AR:$AR,"Claim",'18-Month HS Incidents'!$AW:$AW,'HS FEED'!$A$11) -> 1 | T13: =COUNTIFS('18-Month HS Incidents'!$AO:$AO,'HS FEED'!T$2,'18-Month HS Incidents'!$AR:$AR,"Claim",'18-Month HS Incidents'!$AW:$AW,'HS FEED'!$A$11) -> 0 | U13: =COUNTIFS('18-Month HS Incidents'!$AO:$AO,'HS FEED'!U$2,'18-Month HS Incidents'!$AR:$AR,"Claim",'18-Month HS Incidents'!$AW:$AW,'HS FEED'!$A$11) -> 1 | V13: =SUBTOTAL(9,S13:U13) -> 2 | W13: =COUNTIFS('18-Month HS Incidents'!$AO:$AO,'HS FEED'!W$2,'18-Month HS Incidents'!$AR:$AR,"Claim",'18-Month HS Incidents'!$AW:$AW,'HS FEED'!$A$11) -> 1 | X13: =COUNTIFS('18-Month HS Incidents'!$AO:$AO,'HS FEED'!X$2,'18-Month HS Incidents'!$AR:$AR,"Claim",'18-Month HS Incidents'!$AW:$AW,'HS FEED'!$A$11) -> 1 | Y13: =COUNTIFS('18-Month HS Incidents'!$AO:$AO,'HS FEED'!Y$2,'18-Month HS Incidents'!$AR:$AR,"Claim",'18-Month HS Incidents'!$AW:$AW,'HS FEED'!$A$11) -> 0 | Z13: =SUBTOTAL(9,W13:Y13) -> 2 | AA13: =COUNTIFS('18-Month HS Incidents'!$AO:$AO,'HS FEED'!AA$2,'18-Month HS Incidents'!$AR:$AR,"Claim",'18-Month HS Incidents'!$AW:$AW,'HS FEED'!$A$11) -> 0 | AB13: =COUNTIFS('18-Month HS Incidents'!$AO:$AO,'HS FEED'!AB$2,'18-Month HS Incidents'!$AR:$AR,"Claim",'18-Month HS Incidents'!$AW:$AW,'HS FEED'!$A$11) -> 0 | AC13: =COUNTIFS('18-Month HS Incidents'!$AO:$AO,'HS FEED'!AC$2,'18-Month HS Incidents'!$AR:$AR,"Claim",'18-Month HS Incidents'!$AW:$AW,'HS FEED'!$A$11) -> 0 | AD13: =SUBTOTAL(9,AA13:AC13) -> 0 | AE13: =COUNTIFS('18-Month HS Incidents'!$AO:$AO,'HS FEED'!AE$2,'18-Month HS Incidents'!$AR:$AR,"Claim",'18-Month HS Incidents'!$AW:$AW,'HS FEED'!$A$11) -> 1 | AF13: =COUNTIFS('18-Month HS Incidents'!$AO:$AO,'HS FEED'!AF$2,'18-Month HS Incidents'!$AR:$AR,"Claim",'18-Month HS Incidents'!$AW:$AW,'HS FEED'!$A$11) -> 0 | AG13: =COUNTIFS('18-Month HS Incidents'!$AO:$AO,'HS FEED'!AG$2,'18-Month HS Incidents'!$AR:$AR,"Claim",'18-Month HS Incidents'!$AW:$AW,'HS FEED'!$A$11) -> 0 | AH13: =SUBTOTAL(9,AE13:AG13) -> 1 | AI13: =SUBTOTAL(9,S13:AH13) -> 5 | AJ13: Claims | AK13: 0 | AL13: 10 | AM13: 11 | AN13: 11 | AO13: 8 | AP13: 17
AK18: Under 1 Year | AL18: 1-5 Years | AM18: 6-10 Years | AN18: 11-15 Years | AO18: 16-20 Years | AP18: 21-25 Years | AQ18: 26-30 Years | AR18: More Than 30 Years
AJ19: Incidents | AK19: 62 | AL19: 165 | AM19: 47 | AN19: 17 | AO19: 17 | AP19: 7 | AQ19: 7 | AR19: 5
AJ20: Claims | AK20: 8 | AL20: 28 | AM20: 9 | AN20: 8 | AO20: 3 | AP20: 0 | AQ20: 1 | AR20: 0
AK23: 1 Year | AL23: 2 Years | AM23: 3 Years | AN23: 4 Years | AO23: 5 Years
AJ24: Incidents | AK24: 72 | AL24: 38 | AM24: 23 | AN24: 20 | AO24: 12
AJ25: Claims | AK25: 12 | AL25: 8 | AM25: 3 | AN25: 3 | AO25: 2

Sheet Group FEED
A1: Group | B1: FY24 | S1: FY25
A2: Incidents | B2: ="JUL, "&B1 -> JUL, FY24 | C2: ="AUG, "&B1 -> AUG, FY24 | D2: ="SEP, "&B1 -> SEP, FY24 | E2: ="Q1, "&B1 -> Q1, FY24 | F2: ="OCT, "&B1 -> OCT, FY24 | G2: ="NOV, "&B1 -> NOV, FY24 | H2: ="DEC, "&B1 -> DEC, FY24 | I2: ="Q2, "&B1 -> Q2, FY24 | J2: ="JAN, "&B1 -> JAN, FY24 | K2: ="FEB, "&B1 -> FEB, FY24 | L2: ="MAR, "&B1 -> MAR, FY24 | M2: ="Q3, "&B1 -> Q3, FY24 | N2: ="APR, "&B1 -> APR, FY24 | O2: ="MAY, "&B1 -> MAY, FY24 | P2: ="JUN, "&B1 -> JUN, FY24 | Q2: ="Q4, "&B1 -> Q4, FY24 | R2: ="Full Year, "&B1 -> Full Year, FY24 | S2: ="JUL, "&S1 -> JUL, FY25 | T2: ="AUG, "&S1 -> AUG, FY25 | U2: ="SEP, "&S1 -> SEP, FY25 | V2: ="Q1, "&S1 -> Q1, FY25 | W2: ="OCT, "&S1 -> OCT, FY25 | X2: ="NOV, "&S1 -> NOV, FY25 | Y2: ="DEC, "&S1 -> DEC, FY25 | Z2: ="Q2, "&S1 -> Q2, FY25 | AA2: ="JAN, "&S1 -> JAN, FY25 | AB2: ="FEB, "&S1 -> FEB, FY25 | AC2: ="MAR, "&S1 -> MAR, FY25 | AD2: ="Q3, "&S1 -> Q3, FY25 | AE2: ="APR, "&S1 -> APR, FY25 | AF2: ="MAY, "&S1 -> MAY, FY25 | AG2: ="JUN, "&S1 -> JUN, FY25 | AH2: ="Q4, "&S1 -> Q4, FY25 | AI2: ="Full Year, "&S1 -> Full Year, FY25
A3: Incidents | B3: =COUNTIF('INC DATA DUMP - FY23+'!$AA:$AA,'Group FEED'!B$2) -> 75 | C3: =COUNTIF('INC DATA DUMP - FY23+'!$AA:$AA,'Group FEED'!C$2) -> 107 | D3: =COUNTIF('INC DATA DUMP - FY23+'!$AA:$AA,'Group FEED'!D$2) -> 79 | E3: =SUBTOTAL(9,B3:D3) -> 261 | F3: =COUNTIF('INC DATA DUMP - FY23+'!$AA:$AA,'Group FEED'!F$2) -> 89 | G3: =COUNTIF('INC DATA DUMP - FY23+'!$AA:$AA,'Group FEED'!G$2) -> 107 | H3: =COUNTIF('INC DATA DUMP - FY23+'!$AA:$AA,'Group FEED'!H$2) -> 109 | I3: =SUBTOTAL(9,F3:H3) -> 305 | J3: =COUNTIF('INC DATA DUMP - FY23+'!$AA:$AA,'Group FEED'!J$2) -> 80 | K3: =COUNTIF('INC DATA DUMP - FY23+'!$AA:$AA,'Group FEED'!K$2) -> 93 | L3: =COUNTIF('INC DATA DUMP - FY23+'!$AA:$AA,'Group FEED'!L$2) -> 94 | M3: =SUBTOTAL(9,J3:L3) -> 267 | N3: =COUNTIF('INC DATA DUMP - FY23+'!$AA:$AA,'Group FEED'!N$2) -> 72 | O3: =COUNTIF('INC DATA DUMP - FY23+'!$AA:$AA,'Group FEED'!O$2) -> 114 | P3: =COUNTIF('INC DATA DUMP - FY23+'!$AA:$AA,'Group FEED'!P$2) -> 85 | Q3: =SUBTOTAL(9,N3:P3) -> 271 | R3: =SUBTOTAL(9,B3:Q3) -> 1104 | S3: =COUNTIF('INC DATA DUMP - FY23+'!$AA:$AA,'Group FEED'!S$2) -> 73 | T3: =COUNTIF('INC DATA DUMP - FY23+'!$AA:$AA,'Group FEED'!T$2) -> 103 | U3: =COUNTIF('INC DATA DUMP - FY23+'!$AA:$AA,'Group FEED'!U$2) -> 66 | V3: =SUBTOTAL(9,S3:U3) -> 242 | W3: =COUNTIF('INC DATA DUMP - FY23+'!$AA:$AA,'Group FEED'!W$2) -> 83 | X3: =COUNTIF('INC DATA DUMP - FY23+'!$AA:$AA,'Group FEED'!X$2) -> 101 | Y3: =COUNTIF('INC DATA DUMP - FY23+'!$AA:$AA,'Group FEED'!Y$2) -> 81 | Z3: =SUBTOTAL(9,W3:Y3) -> 265 | AA3: =COUNTIF('INC DATA DUMP - FY23+'!$AA:$AA,'Group FEED'!AA$2) -> 66 | AB3: =COUNTIF('INC DATA DUMP - FY23+'!$AA:$AA,'Group FEED'!AB$2) -> 85 | AC3: =COUNTIF('INC DATA DUMP - FY23+'!$AA:$AA,'Group FEED'!AC$2) -> 81 | AD3: =SUBTOTAL(9,AA3:AC3) -> 232 | AE3: =COUNTIF('INC DATA DUMP - FY23+'!$AA:$AA,'Group FEED'!AE$2) -> 65 | AF3: =COUNTIF('INC DATA DUMP - FY23+'!$AA:$AA,'Group FEED'!AF$2) -> 95 | AG3: =COUNTIF('INC DATA DUMP - FY23+'!$AA:$AA,'Group FEED'!AG$2) -> 0 | AH3: =SUBTOTAL(9,AE3:AG3) -> 160 | AI3: =SUBTOTAL(9,S3:AH3) -> 899
A4: YTD Incidents | B4: =SUBTOTAL(9,$B3:B3) -> 75 | C4: =SUBTOTAL(9,$B3:C3) -> 182 | D4: =SUBTOTAL(9,$B3:D3) -> 261 | E4: =SUBTOTAL(9,$B3:E3) -> 261 | F4: =SUBTOTAL(9,$B3:F3) -> 350 | G4: =SUBTOTAL(9,$B3:G3) -> 457 | H4: =SUBTOTAL(9,$B3:H3) -> 566 | I4: =SUBTOTAL(9,$B3:I3) -> 566 | ... R4: =SUBTOTAL(9,$B3:R3) -> 1104 | S4: =SUBTOTAL(9,$S3:S3) -> 73 | T4: =SUBTOTAL(9,$S3:T3) -> 176 | U4: =SUBTOTAL(9,$S3:U3) -> 242 | V4: =SUBTOTAL(9,$S3:V3) -> 242 | W4: =SUBTOTAL(9,$S3:W3) -> 325 | X4: =SUBTOTAL(9,$S3:X3) -> 426 | Y4: =SUBTOTAL(9,$S3:Y3) -> 507 | Z4: =SUBTOTAL(9,$S3:Z3) -> 507 | ... AI4: =SUBTOTAL(9,$S3:AI3) -> 899
A6: Claims
A7: Claims | B7: =COUNTIFS('INC DATA DUMP - FY23+'!$AD:$AD,"Claim",'INC DATA DUMP - FY23+'!$AA:$AA,'Group FEED'!B$2) -> 7 | C7: =COUNTIFS('INC DATA DUMP - FY23+'!$AD:$AD,"Claim",'INC DATA DUMP - FY23+'!$AA:$AA,'Group FEED'!C$2) -> 18 | D7: =COUNTIFS('INC DATA DUMP - FY23+'!$AD:$AD,"Claim",'INC DATA DUMP - FY23+'!$AA:$AA,'Group FEED'!D$2) -> 11 | E7: =SUBTOTAL(9,B7:D7) -> 36 | F7: =COUNTIFS('INC DATA DUMP - FY23+'!$AD:$AD,"Claim",'INC DATA DUMP - FY23+'!$AA:$AA,'Group FEED'!F$2) -> 12 | G7: =COUNTIFS('INC DATA DUMP - FY23+'!$AD:$AD,"Claim",'INC DATA DUMP - FY23+'!$AA:$AA,'Group FEED'!G$2) -> 14 | H7: =COUNTIFS('INC DATA DUMP - FY23+'!$AD:$AD,"Claim",'INC DATA DUMP - FY23+'!$AA:$AA,'Group FEED'!H$2) -> 9 | I7: =SUBTOTAL(9,F7:H7) -> 35 | J7: =COUNTIFS('INC DATA DUMP - FY23+'!$AD:$AD,"Claim",'INC DATA DUMP - FY23+'!$AA:$AA,'Group FEED'!J$2) -> 11 | K7: =COUNTIFS('INC DATA DUMP - FY23+'!$AD:$AD,"Claim",'INC DATA DUMP - FY23+'!$AA:$AA,'Group FEED'!K$2) -> 11 | L7: =COUNTIFS('INC DATA DUMP - FY23+'!$AD:$AD,"Claim",'INC DATA DUMP - FY23+'!$AA:$AA,'Group FEED'!L$2) -> 15 | M7: =SUBTOTAL(9,J7:L7) -> 37 | N7: =COUNTIFS('INC DATA DUMP - FY23+'!$AD:$AD,"Claim",'INC DATA DUMP - FY23+'!$AA:$AA,'Group FEED'!N$2) -> 7 | O7: =COUNTIFS('INC DATA DUMP - FY23+'!$AD:$AD,"Claim",'INC DATA DUMP - FY23+'!$AA:$AA,'Group FEED'!O$2) -> 19 | P7: =COUNTIFS('INC DATA DUMP - FY23+'!$AD:$AD,"Claim",'INC DATA DUMP - FY23+'!$AA:$AA,'Group FEED'!P$2) -> 16 | Q7: =SUBTOTAL(9,N7:P7) -> 42 | R7: =SUBTOTAL(9,B7:Q7) -> 150 | S7: =COUNTIFS('INC DATA DUMP - FY23+'!$AD:$AD,"Claim",'INC DATA DUMP - FY23+'!$AA:$AA,'Group FEED'!S$2) -> 14 | T7: =COUNTIFS('INC DATA DUMP - FY23+'!$AD:$AD,"Claim",'INC DATA DUMP - FY23+'!$AA:$AA,'Group FEED'!T$2) -> 29 | U7: =COUNTIFS('INC DATA DUMP - FY23+'!$AD:$AD,"Claim",'INC DATA DUMP - FY23+'!$AA:$AA,'Group FEED'!U$2) -> 16 | V7: =SUBTOTAL(9,S7:U7) -> 59 | W7: =COUNTIFS('INC DATA DUMP - FY23+'!$AD:$AD,"Claim",'INC DATA DUMP - FY23+'!$AA:$AA,'Group FEED'!W$2) -> 19 | X7: =COUNTIFS('INC DATA DUMP - FY23+'!$AD:$AD,"Claim",'INC DATA DUMP - FY23+'!$AA:$AA,'Group FEED'!X$2) -> 22 | Y7: =COUNTIFS('INC DATA DUMP - FY23+'!$AD:$AD,"Claim",'INC DATA DUMP - FY23+'!$AA:$AA,'Group FEED'!Y$2) -> 10 | Z7: =SUBTOTAL(9,W7:Y7) -> 51 | AA7: =COUNTIFS('INC DATA DUMP - FY23+'!$AD:$AD,"Claim",'INC DATA DUMP - FY23+'!$AA:$AA,'Group FEED'!AA$2) -> 13 | AB7: =COUNTIFS('INC DATA DUMP - FY23+'!$AD:$AD,"Claim",'INC DATA DUMP - FY23+'!$AA:$AA,'Group FEED'!AB$2) -> 13 | AC7: =COUNTIFS('INC DATA DUMP - FY23+'!$AD:$AD,"Claim",'INC DATA DUMP - FY23+'!$AA:$AA,'Group FEED'!AC$2) -> 11 | AD7: =SUBTOTAL(9,AA7:AC7) -> 37 | AE7: =COUNTIFS('INC DATA DUMP - FY23+'!$AD:$AD,"Claim",'INC DATA DUMP - FY23+'!$AA:$AA,'Group FEED'!AE$2) -> 12 | AF7: =COUNTIFS('INC DATA DUMP - FY23+'!$AD:$AD,"Claim",'INC DATA DUMP - FY23+'!$AA:$AA,'Group FEED'!AF$2) -> 8 | AG7: =COUNTIFS('INC DATA DUMP - FY23+'!$AD:$AD,"Claim",'INC DATA DUMP - FY23+'!$AA:$AA,'Group FEED'!AG$2) -> 0 | AH7: =SUBTOTAL(9,AE7:AG7) -> 20 | AI7: =SUBTOTAL(9,S7:AH7) -> 167
A8: YTD Claims | B8: =SUBTOTAL(9,$B7:B7) -> 7 | C8: =SUBTOTAL(9,$B7:C7) -> 25 | D8: =SUBTOTAL(9,$B7:D7) -> 36 | E8: =SUBTOTAL(9,$B7:E7) -> 36 | F8: =SUBTOTAL(9,$B7:F7) -> 48 | G8: =SUBTOTAL(9,$B7:G7) -> 62 | H8: =SUBTOTAL(9,$B7:H7) -> 71 | I8: =SUBTOTAL(9,$B7:I7) -> 71 | ... R8: =SUBTOTAL(9,$B7:R7) -> 150 | S8: =SUBTOTAL(9,$S7:S7) -> 14 | T8: =SUBTOTAL(9,$S7:T7) -> 43 | U8: =SUBTOTAL(9,$S7:U7) -> 59 | V8: =SUBTOTAL(9,$S7:V7) -> 59 | W8: =SUBTOTAL(9,$S7:W7) -> 78 | X8: =SUBTOTAL(9,$S7:X7) -> 100 | Y8: =SUBTOTAL(9,$S7:Y7) -> 110 | Z8: =SUBTOTAL(9,$S7:Z7) -> 110 | ... AI8: =SUBTOTAL(9,$S7:AI7) -> 167

Sheet INC DATA DUMP - FY23+
A1: SolvInjury ID | B1: Claim Number | C1: Mental Injury | D1: Employee ID | E1: Name | F1: Date of Injury | G1: Time of Injury | H1: Policy | I1: Site | J1: Name | K1: Injury Description | L1: Incident Description | M1: Injury Type | N1: Liability Status | O1: Current Capacity | P1: Open/Closed | Q1: Days Lost | R1: Worksafe Notified | S1: Injury Outcome | T1: Nature of Injury | U1: Bodily Location | V1: Mechanism | W1: Sub Mechanism | X1: Agency | Y1: Equipment | Z1: Closure Rate | AA1: Fiscal Month | AB1: Fiscal Quarter | AC1: Outcome Code | AD1: Claim | AE1: Claim Status | AF1: MOI | AG1: Agency | AH1: Company on Policy | AI1: State | AJ1: Class 3 | AK1: Company | AL1: Region | AM1: Grouping Level 1 | AN1: Grouping Level 2
A2: SRG-INJ-3692 | C2: No | D2: AU239233 | E2: EDWARDS, JODY | F2: 45809 | G2: 0.45486111 | H2: Spotlight NSW | I2: S030 | J2: Birkenhead Point | K2: top of head | L2: Jody was putting back outdoor blinds when the top bar, which had not been properly installed, dislodged and fell on her head. She hadnâ€™t noticed it had hit the bar while lifting the blind. This has been an ongoing issue. A customer heard the bar fall and checked Jodyâ€™s head for any cuts or bleeding. | M2: Injury | O2: No Assessment | P2: Open | Q2: 0 | R2: FALSE | S2: First Aid Injury | T2: Contusion, bruising and superficial crushing | U2: Head - unspecified locations | V2: Being Hit By Moving Objects | W2: Being hit by falling objects | X2: Human agencies | Y2: R-Bar | Z2: 0 | AA2: MAY, FY25 | AB2: Q4, FY25 | AC2: FAIs | AF2: Being Hit By Moving Objects | AG2: Human agencies | AH2: Spotlight | AI2: NSW | AJ2: Store | AK2: Spotlight AU | AL2: NSW Central | AM2: Spotlight AU | AN2: Spotlight AU - NSW Central
A3: SRG-INJ-3695 | C3: No | D3: AU334785 | E3: GORDON, TAMMEE LEE | F3: 45809 | G3: 0.42361111 | H3: Anaconda NSW | I3: A061 | J3: Marsden Park | K3: Left foot, big toe | L3: Tamme was serving customer with the ammunition boxes large maxxtrax recovery boards to slip off the shelf onto her toe Tammee, she visited doctor they dressed the wound on left toe and suggested an X-Ray | M3: Injury | O3: No Assessment | P3: Open | Q3: 0 | R3: FALSE | S3: Lost Time Injury | T3: Laceration or open wound not involving traumatic amputation | U3: Foot and toes | V3: Being Hit By Moving Objects | W3: Being hit by falling objects | X3: Human agencies | Y3: Boxes | Z3: 0 | AA3: MAY, FY25 | AB3: Q4, FY25 | AC3: LTIs | AF3: Being Hit By Moving Objects | AG3: Human agencies | AH3: Anaconda | AI3: NSW | AJ3: Store | AK3: Anaconda | AL3: NSW North | AM3: Anaconda | AN3: Anaconda - NSW North
A4: SRG-INJ-3696 | C4: No | D4: AU338012 | E4: DE CHAZAL, VENETIA | F4: 45808 | G4: 0.49097222 | H4: Spotlight QLD | I4: S080 | J4: Maroochydore | K4: Knee | L4: Ven tripped on a bar that was protruding from a M2M display and fell, landing on her knee. Ven came off the floor and we applied an ide pack to the injury. She sat for 15 minutes then returned to the floor. | M4: Injury | O4: No Assessment | P4: Open | Q4: 0 | R4: FALSE | S4: First Aid Injury | T4: Trauma to muscles and tendons | U4: Knee | V4: Being Hit By Moving Objects | W4: Being hit by falling objects | X4: Human agencies | Z4: 0 | AA4: MAY, FY25 | AB4: Q4, FY25 | AC4: FAIs | AF4: Being Hit By Moving Objects | AG4: Human agencies | AH4: Spotlight | AI4: QLD | AJ4: Store | AK4: Spotlight AU | AL4: QLD Central / TAS | AM4: Spotlight AU | AN4: Spotlight AU - QLD Central / TAS
A5: SRG-INJ-3687 | C5: No | D5: AU300442 | E5: SMART, ROSALIND | F5: 45807 | G5: 0.5625 | H5: Spotlight QLD | I5: S079 | J5: West Burleigh | K5: left knee with already sustained injury | L5: A substance impaired person in store, talking to himself constantly the whole time in store decided when team member was approaching to walk past to put his foot out in front of her. Team member did a big sidestep to avoid going near the guy and tripping over his foot, passing between 2 dump bins. | M5: Injury | O5: No Assessment | P5: Open | Q5: 0 | R5: FALSE | S5: Not Applicable | T5: Trauma to muscles and tendons | U5: Knee | V5: Falls, Trips and Slips of a Person | W5: Falls on the same level | X5: Human agencies | Z5: 0 | AA5: MAY, FY25 | AB5: Q4, FY25 | AC5: Incident | AF5: Falls, Trips and Slips of a Person | AG5: Human agencies | AH5: Spotlight | AI5: QLD | AJ5: Store | AK5: Spotlight AU | AL5: NSW North / QLD South | AM5: Spotlight AU | AN5: Spotlight AU - NSW North / QLD South
A6: SRG-INJ-3689 | C6: No | D6: AU214010 | E6: CHARLTON, VICKIE | F6: 45807 | G6: 0.61458333 | H6: Spotlight TAS | I6: S060 | J6: Hobart - Glenorchy | K6: right thumb and wrist, bit of numbness and aching | L6: Vickie was picking up a box of ready made curtains from the bottom of the pallet and the box of ready mades slipped back onto her hand. | M6: Injury | O6: No Assessment | P6: Open | Q6: 0 | R6: FALSE | S6: Not Applicable | T6: Trauma to muscles and tendons | U6: Hand, finger and thumb | V6: Body Stressing | W6: Muscular stress while lifting, carrying, or putting down objects | X6: Human agencies | Y6: Boxes | Z6: 0 | AA6: MAY, FY25 | AB6: Q4, FY25 | AC6: Incident | AF6: Body Stressing | AG6: Human agencies | AH6: Spotlight | AI6: TAS | AJ6: Store | AK6: Spotlight AU | AL6: QLD Central / TAS | AM6: Spotlight AU | AN6: Spotlight AU - QLD Central / TAS
A7: SRG-INJ-3694 | C7: No | D7: AU307953 | E7: TYLER-WHITEMAN, KYRA | F7: 45807 | G7: 0.64166667 | H7: Anaconda WA | I7: A090 | J7: Mandurah | K7: sprain to right ankle | L7: Kyra was standing on a 3 step ladder, forgot she was above ground level and stepped straight onto the floor. Sprain to right ankle | M7: Injury | O7: No Assessment | P7: Open | Q7: 0 | R7: FALSE | S7: Not Applicable | T7: Trauma to muscles and tendons | U7: Ankle | V7: Falls, Trips and Slips of a Person | W7: Falls from a height | X7: Human agencies | Y7: Ladder | Z7: 0 | AA7: MAY, FY25 | AB7: Q4, FY25 | AC7: Incident | AF7: Falls, Trips and Slips of a Person | AG7: Human agencies | AH7: Anaconda | AI7: WA | AJ7: Store | AK7: Anaconda | AL7: WA | AM7: Anaconda | AN7: Anaconda - WA
A8: SRG-INJ-3685 | C8: No | D8: AU316673 | E8: WELLSTEAD, BENJAMIN | F8: 45806 | G8: 0.59375 | H8: Spotlight WA | I8: S084 | J8: Bunbury | K8: Mid back. Strain and pain. | L8: While serving a customer I picked up a 160x230cm KOO Ombre Charcoal rug and returned the product to the bin. As I picked it up a felt a pull and sharp pain in my mid back. I reported the incident immediately to DTL Paul Rodgers. Rested and stretched in the office for 10 minutes and return to work. | M8: Injury | O8: No Assessment | P8: Open | Q8: 0 | R8: FALSE | S8: Not Applicable | T8: Trauma to muscles and tendons | U8: Back-Upper and lower | V8: Body Stressing | W8: Muscular stress while lifting, carrying, or putting down objects | X8: Human agencies | Z8: 0 | AA8: MAY, FY25 | AB8: Q4, FY25 | AC8: Incident | AF8: Body Stressing | AG8: Human agencies | AH8: Spotlight | AI8: WA | AJ8: Store | AK8: Spotlight AU | AL8: WA | AM8: Spotlight AU | AN8: Spotlight AU - WA
A9: SRG-INJ-3682 | C9: No | D9: AU233860 | E9: MCKEE, SAM | F9: 45806 | G9: 0.60347222 | H9: Anaconda ACT | I9: A027 | J9: Fyshwick | K9: crush/laceration right thumb | L9: throwing fixtures into skip bin, fixture slipped and thumb became jammed between fixture and skip bin | M9: Injury | O9: No Assessment | P9: Open | Q9: 0 | R9: FALSE | S9: First Aid Injury | T9: Laceration or open wound not involving traumatic amputation | U9: Hand, finger and thumb | V9: Being Hit By Moving Objects | W9: Being trapped between stationary and moving objects | X9: Human agencies | Z9: 0 | AA9: MAY, FY25 | AB9: Q4, FY25 | AC9: FAIs | AF9: Being Hit By Moving Objects | AG9: Human agencies | AH9: Anaconda | AI9: ACT | AJ9: Store | AK9: Anaconda | AL9: SA / ACT | AM9: Anaconda | AN9: Anaconda - SA / ACT
A10: SRG-INJ-3686 | C10: No | D10: AU338492 | E10: BESTER, ADDISON | F10: 45806 | G10: 0.78125 | H10: Spotlight TAS | I10: S102 | J10: Burnie | K10: Fingers being cut | L10: Adi was pulling flannelette sheets out of a pallet and onto the tables during nightfill and received a couple of papercuts on her fingers while handling the sheets from the card wrap-around on the sheets. | M10: Injury | O10: No Assessment | P10: Closed | Q10: 0 | R10: FALSE | S10: First Aid Injury | T10: Laceration or open wound not involving traumatic amputation | U10: Hand, finger and thumb | V10: Hitting Objects With a Part of the Body | W10: Hitting stationary objects | X10: Human agencies | Z10: 0 | AA10: MAY, FY25 | AB10: Q4, FY25 | AC10: FAIs | AF10: Hitting Objects With a Part of the Body | AG10: Human agencies | AH10: Spotlight | AI10: TAS | AJ10: Store | AK10: Spotlight AU | AL10: QLD Central / TAS | AM10: Spotlight AU | AN10: Spotlight AU - QLD Central / TAS
A11: SRG-INJ-3677 | C11: No | D11: AU310973 | E11: MCCULLOCH, CHASE | F11: 45806 | G11: 0.47569444 | H11: Spotlight QLD | I11: S161 | J11: Carindale | K11: upper left eyebrow, upper left cheek and left side of nose was hit by falling stock | L11: pulling the roll cage through the fire corridoor, roll cage got stuck in a hole and tiped. stock fell off. hit my upper left cheek left eyebrow and left side of my nose. the floors had been logged due to the unsafe nature of the floor and multiple holes in the concrete that the cages get stuck in. | M11: Injury | O11: No Assessment | P11: Open | Q11: 0 | R11: FALSE | S11: First Aid Injury | T11: Contusion, bruising and superficial crushing | U11: Face, not elsewhere classified | V11: Being Hit By Moving Objects | W11: Being hit by falling objects | X11: Human agencies | Y11: Roll Cages | Z11: 0 | AA11: MAY, FY25 | AB11: Q4, FY25 | AC11: FAIs | AF11: Being Hit By Moving Objects | AG11: Human agencies | AH11: Spotlight | AI11: QLD | AJ11: Store | AK11: Spotlight AU | AL11: QLD Central / TAS | AM11: Spotlight AU | AN11: Spotlight AU - QLD Central / TAS
A12: SRG-INJ-3688 | C12: No | D12: AU337223 | E12: ELLA, CHELSEA | F12: 45806 | G12: 0.63263889 | H12: Spotlight QLD | I12: S168 | J12: Windsor | K12: right hand | L12: Chelsea was up a ladder putting a cast Iron casserole dish on the shelf which was heavier then most baking items and hit her right hand on the ladder which has caused redness and swelling, tightness of the hand in opening and closing fist. | M12: Injury | O12: No Assessment | P12: Open | Q12: 0 | R12: FALSE | S12: Not Applicable | T12: Trauma to muscles and tendons | U12: Hand, finger and thumb | V12: Body Stressing | W12: Muscular stress while lifting, carrying, or putting down objects | X12: Human agencies | Z12: 0 | AA12: MAY, FY25 | AB12: Q4, FY25 | AC12: Incident | AF12: Body Stressing | AG12: Human agencies | AH12: Spotlight | AI12: QLD | AJ12: Store | AK12: Spotlight AU | AL12: QLD North | AM12: Spotlight AU | AN12: Spotlight AU - QLD North
A13: SRG-INJ-3684 | C13: No | D13: AU204295 | E13: SCHILLING, SHERIDAN | F13: 45806 | G13: 0.62361111 | H13: Spotlight SA | I13: S117 | J13: Noarlunga | K13: right temporal lobe | L13: Removing a roller blind from the bay when another blind fell and hit her on right temporal area | M13: Injury | O13: No Assessment | P13: Open | Q13: 0 | R13: FALSE | S13: Not Applicable | T13: Laceration or open wound not involving traumatic amputation | U13: Head - unspecified locations | V13: Being Hit By Moving Objects | W13: Being hit by falling objects | X13: Human agencies | Z13: 0 | AA13: MAY, FY25 | AB13: Q4, FY25 | AC13: Incident | AF13: Being Hit By Moving Objects | AG13: Human agencies | AH13: Spotlight | AI13: SA | AJ13: Store | AK13: Spotlight AU | AL13: SA/NT | AM13: Spotlight AU | AN13: Spotlight AU - SA/NT
A14: SRG-INJ-3675 | C14: No | D14: AU310802 | E14: SOONDRA, AMANDA | F14: 45805 | G14: 0.42083333 | H14: Spotlight SA | I14: S044 | J14: Munno Para | K14: sore hip | L14: Amanda has said when working in greenery her back started to hurt believes it may have been when working Manu cast iron stock but noticed no pain until evening progress back sore around 6:30pm | M14: Injury | O14: No Assessment | P14: Open | Q14: 0 | R14: FALSE | S14: Not Applicable | T14: Trauma to muscles and tendons | U14: Hip | V14: Body Stressing | W14: Muscular stress while lifting, carrying, or putting down objects | X14: Human agencies | Z14: 0 | AA14: MAY, FY25 | AB14: Q4, FY25 | AC14: Incident | AF14: Body Stressing | AG14: Human agencies | AH14: Spotlight | AI14: SA | AJ14: Store | AK14: Spotlight AU | AL14: SA/NT | AM14: Spotlight AU | AN14: Spotlight AU - SA/NT
A15: SRG-INJ-3681 | C15: No | D15: AU337204 | E15: HURLEY, ASTON | F15: 45805 | G15: 0.51388889 | H15: Spotlight VIC | I15: S049 | J15: Horsham | K15: Right Hand | L15: team member walked around corner and his right hand ( top of hand behind the index ) collided with the edge of a cove. the edge did not have a plastic cover insert for protection and was a little sharp however it was blunt force that has cause an abrasion to the skin ( 1 cm width ) as well as immediate swelling and bruising on entire hand. TM dropped to the ground in pain, did not land on the hand. was holding the hand with his left hand and was curdled on the ground. TM proceeded out back and informed Adam DTL and was treated with an ice pack with a tea towel. Pain over night, Panadol for treatment. grip cause pain and stretching. Pain has stayed stagnate and abrasion and swelling have remained the same. Today using avoidance of using to cure pain. does not believe will see a doctor but believes may be fractured. optimistic it will get better on its own. | M15: Injury | O15: No Assessment | P15: Open | Q15: 0 | R15: FALSE | S15: First Aid Injury | T15: Laceration or open wound not involving traumatic amputation | U15: Hand, finger and thumb | V15: Hitting Objects With a Part of the Body | W15: Rubbing and chafing | X15: Human agencies | Z15: 0 | AA15: MAY, FY25 | AB15: Q4, FY25 | AC15: FAIs | AF15: Hitting Objects With a Part of the Body | AG15: Human agencies | AH15: Spotlight | AI15: VIC | AJ15: Store | AK15: Spotlight AU | AL15: VIC West | AM15: Spotlight AU | AN15: Spotlight AU - VIC West
A16: SRG-INJ-3678 | C16: Yes | D16: AU317008 | E16: HARMER, BREANNAH | F16: 45805 | G16: 0.4375 | H16: Anaconda SA | I16: A075 | J16: Munno Para | K16: Bullying | L16: team member threw back her keys and said you can cover my shifts for this and week. texted the regional manager saying she was having the rest of the week off sick due to bullying in the work place and wants to go on stress leave. | M16: Injury | O16: No Assessment | P16: Open | Q16: 0 | R16: FALSE | S16: Lost Time Injury | T16: Mental diseases unspecified | U16: Psychological system | V16: Mental Stress | W16: Work related harassment and/or workplace bullying | X16: Human agencies | Z16: 0 | AA16: MAY, FY25 | AB16: Q4, FY25 | AC16: LTIs | AF16: Mental Stress | AG16: Human agencies | AH16: Anaconda | AI16: SA | AJ16: Store | AK16: Anaconda | AL16: SA / ACT | AM16: Anaconda | AN16: Anaconda - SA / ACT
A17: SRG-INJ-3670 | C17: No | D17: AU339367 | E17: BARTELT, SUZANNE | F17: 45804 | G17: 0.59166667 | H17: Spotlight QLD | I17: S205 | J17: Airlie Beach | K17: Left shoulder | L17: Suzanne Bartelt was unloading a pallet of stock in the sew center, and during the process of lifting multiple fabric rolls at the same time felt a pain the left shoulder. | M17: Injury | O17: No Assessment | P17: Closed | Q17: 0 | R17: FALSE | S17: Not Applicable | T17: Trauma to muscles and tendons | U17: Shoulder | V17: Body Stressing | W17: Muscular stress with no objects being handled | X17: Human agencies | Z17: 0 | AA17: MAY, FY25 | AB17: Q4, FY25 | AC17: Incident | AF17: Body Stressing | AG17: Human agencies | AH17: Spotlight | AI17: QLD | AJ17: Store | AK17: Spotlight AU | AL17: QLD North | AM17: Spotlight AU | AN17: Spotlight AU - QLD North
A18: SRG-INJ-3674 | C18: No | D18: AU237793 | E18: GIBLETT, SAMONE | F18: 45804 | G18: 0.45277778 | H18: Spotlight VIC | I18: S015 | J18: Bairnsdale | K18: both shoulders are sore/ strained and a sore left knee | L18: Had to move the anti fatigue mats behind POS3 to be able to get the wave in to geta print down for a customer. Ella was operating the Wave and was getting a print down but was waiting for Samone to grab another to put it back up. Samone tripped over the 3 mats, piled behind counter as she gave a print to Ella. | M18: Injury | O18: No Assessment | P18: Closed | Q18: 0 | R18: FALSE | S18: Not Applicable | T18: Trauma to muscles and tendons | U18: Upper limb - multiple locations | V18: Falls, Trips and Slips of a Person | W18: Falls on the same level | X18: Human agencies | Z18: 0 | AA18: MAY, FY25 | AB18: Q4, FY25 | AC18: Incident | AF18: Falls, Trips and Slips of a Person | AG18: Human agencies | AH18: Spotlight | AI18: VIC | AJ18: Store | AK18: Spotlight AU | AL18: VIC East | AM18: Spotlight AU | AN18: Spotlight AU - VIC East
A19: SRG-INJ-3676 | C19: No | D19: AU218050 | E19: PHILPOTT, LINDY-ANN | F19: 45804 | G19: 0.75902778 | H19: Spotlight TAS | I19: S102 | J19: Burnie | K19: top of head | L19: she accidentally knocked an A4 frame, which fell and hit Lindy on the head. Sophie provided an ice pack and confirmed Lindy was onfirmed Lindy was okay to continue her shift. Lindy later reported the incident to Henry, and we are completing the repor | M19: Injury | O19: No Assessment | P19: Open | Q19: 0 | R19: FALSE | S19: First Aid Injury | T19: Contusion, bruising and superficial crushing | U19: Head - unspecified locations | V19: Being Hit By Moving Objects | W19: Being hit by falling objects | X19: Human agencies | Z19: 0 | AA19: MAY, FY25 | AB19: Q4, FY25 | AC19: FAIs | AF19: Being Hit By Moving Objects | AG19: Human agencies | AH19: Spotlight | AI19: TAS | AJ19: Store | AK19: Spotlight AU | AL19: QLD Central / TAS | AM19: Spotlight AU | AN19: Spotlight AU - QLD Central / TAS
A20: SRG-INJ-3667 | C20: No | D20: AU298862 | E20: SEKULIC, AMY | F20: 45803 | G20: 0.48263889 | H20: Spotlight NSW | I20: S045 | J20: Lidcombe | K20: Left Knee on impact with Floor as well as right hand and right foot | L20: Team member was picking items in despatch for eComm when loose stock fell from a shelf as she pulled down a box. As she turned to pick up the box, she slipped on a piece of broken plastic and fell, injuring her hand, knee, and foot. | M20: Injury | O20: Unfit | P20: Open | Q20: 5 | R20: FALSE | S20: Lost Time Injury | T20: Contusion, bruising and superficial crushing | U20: Upper limb - multiple locations | V20: Hitting Objects With a Part of the Body | W20: Hitting stationary objects | X20: Human agencies | Z20: 0 | AA20: MAY, FY25 | AB20: Q4, FY25 | AC20: LTIs | AF20: Hitting Objects With a Part of the Body | AG20: Human agencies | AH20: Spotlight | AI20: NSW | AJ20: Store | AK20: Spotlight AU | AL20: NSW South / ACT | AM20: Spotlight AU | AN20: Spotlight AU - NSW South / ACT
A21: SRG-INJ-3666 | C21: No | D21: HS297107 | E21: DANOS, NICOLE | F21: 45803 | G21: 0.34027778 | H21: Harris Scarfe TAS | I21: 4043 | J21: Launceston | K21: Nicky landed on her left shoulder, which it tender | L21: Nicky was picking ecom when cleaners were mopping floor without wet floor signage. Nicky slipped and fell. | M21: Injury | O21: Fit | P21: Open | Q21: 0 | R21: FALSE | S21: Not Applicable | T21: Trauma to muscles and tendons | U21: Shoulder | V21: Falls, Trips and Slips of a Person | W21: Falls on the same level | X21: Human agencies | Z21: 0 | AA21: MAY, FY25 | AB21: Q4, FY25 | AC21: Incident | AF21: Falls, Trips and Slips of a Person | AG21: Human agencies | AH21: Harris Scarfe | AI21: TAS | AJ21: Store | AK21: Harris Scarfe | AL21: SA/TAS | AM21: Harris Scarfe | AN21: Harris Scarfe - SA/TAS
A22: SRG-INJ-3669 | C22: No | D22: HS251836 | E22: CARVER, JOSEPHINE | F22: 45803 | G22: 0.39583333 | H22: Harris Scarfe TAS | I22: 4044 | J22: Devonport | K22: Left side of face cheekbone | L22: Josephine Carver Moving bars from fixtures in shelving flicked up and hit me in the face. | M22: Injury | O22: No Assessment | P22: Closed | Q22: 0 | R22: FALSE | S22: Not Applicable | T22: Contusion, bruising and superficial crushing | U22: Face, not elsewhere classified | V22: Hitting Objects With a Part of the Body | W22: Hitting stationary objects | X22: Human agencies | Z22: 0 | AA22: MAY, FY25 | AB22: Q4, FY25 | AC22: Incident | AF22: Hitting Objects With a Part of the Body | AG22: Human agencies | AH22: Harris Scarfe | AI22: TAS | AJ22: Store | AK22: Harris Scarfe | AL22: SA/TAS | AM22: Harris Scarfe | AN22: Harris Scarfe - SA/TAS
A23: SRG-INJ-3664 | C23: No | D23: HS325818 | E23: PIPER, LILIJANA | F23: 45802 | G23: 0.60763889 | H23: Harris Scarfe TAS | I23: 4044 | J23: Devonport | K23: Left knuckle | L23: When moving stock I scraped my knuckle on shelf bracket. | M23: Injury | O23: No Assessment | P23: Closed | Q23: 0 | R23: FALSE | S23: Not Applicable | T23: Contusion, bruising and superficial crushing | U23: Hand, finger and thumb | V23: Hitting Objects With a Part of the Body | W23: Rubbing and chafing | X23: Human agencies | Z23: 0 | AA23: MAY, FY25 | AB23: Q4, FY25 | AC23: Incident | AF23: Hitting Objects With a Part of the Body | AG23: Human agencies | AH23: Harris Scarfe | AI23: TAS | AJ23: Store | AK23: Harris Scarfe | AL23: SA/TAS | AM23: Harris Scarfe | AN23: Harris Scarfe - SA/TAS
A24: SRG-INJ-3671 | C24: No | D24: AU238405 | E24: CARR, LOREN | F24: 45801 | G24: 0.60416667 | H24: Anaconda VIC | I24: A039 | J24: Highett | K24: Back, right hand side/lower back pain and numbness | L24: Moving display tents around on the tent floor and clearing bulkstacks. Towards the end of the day I could feel my back become quiet sore. By the next morning it felt like muscular pain which has now moved to numbness in the back and sore with movement. | M24: Injury | O24: No Assessment | P24: Open | Q24: 0 | R24: FALSE | S24: Not Applicable | T24: Trauma to muscles and tendons | U24: Back-Upper and lower | V24: Body Stressing | W24: Muscular stress while lifting, carrying, or putting down objects | X24: Human agencies | Z24: 0 | AA24: MAY, FY25 | AB24: Q4, FY25 | AC24: Incident | AF24: Body Stressing | AG24: Human agencies | AH24: Anaconda | AI24: VIC | AJ24: Store | AK24: Anaconda | AL24: VIC North / East | AM24: Anaconda | AN24: Anaconda - VIC North / East
A25: SRG-INJ-3668 | C25: No | D25: AU338493 | E25: GILL, LAMIA | F25: 45801 | G25: 0.625 | H25: Spotlight WA | I25: S115 | J25: Albany | K25: Left little finger nail ripped off. | L25: Team member was reaching in to an eco base to adjust some stock and caught her fingernail on the mesh sides. This then ripped off her little fingernail entirely and she needed to go the hospital to get the remainder of the nail removed. | M25: Injury | O25: No Assessment | P25: Open | Q25: 0 | R25: FALSE | S25: Lost Time Injury | T25: Laceration or open wound not involving traumatic amputation | U25: Hand, finger and thumb | V25: Hitting Objects With a Part of the Body | W25: Hitting stationary objects | X25: Human agencies | Z25: 0 | AA25: MAY, FY25 | AB25: Q4, FY25 | AC25: LTIs | AF25: Hitting Objects With a Part of the Body | AG25: Human agencies | AH25: Spotlight | AI25: WA | AJ25: Store | AK25: Spotlight AU | AL25: WA | AM25: Spotlight AU | AN25: Spotlight AU - WA
A26: SRG-INJ-3661 | C26: No | D26: AU339712 | E26: THOMAS, RILEY | F26: 45800 | G26: 0.5 | H26: Anaconda QLD | I26: A038 | J26: Toowoomba | K26: Right middle side of back | L26: Riley (Sid) was lifting a kids fluid rapid 50cm bike onto 2nd storage shelf in our back storage room (waist height as) and as he lifted the bike box he got a sharp pain in the muscular side of his back. Sid reported it immediately to myself (Ash). I assessed the 2nd shelf and product. Sid refused ICE or medical treatment & said "it happens sometimes" (prior injury) and said he will be all good and wanted to continue his shift. Sid was placed solely on customer service for the remainder of his shift. Manual Handling / product lifting Training will be re-touched on next shift. Sid did say at the commencement of his shift that it was feeling better. Follow up by leaders will be followed over coming days to ensure he is still ok and no medical treatment is needed. | M26: Injury | O26: No Assessment | P26: Closed | Q26: 0 | R26: FALSE | S26: Not Applicable | T26: Trauma to muscles and tendons | U26: Back-Upper and lower | V26: Body Stressing | W26: Muscular stress while lifting, carrying, or putting down objects | X26: Human agencies | Z26: 0 | AA26: MAY, FY25 | AB26: Q4, FY25 | AC26: Incident | AF26: Body Stressing | AG26: Human agencies | AH26: Anaconda | AI26: QLD | AJ26: Store | AK26: Anaconda | AL26: QLD NW / NT | AM26: Anaconda | AN26: Anaconda - QLD NW / NT
