Workbook
Name ANSW: #REF!
Name HC: #REF!

Sheet Go1_LearningStatReport_JUN FY25
B2: Learning Status | D2: Completed | J2: % Complete | M2: In Progress | S2: % In Progress
D3: Completed FEED | E3: Completed FEED | F3: Completed FEED | G3: Completed FEED | H3: Completed FEED | M3: In Progress FEED | N3: In Progress FEED | O3: In Progress FEED | P3: In Progress FEED | Q3: In Progress FEED
D4: FY25 | F4: FY26 | J4: =F6&", "&F4 -> JUL, FY26 | M4: FY25 | O4: FY26 | S4: =O6&", "&O4 -> JUL, FY26
D5: =D6&", "&D4 -> JUL, FY25 | E5: =D6&", "&D4 -> JUL, FY25 | F5: =F6&", "&F4 -> JUL, FY26 | G5: =F6&", "&F4 -> JUL, FY26 | M5: =M6&", "&M4 -> JUL, FY25 | N5: =M6&", "&M4 -> JUL, FY25 | O5: =O6&", "&O4 -> JUL, FY26 | P5: =O6&", "&O4 -> JUL, FY26
B6: Brand/Function | D6: JUL | E6: YTD | F6: JUL | G6: YTD | H6: VAR | J6: Headcount | K6: % | M6: JUL | N6: YTD | O6: JUL | P6: YTD | Q6: VAR | S6: Headcount | T6: %
B7: eCommerce & Omni Channel | D7: {=_xlfn.XLOOKUP($B7,INDIRECT("'"&D$3&"'!"&"$A3:$A14"),_xlfn.XLOOKUP(D$5,INDIRECT("'"&D$3&"'!"&"$B2:$AZ2"),INDIRECT("'"&D$3&"'!"&"$B3:$AZ14")))} -> 1 | E7: {=_xlfn.XLOOKUP(E$6&" "&$B7,INDIRECT("'"&E$3&"'!"&"$A17:$A28"),_xlfn.XLOOKUP(E$5,INDIRECT("'"&E$3&"'!"&"$B2:$AZ2"),INDIRECT("'"&E$3&"'!"&"$B17:$AZ28")))} -> 1 | F7: {=_xlfn.XLOOKUP($B7,INDIRECT("'"&F$3&"'!"&"$A3:$A14"),_xlfn.XLOOKUP(F$5,INDIRECT("'"&F$3&"'!"&"$B2:$AZ2"),INDIRECT("'"&F$3&"'!"&"$B3:$AZ14")))} -> 0 | G7: {=_xlfn.XLOOKUP(G$6&" "&$B7,INDIRECT("'"&G$3&"'!"&"$A17:$A28"),_xlfn.XLOOKUP(G$5,INDIRECT("'"&G$3&"'!"&"$B2:$AZ2"),INDIRECT("'"&G$3&"'!"&"$B17:$AZ28")))} -> 0 | H7: =G7-E7 -> -1 | J7: =COUNTIF('Active Employees '!$R:$R,'Go1_LearningStatReport_JUN FY25'!$B7) -> 64 | K7: =F7/J7 -> 0 | M7: {=_xlfn.XLOOKUP($B7,INDIRECT("'"&M$3&"'!"&"$A3:$A14"),_xlfn.XLOOKUP(M$5,INDIRECT("'"&M$3&"'!"&"$B2:$AZ2"),INDIRECT("'"&M$3&"'!"&"$B3:$AZ14")))} -> 0 | N7: {=_xlfn.XLOOKUP(N$6&" "&$B7,INDIRECT("'"&N$3&"'!"&"$A17:$A28"),_xlfn.XLOOKUP(N$5,INDIRECT("'"&N$3&"'!"&"$B2:$AZ2"),INDIRECT("'"&N$3&"'!"&"$B17:$AZ28")))} -> 9 | O7: {=_xlfn.XLOOKUP($B7,INDIRECT("'"&O$3&"'!"&"$A3:$A14"),_xlfn.XLOOKUP(O$5,INDIRECT("'"&O$3&"'!"&"$B2:$AZ2"),INDIRECT("'"&O$3&"'!"&"$B3:$AZ14")))} -> 1 | P7: {=_xlfn.XLOOKUP(P$6&" "&$B7,INDIRECT("'"&P$3&"'!"&"$A17:$A28"),_xlfn.XLOOKUP(P$5,INDIRECT("'"&P$3&"'!"&"$B2:$AZ2"),INDIRECT("'"&P$3&"'!"&"$B17:$AZ28")))} -> 1 | Q7: =P7-N7 -> -8 | S7: =COUNTIF('Active Employees '!$R:$R,'Go1_LearningStatReport_JUN FY25'!$B7) -> 64 | T7: =O7/S7 -> 0.015625
B8: FFM | D8: {=_xlfn.XLOOKUP($B8,INDIRECT("'"&D$3&"'!"&"$A3:$A14"),_xlfn.XLOOKUP(D$5,INDIRECT("'"&D$3&"'!"&"$B2:$AZ2"),INDIRECT("'"&D$3&"'!"&"$B3:$AZ14")))} -> 0 | E8: {=_xlfn.XLOOKUP(E$6&" "&$B8,INDIRECT("'"&E$3&"'!"&"$A17:$A28"),_xlfn.XLOOKUP(E$5,INDIRECT("'"&E$3&"'!"&"$B2:$AZ2"),INDIRECT("'"&E$3&"'!"&"$B17:$AZ28")))} -> 0 | F8: {=_xlfn.XLOOKUP($B8,INDIRECT("'"&F$3&"'!"&"$A3:$A14"),_xlfn.XLOOKUP(F$5,INDIRECT("'"&F$3&"'!"&"$B2:$AZ2"),INDIRECT("'"&F$3&"'!"&"$B3:$AZ14")))} -> 0 | G8: {=_xlfn.XLOOKUP(G$6&" "&$B8,INDIRECT("'"&G$3&"'!"&"$A17:$A28"),_xlfn.XLOOKUP(G$5,INDIRECT("'"&G$3&"'!"&"$B2:$AZ2"),INDIRECT("'"&G$3&"'!"&"$B17:$AZ28")))} -> 0 | H8: =G8-E8 -> 0 | J8: =COUNTIF('Active Employees '!$R:$R,'Go1_LearningStatReport_JUN FY25'!$B8) -> 29 | K8: =F8/J8 -> 0 | M8: {=_xlfn.XLOOKUP($B8,INDIRECT("'"&M$3&"'!"&"$A3:$A14"),_xlfn.XLOOKUP(M$5,INDIRECT("'"&M$3&"'!"&"$B2:$AZ2"),INDIRECT("'"&M$3&"'!"&"$B3:$AZ14")))} -> 0 | N8: {=_xlfn.XLOOKUP(N$6&" "&$B8,INDIRECT("'"&N$3&"'!"&"$A17:$A28"),_xlfn.XLOOKUP(N$5,INDIRECT("'"&N$3&"'!"&"$B2:$AZ2"),INDIRECT("'"&N$3&"'!"&"$B17:$AZ28")))} -> 2 | O8: {=_xlfn.XLOOKUP($B8,INDIRECT("'"&O$3&"'!"&"$A3:$A14"),_xlfn.XLOOKUP(O$5,INDIRECT("'"&O$3&"'!"&"$B2:$AZ2"),INDIRECT("'"&O$3&"'!"&"$B3:$AZ14")))} -> 0 | P8: {=_xlfn.XLOOKUP(P$6&" "&$B8,INDIRECT("'"&P$3&"'!"&"$A17:$A28"),_xlfn.XLOOKUP(P$5,INDIRECT("'"&P$3&"'!"&"$B2:$AZ2"),INDIRECT("'"&P$3&"'!"&"$B17:$AZ28")))} -> 0 | Q8: =P8-N8 -> -2 | S8: =COUNTIF('Active Employees '!$R:$R,'Go1_LearningStatReport_JUN FY25'!$B8) -> 29 | T8: =O8/S8 -> 0
B9: Finance | D9: {=_xlfn.XLOOKUP($B9,INDIRECT("'"&D$3&"'!"&"$A3:$A14"),_xlfn.XLOOKUP(D$5,INDIRECT("'"&D$3&"'!"&"$B2:$AZ2"),INDIRECT("'"&D$3&"'!"&"$B3:$AZ14")))} -> 0 | E9: {=_xlfn.XLOOKUP(E$6&" "&$B9,INDIRECT("'"&E$3&"'!"&"$A17:$A28"),_xlfn.XLOOKUP(E$5,INDIRECT("'"&E$3&"'!"&"$B2:$AZ2"),INDIRECT("'"&E$3&"'!"&"$B17:$AZ28")))} -> 0 | F9: {=_xlfn.XLOOKUP($B9,INDIRECT("'"&F$3&"'!"&"$A3:$A14"),_xlfn.XLOOKUP(F$5,INDIRECT("'"&F$3&"'!"&"$B2:$AZ2"),INDIRECT("'"&F$3&"'!"&"$B3:$AZ14")))} -> 0 | G9: {=_xlfn.XLOOKUP(G$6&" "&$B9,INDIRECT("'"&G$3&"'!"&"$A17:$A28"),_xlfn.XLOOKUP(G$5,INDIRECT("'"&G$3&"'!"&"$B2:$AZ2"),INDIRECT("'"&G$3&"'!"&"$B17:$AZ28")))} -> 0 | H9: =G9-E9 -> 0 | J9: =COUNTIF('Active Employees '!$R:$R,'Go1_LearningStatReport_JUN FY25'!$B9) -> 34 | K9: =F9/J9 -> 0 | M9: {=_xlfn.XLOOKUP($B9,INDIRECT("'"&M$3&"'!"&"$A3:$A14"),_xlfn.XLOOKUP(M$5,INDIRECT("'"&M$3&"'!"&"$B2:$AZ2"),INDIRECT("'"&M$3&"'!"&"$B3:$AZ14")))} -> 0 | N9: {=_xlfn.XLOOKUP(N$6&" "&$B9,INDIRECT("'"&N$3&"'!"&"$A17:$A28"),_xlfn.XLOOKUP(N$5,INDIRECT("'"&N$3&"'!"&"$B2:$AZ2"),INDIRECT("'"&N$3&"'!"&"$B17:$AZ28")))} -> 1 | O9: {=_xlfn.XLOOKUP($B9,INDIRECT("'"&O$3&"'!"&"$A3:$A14"),_xlfn.XLOOKUP(O$5,INDIRECT("'"&O$3&"'!"&"$B2:$AZ2"),INDIRECT("'"&O$3&"'!"&"$B3:$AZ14")))} -> 0 | P9: {=_xlfn.XLOOKUP(P$6&" "&$B9,INDIRECT("'"&P$3&"'!"&"$A17:$A28"),_xlfn.XLOOKUP(P$5,INDIRECT("'"&P$3&"'!"&"$B2:$AZ2"),INDIRECT("'"&P$3&"'!"&"$B17:$AZ28")))} -> 0 | Q9: =P9-N9 -> -1 | S9: =COUNTIF('Active Employees '!$R:$R,'Go1_LearningStatReport_JUN FY25'!$B9) -> 34 | T9: =O9/S9 -> 0
B10: Human Resources | D10: {=_xlfn.XLOOKUP($B10,INDIRECT("'"&D$3&"'!"&"$A3:$A14"),_xlfn.XLOOKUP(D$5,INDIRECT("'"&D$3&"'!"&"$B2:$AZ2"),INDIRECT("'"&D$3&"'!"&"$B3:$AZ14")))} -> 42 | E10: {=_xlfn.XLOOKUP(E$6&" "&$B10,INDIRECT("'"&E$3&"'!"&"$A17:$A28"),_xlfn.XLOOKUP(E$5,INDIRECT("'"&E$3&"'!"&"$B2:$AZ2"),INDIRECT("'"&E$3&"'!"&"$B17:$AZ28")))} -> 42 | F10: {=_xlfn.XLOOKUP($B10,INDIRECT("'"&F$3&"'!"&"$A3:$A14"),_xlfn.XLOOKUP(F$5,INDIRECT("'"&F$3&"'!"&"$B2:$AZ2"),INDIRECT("'"&F$3&"'!"&"$B3:$AZ14")))} -> 0 | G10: {=_xlfn.XLOOKUP(G$6&" "&$B10,INDIRECT("'"&G$3&"'!"&"$A17:$A28"),_xlfn.XLOOKUP(G$5,INDIRECT("'"&G$3&"'!"&"$B2:$AZ2"),INDIRECT("'"&G$3&"'!"&"$B17:$AZ28")))} -> 0 | H10: =G10-E10 -> -42 | J10: =COUNTIF('Active Employees '!$R:$R,'Go1_LearningStatReport_JUN FY25'!$B10) -> 46 | K10: =F10/J10 -> 0 | M10: {=_xlfn.XLOOKUP($B10,INDIRECT("'"&M$3&"'!"&"$A3:$A14"),_xlfn.XLOOKUP(M$5,INDIRECT("'"&M$3&"'!"&"$B2:$AZ2"),INDIRECT("'"&M$3&"'!"&"$B3:$AZ14")))} -> 11 | N10: {=_xlfn.XLOOKUP(N$6&" "&$B10,INDIRECT("'"&N$3&"'!"&"$A17:$A28"),_xlfn.XLOOKUP(N$5,INDIRECT("'"&N$3&"'!"&"$B2:$AZ2"),INDIRECT("'"&N$3&"'!"&"$B17:$AZ28")))} -> 22 | O10: {=_xlfn.XLOOKUP($B10,INDIRECT("'"&O$3&"'!"&"$A3:$A14"),_xlfn.XLOOKUP(O$5,INDIRECT("'"&O$3&"'!"&"$B2:$AZ2"),INDIRECT("'"&O$3&"'!"&"$B3:$AZ14")))} -> 0 | P10: {=_xlfn.XLOOKUP(P$6&" "&$B10,INDIRECT("'"&P$3&"'!"&"$A17:$A28"),_xlfn.XLOOKUP(P$5,INDIRECT("'"&P$3&"'!"&"$B2:$AZ2"),INDIRECT("'"&P$3&"'!"&"$B17:$AZ28")))} -> 0 | Q10: =P10-N10 -> -22 | S10: =COUNTIF('Active Employees '!$R:$R,'Go1_LearningStatReport_JUN FY25'!$B10) -> 46 | T10: =O10/S10 -> 0
B11: Insights & Analytics | D11: {=_xlfn.XLOOKUP($B11,INDIRECT("'"&D$3&"'!"&"$A3:$A14"),_xlfn.XLOOKUP(D$5,INDIRECT("'"&D$3&"'!"&"$B2:$AZ2"),INDIRECT("'"&D$3&"'!"&"$B3:$AZ14")))} -> 0 | E11: {=_xlfn.XLOOKUP(E$6&" "&$B11,INDIRECT("'"&E$3&"'!"&"$A17:$A28"),_xlfn.XLOOKUP(E$5,INDIRECT("'"&E$3&"'!"&"$B2:$AZ2"),INDIRECT("'"&E$3&"'!"&"$B17:$AZ28")))} -> 0 | F11: {=_xlfn.XLOOKUP($B11,INDIRECT("'"&F$3&"'!"&"$A3:$A14"),_xlfn.XLOOKUP(F$5,INDIRECT("'"&F$3&"'!"&"$B2:$AZ2"),INDIRECT("'"&F$3&"'!"&"$B3:$AZ14")))} -> 0 | G11: {=_xlfn.XLOOKUP(G$6&" "&$B11,INDIRECT("'"&G$3&"'!"&"$A17:$A28"),_xlfn.XLOOKUP(G$5,INDIRECT("'"&G$3&"'!"&"$B2:$AZ2"),INDIRECT("'"&G$3&"'!"&"$B17:$AZ28")))} -> 0 | H11: =G11-E11 -> 0 | J11: =COUNTIF('Active Employees '!$R:$R,'Go1_LearningStatReport_JUN FY25'!$B11) -> 6 | K11: =F11/J11 -> 0 | M11: {=_xlfn.XLOOKUP($B11,INDIRECT("'"&M$3&"'!"&"$A3:$A14"),_xlfn.XLOOKUP(M$5,INDIRECT("'"&M$3&"'!"&"$B2:$AZ2"),INDIRECT("'"&M$3&"'!"&"$B3:$AZ14")))} -> 0 | N11: {=_xlfn.XLOOKUP(N$6&" "&$B11,INDIRECT("'"&N$3&"'!"&"$A17:$A28"),_xlfn.XLOOKUP(N$5,INDIRECT("'"&N$3&"'!"&"$B2:$AZ2"),INDIRECT("'"&N$3&"'!"&"$B17:$AZ28")))} -> 0 | O11: {=_xlfn.XLOOKUP($B11,INDIRECT("'"&O$3&"'!"&"$A3:$A14"),_xlfn.XLOOKUP(O$5,INDIRECT("'"&O$3&"'!"&"$B2:$AZ2"),INDIRECT("'"&O$3&"'!"&"$B3:$AZ14")))} -> 0 | P11: {=_xlfn.XLOOKUP(P$6&" "&$B11,INDIRECT("'"&P$3&"'!"&"$A17:$A28"),_xlfn.XLOOKUP(P$5,INDIRECT("'"&P$3&"'!"&"$B2:$AZ2"),INDIRECT("'"&P$3&"'!"&"$B17:$AZ28")))} -> 0 | Q11: =P11-N11 -> 0 | S11: =COUNTIF('Active Employees '!$R:$R,'Go1_LearningStatReport_JUN FY25'!$B11) -> 6 | T11: =O11/S11 -> 0
B12: IT | D12: {=_xlfn.XLOOKUP($B12,INDIRECT("'"&D$3&"'!"&"$A3:$A14"),_xlfn.XLOOKUP(D$5,INDIRECT("'"&D$3&"'!"&"$B2:$AZ2"),INDIRECT("'"&D$3&"'!"&"$B3:$AZ14")))} -> 0 | E12: {=_xlfn.XLOOKUP(E$6&" "&$B12,INDIRECT("'"&E$3&"'!"&"$A17:$A28"),_xlfn.XLOOKUP(E$5,INDIRECT("'"&E$3&"'!"&"$B2:$AZ2"),INDIRECT("'"&E$3&"'!"&"$B17:$AZ28")))} -> 0 | F12: {=_xlfn.XLOOKUP($B12,INDIRECT("'"&F$3&"'!"&"$A3:$A14"),_xlfn.XLOOKUP(F$5,INDIRECT("'"&F$3&"'!"&"$B2:$AZ2"),INDIRECT("'"&F$3&"'!"&"$B3:$AZ14")))} -> 0 | G12: {=_xlfn.XLOOKUP(G$6&" "&$B12,INDIRECT("'"&G$3&"'!"&"$A17:$A28"),_xlfn.XLOOKUP(G$5,INDIRECT("'"&G$3&"'!"&"$B2:$AZ2"),INDIRECT("'"&G$3&"'!"&"$B17:$AZ28")))} -> 0 | H12: =G12-E12 -> 0 | J12: =COUNTIF('Active Employees '!$R:$R,'Go1_LearningStatReport_JUN FY25'!$B12) -> 70 | K12: =F12/J12 -> 0 | M12: {=_xlfn.XLOOKUP($B12,INDIRECT("'"&M$3&"'!"&"$A3:$A14"),_xlfn.XLOOKUP(M$5,INDIRECT("'"&M$3&"'!"&"$B2:$AZ2"),INDIRECT("'"&M$3&"'!"&"$B3:$AZ14")))} -> 5 | N12: {=_xlfn.XLOOKUP(N$6&" "&$B12,INDIRECT("'"&N$3&"'!"&"$A17:$A28"),_xlfn.XLOOKUP(N$5,INDIRECT("'"&N$3&"'!"&"$B2:$AZ2"),INDIRECT("'"&N$3&"'!"&"$B17:$AZ28")))} -> 22 | O12: {=_xlfn.XLOOKUP($B12,INDIRECT("'"&O$3&"'!"&"$A3:$A14"),_xlfn.XLOOKUP(O$5,INDIRECT("'"&O$3&"'!"&"$B2:$AZ2"),INDIRECT("'"&O$3&"'!"&"$B3:$AZ14")))} -> 0 | P12: {=_xlfn.XLOOKUP(P$6&" "&$B12,INDIRECT("'"&P$3&"'!"&"$A17:$A28"),_xlfn.XLOOKUP(P$5,INDIRECT("'"&P$3&"'!"&"$B2:$AZ2"),INDIRECT("'"&P$3&"'!"&"$B17:$AZ28")))} -> 0 | Q12: =P12-N12 -> -22 | S12: =COUNTIF('Active Employees '!$R:$R,'Go1_LearningStatReport_JUN FY25'!$B12) -> 70 | T12: =O12/S12 -> 0
B13: Marketing | D13: {=_xlfn.XLOOKUP($B13,INDIRECT("'"&D$3&"'!"&"$A3:$A14"),_xlfn.XLOOKUP(D$5,INDIRECT("'"&D$3&"'!"&"$B2:$AZ2"),INDIRECT("'"&D$3&"'!"&"$B3:$AZ14")))} -> 0 | E13: {=_xlfn.XLOOKUP(E$6&" "&$B13,INDIRECT("'"&E$3&"'!"&"$A17:$A28"),_xlfn.XLOOKUP(E$5,INDIRECT("'"&E$3&"'!"&"$B2:$AZ2"),INDIRECT("'"&E$3&"'!"&"$B17:$AZ28")))} -> 0 | F13: {=_xlfn.XLOOKUP($B13,INDIRECT("'"&F$3&"'!"&"$A3:$A14"),_xlfn.XLOOKUP(F$5,INDIRECT("'"&F$3&"'!"&"$B2:$AZ2"),INDIRECT("'"&F$3&"'!"&"$B3:$AZ14")))} -> 0 | G13: {=_xlfn.XLOOKUP(G$6&" "&$B13,INDIRECT("'"&G$3&"'!"&"$A17:$A28"),_xlfn.XLOOKUP(G$5,INDIRECT("'"&G$3&"'!"&"$B2:$AZ2"),INDIRECT("'"&G$3&"'!"&"$B17:$AZ28")))} -> 0 | H13: =G13-E13 -> 0 | J13: =COUNTIF('Active Employees '!$R:$R,'Go1_LearningStatReport_JUN FY25'!$B13) -> 67 | K13: =F13/J13 -> 0 | M13: {=_xlfn.XLOOKUP($B13,INDIRECT("'"&M$3&"'!"&"$A3:$A14"),_xlfn.XLOOKUP(M$5,INDIRECT("'"&M$3&"'!"&"$B2:$AZ2"),INDIRECT("'"&M$3&"'!"&"$B3:$AZ14")))} -> 1 | N13: {=_xlfn.XLOOKUP(N$6&" "&$B13,INDIRECT("'"&N$3&"'!"&"$A17:$A28"),_xlfn.XLOOKUP(N$5,INDIRECT("'"&N$3&"'!"&"$B2:$AZ2"),INDIRECT("'"&N$3&"'!"&"$B17:$AZ28")))} -> 12 | O13: {=_xlfn.XLOOKUP($B13,INDIRECT("'"&O$3&"'!"&"$A3:$A14"),_xlfn.XLOOKUP(O$5,INDIRECT("'"&O$3&"'!"&"$B2:$AZ2"),INDIRECT("'"&O$3&"'!"&"$B3:$AZ14")))} -> 0 | P13: {=_xlfn.XLOOKUP(P$6&" "&$B13,INDIRECT("'"&P$3&"'!"&"$A17:$A28"),_xlfn.XLOOKUP(P$5,INDIRECT("'"&P$3&"'!"&"$B2:$AZ2"),INDIRECT("'"&P$3&"'!"&"$B17:$AZ28")))} -> 0 | Q13: =P13-N13 -> -12 | S13: =COUNTIF('Active Employees '!$R:$R,'Go1_LearningStatReport_JUN FY25'!$B13) -> 67 | T13: =O13/S13 -> 0
B14: Property and Store Development | D14: {=_xlfn.XLOOKUP($B14,INDIRECT("'"&D$3&"'!"&"$A3:$A14"),_xlfn.XLOOKUP(D$5,INDIRECT("'"&D$3&"'!"&"$B2:$AZ2"),INDIRECT("'"&D$3&"'!"&"$B3:$AZ14")))} -> 7 | E14: {=_xlfn.XLOOKUP(E$6&" "&$B14,INDIRECT("'"&E$3&"'!"&"$A17:$A28"),_xlfn.XLOOKUP(E$5,INDIRECT("'"&E$3&"'!"&"$B2:$AZ2"),INDIRECT("'"&E$3&"'!"&"$B17:$AZ28")))} -> 7 | F14: {=_xlfn.XLOOKUP($B14,INDIRECT("'"&F$3&"'!"&"$A3:$A14"),_xlfn.XLOOKUP(F$5,INDIRECT("'"&F$3&"'!"&"$B2:$AZ2"),INDIRECT("'"&F$3&"'!"&"$B3:$AZ14")))} -> 0 | G14: {=_xlfn.XLOOKUP(G$6&" "&$B14,INDIRECT("'"&G$3&"'!"&"$A17:$A28"),_xlfn.XLOOKUP(G$5,INDIRECT("'"&G$3&"'!"&"$B2:$AZ2"),INDIRECT("'"&G$3&"'!"&"$B17:$AZ28")))} -> 0 | H14: =G14-E14 -> -7 | J14: =COUNTIF('Active Employees '!$R:$R,'Go1_LearningStatReport_JUN FY25'!$B14) -> 26 | K14: =F14/J14 -> 0 | M14: {=_xlfn.XLOOKUP($B14,INDIRECT("'"&M$3&"'!"&"$A3:$A14"),_xlfn.XLOOKUP(M$5,INDIRECT("'"&M$3&"'!"&"$B2:$AZ2"),INDIRECT("'"&M$3&"'!"&"$B3:$AZ14")))} -> 2 | N14: {=_xlfn.XLOOKUP(N$6&" "&$B14,INDIRECT("'"&N$3&"'!"&"$A17:$A28"),_xlfn.XLOOKUP(N$5,INDIRECT("'"&N$3&"'!"&"$B2:$AZ2"),INDIRECT("'"&N$3&"'!"&"$B17:$AZ28")))} -> 7 | O14: {=_xlfn.XLOOKUP($B14,INDIRECT("'"&O$3&"'!"&"$A3:$A14"),_xlfn.XLOOKUP(O$5,INDIRECT("'"&O$3&"'!"&"$B2:$AZ2"),INDIRECT("'"&O$3&"'!"&"$B3:$AZ14")))} -> 0 | P14: {=_xlfn.XLOOKUP(P$6&" "&$B14,INDIRECT("'"&P$3&"'!"&"$A17:$A28"),_xlfn.XLOOKUP(P$5,INDIRECT("'"&P$3&"'!"&"$B2:$AZ2"),INDIRECT("'"&P$3&"'!"&"$B17:$AZ28")))} -> 0 | Q14: =P14-N14 -> -7 | S14: =COUNTIF('Active Employees '!$R:$R,'Go1_LearningStatReport_JUN FY25'!$B14) -> 26 | T14: =O14/S14 -> 0
B15: SPG Development | D15: {=_xlfn.XLOOKUP($B15,INDIRECT("'"&D$3&"'!"&"$A3:$A14"),_xlfn.XLOOKUP(D$5,INDIRECT("'"&D$3&"'!"&"$B2:$AZ2"),INDIRECT("'"&D$3&"'!"&"$B3:$AZ14")))} -> 0 | E15: {=_xlfn.XLOOKUP(E$6&" "&$B15,INDIRECT("'"&E$3&"'!"&"$A17:$A28"),_xlfn.XLOOKUP(E$5,INDIRECT("'"&E$3&"'!"&"$B2:$AZ2"),INDIRECT("'"&E$3&"'!"&"$B17:$AZ28")))} -> 0 | F15: {=_xlfn.XLOOKUP($B15,INDIRECT("'"&F$3&"'!"&"$A3:$A14"),_xlfn.XLOOKUP(F$5,INDIRECT("'"&F$3&"'!"&"$B2:$AZ2"),INDIRECT("'"&F$3&"'!"&"$B3:$AZ14")))} -> 0 | G15: {=_xlfn.XLOOKUP(G$6&" "&$B15,INDIRECT("'"&G$3&"'!"&"$A17:$A28"),_xlfn.XLOOKUP(G$5,INDIRECT("'"&G$3&"'!"&"$B2:$AZ2"),INDIRECT("'"&G$3&"'!"&"$B17:$AZ28")))} -> 0 | H15: =G15-E15 -> 0 | J15: =COUNTIF('Active Employees '!$R:$R,'Go1_LearningStatReport_JUN FY25'!$B15) -> 14 | K15: =F15/J15 -> 0 | M15: {=_xlfn.XLOOKUP($B15,INDIRECT("'"&M$3&"'!"&"$A3:$A14"),_xlfn.XLOOKUP(M$5,INDIRECT("'"&M$3&"'!"&"$B2:$AZ2"),INDIRECT("'"&M$3&"'!"&"$B3:$AZ14")))} -> 0 | N15: {=_xlfn.XLOOKUP(N$6&" "&$B15,INDIRECT("'"&N$3&"'!"&"$A17:$A28"),_xlfn.XLOOKUP(N$5,INDIRECT("'"&N$3&"'!"&"$B2:$AZ2"),INDIRECT("'"&N$3&"'!"&"$B17:$AZ28")))} -> 1 | O15: {=_xlfn.XLOOKUP($B15,INDIRECT("'"&O$3&"'!"&"$A3:$A14"),_xlfn.XLOOKUP(O$5,INDIRECT("'"&O$3&"'!"&"$B2:$AZ2"),INDIRECT("'"&O$3&"'!"&"$B3:$AZ14")))} -> 0 | P15: {=_xlfn.XLOOKUP(P$6&" "&$B15,INDIRECT("'"&P$3&"'!"&"$A17:$A28"),_xlfn.XLOOKUP(P$5,INDIRECT("'"&P$3&"'!"&"$B2:$AZ2"),INDIRECT("'"&P$3&"'!"&"$B17:$AZ28")))} -> 0 | Q15: =P15-N15 -> -1 | S15: =COUNTIF('Active Employees '!$R:$R,'Go1_LearningStatReport_JUN FY25'!$B15) -> 14 | T15: =O15/S15 -> 0
B16: Spot Merch | D16: {=_xlfn.XLOOKUP($B16,INDIRECT("'"&D$3&"'!"&"$A3:$A14"),_xlfn.XLOOKUP(D$5,INDIRECT("'"&D$3&"'!"&"$B2:$AZ2"),INDIRECT("'"&D$3&"'!"&"$B3:$AZ14")))} -> 0 | E16: {=_xlfn.XLOOKUP(E$6&" "&$B16,INDIRECT("'"&E$3&"'!"&"$A17:$A28"),_xlfn.XLOOKUP(E$5,INDIRECT("'"&E$3&"'!"&"$B2:$AZ2"),INDIRECT("'"&E$3&"'!"&"$B17:$AZ28")))} -> 0 | F16: {=_xlfn.XLOOKUP($B16,INDIRECT("'"&F$3&"'!"&"$A3:$A14"),_xlfn.XLOOKUP(F$5,INDIRECT("'"&F$3&"'!"&"$B2:$AZ2"),INDIRECT("'"&F$3&"'!"&"$B3:$AZ14")))} -> 0 | G16: {=_xlfn.XLOOKUP(G$6&" "&$B16,INDIRECT("'"&G$3&"'!"&"$A17:$A28"),_xlfn.XLOOKUP(G$5,INDIRECT("'"&G$3&"'!"&"$B2:$AZ2"),INDIRECT("'"&G$3&"'!"&"$B17:$AZ28")))} -> 0 | H16: =G16-E16 -> 0 | J16: =COUNTIF('Active Employees '!$R:$R,'Go1_LearningStatReport_JUN FY25'!$B16) -> 97 | K16: =F16/J16 -> 0 | M16: {=_xlfn.XLOOKUP($B16,INDIRECT("'"&M$3&"'!"&"$A3:$A14"),_xlfn.XLOOKUP(M$5,INDIRECT("'"&M$3&"'!"&"$B2:$AZ2"),INDIRECT("'"&M$3&"'!"&"$B3:$AZ14")))} -> 0 | N16: {=_xlfn.XLOOKUP(N$6&" "&$B16,INDIRECT("'"&N$3&"'!"&"$A17:$A28"),_xlfn.XLOOKUP(N$5,INDIRECT("'"&N$3&"'!"&"$B2:$AZ2"),INDIRECT("'"&N$3&"'!"&"$B17:$AZ28")))} -> 0 | O16: {=_xlfn.XLOOKUP($B16,INDIRECT("'"&O$3&"'!"&"$A3:$A14"),_xlfn.XLOOKUP(O$5,INDIRECT("'"&O$3&"'!"&"$B2:$AZ2"),INDIRECT("'"&O$3&"'!"&"$B3:$AZ14")))} -> 0 | P16: {=_xlfn.XLOOKUP(P$6&" "&$B16,INDIRECT("'"&P$3&"'!"&"$A17:$A28"),_xlfn.XLOOKUP(P$5,INDIRECT("'"&P$3&"'!"&"$B2:$AZ2"),INDIRECT("'"&P$3&"'!"&"$B17:$AZ28")))} -> 0 | Q16: =P16-N16 -> 0 | S16: =COUNTIF('Active Employees '!$R:$R,'Go1_LearningStatReport_JUN FY25'!$B16) -> 97 | T16: =O16/S16 -> 0
B17: Spotlight Group Aviation | D17: {=_xlfn.XLOOKUP($B17,INDIRECT("'"&D$3&"'!"&"$A3:$A14"),_xlfn.XLOOKUP(D$5,INDIRECT("'"&D$3&"'!"&"$B2:$AZ2"),INDIRECT("'"&D$3&"'!"&"$B3:$AZ14")))} -> 0 | E17: {=_xlfn.XLOOKUP(E$6&" "&$B17,INDIRECT("'"&E$3&"'!"&"$A17:$A28"),_xlfn.XLOOKUP(E$5,INDIRECT("'"&E$3&"'!"&"$B2:$AZ2"),INDIRECT("'"&E$3&"'!"&"$B17:$AZ28")))} -> 0 | F17: {=_xlfn.XLOOKUP($B17,INDIRECT("'"&F$3&"'!"&"$A3:$A14"),_xlfn.XLOOKUP(F$5,INDIRECT("'"&F$3&"'!"&"$B2:$AZ2"),INDIRECT("'"&F$3&"'!"&"$B3:$AZ14")))} -> 0 | G17: {=_xlfn.XLOOKUP(G$6&" "&$B17,INDIRECT("'"&G$3&"'!"&"$A17:$A28"),_xlfn.XLOOKUP(G$5,INDIRECT("'"&G$3&"'!"&"$B2:$AZ2"),INDIRECT("'"&G$3&"'!"&"$B17:$AZ28")))} -> 0 | H17: =G17-E17 -> 0 | J17: =COUNTIF('Active Employees '!$R:$R,'Go1_LearningStatReport_JUN FY25'!$B17) -> 6 | K17: =F17/J17 -> 0 | M17: {=_xlfn.XLOOKUP($B17,INDIRECT("'"&M$3&"'!"&"$A3:$A14"),_xlfn.XLOOKUP(M$5,INDIRECT("'"&M$3&"'!"&"$B2:$AZ2"),INDIRECT("'"&M$3&"'!"&"$B3:$AZ14")))} -> 0 | N17: {=_xlfn.XLOOKUP(N$6&" "&$B17,INDIRECT("'"&N$3&"'!"&"$A17:$A28"),_xlfn.XLOOKUP(N$5,INDIRECT("'"&N$3&"'!"&"$B2:$AZ2"),INDIRECT("'"&N$3&"'!"&"$B17:$AZ28")))} -> 0 | O17: {=_xlfn.XLOOKUP($B17,INDIRECT("'"&O$3&"'!"&"$A3:$A14"),_xlfn.XLOOKUP(O$5,INDIRECT("'"&O$3&"'!"&"$B2:$AZ2"),INDIRECT("'"&O$3&"'!"&"$B3:$AZ14")))} -> 0 | P17: {=_xlfn.XLOOKUP(P$6&" "&$B17,INDIRECT("'"&P$3&"'!"&"$A17:$A28"),_xlfn.XLOOKUP(P$5,INDIRECT("'"&P$3&"'!"&"$B2:$AZ2"),INDIRECT("'"&P$3&"'!"&"$B17:$AZ28")))} -> 0 | Q17: =P17-N17 -> 0 | S17: =COUNTIF('Active Employees '!$R:$R,'Go1_LearningStatReport_JUN FY25'!$B17) -> 6 | T17: =O17/S17 -> 0
B18: Supply Chain | D18: {=_xlfn.XLOOKUP($B18,INDIRECT("'"&D$3&"'!"&"$A3:$A14"),_xlfn.XLOOKUP(D$5,INDIRECT("'"&D$3&"'!"&"$B2:$AZ2"),INDIRECT("'"&D$3&"'!"&"$B3:$AZ14")))} -> 5 | E18: {=_xlfn.XLOOKUP(E$6&" "&$B18,INDIRECT("'"&E$3&"'!"&"$A17:$A28"),_xlfn.XLOOKUP(E$5,INDIRECT("'"&E$3&"'!"&"$B2:$AZ2"),INDIRECT("'"&E$3&"'!"&"$B17:$AZ28")))} -> 5 | F18: {=_xlfn.XLOOKUP($B18,INDIRECT("'"&F$3&"'!"&"$A3:$A14"),_xlfn.XLOOKUP(F$5,INDIRECT("'"&F$3&"'!"&"$B2:$AZ2"),INDIRECT("'"&F$3&"'!"&"$B3:$AZ14")))} -> 0 | G18: {=_xlfn.XLOOKUP(G$6&" "&$B18,INDIRECT("'"&G$3&"'!"&"$A17:$A28"),_xlfn.XLOOKUP(G$5,INDIRECT("'"&G$3&"'!"&"$B2:$AZ2"),INDIRECT("'"&G$3&"'!"&"$B17:$AZ28")))} -> 0 | H18: =G18-E18 -> -5 | J18: =COUNTIF('Active Employees '!$R:$R,'Go1_LearningStatReport_JUN FY25'!$B18) -> 168 | K18: =F18/J18 -> 0 | M18: {=_xlfn.XLOOKUP($B18,INDIRECT("'"&M$3&"'!"&"$A3:$A14"),_xlfn.XLOOKUP(M$5,INDIRECT("'"&M$3&"'!"&"$B2:$AZ2"),INDIRECT("'"&M$3&"'!"&"$B3:$AZ14")))} -> 0 | N18: {=_xlfn.XLOOKUP(N$6&" "&$B18,INDIRECT("'"&N$3&"'!"&"$A17:$A28"),_xlfn.XLOOKUP(N$5,INDIRECT("'"&N$3&"'!"&"$B2:$AZ2"),INDIRECT("'"&N$3&"'!"&"$B17:$AZ28")))} -> 8 | O18: {=_xlfn.XLOOKUP($B18,INDIRECT("'"&O$3&"'!"&"$A3:$A14"),_xlfn.XLOOKUP(O$5,INDIRECT("'"&O$3&"'!"&"$B2:$AZ2"),INDIRECT("'"&O$3&"'!"&"$B3:$AZ14")))} -> 0 | P18: {=_xlfn.XLOOKUP(P$6&" "&$B18,INDIRECT("'"&P$3&"'!"&"$A17:$A28"),_xlfn.XLOOKUP(P$5,INDIRECT("'"&P$3&"'!"&"$B2:$AZ2"),INDIRECT("'"&P$3&"'!"&"$B17:$AZ28")))} -> 0 | Q18: =P18-N18 -> -8 | S18: =COUNTIF('Active Employees '!$R:$R,'Go1_LearningStatReport_JUN FY25'!$B18) -> 168 | T18: =O18/S18 -> 0
B19: Grand Total | D19: =SUM(D7:D18) -> 55 | E19: =SUM(E7:E18) -> 55 | F19: =SUM(F7:F18) -> 0 | G19: =SUM(G7:G18) -> 0 | H19: =SUM(H7:H18) -> -55 | J19: =SUM(J7:J18) -> 627 | K19: =F19/J19 -> 0 | M19: =SUM(M7:M18) -> 19 | N19: =SUM(N7:N18) -> 84 | O19: =SUM(O7:O18) -> 1 | P19: =SUM(P7:P18) -> 1 | Q19: =SUM(Q7:Q18) -> -83 | S19: =SUM(S7:S18) -> 627 | T19: =O19/S19 -> 0.0015948963
B20: *Var denotes the Variance in YTD Columns

Sheet Currently Assigned
A3: Count of Status | B3: Column Labels
A4: Row Labels | B4: Assigned | C4: Grand Total
A5: Finance | B5: 121 | C5: 121
A6: Human Resources | B6: 83 | C6: 83
A7: IT | B7: 371 | C7: 371
A8: Marketing | B8: 212 | C8: 212
A9: SPG Development | B9: 70 | C9: 70
A10: Supply Chain | B10: 141 | C10: 141
A11: Grand Total | B11: 998 | C11: 998
A23: Status | B23: Completed
A25: Count of Status | B25: Column Labels
A26: Row Labels | B26: JUL, FY25 | C26: AUG, FY25 | D26: SEP, FY25 | E26: OCT, FY25 | F26: NOV, FY25 | G26: DEC, FY25 | H26: JAN, FY25 | I26: FEB, FY25 | J26: MAR, FY25 | K26: APR, FY25 | L26: MAY, FY25 | M26: JUN, FY25 | N26: Grand Total
A27: Finance | L27: 3 | M27: 4 | N27: 7
A28: Human Resources | B28: 42 | C28: 4 | D28: 10 | E28: 3 | F28: 1 | G28: 2 | H28: 1 | I28: 4 | J28: 3 | N28: 70
A29: IT | C29: 1 | D29: 2 | F29: 1 | I29: 2 | N29: 6
A30: Marketing | C30: 6 | J30: 2 | L30: 4 | N30: 12
A31: Supply Chain | B31: 5 | J31: 5 | K31: 5 | L31: 1 | M31: 2 | N31: 18
A32: Grand Total | B32: 47 | C32: 11 | D32: 12 | E32: 3 | F32: 2 | G32: 2 | H32: 1 | I32: 6 | J32: 10 | K32: 5 | L32: 8 | M32: 6 | N32: 113
A38: Status | B38: In Progress
A40: Count of Status | B40: Column Labels
A41: Row Labels | B41: JUL, FY25 | C41: AUG, FY25 | D41: SEP, FY25 | E41: OCT, FY25 | F41: NOV, FY25 | G41: DEC, FY25 | H41: FEB, FY25 | I41: MAR, FY25 | J41: MAY, FY25 | K41: JUN, FY25 | L41: Grand Total
A42: Finance | J42: 1 | K42: 2 | L42: 3
A43: Human Resources | B43: 11 | D43: 2 | E43: 1 | F43: 2 | I43: 1 | J43: 3 | L43: 20
A44: IT | B44: 5 | C44: 1 | H44: 2 | L44: 8
A45: Marketing | B45: 1 | G45: 1 | I45: 1 | L45: 3
A46: SPG Development | F46: 3 | L46: 3
A47: Supply Chain | G47: 1 | I47: 2 | L47: 3
A48: Grand Total | B48: 17 | C48: 1 | D48: 2 | E48: 1 | F48: 5 | G48: 2 | H48: 2 | I48: 4 | J48: 4 | K48: 2 | L48: 40

Sheet Completed FEED
A1: Completed | B1: FY24 | S1: FY25 | AJ1: FY26
A2: Shared Services | B2: ="JUL, "&B1 -> JUL, FY24 | C2: ="AUG, "&B1 -> AUG, FY24 | D2: ="SEP, "&B1 -> SEP, FY24 | E2: ="Q1, "&B1 -> Q1, FY24 | F2: ="OCT, "&B1 -> OCT, FY24 | G2: ="NOV, "&B1 -> NOV, FY24 | H2: ="DEC, "&B1 -> DEC, FY24 | I2: ="Q2, "&B1 -> Q2, FY24 | J2: ="JAN, "&B1 -> JAN, FY24 | K2: ="FEB, "&B1 -> FEB, FY24 | L2: ="MAR, "&B1 -> MAR, FY24 | M2: ="Q3, "&B1 -> Q3, FY24 | N2: ="APR, "&B1 -> APR, FY24 | O2: ="MAY, "&B1 -> MAY, FY24 | P2: ="JUN, "&B1 -> JUN, FY24 | Q2: ="Q4, "&B1 -> Q4, FY24 | R2: ="Full Year, "&B1 -> Full Year, FY24 | S2: ="JUL, "&S1 -> JUL, FY25 | T2: ="AUG, "&S1 -> AUG, FY25 | U2: ="SEP, "&S1 -> SEP, FY25 | V2: ="Q1, "&S1 -> Q1, FY25 | W2: ="OCT, "&S1 -> OCT, FY25 | X2: ="NOV, "&S1 -> NOV, FY25 | Y2: ="DEC, "&S1 -> DEC, FY25 | Z2: ="Q2, "&S1 -> Q2, FY25 | AA2: ="JAN, "&S1 -> JAN, FY25 | AB2: ="FEB, "&S1 -> FEB, FY25 | AC2: ="MAR, "&S1 -> MAR, FY25 | AD2: ="Q3, "&S1 -> Q3, FY25 | AE2: ="APR, "&S1 -> APR, FY25 | AF2: ="MAY, "&S1 -> MAY, FY25 | AG2: ="JUN, "&S1 -> JUN, FY25 | AH2: ="Q4, "&S1 -> Q4, FY25 | AI2: ="Full Year, "&S1 -> Full Year, FY25 | AJ2: ="JUL, "&AJ1 -> JUL, FY26 | AK2: ="AUG, "&AJ1 -> AUG, FY26 | AL2: ="SEP, "&AJ1 -> SEP, FY26 | AM2: ="Q1, "&AJ1 -> Q1, FY26 | AN2: ="OCT, "&AJ1 -> OCT, FY26 | AO2: ="NOV, "&AJ1 -> NOV, FY26 | AP2: ="DEC, "&AJ1 -> DEC, FY26 | AQ2: ="Q2, "&AJ1 -> Q2, FY26 | AR2: ="JAN, "&AJ1 -> JAN, FY26 | AS2: ="FEB, "&AJ1 -> FEB, FY26 | AT2: ="MAR, "&AJ1 -> MAR, FY26 | AU2: ="Q3, "&AJ1 -> Q3, FY26 | AV2: ="APR, "&AJ1 -> APR, FY26 | AW2: ="MAY, "&AJ1 -> MAY, FY26 | AX2: ="JUN, "&AJ1 -> JUN, FY26 | AY2: ="Q4, "&AJ1 -> Q4, FY26 | AZ2: ="Full Year, "&AJ1 -> Full Year, FY26
A3: eCommerce & Omni Channel | B3: =COUNTIFS('Assigned Learning Data Dump'!$W:$W,'Completed FEED'!$A3,'Assigned Learning Data Dump'!$F:$F,$A$1,'Assigned Learning Data Dump'!$U:$U,'Completed FEED'!B$2) -> 8 | C3: =COUNTIFS('Assigned Learning Data Dump'!$W:$W,'Completed FEED'!$A3,'Assigned Learning Data Dump'!$F:$F,$A$1,'Assigned Learning Data Dump'!$U:$U,'Completed FEED'!C$2) -> 0 | D3: =COUNTIFS('Assigned Learning Data Dump'!$W:$W,'Completed FEED'!$A3,'Assigned Learning Data Dump'!$F:$F,$A$1,'Assigned Learning Data Dump'!$U:$U,'Completed FEED'!D$2) -> 1 | E3: =SUBTOTAL(9,B3:D3) -> 9 | F3: =COUNTIFS('Assigned Learning Data Dump'!$W:$W,'Completed FEED'!$A3,'Assigned Learning Data Dump'!$F:$F,$A$1,'Assigned Learning Data Dump'!$U:$U,'Completed FEED'!F$2) -> 0 | G3: =COUNTIFS('Assigned Learning Data Dump'!$W:$W,'Completed FEED'!$A3,'Assigned Learning Data Dump'!$F:$F,$A$1,'Assigned Learning Data Dump'!$U:$U,'Completed FEED'!G$2) -> 0 | H3: =COUNTIFS('Assigned Learning Data Dump'!$W:$W,'Completed FEED'!$A3,'Assigned Learning Data Dump'!$F:$F,$A$1,'Assigned Learning Data Dump'!$U:$U,'Completed FEED'!H$2) -> 0 | I3: =SUBTOTAL(9,F3:H3) -> 0 | J3: =COUNTIFS('Assigned Learning Data Dump'!$W:$W,'Completed FEED'!$A3,'Assigned Learning Data Dump'!$F:$F,$A$1,'Assigned Learning Data Dump'!$U:$U,'Completed FEED'!J$2) -> 2 | K3: =COUNTIFS('Assigned Learning Data Dump'!$W:$W,'Completed FEED'!$A3,'Assigned Learning Data Dump'!$F:$F,$A$1,'Assigned Learning Data Dump'!$U:$U,'Completed FEED'!K$2) -> 2 | L3: =COUNTIFS('Assigned Learning Data Dump'!$W:$W,'Completed FEED'!$A3,'Assigned Learning Data Dump'!$F:$F,$A$1,'Assigned Learning Data Dump'!$U:$U,'Completed FEED'!L$2) -> 4 | M3: =SUBTOTAL(9,J3:L3) -> 8 | N3: =COUNTIFS('Assigned Learning Data Dump'!$W:$W,'Completed FEED'!$A3,'Assigned Learning Data Dump'!$F:$F,$A$1,'Assigned Learning Data Dump'!$U:$U,'Completed FEED'!N$2) -> 0 | O3: =COUNTIFS('Assigned Learning Data Dump'!$W:$W,'Completed FEED'!$A3,'Assigned Learning Data Dump'!$F:$F,$A$1,'Assigned Learning Data Dump'!$U:$U,'Completed FEED'!O$2) -> 1 | P3: =COUNTIFS('Assigned Learning Data Dump'!$W:$W,'Completed FEED'!$A3,'Assigned Learning Data Dump'!$F:$F,$A$1,'Assigned Learning Data Dump'!$U:$U,'Completed FEED'!P$2) -> 13 | Q3: =SUBTOTAL(9,N3:P3) -> 14 | R3: =SUBTOTAL(9,B3:Q3) -> 31 | S3: =COUNTIFS('Assigned Learning Data Dump'!$W:$W,'Completed FEED'!$A3,'Assigned Learning Data Dump'!$F:$F,$A$1,'Assigned Learning Data Dump'!$U:$U,'Completed FEED'!S$2) -> 1 | T3: =COUNTIFS('Assigned Learning Data Dump'!$W:$W,'Completed FEED'!$A3,'Assigned Learning Data Dump'!$F:$F,$A$1,'Assigned Learning Data Dump'!$U:$U,'Completed FEED'!T$2) -> 0 | U3: =COUNTIFS('Assigned Learning Data Dump'!$W:$W,'Completed FEED'!$A3,'Assigned Learning Data Dump'!$F:$F,$A$1,'Assigned Learning Data Dump'!$U:$U,'Completed FEED'!U$2) -> 0 | V3: =SUBTOTAL(9,S3:U3) -> 1 | W3: =COUNTIFS('Assigned Learning Data Dump'!$W:$W,'Completed FEED'!$A3,'Assigned Learning Data Dump'!$F:$F,$A$1,'Assigned Learning Data Dump'!$U:$U,'Completed FEED'!W$2) -> 2 | X3: =COUNTIFS('Assigned Learning Data Dump'!$W:$W,'Completed FEED'!$A3,'Assigned Learning Data Dump'!$F:$F,$A$1,'Assigned Learning Data Dump'!$U:$U,'Completed FEED'!X$2) -> 0 | Y3: =COUNTIFS('Assigned Learning Data Dump'!$W:$W,'Completed FEED'!$A3,'Assigned Learning Data Dump'!$F:$F,$A$1,'Assigned Learning Data Dump'!$U:$U,'Completed FEED'!Y$2) -> 6 | Z3: =SUBTOTAL(9,W3:Y3) -> 8 | AA3: =COUNTIFS('Assigned Learning Data Dump'!$W:$W,'Completed FEED'!$A3,'Assigned Learning Data Dump'!$F:$F,$A$1,'Assigned Learning Data Dump'!$U:$U,'Completed FEED'!AA$2) -> 0 | AB3: =COUNTIFS('Assigned Learning Data Dump'!$W:$W,'Completed FEED'!$A3,'Assigned Learning Data Dump'!$F:$F,$A$1,'Assigned Learning Data Dump'!$U:$U,'Completed FEED'!AB$2) -> 5 | AC3: =COUNTIFS('Assigned Learning Data Dump'!$W:$W,'Completed FEED'!$A3,'Assigned Learning Data Dump'!$F:$F,$A$1,'Assigned Learning Data Dump'!$U:$U,'Completed FEED'!AC$2) -> 0 | AD3: =SUBTOTAL(9,AA3:AC3) -> 5 | AE3: =COUNTIFS('Assigned Learning Data Dump'!$W:$W,'Completed FEED'!$A3,'Assigned Learning Data Dump'!$F:$F,$A$1,'Assigned Learning Data Dump'!$U:$U,'Completed FEED'!AE$2) -> 0 | AF3: =COUNTIFS('Assigned Learning Data Dump'!$W:$W,'Completed FEED'!$A3,'Assigned Learning Data Dump'!$F:$F,$A$1,'Assigned Learning Data Dump'!$U:$U,'Completed FEED'!AF$2) -> 1 | AG3: =COUNTIFS('Assigned Learning Data Dump'!$W:$W,'Completed FEED'!$A3,'Assigned Learning Data Dump'!$F:$F,$A$1,'Assigned Learning Data Dump'!$U:$U,'Completed FEED'!AG$2) -> 0 | AH3: =SUBTOTAL(9,AE3:AG3) -> 1 | AI3: =SUBTOTAL(9,S3:AH3) -> 15 | AJ3: =COUNTIFS('Assigned Learning Data Dump'!$W:$W,'Completed FEED'!$A3,'Assigned Learning Data Dump'!$F:$F,$A$1,'Assigned Learning Data Dump'!$U:$U,'Completed FEED'!AJ$2) -> 0 | AK3: =COUNTIFS('Assigned Learning Data Dump'!$W:$W,'Completed FEED'!$A3,'Assigned Learning Data Dump'!$F:$F,$A$1,'Assigned Learning Data Dump'!$U:$U,'Completed FEED'!AK$2) -> 0 | AL3: =COUNTIFS('Assigned Learning Data Dump'!$W:$W,'Completed FEED'!$A3,'Assigned Learning Data Dump'!$F:$F,$A$1,'Assigned Learning Data Dump'!$U:$U,'Completed FEED'!AL$2) -> 0 | AM3: =SUBTOTAL(9,AJ3:AL3) -> 0 | AN3: =COUNTIFS('Assigned Learning Data Dump'!$W:$W,'Completed FEED'!$A3,'Assigned Learning Data Dump'!$F:$F,$A$1,'Assigned Learning Data Dump'!$U:$U,'Completed FEED'!AN$2) -> 0 | AO3: =COUNTIFS('Assigned Learning Data Dump'!$W:$W,'Completed FEED'!$A3,'Assigned Learning Data Dump'!$F:$F,$A$1,'Assigned Learning Data Dump'!$U:$U,'Completed FEED'!AO$2) -> 0 | AP3: =COUNTIFS('Assigned Learning Data Dump'!$W:$W,'Completed FEED'!$A3,'Assigned Learning Data Dump'!$F:$F,$A$1,'Assigned Learning Data Dump'!$U:$U,'Completed FEED'!AP$2) -> 0 | AQ3: =SUBTOTAL(9,AN3:AP3) -> 0 | AR3: =COUNTIFS('Assigned Learning Data Dump'!$W:$W,'Completed FEED'!$A3,'Assigned Learning Data Dump'!$F:$F,$A$1,'Assigned Learning Data Dump'!$U:$U,'Completed FEED'!AR$2) -> 0 | AS3: =COUNTIFS('Assigned Learning Data Dump'!$W:$W,'Completed FEED'!$A3,'Assigned Learning Data Dump'!$F:$F,$A$1,'Assigned Learning Data Dump'!$U:$U,'Completed FEED'!AS$2) -> 0 | AT3: =COUNTIFS('Assigned Learning Data Dump'!$W:$W,'Completed FEED'!$A3,'Assigned Learning Data Dump'!$F:$F,$A$1,'Assigned Learning Data Dump'!$U:$U,'Completed FEED'!AT$2) -> 0 | AU3: =SUBTOTAL(9,AR3:AT3) -> 0 | AV3: =COUNTIFS('Assigned Learning Data Dump'!$W:$W,'Completed FEED'!$A3,'Assigned Learning Data Dump'!$F:$F,$A$1,'Assigned Learning Data Dump'!$U:$U,'Completed FEED'!AV$2) -> 0 | AW3: =COUNTIFS('Assigned Learning Data Dump'!$W:$W,'Completed FEED'!$A3,'Assigned Learning Data Dump'!$F:$F,$A$1,'Assigned Learning Data Dump'!$U:$U,'Completed FEED'!AW$2) -> 0 | AX3: =COUNTIFS('Assigned Learning Data Dump'!$W:$W,'Completed FEED'!$A3,'Assigned Learning Data Dump'!$F:$F,$A$1,'Assigned Learning Data Dump'!$U:$U,'Completed FEED'!AX$2) -> 0 | AY3: =SUBTOTAL(9,AV3:AX3) -> 0 | AZ3: =SUBTOTAL(9,AJ3:AY3) -> 0
A4: FFM | B4: =COUNTIFS('Assigned Learning Data Dump'!$W:$W,'Completed FEED'!$A4,'Assigned Learning Data Dump'!$F:$F,$A$1,'Assigned Learning Data Dump'!$U:$U,'Completed FEED'!B$2) -> 2 | C4: =COUNTIFS('Assigned Learning Data Dump'!$W:$W,'Completed FEED'!$A4,'Assigned Learning Data Dump'!$F:$F,$A$1,'Assigned Learning Data Dump'!$U:$U,'Completed FEED'!C$2) -> 0 | D4: =COUNTIFS('Assigned Learning Data Dump'!$W:$W,'Completed FEED'!$A4,'Assigned Learning Data Dump'!$F:$F,$A$1,'Assigned Learning Data Dump'!$U:$U,'Completed FEED'!D$2) -> 0 | E4: =SUBTOTAL(9,B4:D4) -> 2 | F4: =COUNTIFS('Assigned Learning Data Dump'!$W:$W,'Completed FEED'!$A4,'Assigned Learning Data Dump'!$F:$F,$A$1,'Assigned Learning Data Dump'!$U:$U,'Completed FEED'!F$2) -> 0 | G4: =COUNTIFS('Assigned Learning Data Dump'!$W:$W,'Completed FEED'!$A4,'Assigned Learning Data Dump'!$F:$F,$A$1,'Assigned Learning Data Dump'!$U:$U,'Completed FEED'!G$2) -> 0 | H4: =COUNTIFS('Assigned Learning Data Dump'!$W:$W,'Completed FEED'!$A4,'Assigned Learning Data Dump'!$F:$F,$A$1,'Assigned Learning Data Dump'!$U:$U,'Completed FEED'!H$2) -> 0 | I4: =SUBTOTAL(9,F4:H4) -> 0 | J4: =COUNTIFS('Assigned Learning Data Dump'!$W:$W,'Completed FEED'!$A4,'Assigned Learning Data Dump'!$F:$F,$A$1,'Assigned Learning Data Dump'!$U:$U,'Completed FEED'!J$2) -> 0 | K4: =COUNTIFS('Assigned Learning Data Dump'!$W:$W,'Completed FEED'!$A4,'Assigned Learning Data Dump'!$F:$F,$A$1,'Assigned Learning Data Dump'!$U:$U,'Completed FEED'!K$2) -> 0 | L4: =COUNTIFS('Assigned Learning Data Dump'!$W:$W,'Completed FEED'!$A4,'Assigned Learning Data Dump'!$F:$F,$A$1,'Assigned Learning Data Dump'!$U:$U,'Completed FEED'!L$2) -> 0 | M4: =SUBTOTAL(9,J4:L4) -> 0 | N4: =COUNTIFS('Assigned Learning Data Dump'!$W:$W,'Completed FEED'!$A4,'Assigned Learning Data Dump'!$F:$F,$A$1,'Assigned Learning Data Dump'!$U:$U,'Completed FEED'!N$2) -> 1 | O4: =COUNTIFS('Assigned Learning Data Dump'!$W:$W,'Completed FEED'!$A4,'Assigned Learning Data Dump'!$F:$F,$A$1,'Assigned Learning Data Dump'!$U:$U,'Completed FEED'!O$2) -> 0 | P4: =COUNTIFS('Assigned Learning Data Dump'!$W:$W,'Completed FEED'!$A4,'Assigned Learning Data Dump'!$F:$F,$A$1,'Assigned Learning Data Dump'!$U:$U,'Completed FEED'!P$2) -> 0 | Q4: =SUBTOTAL(9,N4:P4) -> 1 | R4: =SUBTOTAL(9,B4:Q4) -> 3 | S4: =COUNTIFS('Assigned Learning Data Dump'!$W:$W,'Completed FEED'!$A4,'Assigned Learning Data Dump'!$F:$F,$A$1,'Assigned Learning Data Dump'!$U:$U,'Completed FEED'!S$2) -> 0 | T4: =COUNTIFS('Assigned Learning Data Dump'!$W:$W,'Completed FEED'!$A4,'Assigned Learning Data Dump'!$F:$F,$A$1,'Assigned Learning Data Dump'!$U:$U,'Completed FEED'!T$2) -> 0 | U4: =COUNTIFS('Assigned Learning Data Dump'!$W:$W,'Completed FEED'!$A4,'Assigned Learning Data Dump'!$F:$F,$A$1,'Assigned Learning Data Dump'!$U:$U,'Completed FEED'!U$2) -> 0 | V4: =SUBTOTAL(9,S4:U4) -> 0 | W4: =COUNTIFS('Assigned Learning Data Dump'!$W:$W,'Completed FEED'!$A4,'Assigned Learning Data Dump'!$F:$F,$A$1,'Assigned Learning Data Dump'!$U:$U,'Completed FEED'!W$2) -> 0 | X4: =COUNTIFS('Assigned Learning Data Dump'!$W:$W,'Completed FEED'!$A4,'Assigned Learning Data Dump'!$F:$F,$A$1,'Assigned Learning Data Dump'!$U:$U,'Completed FEED'!X$2) -> 0 | Y4: =COUNTIFS('Assigned Learning Data Dump'!$W:$W,'Completed FEED'!$A4,'Assigned Learning Data Dump'!$F:$F,$A$1,'Assigned Learning Data Dump'!$U:$U,'Completed FEED'!Y$2) -> 0 | Z4: =SUBTOTAL(9,W4:Y4) -> 0 | AA4: =COUNTIFS('Assigned Learning Data Dump'!$W:$W,'Completed FEED'!$A4,'Assigned Learning Data Dump'!$F:$F,$A$1,'Assigned Learning Data Dump'!$U:$U,'Completed FEED'!AA$2) -> 0 | AB4: =COUNTIFS('Assigned Learning Data Dump'!$W:$W,'Completed FEED'!$A4,'Assigned Learning Data Dump'!$F:$F,$A$1,'Assigned Learning Data Dump'!$U:$U,'Completed FEED'!AB$2) -> 0 | AC4: =COUNTIFS('Assigned Learning Data Dump'!$W:$W,'Completed FEED'!$A4,'Assigned Learning Data Dump'!$F:$F,$A$1,'Assigned Learning Data Dump'!$U:$U,'Completed FEED'!AC$2) -> 0 | AD4: =SUBTOTAL(9,AA4:AC4) -> 0 | AE4: =COUNTIFS('Assigned Learning Data Dump'!$W:$W,'Completed FEED'!$A4,'Assigned Learning Data Dump'!$F:$F,$A$1,'Assigned Learning Data Dump'!$U:$U,'Completed FEED'!AE$2) -> 0 | AF4: =COUNTIFS('Assigned Learning Data Dump'!$W:$W,'Completed FEED'!$A4,'Assigned Learning Data Dump'!$F:$F,$A$1,'Assigned Learning Data Dump'!$U:$U,'Completed FEED'!AF$2) -> 0 | AG4: =COUNTIFS('Assigned Learning Data Dump'!$W:$W,'Completed FEED'!$A4,'Assigned Learning Data Dump'!$F:$F,$A$1,'Assigned Learning Data Dump'!$U:$U,'Completed FEED'!AG$2) -> 0 | AH4: =SUBTOTAL(9,AE4:AG4) -> 0 | AI4: =SUBTOTAL(9,S4:AH4) -> 0 | AJ4: =COUNTIFS('Assigned Learning Data Dump'!$W:$W,'Completed FEED'!$A4,'Assigned Learning Data Dump'!$F:$F,$A$1,'Assigned Learning Data Dump'!$U:$U,'Completed FEED'!AJ$2) -> 0 | AK4: =COUNTIFS('Assigned Learning Data Dump'!$W:$W,'Completed FEED'!$A4,'Assigned Learning Data Dump'!$F:$F,$A$1,'Assigned Learning Data Dump'!$U:$U,'Completed FEED'!AK$2) -> 0 | AL4: =COUNTIFS('Assigned Learning Data Dump'!$W:$W,'Completed FEED'!$A4,'Assigned Learning Data Dump'!$F:$F,$A$1,'Assigned Learning Data Dump'!$U:$U,'Completed FEED'!AL$2) -> 0 | AM4: =SUBTOTAL(9,AJ4:AL4) -> 0 | AN4: =COUNTIFS('Assigned Learning Data Dump'!$W:$W,'Completed FEED'!$A4,'Assigned Learning Data Dump'!$F:$F,$A$1,'Assigned Learning Data Dump'!$U:$U,'Completed FEED'!AN$2) -> 0 | AO4: =COUNTIFS('Assigned Learning Data Dump'!$W:$W,'Completed FEED'!$A4,'Assigned Learning Data Dump'!$F:$F,$A$1,'Assigned Learning Data Dump'!$U:$U,'Completed FEED'!AO$2) -> 0 | AP4: =COUNTIFS('Assigned Learning Data Dump'!$W:$W,'Completed FEED'!$A4,'Assigned Learning Data Dump'!$F:$F,$A$1,'Assigned Learning Data Dump'!$U:$U,'Completed FEED'!AP$2) -> 0 | AQ4: =SUBTOTAL(9,AN4:AP4) -> 0 | AR4: =COUNTIFS('Assigned Learning Data Dump'!$W:$W,'Completed FEED'!$A4,'Assigned Learning Data Dump'!$F:$F,$A$1,'Assigned Learning Data Dump'!$U:$U,'Completed FEED'!AR$2) -> 0 | AS4: =COUNTIFS('Assigned Learning Data Dump'!$W:$W,'Completed FEED'!$A4,'Assigned Learning Data Dump'!$F:$F,$A$1,'Assigned Learning Data Dump'!$U:$U,'Completed FEED'!AS$2) -> 0 | AT4: =COUNTIFS('Assigned Learning Data Dump'!$W:$W,'Completed FEED'!$A4,'Assigned Learning Data Dump'!$F:$F,$A$1,'Assigned Learning Data Dump'!$U:$U,'Completed FEED'!AT$2) -> 0 | AU4: =SUBTOTAL(9,AR4:AT4) -> 0 | AV4: =COUNTIFS('Assigned Learning Data Dump'!$W:$W,'Completed FEED'!$A4,'Assigned Learning Data Dump'!$F:$F,$A$1,'Assigned Learning Data Dump'!$U:$U,'Completed FEED'!AV$2) -> 0 | AW4: =COUNTIFS('Assigned Learning Data Dump'!$W:$W,'Completed FEED'!$A4,'Assigned Learning Data Dump'!$F:$F,$A$1,'Assigned Learning Data Dump'!$U:$U,'Completed FEED'!AW$2) -> 0 | AX4: =COUNTIFS('Assigned Learning Data Dump'!$W:$W,'Completed FEED'!$A4,'Assigned Learning Data Dump'!$F:$F,$A$1,'Assigned Learning Data Dump'!$U:$U,'Completed FEED'!AX$2) -> 0 | AY4: =SUBTOTAL(9,AV4:AX4) -> 0 | AZ4: =SUBTOTAL(9,AJ4:AY4) -> 0
A5: Finance | B5: =COUNTIFS('Assigned Learning Data Dump'!$W:$W,'Completed FEED'!$A5,'Assigned Learning Data Dump'!$F:$F,$A$1,'Assigned Learning Data Dump'!$U:$U,'Completed FEED'!B$2) -> 2 | C5: =COUNTIFS('Assigned Learning Data Dump'!$W:$W,'Completed FEED'!$A5,'Assigned Learning Data Dump'!$F:$F,$A$1,'Assigned Learning Data Dump'!$U:$U,'Completed FEED'!C$2) -> 0 | D5: =COUNTIFS('Assigned Learning Data Dump'!$W:$W,'Completed FEED'!$A5,'Assigned Learning Data Dump'!$F:$F,$A$1,'Assigned Learning Data Dump'!$U:$U,'Completed FEED'!D$2) -> 0 | E5: =SUBTOTAL(9,B5:D5) -> 2 | F5: =COUNTIFS('Assigned Learning Data Dump'!$W:$W,'Completed FEED'!$A5,'Assigned Learning Data Dump'!$F:$F,$A$1,'Assigned Learning Data Dump'!$U:$U,'Completed FEED'!F$2) -> 0 | G5: =COUNTIFS('Assigned Learning Data Dump'!$W:$W,'Completed FEED'!$A5,'Assigned Learning Data Dump'!$F:$F,$A$1,'Assigned Learning Data Dump'!$U:$U,'Completed FEED'!G$2) -> 0 | H5: =COUNTIFS('Assigned Learning Data Dump'!$W:$W,'Completed FEED'!$A5,'Assigned Learning Data Dump'!$F:$F,$A$1,'Assigned Learning Data Dump'!$U:$U,'Completed FEED'!H$2) -> 0 | I5: =SUBTOTAL(9,F5:H5) -> 0 | J5: =COUNTIFS('Assigned Learning Data Dump'!$W:$W,'Completed FEED'!$A5,'Assigned Learning Data Dump'!$F:$F,$A$1,'Assigned Learning Data Dump'!$U:$U,'Completed FEED'!J$2) -> 0 | K5: =COUNTIFS('Assigned Learning Data Dump'!$W:$W,'Completed FEED'!$A5,'Assigned Learning Data Dump'!$F:$F,$A$1,'Assigned Learning Data Dump'!$U:$U,'Completed FEED'!K$2) -> 0 | L5: =COUNTIFS('Assigned Learning Data Dump'!$W:$W,'Completed FEED'!$A5,'Assigned Learning Data Dump'!$F:$F,$A$1,'Assigned Learning Data Dump'!$U:$U,'Completed FEED'!L$2) -> 0 | M5: =SUBTOTAL(9,J5:L5) -> 0 | N5: =COUNTIFS('Assigned Learning Data Dump'!$W:$W,'Completed FEED'!$A5,'Assigned Learning Data Dump'!$F:$F,$A$1,'Assigned Learning Data Dump'!$U:$U,'Completed FEED'!N$2) -> 0 | O5: =COUNTIFS('Assigned Learning Data Dump'!$W:$W,'Completed FEED'!$A5,'Assigned Learning Data Dump'!$F:$F,$A$1,'Assigned Learning Data Dump'!$U:$U,'Completed FEED'!O$2) -> 0 | P5: =COUNTIFS('Assigned Learning Data Dump'!$W:$W,'Completed FEED'!$A5,'Assigned Learning Data Dump'!$F:$F,$A$1,'Assigned Learning Data Dump'!$U:$U,'Completed FEED'!P$2) -> 0 | Q5: =SUBTOTAL(9,N5:P5) -> 0 | R5: =SUBTOTAL(9,B5:Q5) -> 2 | S5: =COUNTIFS('Assigned Learning Data Dump'!$W:$W,'Completed FEED'!$A5,'Assigned Learning Data Dump'!$F:$F,$A$1,'Assigned Learning Data Dump'!$U:$U,'Completed FEED'!S$2) -> 0 | T5: =COUNTIFS('Assigned Learning Data Dump'!$W:$W,'Completed FEED'!$A5,'Assigned Learning Data Dump'!$F:$F,$A$1,'Assigned Learning Data Dump'!$U:$U,'Completed FEED'!T$2) -> 0 | U5: =COUNTIFS('Assigned Learning Data Dump'!$W:$W,'Completed FEED'!$A5,'Assigned Learning Data Dump'!$F:$F,$A$1,'Assigned Learning Data Dump'!$U:$U,'Completed FEED'!U$2) -> 0 | V5: =SUBTOTAL(9,S5:U5) -> 0 | W5: =COUNTIFS('Assigned Learning Data Dump'!$W:$W,'Completed FEED'!$A5,'Assigned Learning Data Dump'!$F:$F,$A$1,'Assigned Learning Data Dump'!$U:$U,'Completed FEED'!W$2) -> 0 | X5: =COUNTIFS('Assigned Learning Data Dump'!$W:$W,'Completed FEED'!$A5,'Assigned Learning Data Dump'!$F:$F,$A$1,'Assigned Learning Data Dump'!$U:$U,'Completed FEED'!X$2) -> 0 | Y5: =COUNTIFS('Assigned Learning Data Dump'!$W:$W,'Completed FEED'!$A5,'Assigned Learning Data Dump'!$F:$F,$A$1,'Assigned Learning Data Dump'!$U:$U,'Completed FEED'!Y$2) -> 0 | Z5: =SUBTOTAL(9,W5:Y5) -> 0 | AA5: =COUNTIFS('Assigned Learning Data Dump'!$W:$W,'Completed FEED'!$A5,'Assigned Learning Data Dump'!$F:$F,$A$1,'Assigned Learning Data Dump'!$U:$U,'Completed FEED'!AA$2) -> 0 | AB5: =COUNTIFS('Assigned Learning Data Dump'!$W:$W,'Completed FEED'!$A5,'Assigned Learning Data Dump'!$F:$F,$A$1,'Assigned Learning Data Dump'!$U:$U,'Completed FEED'!AB$2) -> 0 | AC5: =COUNTIFS('Assigned Learning Data Dump'!$W:$W,'Completed FEED'!$A5,'Assigned Learning Data Dump'!$F:$F,$A$1,'Assigned Learning Data Dump'!$U:$U,'Completed FEED'!AC$2) -> 0 | AD5: =SUBTOTAL(9,AA5:AC5) -> 0 | AE5: =COUNTIFS('Assigned Learning Data Dump'!$W:$W,'Completed FEED'!$A5,'Assigned Learning Data Dump'!$F:$F,$A$1,'Assigned Learning Data Dump'!$U:$U,'Completed FEED'!AE$2) -> 0 | AF5: =COUNTIFS('Assigned Learning Data Dump'!$W:$W,'Completed FEED'!$A5,'Assigned Learning Data Dump'!$F:$F,$A$1,'Assigned Learning Data Dump'!$U:$U,'Completed FEED'!AF$2) -> 3 | AG5: =COUNTIFS('Assigned Learning Data Dump'!$W:$W,'Completed FEED'!$A5,'Assigned Learning Data Dump'!$F:$F,$A$1,'Assigned Learning Data Dump'!$U:$U,'Completed FEED'!AG$2) -> 4 | AH5: =SUBTOTAL(9,AE5:AG5) -> 7 | AI5: =SUBTOTAL(9,S5:AH5) -> 7 | AJ5: =COUNTIFS('Assigned Learning Data Dump'!$W:$W,'Completed FEED'!$A5,'Assigned Learning Data Dump'!$F:$F,$A$1,'Assigned Learning Data Dump'!$U:$U,'Completed FEED'!AJ$2) -> 0 | AK5: =COUNTIFS('Assigned Learning Data Dump'!$W:$W,'Completed FEED'!$A5,'Assigned Learning Data Dump'!$F:$F,$A$1,'Assigned Learning Data Dump'!$U:$U,'Completed FEED'!AK$2) -> 0 | AL5: =COUNTIFS('Assigned Learning Data Dump'!$W:$W,'Completed FEED'!$A5,'Assigned Learning Data Dump'!$F:$F,$A$1,'Assigned Learning Data Dump'!$U:$U,'Completed FEED'!AL$2) -> 0 | AM5: =SUBTOTAL(9,AJ5:AL5) -> 0 | AN5: =COUNTIFS('Assigned Learning Data Dump'!$W:$W,'Completed FEED'!$A5,'Assigned Learning Data Dump'!$F:$F,$A$1,'Assigned Learning Data Dump'!$U:$U,'Completed FEED'!AN$2) -> 0 | AO5: =COUNTIFS('Assigned Learning Data Dump'!$W:$W,'Completed FEED'!$A5,'Assigned Learning Data Dump'!$F:$F,$A$1,'Assigned Learning Data Dump'!$U:$U,'Completed FEED'!AO$2) -> 0 | AP5: =COUNTIFS('Assigned Learning Data Dump'!$W:$W,'Completed FEED'!$A5,'Assigned Learning Data Dump'!$F:$F,$A$1,'Assigned Learning Data Dump'!$U:$U,'Completed FEED'!AP$2) -> 0 | AQ5: =SUBTOTAL(9,AN5:AP5) -> 0 | AR5: =COUNTIFS('Assigned Learning Data Dump'!$W:$W,'Completed FEED'!$A5,'Assigned Learning Data Dump'!$F:$F,$A$1,'Assigned Learning Data Dump'!$U:$U,'Completed FEED'!AR$2) -> 0 | AS5: =COUNTIFS('Assigned Learning Data Dump'!$W:$W,'Completed FEED'!$A5,'Assigned Learning Data Dump'!$F:$F,$A$1,'Assigned Learning Data Dump'!$U:$U,'Completed FEED'!AS$2) -> 0 | AT5: =COUNTIFS('Assigned Learning Data Dump'!$W:$W,'Completed FEED'!$A5,'Assigned Learning Data Dump'!$F:$F,$A$1,'Assigned Learning Data Dump'!$U:$U,'Completed FEED'!AT$2) -> 0 | AU5: =SUBTOTAL(9,AR5:AT5) -> 0 | AV5: =COUNTIFS('Assigned Learning Data Dump'!$W:$W,'Completed FEED'!$A5,'Assigned Learning Data Dump'!$F:$F,$A$1,'Assigned Learning Data Dump'!$U:$U,'Completed FEED'!AV$2) -> 0 | AW5: =COUNTIFS('Assigned Learning Data Dump'!$W:$W,'Completed FEED'!$A5,'Assigned Learning Data Dump'!$F:$F,$A$1,'Assigned Learning Data Dump'!$U:$U,'Completed FEED'!AW$2) -> 0 | AX5: =COUNTIFS('Assigned Learning Data Dump'!$W:$W,'Completed FEED'!$A5,'Assigned Learning Data Dump'!$F:$F,$A$1,'Assigned Learning Data Dump'!$U:$U,'Completed FEED'!AX$2) -> 0 | AY5: =SUBTOTAL(9,AV5:AX5) -> 0 | AZ5: =SUBTOTAL(9,AJ5:AY5) -> 0
A6: Human Resources | B6: =COUNTIFS('Assigned Learning Data Dump'!$W:$W,'Completed FEED'!$A6,'Assigned Learning Data Dump'!$F:$F,$A$1,'Assigned Learning Data Dump'!$U:$U,'Completed FEED'!B$2) -> 12 | C6: =COUNTIFS('Assigned Learning Data Dump'!$W:$W,'Completed FEED'!$A6,'Assigned Learning Data Dump'!$F:$F,$A$1,'Assigned Learning Data Dump'!$U:$U,'Completed FEED'!C$2) -> 0 | D6: =COUNTIFS('Assigned Learning Data Dump'!$W:$W,'Completed FEED'!$A6,'Assigned Learning Data Dump'!$F:$F,$A$1,'Assigned Learning Data Dump'!$U:$U,'Completed FEED'!D$2) -> 61 | E6: =SUBTOTAL(9,B6:D6) -> 73 | F6: =COUNTIFS('Assigned Learning Data Dump'!$W:$W,'Completed FEED'!$A6,'Assigned Learning Data Dump'!$F:$F,$A$1,'Assigned Learning Data Dump'!$U:$U,'Completed FEED'!F$2) -> 0 | G6: =COUNTIFS('Assigned Learning Data Dump'!$W:$W,'Completed FEED'!$A6,'Assigned Learning Data Dump'!$F:$F,$A$1,'Assigned Learning Data Dump'!$U:$U,'Completed FEED'!G$2) -> 0 | H6: =COUNTIFS('Assigned Learning Data Dump'!$W:$W,'Completed FEED'!$A6,'Assigned Learning Data Dump'!$F:$F,$A$1,'Assigned Learning Data Dump'!$U:$U,'Completed FEED'!H$2) -> 8 | I6: =SUBTOTAL(9,F6:H6) -> 8 | J6: =COUNTIFS('Assigned Learning Data Dump'!$W:$W,'Completed FEED'!$A6,'Assigned Learning Data Dump'!$F:$F,$A$1,'Assigned Learning Data Dump'!$U:$U,'Completed FEED'!J$2) -> 1 | K6: =COUNTIFS('Assigned Learning Data Dump'!$W:$W,'Completed FEED'!$A6,'Assigned Learning Data Dump'!$F:$F,$A$1,'Assigned Learning Data Dump'!$U:$U,'Completed FEED'!K$2) -> 8 | L6: =COUNTIFS('Assigned Learning Data Dump'!$W:$W,'Completed FEED'!$A6,'Assigned Learning Data Dump'!$F:$F,$A$1,'Assigned Learning Data Dump'!$U:$U,'Completed FEED'!L$2) -> 1 | M6: =SUBTOTAL(9,J6:L6) -> 10 | N6: =COUNTIFS('Assigned Learning Data Dump'!$W:$W,'Completed FEED'!$A6,'Assigned Learning Data Dump'!$F:$F,$A$1,'Assigned Learning Data Dump'!$U:$U,'Completed FEED'!N$2) -> 1 | O6: =COUNTIFS('Assigned Learning Data Dump'!$W:$W,'Completed FEED'!$A6,'Assigned Learning Data Dump'!$F:$F,$A$1,'Assigned Learning Data Dump'!$U:$U,'Completed FEED'!O$2) -> 4 | P6: =COUNTIFS('Assigned Learning Data Dump'!$W:$W,'Completed FEED'!$A6,'Assigned Learning Data Dump'!$F:$F,$A$1,'Assigned Learning Data Dump'!$U:$U,'Completed FEED'!P$2) -> 9 | Q6: =SUBTOTAL(9,N6:P6) -> 14 | R6: =SUBTOTAL(9,B6:Q6) -> 105 | S6: =COUNTIFS('Assigned Learning Data Dump'!$W:$W,'Completed FEED'!$A6,'Assigned Learning Data Dump'!$F:$F,$A$1,'Assigned Learning Data Dump'!$U:$U,'Completed FEED'!S$2) -> 42 | T6: =COUNTIFS('Assigned Learning Data Dump'!$W:$W,'Completed FEED'!$A6,'Assigned Learning Data Dump'!$F:$F,$A$1,'Assigned Learning Data Dump'!$U:$U,'Completed FEED'!T$2) -> 4 | U6: =COUNTIFS('Assigned Learning Data Dump'!$W:$W,'Completed FEED'!$A6,'Assigned Learning Data Dump'!$F:$F,$A$1,'Assigned Learning Data Dump'!$U:$U,'Completed FEED'!U$2) -> 10 | V6: =SUBTOTAL(9,S6:U6) -> 56 | W6: =COUNTIFS('Assigned Learning Data Dump'!$W:$W,'Completed FEED'!$A6,'Assigned Learning Data Dump'!$F:$F,$A$1,'Assigned Learning Data Dump'!$U:$U,'Completed FEED'!W$2) -> 3 | X6: =COUNTIFS('Assigned Learning Data Dump'!$W:$W,'Completed FEED'!$A6,'Assigned Learning Data Dump'!$F:$F,$A$1,'Assigned Learning Data Dump'!$U:$U,'Completed FEED'!X$2) -> 1 | Y6: =COUNTIFS('Assigned Learning Data Dump'!$W:$W,'Completed FEED'!$A6,'Assigned Learning Data Dump'!$F:$F,$A$1,'Assigned Learning Data Dump'!$U:$U,'Completed FEED'!Y$2) -> 2 | Z6: =SUBTOTAL(9,W6:Y6) -> 6 | AA6: =COUNTIFS('Assigned Learning Data Dump'!$W:$W,'Completed FEED'!$A6,'Assigned Learning Data Dump'!$F:$F,$A$1,'Assigned Learning Data Dump'!$U:$U,'Completed FEED'!AA$2) -> 1 | AB6: =COUNTIFS('Assigned Learning Data Dump'!$W:$W,'Completed FEED'!$A6,'Assigned Learning Data Dump'!$F:$F,$A$1,'Assigned Learning Data Dump'!$U:$U,'Completed FEED'!AB$2) -> 4 | AC6: =COUNTIFS('Assigned Learning Data Dump'!$W:$W,'Completed FEED'!$A6,'Assigned Learning Data Dump'!$F:$F,$A$1,'Assigned Learning Data Dump'!$U:$U,'Completed FEED'!AC$2) -> 3 | AD6: =SUBTOTAL(9,AA6:AC6) -> 8 | AE6: =COUNTIFS('Assigned Learning Data Dump'!$W:$W,'Completed FEED'!$A6,'Assigned Learning Data Dump'!$F:$F,$A$1,'Assigned Learning Data Dump'!$U:$U,'Completed FEED'!AE$2) -> 0 | AF6: =COUNTIFS('Assigned Learning Data Dump'!$W:$W,'Completed FEED'!$A6,'Assigned Learning Data Dump'!$F:$F,$A$1,'Assigned Learning Data Dump'!$U:$U,'Completed FEED'!AF$2) -> 0 | AG6: =COUNTIFS('Assigned Learning Data Dump'!$W:$W,'Completed FEED'!$A6,'Assigned Learning Data Dump'!$F:$F,$A$1,'Assigned Learning Data Dump'!$U:$U,'Completed FEED'!AG$2) -> 0 | AH6: =SUBTOTAL(9,AE6:AG6) -> 0 | AI6: =SUBTOTAL(9,S6:AH6) -> 70 | AJ6: =COUNTIFS('Assigned Learning Data Dump'!$W:$W,'Completed FEED'!$A6,'Assigned Learning Data Dump'!$F:$F,$A$1,'Assigned Learning Data Dump'!$U:$U,'Completed FEED'!AJ$2) -> 0 | AK6: =COUNTIFS('Assigned Learning Data Dump'!$W:$W,'Completed FEED'!$A6,'Assigned Learning Data Dump'!$F:$F,$A$1,'Assigned Learning Data Dump'!$U:$U,'Completed FEED'!AK$2) -> 0 | AL6: =COUNTIFS('Assigned Learning Data Dump'!$W:$W,'Completed FEED'!$A6,'Assigned Learning Data Dump'!$F:$F,$A$1,'Assigned Learning Data Dump'!$U:$U,'Completed FEED'!AL$2) -> 0 | AM6: =SUBTOTAL(9,AJ6:AL6) -> 0 | AN6: =COUNTIFS('Assigned Learning Data Dump'!$W:$W,'Completed FEED'!$A6,'Assigned Learning Data Dump'!$F:$F,$A$1,'Assigned Learning Data Dump'!$U:$U,'Completed FEED'!AN$2) -> 0 | AO6: =COUNTIFS('Assigned Learning Data Dump'!$W:$W,'Completed FEED'!$A6,'Assigned Learning Data Dump'!$F:$F,$A$1,'Assigned Learning Data Dump'!$U:$U,'Completed FEED'!AO$2) -> 0 | AP6: =COUNTIFS('Assigned Learning Data Dump'!$W:$W,'Completed FEED'!$A6,'Assigned Learning Data Dump'!$F:$F,$A$1,'Assigned Learning Data Dump'!$U:$U,'Completed FEED'!AP$2) -> 0 | AQ6: =SUBTOTAL(9,AN6:AP6) -> 0 | AR6: =COUNTIFS('Assigned Learning Data Dump'!$W:$W,'Completed FEED'!$A6,'Assigned Learning Data Dump'!$F:$F,$A$1,'Assigned Learning Data Dump'!$U:$U,'Completed FEED'!AR$2) -> 0 | AS6: =COUNTIFS('Assigned Learning Data Dump'!$W:$W,'Completed FEED'!$A6,'Assigned Learning Data Dump'!$F:$F,$A$1,'Assigned Learning Data Dump'!$U:$U,'Completed FEED'!AS$2) -> 0 | AT6: =COUNTIFS('Assigned Learning Data Dump'!$W:$W,'Completed FEED'!$A6,'Assigned Learning Data Dump'!$F:$F,$A$1,'Assigned Learning Data Dump'!$U:$U,'Completed FEED'!AT$2) -> 0 | AU6: =SUBTOTAL(9,AR6:AT6) -> 0 | AV6: =COUNTIFS('Assigned Learning Data Dump'!$W:$W,'Completed FEED'!$A6,'Assigned Learning Data Dump'!$F:$F,$A$1,'Assigned Learning Data Dump'!$U:$U,'Completed FEED'!AV$2) -> 0 | AW6: =COUNTIFS('Assigned Learning Data Dump'!$W:$W,'Completed FEED'!$A6,'Assigned Learning Data Dump'!$F:$F,$A$1,'Assigned Learning Data Dump'!$U:$U,'Completed FEED'!AW$2) -> 0 | AX6: =COUNTIFS('Assigned Learning Data Dump'!$W:$W,'Completed FEED'!$A6,'Assigned Learning Data Dump'!$F:$F,$A$1,'Assigned Learning Data Dump'!$U:$U,'Completed FEED'!AX$2) -> 0 | AY6: =SUBTOTAL(9,AV6:AX6) -> 0 | AZ6: =SUBTOTAL(9,AJ6:AY6) -> 0
A7: Insights & Analytics | B7: =COUNTIFS('Assigned Learning Data Dump'!$W:$W,'Completed FEED'!$A7,'Assigned Learning Data Dump'!$F:$F,$A$1,'Assigned Learning Data Dump'!$U:$U,'Completed FEED'!B$2) -> 0 | C7: =COUNTIFS('Assigned Learning Data Dump'!$W:$W,'Completed FEED'!$A7,'Assigned Learning Data Dump'!$F:$F,$A$1,'Assigned Learning Data Dump'!$U:$U,'Completed FEED'!C$2) -> 0 | D7: =COUNTIFS('Assigned Learning Data Dump'!$W:$W,'Completed FEED'!$A7,'Assigned Learning Data Dump'!$F:$F,$A$1,'Assigned Learning Data Dump'!$U:$U,'Completed FEED'!D$2) -> 0 | E7: =SUBTOTAL(9,B7:D7) -> 0 | F7: =COUNTIFS('Assigned Learning Data Dump'!$W:$W,'Completed FEED'!$A7,'Assigned Learning Data Dump'!$F:$F,$A$1,'Assigned Learning Data Dump'!$U:$U,'Completed FEED'!F$2) -> 0 | G7: =COUNTIFS('Assigned Learning Data Dump'!$W:$W,'Completed FEED'!$A7,'Assigned Learning Data Dump'!$F:$F,$A$1,'Assigned Learning Data Dump'!$U:$U,'Completed FEED'!G$2) -> 0 | H7: =COUNTIFS('Assigned Learning Data Dump'!$W:$W,'Completed FEED'!$A7,'Assigned Learning Data Dump'!$F:$F,$A$1,'Assigned Learning Data Dump'!$U:$U,'Completed FEED'!H$2) -> 0 | I7: =SUBTOTAL(9,F7:H7) -> 0 | J7: =COUNTIFS('Assigned Learning Data Dump'!$W:$W,'Completed FEED'!$A7,'Assigned Learning Data Dump'!$F:$F,$A$1,'Assigned Learning Data Dump'!$U:$U,'Completed FEED'!J$2) -> 0 | K7: =COUNTIFS('Assigned Learning Data Dump'!$W:$W,'Completed FEED'!$A7,'Assigned Learning Data Dump'!$F:$F,$A$1,'Assigned Learning Data Dump'!$U:$U,'Completed FEED'!K$2) -> 0 | L7: =COUNTIFS('Assigned Learning Data Dump'!$W:$W,'Completed FEED'!$A7,'Assigned Learning Data Dump'!$F:$F,$A$1,'Assigned Learning Data Dump'!$U:$U,'Completed FEED'!L$2) -> 0 | M7: =SUBTOTAL(9,J7:L7) -> 0 | N7: =COUNTIFS('Assigned Learning Data Dump'!$W:$W,'Completed FEED'!$A7,'Assigned Learning Data Dump'!$F:$F,$A$1,'Assigned Learning Data Dump'!$U:$U,'Completed FEED'!N$2) -> 0 | O7: =COUNTIFS('Assigned Learning Data Dump'!$W:$W,'Completed FEED'!$A7,'Assigned Learning Data Dump'!$F:$F,$A$1,'Assigned Learning Data Dump'!$U:$U,'Completed FEED'!O$2) -> 0 | P7: =COUNTIFS('Assigned Learning Data Dump'!$W:$W,'Completed FEED'!$A7,'Assigned Learning Data Dump'!$F:$F,$A$1,'Assigned Learning Data Dump'!$U:$U,'Completed FEED'!P$2) -> 0 | Q7: =SUBTOTAL(9,N7:P7) -> 0 | R7: =SUBTOTAL(9,B7:Q7) -> 0 | S7: =COUNTIFS('Assigned Learning Data Dump'!$W:$W,'Completed FEED'!$A7,'Assigned Learning Data Dump'!$F:$F,$A$1,'Assigned Learning Data Dump'!$U:$U,'Completed FEED'!S$2) -> 0 | T7: =COUNTIFS('Assigned Learning Data Dump'!$W:$W,'Completed FEED'!$A7,'Assigned Learning Data Dump'!$F:$F,$A$1,'Assigned Learning Data Dump'!$U:$U,'Completed FEED'!T$2) -> 0 | U7: =COUNTIFS('Assigned Learning Data Dump'!$W:$W,'Completed FEED'!$A7,'Assigned Learning Data Dump'!$F:$F,$A$1,'Assigned Learning Data Dump'!$U:$U,'Completed FEED'!U$2) -> 0 | V7: =SUBTOTAL(9,S7:U7) -> 0 | W7: =COUNTIFS('Assigned Learning Data Dump'!$W:$W,'Completed FEED'!$A7,'Assigned Learning Data Dump'!$F:$F,$A$1,'Assigned Learning Data Dump'!$U:$U,'Completed FEED'!W$2) -> 0 | X7: =COUNTIFS('Assigned Learning Data Dump'!$W:$W,'Completed FEED'!$A7,'Assigned Learning Data Dump'!$F:$F,$A$1,'Assigned Learning Data Dump'!$U:$U,'Completed FEED'!X$2) -> 0 | Y7: =COUNTIFS('Assigned Learning Data Dump'!$W:$W,'Completed FEED'!$A7,'Assigned Learning Data Dump'!$F:$F,$A$1,'Assigned Learning Data Dump'!$U:$U,'Completed FEED'!Y$2) -> 0 | Z7: =SUBTOTAL(9,W7:Y7) -> 0 | AA7: =COUNTIFS('Assigned Learning Data Dump'!$W:$W,'Completed FEED'!$A7,'Assigned Learning Data Dump'!$F:$F,$A$1,'Assigned Learning Data Dump'!$U:$U,'Completed FEED'!AA$2) -> 0 | AB7: =COUNTIFS('Assigned Learning Data Dump'!$W:$W,'Completed FEED'!$A7,'Assigned Learning Data Dump'!$F:$F,$A$1,'Assigned Learning Data Dump'!$U:$U,'Completed FEED'!AB$2) -> 1 | AC7: =COUNTIFS('Assigned Learning Data Dump'!$W:$W,'Completed FEED'!$A7,'Assigned Learning Data Dump'!$F:$F,$A$1,'Assigned Learning Data Dump'!$U:$U,'Completed FEED'!AC$2) -> 0 | AD7: =SUBTOTAL(9,AA7:AC7) -> 1 | AE7: =COUNTIFS('Assigned Learning Data Dump'!$W:$W,'Completed FEED'!$A7,'Assigned Learning Data Dump'!$F:$F,$A$1,'Assigned Learning Data Dump'!$U:$U,'Completed FEED'!AE$2) -> 0 | AF7: =COUNTIFS('Assigned Learning Data Dump'!$W:$W,'Completed FEED'!$A7,'Assigned Learning Data Dump'!$F:$F,$A$1,'Assigned Learning Data Dump'!$U:$U,'Completed FEED'!AF$2) -> 2 | AG7: =COUNTIFS('Assigned Learning Data Dump'!$W:$W,'Completed FEED'!$A7,'Assigned Learning Data Dump'!$F:$F,$A$1,'Assigned Learning Data Dump'!$U:$U,'Completed FEED'!AG$2) -> 0 | AH7: =SUBTOTAL(9,AE7:AG7) -> 2 | AI7: =SUBTOTAL(9,S7:AH7) -> 3 | AJ7: =COUNTIFS('Assigned Learning Data Dump'!$W:$W,'Completed FEED'!$A7,'Assigned Learning Data Dump'!$F:$F,$A$1,'Assigned Learning Data Dump'!$U:$U,'Completed FEED'!AJ$2) -> 0 | AK7: =COUNTIFS('Assigned Learning Data Dump'!$W:$W,'Completed FEED'!$A7,'Assigned Learning Data Dump'!$F:$F,$A$1,'Assigned Learning Data Dump'!$U:$U,'Completed FEED'!AK$2) -> 0 | AL7: =COUNTIFS('Assigned Learning Data Dump'!$W:$W,'Completed FEED'!$A7,'Assigned Learning Data Dump'!$F:$F,$A$1,'Assigned Learning Data Dump'!$U:$U,'Completed FEED'!AL$2) -> 0 | AM7: =SUBTOTAL(9,AJ7:AL7) -> 0 | AN7: =COUNTIFS('Assigned Learning Data Dump'!$W:$W,'Completed FEED'!$A7,'Assigned Learning Data Dump'!$F:$F,$A$1,'Assigned Learning Data Dump'!$U:$U,'Completed FEED'!AN$2) -> 0 | AO7: =COUNTIFS('Assigned Learning Data Dump'!$W:$W,'Completed FEED'!$A7,'Assigned Learning Data Dump'!$F:$F,$A$1,'Assigned Learning Data Dump'!$U:$U,'Completed FEED'!AO$2) -> 0 | AP7: =COUNTIFS('Assigned Learning Data Dump'!$W:$W,'Completed FEED'!$A7,'Assigned Learning Data Dump'!$F:$F,$A$1,'Assigned Learning Data Dump'!$U:$U,'Completed FEED'!AP$2) -> 0 | AQ7: =SUBTOTAL(9,AN7:AP7) -> 0 | AR7: =COUNTIFS('Assigned Learning Data Dump'!$W:$W,'Completed FEED'!$A7,'Assigned Learning Data Dump'!$F:$F,$A$1,'Assigned Learning Data Dump'!$U:$U,'Completed FEED'!AR$2) -> 0 | AS7: =COUNTIFS('Assigned Learning Data Dump'!$W:$W,'Completed FEED'!$A7,'Assigned Learning Data Dump'!$F:$F,$A$1,'Assigned Learning Data Dump'!$U:$U,'Completed FEED'!AS$2) -> 0 | AT7: =COUNTIFS('Assigned Learning Data Dump'!$W:$W,'Completed FEED'!$A7,'Assigned Learning Data Dump'!$F:$F,$A$1,'Assigned Learning Data Dump'!$U:$U,'Completed FEED'!AT$2) -> 0 | AU7: =SUBTOTAL(9,AR7:AT7) -> 0 | AV7: =COUNTIFS('Assigned Learning Data Dump'!$W:$W,'Completed FEED'!$A7,'Assigned Learning Data Dump'!$F:$F,$A$1,'Assigned Learning Data Dump'!$U:$U,'Completed FEED'!AV$2) -> 0 | AW7: =COUNTIFS('Assigned Learning Data Dump'!$W:$W,'Completed FEED'!$A7,'Assigned Learning Data Dump'!$F:$F,$A$1,'Assigned Learning Data Dump'!$U:$U,'Completed FEED'!AW$2) -> 0 | AX7: =COUNTIFS('Assigned Learning Data Dump'!$W:$W,'Completed FEED'!$A7,'Assigned Learning Data Dump'!$F:$F,$A$1,'Assigned Learning Data Dump'!$U:$U,'Completed FEED'!AX$2) -> 0 | AY7: =SUBTOTAL(9,AV7:AX7) -> 0 | AZ7: =SUBTOTAL(9,AJ7:AY7) -> 0
