Workbook

Sheet INC REPORT_MAY
B2: Combined DC Incident Types | D2: Combined DC Incident Types - Month | J2: Combined DC Incident Types - Quarter
D3: IT FEED | E3: IT FEED | F3: IT FEED | G3: IT FEED | H3: IT FEED | J3: IT FEED | K3: IT FEED | L3: IT FEED | M3: IT FEED | N3: IT FEED
D4: FY24 | F4: FY25 | J4: FY24 | L4: FY25
D5: =D6&", "&D4 -> MAY, FY24 | E5: =D6&", "&D4 -> MAY, FY24 | F5: =F6&", "&F4 -> MAY, FY25 | G5: =F6&", "&F4 -> MAY, FY25 | J5: =J6&", "&J4 -> Q3, FY24 | K5: =J6&", "&J4 -> Q3, FY24 | L5: =L6&", "&L4 -> Q3, FY25 | M5: =L6&", "&L4 -> Q3, FY25
B6: Incident Types | D6: MAY | E6: YTD | F6: MAY | G6: YTD | H6: VAR | J6: Q3 | K6: YTD | L6: Q3 | M6: YTD | N6: VAR
B7: Team Member Injury | D7: {=_xlfn.XLOOKUP($B7,INDIRECT("'"&D$3&"'!"&"$B3:$B5"),_xlfn.XLOOKUP(D$5,INDIRECT("'"&D$3&"'!"&"$C2:$AZ2"),INDIRECT("'"&D$3&"'!"&"$C3:$AZ5")))} -> 4 | E7: {=_xlfn.XLOOKUP(E$6&" "&$B7,INDIRECT("'"&E$3&"'!"&"$B18:$B20"),_xlfn.XLOOKUP(E$5,INDIRECT("'"&E$3&"'!"&"$C2:$AZ2"),INDIRECT("'"&E$3&"'!"&"$C18:$AZ20")))} -> 25 | F7: {=_xlfn.XLOOKUP($B7,INDIRECT("'"&F$3&"'!"&"$B3:$B5"),_xlfn.XLOOKUP(F$5,INDIRECT("'"&F$3&"'!"&"$C2:$AZ2"),INDIRECT("'"&F$3&"'!"&"$C3:$AZ5")))} -> 2 | G7: {=_xlfn.XLOOKUP(G$6&" "&$B7,INDIRECT("'"&G$3&"'!"&"$B18:$B20"),_xlfn.XLOOKUP(G$5,INDIRECT("'"&G$3&"'!"&"$C2:$AZ2"),INDIRECT("'"&G$3&"'!"&"$C18:$AZ20")))} -> 10 | H7: =G7-E7 -> -15 | J7: {=_xlfn.XLOOKUP($B7,INDIRECT("'"&J$3&"'!"&"$B3:$B5"),_xlfn.XLOOKUP(J$5,INDIRECT("'"&J$3&"'!"&"$C2:$AZ2"),INDIRECT("'"&J$3&"'!"&"$C3:$AZ5")))} -> 5 | K7: {=_xlfn.XLOOKUP(K$6&" "&$B7,INDIRECT("'"&K$3&"'!"&"$B18:$B20"),_xlfn.XLOOKUP(K$5,INDIRECT("'"&K$3&"'!"&"$C2:$AZ2"),INDIRECT("'"&K$3&"'!"&"$C18:$AZ20")))} -> 21 | L7: {=_xlfn.XLOOKUP($B7,INDIRECT("'"&L$3&"'!"&"$B3:$B5"),_xlfn.XLOOKUP(L$5,INDIRECT("'"&L$3&"'!"&"$C2:$AZ2"),INDIRECT("'"&L$3&"'!"&"$C3:$AZ5")))} -> 1 | M7: {=_xlfn.XLOOKUP(M$6&" "&$B7,INDIRECT("'"&M$3&"'!"&"$B18:$B20"),_xlfn.XLOOKUP(M$5,INDIRECT("'"&M$3&"'!"&"$C2:$AZ2"),INDIRECT("'"&M$3&"'!"&"$C18:$AZ20")))} -> 6 | N7: =M7-K7 -> -15
B8: Safety Near Miss | D8: {=_xlfn.XLOOKUP($B8,INDIRECT("'"&D$3&"'!"&"$B3:$B5"),_xlfn.XLOOKUP(D$5,INDIRECT("'"&D$3&"'!"&"$C2:$AZ2"),INDIRECT("'"&D$3&"'!"&"$C3:$AZ5")))} -> 0 | E8: {=_xlfn.XLOOKUP(E$6&" "&$B8,INDIRECT("'"&E$3&"'!"&"$B18:$B20"),_xlfn.XLOOKUP(E$5,INDIRECT("'"&E$3&"'!"&"$C2:$AZ2"),INDIRECT("'"&E$3&"'!"&"$C18:$AZ20")))} -> 39 | F8: {=_xlfn.XLOOKUP($B8,INDIRECT("'"&F$3&"'!"&"$B3:$B5"),_xlfn.XLOOKUP(F$5,INDIRECT("'"&F$3&"'!"&"$C2:$AZ2"),INDIRECT("'"&F$3&"'!"&"$C3:$AZ5")))} -> 2 | G8: {=_xlfn.XLOOKUP(G$6&" "&$B8,INDIRECT("'"&G$3&"'!"&"$B18:$B20"),_xlfn.XLOOKUP(G$5,INDIRECT("'"&G$3&"'!"&"$C2:$AZ2"),INDIRECT("'"&G$3&"'!"&"$C18:$AZ20")))} -> 31 | H8: =G8-E8 -> -8 | J8: {=_xlfn.XLOOKUP($B8,INDIRECT("'"&J$3&"'!"&"$B3:$B5"),_xlfn.XLOOKUP(J$5,INDIRECT("'"&J$3&"'!"&"$C2:$AZ2"),INDIRECT("'"&J$3&"'!"&"$C3:$AZ5")))} -> 3 | K8: {=_xlfn.XLOOKUP(K$6&" "&$B8,INDIRECT("'"&K$3&"'!"&"$B18:$B20"),_xlfn.XLOOKUP(K$5,INDIRECT("'"&K$3&"'!"&"$C2:$AZ2"),INDIRECT("'"&K$3&"'!"&"$C18:$AZ20")))} -> 37 | L8: {=_xlfn.XLOOKUP($B8,INDIRECT("'"&L$3&"'!"&"$B3:$B5"),_xlfn.XLOOKUP(L$5,INDIRECT("'"&L$3&"'!"&"$C2:$AZ2"),INDIRECT("'"&L$3&"'!"&"$C3:$AZ5")))} -> 9 | M8: {=_xlfn.XLOOKUP(M$6&" "&$B8,INDIRECT("'"&M$3&"'!"&"$B18:$B20"),_xlfn.XLOOKUP(M$5,INDIRECT("'"&M$3&"'!"&"$C2:$AZ2"),INDIRECT("'"&M$3&"'!"&"$C18:$AZ20")))} -> 24 | N8: =M8-K8 -> -13
B9: Customer / Contractor | D9: {=_xlfn.XLOOKUP($B9,INDIRECT("'"&D$3&"'!"&"$B3:$B5"),_xlfn.XLOOKUP(D$5,INDIRECT("'"&D$3&"'!"&"$C2:$AZ2"),INDIRECT("'"&D$3&"'!"&"$C3:$AZ5")))} -> 7 | E9: {=_xlfn.XLOOKUP(E$6&" "&$B9,INDIRECT("'"&E$3&"'!"&"$B18:$B20"),_xlfn.XLOOKUP(E$5,INDIRECT("'"&E$3&"'!"&"$C2:$AZ2"),INDIRECT("'"&E$3&"'!"&"$C18:$AZ20")))} -> 31 | F9: {=_xlfn.XLOOKUP($B9,INDIRECT("'"&F$3&"'!"&"$B3:$B5"),_xlfn.XLOOKUP(F$5,INDIRECT("'"&F$3&"'!"&"$C2:$AZ2"),INDIRECT("'"&F$3&"'!"&"$C3:$AZ5")))} -> 3 | G9: {=_xlfn.XLOOKUP(G$6&" "&$B9,INDIRECT("'"&G$3&"'!"&"$B18:$B20"),_xlfn.XLOOKUP(G$5,INDIRECT("'"&G$3&"'!"&"$C2:$AZ2"),INDIRECT("'"&G$3&"'!"&"$C18:$AZ20")))} -> 52 | H9: =G9-E9 -> 21 | J9: {=_xlfn.XLOOKUP($B9,INDIRECT("'"&J$3&"'!"&"$B3:$B5"),_xlfn.XLOOKUP(J$5,INDIRECT("'"&J$3&"'!"&"$C2:$AZ2"),INDIRECT("'"&J$3&"'!"&"$C3:$AZ5")))} -> 10 | K9: {=_xlfn.XLOOKUP(K$6&" "&$B9,INDIRECT("'"&K$3&"'!"&"$B18:$B20"),_xlfn.XLOOKUP(K$5,INDIRECT("'"&K$3&"'!"&"$C2:$AZ2"),INDIRECT("'"&K$3&"'!"&"$C18:$AZ20")))} -> 23 | L9: {=_xlfn.XLOOKUP($B9,INDIRECT("'"&L$3&"'!"&"$B3:$B5"),_xlfn.XLOOKUP(L$5,INDIRECT("'"&L$3&"'!"&"$C2:$AZ2"),INDIRECT("'"&L$3&"'!"&"$C3:$AZ5")))} -> 16 | M9: {=_xlfn.XLOOKUP(M$6&" "&$B9,INDIRECT("'"&M$3&"'!"&"$B18:$B20"),_xlfn.XLOOKUP(M$5,INDIRECT("'"&M$3&"'!"&"$C2:$AZ2"),INDIRECT("'"&M$3&"'!"&"$C18:$AZ20")))} -> 49 | N9: =M9-K9 -> 26
B10: Grand Total | D10: =SUM(D7:D9) -> 11 | E10: =SUM(E7:E9) -> 95 | F10: =SUM(F7:F9) -> 7 | G10: =SUM(G7:G9) -> 93 | H10: =G10-E10 -> -2 | J10: =SUM(J7:J9) -> 18 | K10: =SUM(K7:K9) -> 81 | L10: =SUM(L7:L9) -> 26 | M10: =SUM(M7:M9) -> 79 | N10: =M10-K10 -> -2
B12: Spotlight DC | D12: Spotlight DC Incident Types - Month | J12: Spotlight DC Incident Types - Quarter
D13: IT FEED | E13: IT FEED | F13: IT FEED | G13: IT FEED | H13: IT FEED | J13: IT FEED | K13: IT FEED | L13: IT FEED | M13: IT FEED | N13: IT FEED
D14: FY24 | F14: FY25 | J14: FY24 | L14: FY25
D15: =D16&", "&D14 -> MAY, FY24 | E15: =D16&", "&D14 -> MAY, FY24 | F15: =F16&", "&F14 -> MAY, FY25 | G15: =F16&", "&F14 -> MAY, FY25 | J15: =J16&", "&J14 -> Q3, FY24 | K15: =J16&", "&J14 -> Q3, FY24 | L15: =L16&", "&L14 -> Q3, FY25 | M15: =L16&", "&L14 -> Q3, FY25
B16: Incident Types | D16: MAY | E16: YTD | F16: MAY | G16: YTD | H16: VAR | J16: Q3 | K16: YTD | L16: Q3 | M16: YTD | N16: VAR
B17: Team Member Injury | D17: {=_xlfn.XLOOKUP($B17,INDIRECT("'"&D$13&"'!"&"$B6:$B8"),_xlfn.XLOOKUP(D$15,INDIRECT("'"&D$13&"'!"&"$C2:$AZ2"),INDIRECT("'"&D$13&"'!"&"$C6:$AZ8")))} -> 1 | E17: {=_xlfn.XLOOKUP(E$16&" "&$B17,INDIRECT("'"&E$13&"'!"&"$B21:$B23"),_xlfn.XLOOKUP(E$15,INDIRECT("'"&E$13&"'!"&"$C2:$AZ2"),INDIRECT("'"&E$13&"'!"&"$C21:$AZ23")))} -> 11 | F17: {=_xlfn.XLOOKUP($B17,INDIRECT("'"&F$13&"'!"&"$B6:$B8"),_xlfn.XLOOKUP(F$15,INDIRECT("'"&F$13&"'!"&"$C2:$AZ2"),INDIRECT("'"&F$13&"'!"&"$C6:$AZ8")))} -> 1 | G17: {=_xlfn.XLOOKUP(G$16&" "&$B17,INDIRECT("'"&G$13&"'!"&"$B21:$B23"),_xlfn.XLOOKUP(G$15,INDIRECT("'"&G$13&"'!"&"$C2:$AZ2"),INDIRECT("'"&G$13&"'!"&"$C21:$AZ23")))} -> 7 | H17: =G17-E17 -> -4 | J17: {=_xlfn.XLOOKUP($B17,INDIRECT("'"&J$13&"'!"&"$B6:$B8"),_xlfn.XLOOKUP(J$15,INDIRECT("'"&J$13&"'!"&"$C2:$AZ2"),INDIRECT("'"&J$13&"'!"&"$C6:$AZ8")))} -> 5 | K17: {=_xlfn.XLOOKUP(K$16&" "&$B17,INDIRECT("'"&K$13&"'!"&"$B21:$B23"),_xlfn.XLOOKUP(K$15,INDIRECT("'"&K$13&"'!"&"$C2:$AZ2"),INDIRECT("'"&K$13&"'!"&"$C21:$AZ23")))} -> 10 | L17: {=_xlfn.XLOOKUP($B17,INDIRECT("'"&L$13&"'!"&"$B6:$B8"),_xlfn.XLOOKUP(L$15,INDIRECT("'"&L$13&"'!"&"$C2:$AZ2"),INDIRECT("'"&L$13&"'!"&"$C6:$AZ8")))} -> 1 | M17: {=_xlfn.XLOOKUP(M$16&" "&$B17,INDIRECT("'"&M$13&"'!"&"$B21:$B23"),_xlfn.XLOOKUP(M$15,INDIRECT("'"&M$13&"'!"&"$C2:$AZ2"),INDIRECT("'"&M$13&"'!"&"$C21:$AZ23")))} -> 5 | N17: =M17-K17 -> -5
B18: Safety Near Miss | D18: {=_xlfn.XLOOKUP($B18,INDIRECT("'"&D$13&"'!"&"$B6:$B8"),_xlfn.XLOOKUP(D$15,INDIRECT("'"&D$13&"'!"&"$C2:$AZ2"),INDIRECT("'"&D$13&"'!"&"$C6:$AZ8")))} -> 0 | E18: {=_xlfn.XLOOKUP(E$16&" "&$B18,INDIRECT("'"&E$13&"'!"&"$B21:$B23"),_xlfn.XLOOKUP(E$15,INDIRECT("'"&E$13&"'!"&"$C2:$AZ2"),INDIRECT("'"&E$13&"'!"&"$C21:$AZ23")))} -> 12 | F18: {=_xlfn.XLOOKUP($B18,INDIRECT("'"&F$13&"'!"&"$B6:$B8"),_xlfn.XLOOKUP(F$15,INDIRECT("'"&F$13&"'!"&"$C2:$AZ2"),INDIRECT("'"&F$13&"'!"&"$C6:$AZ8")))} -> 2 | G18: {=_xlfn.XLOOKUP(G$16&" "&$B18,INDIRECT("'"&G$13&"'!"&"$B21:$B23"),_xlfn.XLOOKUP(G$15,INDIRECT("'"&G$13&"'!"&"$C2:$AZ2"),INDIRECT("'"&G$13&"'!"&"$C21:$AZ23")))} -> 22 | H18: =G18-E18 -> 10 | J18: {=_xlfn.XLOOKUP($B18,INDIRECT("'"&J$13&"'!"&"$B6:$B8"),_xlfn.XLOOKUP(J$15,INDIRECT("'"&J$13&"'!"&"$C2:$AZ2"),INDIRECT("'"&J$13&"'!"&"$C6:$AZ8")))} -> 3 | K18: {=_xlfn.XLOOKUP(K$16&" "&$B18,INDIRECT("'"&K$13&"'!"&"$B21:$B23"),_xlfn.XLOOKUP(K$15,INDIRECT("'"&K$13&"'!"&"$C2:$AZ2"),INDIRECT("'"&K$13&"'!"&"$C21:$AZ23")))} -> 10 | L18: {=_xlfn.XLOOKUP($B18,INDIRECT("'"&L$13&"'!"&"$B6:$B8"),_xlfn.XLOOKUP(L$15,INDIRECT("'"&L$13&"'!"&"$C2:$AZ2"),INDIRECT("'"&L$13&"'!"&"$C6:$AZ8")))} -> 7 | M18: {=_xlfn.XLOOKUP(M$16&" "&$B18,INDIRECT("'"&M$13&"'!"&"$B21:$B23"),_xlfn.XLOOKUP(M$15,INDIRECT("'"&M$13&"'!"&"$C2:$AZ2"),INDIRECT("'"&M$13&"'!"&"$C21:$AZ23")))} -> 16 | N18: =M18-K18 -> 6
B19: Customer / Contractor | D19: {=_xlfn.XLOOKUP($B19,INDIRECT("'"&D$13&"'!"&"$B6:$B8"),_xlfn.XLOOKUP(D$15,INDIRECT("'"&D$13&"'!"&"$C2:$AZ2"),INDIRECT("'"&D$13&"'!"&"$C6:$AZ8")))} -> 5 | E19: {=_xlfn.XLOOKUP(E$16&" "&$B19,INDIRECT("'"&E$13&"'!"&"$B21:$B23"),_xlfn.XLOOKUP(E$15,INDIRECT("'"&E$13&"'!"&"$C2:$AZ2"),INDIRECT("'"&E$13&"'!"&"$C21:$AZ23")))} -> 14 | F19: {=_xlfn.XLOOKUP($B19,INDIRECT("'"&F$13&"'!"&"$B6:$B8"),_xlfn.XLOOKUP(F$15,INDIRECT("'"&F$13&"'!"&"$C2:$AZ2"),INDIRECT("'"&F$13&"'!"&"$C6:$AZ8")))} -> 1 | G19: {=_xlfn.XLOOKUP(G$16&" "&$B19,INDIRECT("'"&G$13&"'!"&"$B21:$B23"),_xlfn.XLOOKUP(G$15,INDIRECT("'"&G$13&"'!"&"$C2:$AZ2"),INDIRECT("'"&G$13&"'!"&"$C21:$AZ23")))} -> 35 | H19: =G19-E19 -> 21 | J19: {=_xlfn.XLOOKUP($B19,INDIRECT("'"&J$13&"'!"&"$B6:$B8"),_xlfn.XLOOKUP(J$15,INDIRECT("'"&J$13&"'!"&"$C2:$AZ2"),INDIRECT("'"&J$13&"'!"&"$C6:$AZ8")))} -> 9 | K19: {=_xlfn.XLOOKUP(K$16&" "&$B19,INDIRECT("'"&K$13&"'!"&"$B21:$B23"),_xlfn.XLOOKUP(K$15,INDIRECT("'"&K$13&"'!"&"$C2:$AZ2"),INDIRECT("'"&K$13&"'!"&"$C21:$AZ23")))} -> 9 | L19: {=_xlfn.XLOOKUP($B19,INDIRECT("'"&L$13&"'!"&"$B6:$B8"),_xlfn.XLOOKUP(L$15,INDIRECT("'"&L$13&"'!"&"$C2:$AZ2"),INDIRECT("'"&L$13&"'!"&"$C6:$AZ8")))} -> 10 | M19: {=_xlfn.XLOOKUP(M$16&" "&$B19,INDIRECT("'"&M$13&"'!"&"$B21:$B23"),_xlfn.XLOOKUP(M$15,INDIRECT("'"&M$13&"'!"&"$C2:$AZ2"),INDIRECT("'"&M$13&"'!"&"$C21:$AZ23")))} -> 34 | N19: =M19-K19 -> 25
B20: Grand Total | D20: =SUM(D17:D19) -> 6 | E20: =SUM(E17:E19) -> 37 | F20: =SUM(F17:F19) -> 4 | G20: =SUM(G17:G19) -> 64 | H20: =G20-E20 -> 27 | J20: =SUM(J17:J19) -> 17 | K20: =SUM(K17:K19) -> 29 | L20: =SUM(L17:L19) -> 18 | M20: =SUM(M17:M19) -> 55 | N20: =M20-K20 -> 26
B22: Anaconda DC | D22: Anaconda DC Incident Types - Month | J22: Anaconda DC Incident Types - Quarter
D23: IT FEED | E23: IT FEED | F23: IT FEED | G23: IT FEED | H23: IT FEED | J23: IT FEED | K23: IT FEED | L23: IT FEED | M23: IT FEED | N23: IT FEED
D24: FY24 | F24: FY25 | J24: FY24 | L24: FY25
D25: =D26&", "&D24 -> MAY, FY24 | E25: =D26&", "&D24 -> MAY, FY24 | F25: =F26&", "&F24 -> MAY, FY25 | G25: =F26&", "&F24 -> MAY, FY25 | J25: =J26&", "&J24 -> Q3, FY24 | K25: =J26&", "&J24 -> Q3, FY24 | L25: =L26&", "&L24 -> Q3, FY25 | M25: =L26&", "&L24 -> Q3, FY25
B26: Incident Types | D26: MAY | E26: YTD | F26: MAY | G26: YTD | H26: VAR | J26: Q3 | K26: YTD | L26: Q3 | M26: YTD | N26: VAR
B27: Team Member Injury | D27: {=_xlfn.XLOOKUP($B27,INDIRECT("'"&D$23&"'!"&"$B9:$B11"),_xlfn.XLOOKUP(D$25,INDIRECT("'"&D$23&"'!"&"$C2:$AZ2"),INDIRECT("'"&D$23&"'!"&"$C9:$AZ11")))} -> 1 | E27: {=_xlfn.XLOOKUP(E$26&" "&$B27,INDIRECT("'"&E$23&"'!"&"$B24:$B26"),_xlfn.XLOOKUP(E$25,INDIRECT("'"&E$23&"'!"&"$C2:$AZ2"),INDIRECT("'"&E$23&"'!"&"$C24:$AZ26")))} -> 12 | F27: {=_xlfn.XLOOKUP($B27,INDIRECT("'"&F$23&"'!"&"$B9:$B11"),_xlfn.XLOOKUP(F$25,INDIRECT("'"&F$23&"'!"&"$C2:$AZ2"),INDIRECT("'"&F$23&"'!"&"$C9:$AZ11")))} -> 0 | G27: {=_xlfn.XLOOKUP(G$26&" "&$B27,INDIRECT("'"&G$23&"'!"&"$B24:$B26"),_xlfn.XLOOKUP(G$25,INDIRECT("'"&G$23&"'!"&"$C2:$AZ2"),INDIRECT("'"&G$23&"'!"&"$C24:$AZ26")))} -> 0 | H27: =G27-E27 -> -12 | J27: {=_xlfn.XLOOKUP($B27,INDIRECT("'"&J$23&"'!"&"$B9:$B11"),_xlfn.XLOOKUP(J$25,INDIRECT("'"&J$23&"'!"&"$C2:$AZ2"),INDIRECT("'"&J$23&"'!"&"$C9:$AZ11")))} -> 0 | K27: {=_xlfn.XLOOKUP(K$26&" "&$B27,INDIRECT("'"&K$23&"'!"&"$B24:$B26"),_xlfn.XLOOKUP(K$25,INDIRECT("'"&K$23&"'!"&"$C2:$AZ2"),INDIRECT("'"&K$23&"'!"&"$C24:$AZ26")))} -> 11 | L27: {=_xlfn.XLOOKUP($B27,INDIRECT("'"&L$23&"'!"&"$B9:$B11"),_xlfn.XLOOKUP(L$25,INDIRECT("'"&L$23&"'!"&"$C2:$AZ2"),INDIRECT("'"&L$23&"'!"&"$C9:$AZ11")))} -> 0 | M27: {=_xlfn.XLOOKUP(M$26&" "&$B27,INDIRECT("'"&M$23&"'!"&"$B24:$B26"),_xlfn.XLOOKUP(M$25,INDIRECT("'"&M$23&"'!"&"$C2:$AZ2"),INDIRECT("'"&M$23&"'!"&"$C24:$AZ26")))} -> 0 | N27: =M27-K27 -> -11
B28: Safety Near Miss | D28: {=_xlfn.XLOOKUP($B28,INDIRECT("'"&D$23&"'!"&"$B9:$B11"),_xlfn.XLOOKUP(D$25,INDIRECT("'"&D$23&"'!"&"$C2:$AZ2"),INDIRECT("'"&D$23&"'!"&"$C9:$AZ11")))} -> 0 | E28: {=_xlfn.XLOOKUP(E$26&" "&$B28,INDIRECT("'"&E$23&"'!"&"$B24:$B26"),_xlfn.XLOOKUP(E$25,INDIRECT("'"&E$23&"'!"&"$C2:$AZ2"),INDIRECT("'"&E$23&"'!"&"$C24:$AZ26")))} -> 27 | F28: {=_xlfn.XLOOKUP($B28,INDIRECT("'"&F$23&"'!"&"$B9:$B11"),_xlfn.XLOOKUP(F$25,INDIRECT("'"&F$23&"'!"&"$C2:$AZ2"),INDIRECT("'"&F$23&"'!"&"$C9:$AZ11")))} -> 0 | G28: {=_xlfn.XLOOKUP(G$26&" "&$B28,INDIRECT("'"&G$23&"'!"&"$B24:$B26"),_xlfn.XLOOKUP(G$25,INDIRECT("'"&G$23&"'!"&"$C2:$AZ2"),INDIRECT("'"&G$23&"'!"&"$C24:$AZ26")))} -> 4 | H28: =G28-E28 -> -23 | J28: {=_xlfn.XLOOKUP($B28,INDIRECT("'"&J$23&"'!"&"$B9:$B11"),_xlfn.XLOOKUP(J$25,INDIRECT("'"&J$23&"'!"&"$C2:$AZ2"),INDIRECT("'"&J$23&"'!"&"$C9:$AZ11")))} -> 0 | K28: {=_xlfn.XLOOKUP(K$26&" "&$B28,INDIRECT("'"&K$23&"'!"&"$B24:$B26"),_xlfn.XLOOKUP(K$25,INDIRECT("'"&K$23&"'!"&"$C2:$AZ2"),INDIRECT("'"&K$23&"'!"&"$C24:$AZ26")))} -> 27 | L28: {=_xlfn.XLOOKUP($B28,INDIRECT("'"&L$23&"'!"&"$B9:$B11"),_xlfn.XLOOKUP(L$25,INDIRECT("'"&L$23&"'!"&"$C2:$AZ2"),INDIRECT("'"&L$23&"'!"&"$C9:$AZ11")))} -> 1 | M28: {=_xlfn.XLOOKUP(M$26&" "&$B28,INDIRECT("'"&M$23&"'!"&"$B24:$B26"),_xlfn.XLOOKUP(M$25,INDIRECT("'"&M$23&"'!"&"$C2:$AZ2"),INDIRECT("'"&M$23&"'!"&"$C24:$AZ26")))} -> 4 | N28: =M28-K28 -> -23
B29: Customer / Contractor | D29: {=_xlfn.XLOOKUP($B29,INDIRECT("'"&D$23&"'!"&"$B9:$B11"),_xlfn.XLOOKUP(D$25,INDIRECT("'"&D$23&"'!"&"$C2:$AZ2"),INDIRECT("'"&D$23&"'!"&"$C9:$AZ11")))} -> 0 | E29: {=_xlfn.XLOOKUP(E$26&" "&$B29,INDIRECT("'"&E$23&"'!"&"$B24:$B26"),_xlfn.XLOOKUP(E$25,INDIRECT("'"&E$23&"'!"&"$C2:$AZ2"),INDIRECT("'"&E$23&"'!"&"$C24:$AZ26")))} -> 14 | F29: {=_xlfn.XLOOKUP($B29,INDIRECT("'"&F$23&"'!"&"$B9:$B11"),_xlfn.XLOOKUP(F$25,INDIRECT("'"&F$23&"'!"&"$C2:$AZ2"),INDIRECT("'"&F$23&"'!"&"$C9:$AZ11")))} -> 1 | G29: {=_xlfn.XLOOKUP(G$26&" "&$B29,INDIRECT("'"&G$23&"'!"&"$B24:$B26"),_xlfn.XLOOKUP(G$25,INDIRECT("'"&G$23&"'!"&"$C2:$AZ2"),INDIRECT("'"&G$23&"'!"&"$C24:$AZ26")))} -> 8 | H29: =G29-E29 -> -6 | J29: {=_xlfn.XLOOKUP($B29,INDIRECT("'"&J$23&"'!"&"$B9:$B11"),_xlfn.XLOOKUP(J$25,INDIRECT("'"&J$23&"'!"&"$C2:$AZ2"),INDIRECT("'"&J$23&"'!"&"$C9:$AZ11")))} -> 1 | K29: {=_xlfn.XLOOKUP(K$26&" "&$B29,INDIRECT("'"&K$23&"'!"&"$B24:$B26"),_xlfn.XLOOKUP(K$25,INDIRECT("'"&K$23&"'!"&"$C2:$AZ2"),INDIRECT("'"&K$23&"'!"&"$C24:$AZ26")))} -> 14 | L29: {=_xlfn.XLOOKUP($B29,INDIRECT("'"&L$23&"'!"&"$B9:$B11"),_xlfn.XLOOKUP(L$25,INDIRECT("'"&L$23&"'!"&"$C2:$AZ2"),INDIRECT("'"&L$23&"'!"&"$C9:$AZ11")))} -> 2 | M29: {=_xlfn.XLOOKUP(M$26&" "&$B29,INDIRECT("'"&M$23&"'!"&"$B24:$B26"),_xlfn.XLOOKUP(M$25,INDIRECT("'"&M$23&"'!"&"$C2:$AZ2"),INDIRECT("'"&M$23&"'!"&"$C24:$AZ26")))} -> 7 | N29: =M29-K29 -> -7
B30: Grand Total | D30: =SUM(D27:D29) -> 1 | E30: =SUM(E27:E29) -> 53 | F30: =SUM(F27:F29) -> 1 | G30: =SUM(G27:G29) -> 12 | H30: =G30-E30 -> -41 | J30: =SUM(J27:J29) -> 1 | K30: =SUM(K27:K29) -> 52 | L30: =SUM(L27:L29) -> 3 | M30: =SUM(M27:M29) -> 11 | N30: =M30-K30 -> -41
B32: Harris Scarfe DC | D32: Harris Scarfe DC Incident Types - Month | J32: Harris Scarfe DC Incident Types - Quarter
D33: IT FEED | E33: IT FEED | F33: IT FEED | G33: IT FEED | H33: IT FEED | J33: IT FEED | K33: IT FEED | L33: IT FEED | M33: IT FEED | N33: IT FEED
D34: FY24 | F34: FY25 | J34: FY24 | L34: FY25
D35: =D36&", "&D34 -> MAY, FY24 | E35: =D36&", "&D34 -> MAY, FY24 | F35: =F36&", "&F34 -> MAY, FY25 | G35: =F36&", "&F34 -> MAY, FY25 | J35: =J36&", "&J34 -> Q3, FY24 | K35: =J36&", "&J34 -> Q3, FY24 | L35: =L36&", "&L34 -> Q3, FY25 | M35: =L36&", "&L34 -> Q3, FY25
B36: Incident Types | D36: MAY | E36: YTD | F36: MAY | G36: YTD | H36: VAR | J36: Q3 | K36: YTD | L36: Q3 | M36: YTD | N36: VAR
B37: Team Member Injury | D37: {=_xlfn.XLOOKUP($B37,INDIRECT("'"&D$33&"'!"&"$B12:$B14"),_xlfn.XLOOKUP(D$35,INDIRECT("'"&D$33&"'!"&"$C2:$AZ2"),INDIRECT("'"&D$33&"'!"&"$C12:$AZ14")))} -> 2 | E37: {=_xlfn.XLOOKUP(E$36&" "&$B37,INDIRECT("'"&E$33&"'!"&"$B27:$B29"),_xlfn.XLOOKUP(E$35,INDIRECT("'"&E$33&"'!"&"$C2:$AZ2"),INDIRECT("'"&E$33&"'!"&"$C27:$AZ29")))} -> 2 | F37: {=_xlfn.XLOOKUP($B37,INDIRECT("'"&F$33&"'!"&"$B12:$B14"),_xlfn.XLOOKUP(F$35,INDIRECT("'"&F$33&"'!"&"$C2:$AZ2"),INDIRECT("'"&F$33&"'!"&"$C12:$AZ14")))} -> 1 | G37: {=_xlfn.XLOOKUP(G$36&" "&$B37,INDIRECT("'"&G$33&"'!"&"$B27:$B29"),_xlfn.XLOOKUP(G$35,INDIRECT("'"&G$33&"'!"&"$C2:$AZ2"),INDIRECT("'"&G$33&"'!"&"$C27:$AZ29")))} -> 3 | H37: =G37-E37 -> 1 | J37: {=_xlfn.XLOOKUP($B37,INDIRECT("'"&J$33&"'!"&"$B12:$B14"),_xlfn.XLOOKUP(J$35,INDIRECT("'"&J$33&"'!"&"$C2:$AZ2"),INDIRECT("'"&J$33&"'!"&"$C12:$AZ14")))} -> 0 | K37: {=_xlfn.XLOOKUP(K$36&" "&$B37,INDIRECT("'"&K$33&"'!"&"$B27:$B29"),_xlfn.XLOOKUP(K$35,INDIRECT("'"&K$33&"'!"&"$C2:$AZ2"),INDIRECT("'"&K$33&"'!"&"$C27:$AZ29")))} -> 0 | L37: {=_xlfn.XLOOKUP($B37,INDIRECT("'"&L$33&"'!"&"$B12:$B14"),_xlfn.XLOOKUP(L$35,INDIRECT("'"&L$33&"'!"&"$C2:$AZ2"),INDIRECT("'"&L$33&"'!"&"$C12:$AZ14")))} -> 0 | M37: {=_xlfn.XLOOKUP(M$36&" "&$B37,INDIRECT("'"&M$33&"'!"&"$B27:$B29"),_xlfn.XLOOKUP(M$35,INDIRECT("'"&M$33&"'!"&"$C2:$AZ2"),INDIRECT("'"&M$33&"'!"&"$C27:$AZ29")))} -> 1 | N37: =M37-K37 -> 1
B38: Safety Near Miss | D38: {=_xlfn.XLOOKUP($B38,INDIRECT("'"&D$33&"'!"&"$B12:$B14"),_xlfn.XLOOKUP(D$35,INDIRECT("'"&D$33&"'!"&"$C2:$AZ2"),INDIRECT("'"&D$33&"'!"&"$C12:$AZ14")))} -> 0 | E38: {=_xlfn.XLOOKUP(E$36&" "&$B38,INDIRECT("'"&E$33&"'!"&"$B27:$B29"),_xlfn.XLOOKUP(E$35,INDIRECT("'"&E$33&"'!"&"$C2:$AZ2"),INDIRECT("'"&E$33&"'!"&"$C27:$AZ29")))} -> 0 | F38: {=_xlfn.XLOOKUP($B38,INDIRECT("'"&F$33&"'!"&"$B12:$B14"),_xlfn.XLOOKUP(F$35,INDIRECT("'"&F$33&"'!"&"$C2:$AZ2"),INDIRECT("'"&F$33&"'!"&"$C12:$AZ14")))} -> 0 | G38: {=_xlfn.XLOOKUP(G$36&" "&$B38,INDIRECT("'"&G$33&"'!"&"$B27:$B29"),_xlfn.XLOOKUP(G$35,INDIRECT("'"&G$33&"'!"&"$C2:$AZ2"),INDIRECT("'"&G$33&"'!"&"$C27:$AZ29")))} -> 5 | H38: =G38-E38 -> 5 | J38: {=_xlfn.XLOOKUP($B38,INDIRECT("'"&J$33&"'!"&"$B12:$B14"),_xlfn.XLOOKUP(J$35,INDIRECT("'"&J$33&"'!"&"$C2:$AZ2"),INDIRECT("'"&J$33&"'!"&"$C12:$AZ14")))} -> 0 | K38: {=_xlfn.XLOOKUP(K$36&" "&$B38,INDIRECT("'"&K$33&"'!"&"$B27:$B29"),_xlfn.XLOOKUP(K$35,INDIRECT("'"&K$33&"'!"&"$C2:$AZ2"),INDIRECT("'"&K$33&"'!"&"$C27:$AZ29")))} -> 0 | L38: {=_xlfn.XLOOKUP($B38,INDIRECT("'"&L$33&"'!"&"$B12:$B14"),_xlfn.XLOOKUP(L$35,INDIRECT("'"&L$33&"'!"&"$C2:$AZ2"),INDIRECT("'"&L$33&"'!"&"$C12:$AZ14")))} -> 1 | M38: {=_xlfn.XLOOKUP(M$36&" "&$B38,INDIRECT("'"&M$33&"'!"&"$B27:$B29"),_xlfn.XLOOKUP(M$35,INDIRECT("'"&M$33&"'!"&"$C2:$AZ2"),INDIRECT("'"&M$33&"'!"&"$C27:$AZ29")))} -> 4 | N38: =M38-K38 -> 4
B39: Customer / Contractor | D39: {=_xlfn.XLOOKUP($B39,INDIRECT("'"&D$33&"'!"&"$B12:$B14"),_xlfn.XLOOKUP(D$35,INDIRECT("'"&D$33&"'!"&"$C2:$AZ2"),INDIRECT("'"&D$33&"'!"&"$C12:$AZ14")))} -> 2 | E39: {=_xlfn.XLOOKUP(E$36&" "&$B39,INDIRECT("'"&E$33&"'!"&"$B27:$B29"),_xlfn.XLOOKUP(E$35,INDIRECT("'"&E$33&"'!"&"$C2:$AZ2"),INDIRECT("'"&E$33&"'!"&"$C27:$AZ29")))} -> 3 | F39: {=_xlfn.XLOOKUP($B39,INDIRECT("'"&F$33&"'!"&"$B12:$B14"),_xlfn.XLOOKUP(F$35,INDIRECT("'"&F$33&"'!"&"$C2:$AZ2"),INDIRECT("'"&F$33&"'!"&"$C12:$AZ14")))} -> 1 | G39: {=_xlfn.XLOOKUP(G$36&" "&$B39,INDIRECT("'"&G$33&"'!"&"$B27:$B29"),_xlfn.XLOOKUP(G$35,INDIRECT("'"&G$33&"'!"&"$C2:$AZ2"),INDIRECT("'"&G$33&"'!"&"$C27:$AZ29")))} -> 9 | H39: =G39-E39 -> 6 | J39: {=_xlfn.XLOOKUP($B39,INDIRECT("'"&J$33&"'!"&"$B12:$B14"),_xlfn.XLOOKUP(J$35,INDIRECT("'"&J$33&"'!"&"$C2:$AZ2"),INDIRECT("'"&J$33&"'!"&"$C12:$AZ14")))} -> 0 | K39: {=_xlfn.XLOOKUP(K$36&" "&$B39,INDIRECT("'"&K$33&"'!"&"$B27:$B29"),_xlfn.XLOOKUP(K$35,INDIRECT("'"&K$33&"'!"&"$C2:$AZ2"),INDIRECT("'"&K$33&"'!"&"$C27:$AZ29")))} -> 0 | L39: {=_xlfn.XLOOKUP($B39,INDIRECT("'"&L$33&"'!"&"$B12:$B14"),_xlfn.XLOOKUP(L$35,INDIRECT("'"&L$33&"'!"&"$C2:$AZ2"),INDIRECT("'"&L$33&"'!"&"$C12:$AZ14")))} -> 4 | M39: {=_xlfn.XLOOKUP(M$36&" "&$B39,INDIRECT("'"&M$33&"'!"&"$B27:$B29"),_xlfn.XLOOKUP(M$35,INDIRECT("'"&M$33&"'!"&"$C2:$AZ2"),INDIRECT("'"&M$33&"'!"&"$C27:$AZ29")))} -> 8 | N39: =M39-K39 -> 8
B40: Grand Total | D40: =SUM(D37:D39) -> 4 | E40: =SUM(E37:E39) -> 5 | F40: =SUM(F37:F39) -> 2 | G40: =SUM(G37:G39) -> 17 | H40: =G40-E40 -> 12 | J40: =SUM(J37:J39) -> 0 | K40: =SUM(K37:K39) -> 0 | L40: =SUM(L37:L39) -> 5 | M40: =SUM(M37:M39) -> 13 | N40: =M40-K40 -> 13
B42: *Var denotes the Variance in YTD Columns

Sheet INC Pivot REPORT_MAY
A1: Fiscal Month | B1: (All) | H1: Fiscal Month | I1: (All)
A3: Count of Mechanism of Injury | B3: Column Labels | H3: Count of Nature of Injury | I3: Column Labels
A4: Row Labels | B4: Anaconda DC | C4: Harris Scarfe DC | D4: Spotlight DC | E4: Grand Total | H4: Row Labels | I4: Anaconda DC | J4: Harris Scarfe DC | K4: Spotlight DC | L4: Grand Total
A5: Contact | B5: 7 | C5: 1 | D5: 1 | E5: 9 | H5: Bruise/Pain/Soreness | I5: 20 | J5: 4 | K5: 21 | L5: 45
A6: Hit-Falling Object | B6: 6 | C6: 1 | D6: 6 | E6: 13 | H6: Cut/Abrasion | I6: 6 | J6: 3 | K6: 2 | L6: 11
A7: Hit-Falling Object, Impact/Knock, Manual handling | D7: 1 | E7: 1 | H7: Other | I7: 5 | J7: 9 | K7: 29 | L7: 43
A8: Hit-Moving object | B8: 2 | D8: 8 | E8: 10 | H8: Property Injury | I8: 2 | L8: 2
A9: Hit-Moving object, Impact/Knock | B9: 1 | D9: 1 | E9: 2 | H9: Sprain/Strain | I9: 6 | J9: 1 | K9: 9 | L9: 16
A10: Impact/Knock | B10: 7 | C10: 4 | D10: 10 | E10: 21 | H10: Grand Total | I10: 39 | J10: 17 | K10: 61 | L10: 117
A11: Impact/Knock, Manual handling | B11: 1 | E11: 1
A12: Impact/Knock, Vehicle Accident | D12: 2 | E12: 2
A13: Manual handling | B13: 6 | C13: 2 | D13: 10 | E13: 18
A14: Other | B14: 4 | C14: 7 | D14: 17 | E14: 28
A15: Slip/Trip/Fall | B15: 4 | D15: 3 | E15: 7
A16: Vehicle Accident | C16: 3 | D16: 1 | E16: 4
A17: Vehicle Accident, Other | B17: 1 | E17: 1
A18: Grand Total | B18: 39 | C18: 18 | D18: 60 | E18: 117
A22: Fiscal Month | B22: (All) | H22: Fiscal Month | I22: (All)
H23: Team Member of Injury Only
A24: Count of Body Parts | B24: Column Labels | H24: Count of Agency of Injury | I24: Column Labels
A25: Row Labels | B25: Anaconda DC | C25: Harris Scarfe DC | D25: Spotlight DC | E25: Grand Total | H25: Row Labels | I25: Anaconda DC | J25: Harris Scarfe DC | K25: Spotlight DC | L25: Grand Total
A26: back_foot_left | B26: 1 | D26: 2 | E26: 3 | H26: Human agencies | I26: 10 | J26: 4 | K26: 12 | L26: 26
A27: back_foot_right | B27: 2 | E27: 2 | H27: Other materials and objects | I27: 7 | J27: 2 | K27: 7 | L27: 16
A28: back_hand_right,front_hand_right | D28: 1 | E28: 1 | H28: Road transport | K28: 1 | L28: 1
A29: back_head | B29: 1 | D29: 1 | E29: 2 | H29: Grand Total | I29: 17 | J29: 6 | K29: 20 | L29: 43
A30: back_hips_knees,front_hips_knees | B30: 1 | E30: 1
A31: back_lower_back | B31: 2 | D31: 4 | E31: 6
A32: front_foot_right | B32: 3 | D32: 1 | E32: 4
A33: front_hand_left | B33: 1 | D33: 1 | E33: 2
A34: front_hand_right | C34: 3 | D34: 1 | E34: 4
A35: front_hips_knees | B35: 1 | C35: 1 | D35: 2 | E35: 4
A36: front_hips_knees,back_hips_knees | D36: 1 | E36: 1
A37: Head (back) | B37: 1 | D37: 1 | E37: 2
A38: Head (front) | B38: 3 | C38: 1 | D38: 1 | E38: 5
A39: head_front | B39: 1 | C39: 2 | D39: 1 | E39: 4
A40: head_front,back_shoulder_right | D40: 1 | E40: 1
A41: Left foot (front) | B41: 1 | D41: 3 | E41: 4
A42: Lower back | B42: 2 | C42: 2 | E42: 4
A43: Right hand (front) | B43: 3 | C43: 1 | D43: 1 | E43: 5
A44: Upper back / neck | D44: 1 | E44: 1
...

Sheet INC REPORT_12-month Graphs 

Sheet HAZ REPORT_APR & Q3 FY25
B2: Hazard | D2: Hazard - Month | J2: Hazard - Quarter
D3: HAZARD FEED | E3: HAZARD FEED | F3: HAZARD FEED | G3: HAZARD FEED | H3: HAZARD FEED | J3: HAZARD FEED | K3: HAZARD FEED | L3: HAZARD FEED | M3: HAZARD FEED | N3: HAZARD FEED
D4: FY24 | F4: FY25 | J4: FY24 | L4: FY25
D5: =D6&", "&D4 -> MAY, FY24 | E5: =D6&", "&D4 -> MAY, FY24 | F5: =F6&", "&F4 -> MAY, FY25 | G5: =F6&", "&F4 -> MAY, FY25 | J5: =J6&", "&J4 -> Q3, FY24 | K5: =J6&", "&J4 -> Q3, FY24 | L5: =L6&", "&L4 -> Q3, FY25 | M5: =L6&", "&L4 -> Q3, FY25
B6: Hazard by Brand | D6: MAY | E6: YTD | F6: MAY | G6: YTD | H6: VAR | J6: Q3 | K6: YTD | L6: Q3 | M6: YTD | N6: VAR
B7: Spotlight DC | D7: {=_xlfn.XLOOKUP($B7,INDIRECT("'"&D$3&"'!"&"$A3:$A5"),_xlfn.XLOOKUP(D$5,INDIRECT("'"&D$3&"'!"&"$B2:$AZ2"),INDIRECT("'"&D$3&"'!"&"$B3:$AZ5")))} -> 4 | E7: {=_xlfn.XLOOKUP($B7,INDIRECT("'"&E$3&"'!"&"$A9:$A11"),_xlfn.XLOOKUP(E$5,INDIRECT("'"&E$3&"'!"&"$B2:$AZ2"),INDIRECT("'"&E$3&"'!"&"$B9:$AZ11")))} -> 14 | F7: {=_xlfn.XLOOKUP($B7,INDIRECT("'"&F$3&"'!"&"$A3:$A5"),_xlfn.XLOOKUP(F$5,INDIRECT("'"&F$3&"'!"&"$B2:$AZ2"),INDIRECT("'"&F$3&"'!"&"$B3:$AZ5")))} -> 0 | G7: {=_xlfn.XLOOKUP($B7,INDIRECT("'"&G$3&"'!"&"$A9:$A11"),_xlfn.XLOOKUP(G$5,INDIRECT("'"&G$3&"'!"&"$B2:$AZ2"),INDIRECT("'"&G$3&"'!"&"$B9:$AZ11")))} -> 12 | H7: =G7-E7 -> -2 | J7: {=_xlfn.XLOOKUP($B7,INDIRECT("'"&J$3&"'!"&"$A3:$A5"),_xlfn.XLOOKUP(J$5,INDIRECT("'"&J$3&"'!"&"$B2:$AZ2"),INDIRECT("'"&J$3&"'!"&"$B3:$AZ5")))} -> 3 | K7: {=_xlfn.XLOOKUP($B7,INDIRECT("'"&K$3&"'!"&"$A9:$A11"),_xlfn.XLOOKUP(K$5,INDIRECT("'"&K$3&"'!"&"$B2:$AZ2"),INDIRECT("'"&K$3&"'!"&"$B9:$AZ11")))} -> 4 | L7: {=_xlfn.XLOOKUP($B7,INDIRECT("'"&L$3&"'!"&"$A3:$A5"),_xlfn.XLOOKUP(L$5,INDIRECT("'"&L$3&"'!"&"$B2:$AZ2"),INDIRECT("'"&L$3&"'!"&"$B3:$AZ5")))} -> 5 | M7: {=_xlfn.XLOOKUP($B7,INDIRECT("'"&M$3&"'!"&"$A9:$A11"),_xlfn.XLOOKUP(M$5,INDIRECT("'"&M$3&"'!"&"$B2:$AZ2"),INDIRECT("'"&M$3&"'!"&"$B9:$AZ11")))} -> 12 | N7: =M7-K7 -> 8
B8: Anaconda DC | D8: {=_xlfn.XLOOKUP($B8,INDIRECT("'"&D$3&"'!"&"$A3:$A5"),_xlfn.XLOOKUP(D$5,INDIRECT("'"&D$3&"'!"&"$B2:$AZ2"),INDIRECT("'"&D$3&"'!"&"$B3:$AZ5")))} -> 0 | E8: {=_xlfn.XLOOKUP($B8,INDIRECT("'"&E$3&"'!"&"$A9:$A11"),_xlfn.XLOOKUP(E$5,INDIRECT("'"&E$3&"'!"&"$B2:$AZ2"),INDIRECT("'"&E$3&"'!"&"$B9:$AZ11")))} -> 19 | F8: {=_xlfn.XLOOKUP($B8,INDIRECT("'"&F$3&"'!"&"$A3:$A5"),_xlfn.XLOOKUP(F$5,INDIRECT("'"&F$3&"'!"&"$B2:$AZ2"),INDIRECT("'"&F$3&"'!"&"$B3:$AZ5")))} -> 0 | G8: {=_xlfn.XLOOKUP($B8,INDIRECT("'"&G$3&"'!"&"$A9:$A11"),_xlfn.XLOOKUP(G$5,INDIRECT("'"&G$3&"'!"&"$B2:$AZ2"),INDIRECT("'"&G$3&"'!"&"$B9:$AZ11")))} -> 9 | H8: =G8-E8 -> -10 | J8: {=_xlfn.XLOOKUP($B8,INDIRECT("'"&J$3&"'!"&"$A3:$A5"),_xlfn.XLOOKUP(J$5,INDIRECT("'"&J$3&"'!"&"$B2:$AZ2"),INDIRECT("'"&J$3&"'!"&"$B3:$AZ5")))} -> 0 | K8: {=_xlfn.XLOOKUP($B8,INDIRECT("'"&K$3&"'!"&"$A9:$A11"),_xlfn.XLOOKUP(K$5,INDIRECT("'"&K$3&"'!"&"$B2:$AZ2"),INDIRECT("'"&K$3&"'!"&"$B9:$AZ11")))} -> 18 | L8: {=_xlfn.XLOOKUP($B8,INDIRECT("'"&L$3&"'!"&"$A3:$A5"),_xlfn.XLOOKUP(L$5,INDIRECT("'"&L$3&"'!"&"$B2:$AZ2"),INDIRECT("'"&L$3&"'!"&"$B3:$AZ5")))} -> 0 | M8: {=_xlfn.XLOOKUP($B8,INDIRECT("'"&M$3&"'!"&"$A9:$A11"),_xlfn.XLOOKUP(M$5,INDIRECT("'"&M$3&"'!"&"$B2:$AZ2"),INDIRECT("'"&M$3&"'!"&"$B9:$AZ11")))} -> 9 | N8: =M8-K8 -> -9
B9: Harris Scarfe DC | D9: {=_xlfn.XLOOKUP($B9,INDIRECT("'"&D$3&"'!"&"$A3:$A5"),_xlfn.XLOOKUP(D$5,INDIRECT("'"&D$3&"'!"&"$B2:$AZ2"),INDIRECT("'"&D$3&"'!"&"$B3:$AZ5")))} -> 1 | E9: {=_xlfn.XLOOKUP($B9,INDIRECT("'"&E$3&"'!"&"$A9:$A11"),_xlfn.XLOOKUP(E$5,INDIRECT("'"&E$3&"'!"&"$B2:$AZ2"),INDIRECT("'"&E$3&"'!"&"$B9:$AZ11")))} -> 1 | F9: {=_xlfn.XLOOKUP($B9,INDIRECT("'"&F$3&"'!"&"$A3:$A5"),_xlfn.XLOOKUP(F$5,INDIRECT("'"&F$3&"'!"&"$B2:$AZ2"),INDIRECT("'"&F$3&"'!"&"$B3:$AZ5")))} -> 0 | G9: {=_xlfn.XLOOKUP($B9,INDIRECT("'"&G$3&"'!"&"$A9:$A11"),_xlfn.XLOOKUP(G$5,INDIRECT("'"&G$3&"'!"&"$B2:$AZ2"),INDIRECT("'"&G$3&"'!"&"$B9:$AZ11")))} -> 4 | H9: =G9-E9 -> 3 | J9: {=_xlfn.XLOOKUP($B9,INDIRECT("'"&J$3&"'!"&"$A3:$A5"),_xlfn.XLOOKUP(J$5,INDIRECT("'"&J$3&"'!"&"$B2:$AZ2"),INDIRECT("'"&J$3&"'!"&"$B3:$AZ5")))} -> 0 | K9: {=_xlfn.XLOOKUP($B9,INDIRECT("'"&K$3&"'!"&"$A9:$A11"),_xlfn.XLOOKUP(K$5,INDIRECT("'"&K$3&"'!"&"$B2:$AZ2"),INDIRECT("'"&K$3&"'!"&"$B9:$AZ11")))} -> 0 | L9: {=_xlfn.XLOOKUP($B9,INDIRECT("'"&L$3&"'!"&"$A3:$A5"),_xlfn.XLOOKUP(L$5,INDIRECT("'"&L$3&"'!"&"$B2:$AZ2"),INDIRECT("'"&L$3&"'!"&"$B3:$AZ5")))} -> 4 | M9: {=_xlfn.XLOOKUP($B9,INDIRECT("'"&M$3&"'!"&"$A9:$A11"),_xlfn.XLOOKUP(M$5,INDIRECT("'"&M$3&"'!"&"$B2:$AZ2"),INDIRECT("'"&M$3&"'!"&"$B9:$AZ11")))} -> 4 | N9: =M9-K9 -> 4
B10: Grand Total | D10: =SUM(D7:D9) -> 5 | E10: =SUM(E7:E9) -> 34 | F10: =SUM(F7:F9) -> 0 | G10: =SUM(G7:G9) -> 25 | H10: =G10-E10 -> -9 | J10: =SUM(J7:J9) -> 3 | K10: =SUM(K7:K9) -> 22 | L10: =SUM(L7:L9) -> 9 | M10: =SUM(M7:M9) -> 25 | N10: =M10-K10 -> 3
B11: *Var denotes the Variance in YTD Columns

Sheet HAZ REPORT_12-month Graphs 

Sheet IT FEED
B1: Incident Types | C1: FY24 | T1: FY25
B2: Incident Types | C2: ="JUL, "&C1 -> JUL, FY24 | D2: ="AUG, "&C1 -> AUG, FY24 | E2: ="SEP, "&C1 -> SEP, FY24 | F2: ="Q1, "&C1 -> Q1, FY24 | G2: ="OCT, "&C1 -> OCT, FY24 | H2: ="NOV, "&C1 -> NOV, FY24 | I2: ="DEC, "&C1 -> DEC, FY24 | J2: ="Q2, "&C1 -> Q2, FY24 | K2: ="JAN, "&C1 -> JAN, FY24 | L2: ="FEB, "&C1 -> FEB, FY24 | M2: ="MAR, "&C1 -> MAR, FY24 | N2: ="Q3, "&C1 -> Q3, FY24 | O2: ="APR, "&C1 -> APR, FY24 | P2: ="MAY, "&C1 -> MAY, FY24 | Q2: ="JUN, "&C1 -> JUN, FY24 | R2: ="Q4, "&C1 -> Q4, FY24 | S2: ="Full Year, "&C1 -> Full Year, FY24 | T2: ="JUL, "&T1 -> JUL, FY25 | U2: ="AUG, "&T1 -> AUG, FY25 | V2: ="SEP, "&T1 -> SEP, FY25 | W2: ="Q1, "&T1 -> Q1, FY25 | X2: ="OCT, "&T1 -> OCT, FY25 | Y2: ="NOV, "&T1 -> NOV, FY25 | Z2: ="DEC, "&T1 -> DEC, FY25 | AA2: ="Q2, "&T1 -> Q2, FY25 | AB2: ="JAN, "&T1 -> JAN, FY25 | AC2: ="FEB, "&T1 -> FEB, FY25 | AD2: ="MAR, "&T1 -> MAR, FY25 | AE2: ="Q3, "&T1 -> Q3, FY25 | AF2: ="APR, "&T1 -> APR, FY25 | AG2: ="MAY, "&T1 -> MAY, FY25 | AH2: ="JUN, "&T1 -> JUN, FY25 | AI2: ="Q4, "&T1 -> Q4, FY25 | AJ2: ="Full Year, "&T1 -> Full Year, FY25
A3: All Incident Types | B3: Team Member Injury | C3: =COUNTIFS('Incident Data Dump'!$H:$H,'IT FEED'!$B3,'Incident Data Dump'!$Q:$Q,'IT FEED'!C$2) -> 1 | D3: =COUNTIFS('Incident Data Dump'!$H:$H,'IT FEED'!$B3,'Incident Data Dump'!$Q:$Q,'IT FEED'!D$2) -> 4 | E3: =COUNTIFS('Incident Data Dump'!$H:$H,'IT FEED'!$B3,'Incident Data Dump'!$Q:$Q,'IT FEED'!E$2) -> 3 | F3: =SUBTOTAL(9,C3:E3) -> 8 | G3: =COUNTIFS('Incident Data Dump'!$H:$H,'IT FEED'!$B3,'Incident Data Dump'!$Q:$Q,'IT FEED'!G$2) -> 0 | H3: =COUNTIFS('Incident Data Dump'!$H:$H,'IT FEED'!$B3,'Incident Data Dump'!$Q:$Q,'IT FEED'!H$2) -> 5 | I3: =COUNTIFS('Incident Data Dump'!$H:$H,'IT FEED'!$B3,'Incident Data Dump'!$Q:$Q,'IT FEED'!I$2) -> 3 | J3: =SUBTOTAL(9,G3:I3) -> 8 | K3: =COUNTIFS('Incident Data Dump'!$H:$H,'IT FEED'!$B3,'Incident Data Dump'!$Q:$Q,'IT FEED'!K$2) -> 1 | L3: =COUNTIFS('Incident Data Dump'!$H:$H,'IT FEED'!$B3,'Incident Data Dump'!$Q:$Q,'IT FEED'!L$2) -> 1 | M3: =COUNTIFS('Incident Data Dump'!$H:$H,'IT FEED'!$B3,'Incident Data Dump'!$Q:$Q,'IT FEED'!M$2) -> 3 | N3: =SUBTOTAL(9,K3:M3) -> 5 | O3: =COUNTIFS('Incident Data Dump'!$H:$H,'IT FEED'!$B3,'Incident Data Dump'!$Q:$Q,'IT FEED'!O$2) -> 0 | P3: =COUNTIFS('Incident Data Dump'!$H:$H,'IT FEED'!$B3,'Incident Data Dump'!$Q:$Q,'IT FEED'!P$2) -> 4 | Q3: =COUNTIFS('Incident Data Dump'!$H:$H,'IT FEED'!$B3,'Incident Data Dump'!$Q:$Q,'IT FEED'!Q$2) -> 2 | R3: =SUBTOTAL(9,O3:Q3) -> 6 | S3: =SUBTOTAL(9,C3:R3) -> 27 | T3: =COUNTIFS('Incident Data Dump'!$H:$H,'IT FEED'!$B3,'Incident Data Dump'!$Q:$Q,'IT FEED'!T$2) -> 1 | U3: =COUNTIFS('Incident Data Dump'!$H:$H,'IT FEED'!$B3,'Incident Data Dump'!$Q:$Q,'IT FEED'!U$2) -> 2 | V3: =COUNTIFS('Incident Data Dump'!$H:$H,'IT FEED'!$B3,'Incident Data Dump'!$Q:$Q,'IT FEED'!V$2) -> 1 | W3: =SUBTOTAL(9,T3:V3) -> 4 | X3: =COUNTIFS('Incident Data Dump'!$H:$H,'IT FEED'!$B3,'Incident Data Dump'!$Q:$Q,'IT FEED'!X$2) -> 0 | Y3: =COUNTIFS('Incident Data Dump'!$H:$H,'IT FEED'!$B3,'Incident Data Dump'!$Q:$Q,'IT FEED'!Y$2) -> 0 | Z3: =COUNTIFS('Incident Data Dump'!$H:$H,'IT FEED'!$B3,'Incident Data Dump'!$Q:$Q,'IT FEED'!Z$2) -> 1 | AA3: =SUBTOTAL(9,X3:Z3) -> 1 | AB3: =COUNTIFS('Incident Data Dump'!$H:$H,'IT FEED'!$B3,'Incident Data Dump'!$Q:$Q,'IT FEED'!AB$2) -> 1 | AC3: =COUNTIFS('Incident Data Dump'!$H:$H,'IT FEED'!$B3,'Incident Data Dump'!$Q:$Q,'IT FEED'!AC$2) -> 0 | AD3: =COUNTIFS('Incident Data Dump'!$H:$H,'IT FEED'!$B3,'Incident Data Dump'!$Q:$Q,'IT FEED'!AD$2) -> 0 | AE3: =SUBTOTAL(9,AB3:AD3) -> 1 | AF3: =COUNTIFS('Incident Data Dump'!$H:$H,'IT FEED'!$B3,'Incident Data Dump'!$Q:$Q,'IT FEED'!AF$2) -> 2 | AG3: =COUNTIFS('Incident Data Dump'!$H:$H,'IT FEED'!$B3,'Incident Data Dump'!$Q:$Q,'IT FEED'!AG$2) -> 2 | AH3: =COUNTIFS('Incident Data Dump'!$H:$H,'IT FEED'!$B3,'Incident Data Dump'!$Q:$Q,'IT FEED'!AH$2) -> 0 | AI3: =SUBTOTAL(9,AF3:AH3) -> 4 | AJ3: =SUBTOTAL(9,T3:AI3) -> 10
B4: Safety Near Miss | C4: =COUNTIFS('Incident Data Dump'!$H:$H,'IT FEED'!$B4,'Incident Data Dump'!$Q:$Q,'IT FEED'!C$2) -> 4 | D4: =COUNTIFS('Incident Data Dump'!$H:$H,'IT FEED'!$B4,'Incident Data Dump'!$Q:$Q,'IT FEED'!D$2) -> 6 | E4: =COUNTIFS('Incident Data Dump'!$H:$H,'IT FEED'!$B4,'Incident Data Dump'!$Q:$Q,'IT FEED'!E$2) -> 7 | F4: =SUBTOTAL(9,C4:E4) -> 17 | G4: =COUNTIFS('Incident Data Dump'!$H:$H,'IT FEED'!$B4,'Incident Data Dump'!$Q:$Q,'IT FEED'!G$2) -> 9 | H4: =COUNTIFS('Incident Data Dump'!$H:$H,'IT FEED'!$B4,'Incident Data Dump'!$Q:$Q,'IT FEED'!H$2) -> 5 | I4: =COUNTIFS('Incident Data Dump'!$H:$H,'IT FEED'!$B4,'Incident Data Dump'!$Q:$Q,'IT FEED'!I$2) -> 3 | J4: =SUBTOTAL(9,G4:I4) -> 17 | K4: =COUNTIFS('Incident Data Dump'!$H:$H,'IT FEED'!$B4,'Incident Data Dump'!$Q:$Q,'IT FEED'!K$2) -> 2 | L4: =COUNTIFS('Incident Data Dump'!$H:$H,'IT FEED'!$B4,'Incident Data Dump'!$Q:$Q,'IT FEED'!L$2) -> 1 | M4: =COUNTIFS('Incident Data Dump'!$H:$H,'IT FEED'!$B4,'Incident Data Dump'!$Q:$Q,'IT FEED'!M$2) -> 0 | N4: =SUBTOTAL(9,K4:M4) -> 3 | O4: =COUNTIFS('Incident Data Dump'!$H:$H,'IT FEED'!$B4,'Incident Data Dump'!$Q:$Q,'IT FEED'!O$2) -> 2 | P4: =COUNTIFS('Incident Data Dump'!$H:$H,'IT FEED'!$B4,'Incident Data Dump'!$Q:$Q,'IT FEED'!P$2) -> 0 | Q4: =COUNTIFS('Incident Data Dump'!$H:$H,'IT FEED'!$B4,'Incident Data Dump'!$Q:$Q,'IT FEED'!Q$2) -> 2 | R4: =SUBTOTAL(9,O4:Q4) -> 4 | S4: =SUBTOTAL(9,C4:R4) -> 41 | T4: =COUNTIFS('Incident Data Dump'!$H:$H,'IT FEED'!$B4,'Incident Data Dump'!$Q:$Q,'IT FEED'!T$2) -> 1 | U4: =COUNTIFS('Incident Data Dump'!$H:$H,'IT FEED'!$B4,'Incident Data Dump'!$Q:$Q,'IT FEED'!U$2) -> 7 | V4: =COUNTIFS('Incident Data Dump'!$H:$H,'IT FEED'!$B4,'Incident Data Dump'!$Q:$Q,'IT FEED'!V$2) -> 0 | W4: =SUBTOTAL(9,T4:V4) -> 8 | X4: =COUNTIFS('Incident Data Dump'!$H:$H,'IT FEED'!$B4,'Incident Data Dump'!$Q:$Q,'IT FEED'!X$2) -> 1 | Y4: =COUNTIFS('Incident Data Dump'!$H:$H,'IT FEED'!$B4,'Incident Data Dump'!$Q:$Q,'IT FEED'!Y$2) -> 6 | Z4: =COUNTIFS('Incident Data Dump'!$H:$H,'IT FEED'!$B4,'Incident Data Dump'!$Q:$Q,'IT FEED'!Z$2) -> 0 | AA4: =SUBTOTAL(9,X4:Z4) -> 7 | AB4: =COUNTIFS('Incident Data Dump'!$H:$H,'IT FEED'!$B4,'Incident Data Dump'!$Q:$Q,'IT FEED'!AB$2) -> 4 | AC4: =COUNTIFS('Incident Data Dump'!$H:$H,'IT FEED'!$B4,'Incident Data Dump'!$Q:$Q,'IT FEED'!AC$2) -> 4 | AD4: =COUNTIFS('Incident Data Dump'!$H:$H,'IT FEED'!$B4,'Incident Data Dump'!$Q:$Q,'IT FEED'!AD$2) -> 1 | AE4: =SUBTOTAL(9,AB4:AD4) -> 9 | AF4: =COUNTIFS('Incident Data Dump'!$H:$H,'IT FEED'!$B4,'Incident Data Dump'!$Q:$Q,'IT FEED'!AF$2) -> 5 | AG4: =COUNTIFS('Incident Data Dump'!$H:$H,'IT FEED'!$B4,'Incident Data Dump'!$Q:$Q,'IT FEED'!AG$2) -> 2 | AH4: =COUNTIFS('Incident Data Dump'!$H:$H,'IT FEED'!$B4,'Incident Data Dump'!$Q:$Q,'IT FEED'!AH$2) -> 0 | AI4: =SUBTOTAL(9,AF4:AH4) -> 7 | AJ4: =SUBTOTAL(9,T4:AI4) -> 31
B5: Customer / Contractor | C5: =COUNTIFS('Incident Data Dump'!$H:$H,'IT FEED'!$B5,'Incident Data Dump'!$Q:$Q,'IT FEED'!C$2) -> 2 | D5: =COUNTIFS('Incident Data Dump'!$H:$H,'IT FEED'!$B5,'Incident Data Dump'!$Q:$Q,'IT FEED'!D$2) -> 2 | E5: =COUNTIFS('Incident Data Dump'!$H:$H,'IT FEED'!$B5,'Incident Data Dump'!$Q:$Q,'IT FEED'!E$2) -> 3 | F5: =SUBTOTAL(9,C5:E5) -> 7 | G5: =COUNTIFS('Incident Data Dump'!$H:$H,'IT FEED'!$B5,'Incident Data Dump'!$Q:$Q,'IT FEED'!G$2) -> 0 | H5: =COUNTIFS('Incident Data Dump'!$H:$H,'IT FEED'!$B5,'Incident Data Dump'!$Q:$Q,'IT FEED'!H$2) -> 4 | I5: =COUNTIFS('Incident Data Dump'!$H:$H,'IT FEED'!$B5,'Incident Data Dump'!$Q:$Q,'IT FEED'!I$2) -> 2 | J5: =SUBTOTAL(9,G5:I5) -> 6 | K5: =COUNTIFS('Incident Data Dump'!$H:$H,'IT FEED'!$B5,'Incident Data Dump'!$Q:$Q,'IT FEED'!K$2) -> 3 | L5: =COUNTIFS('Incident Data Dump'!$H:$H,'IT FEED'!$B5,'Incident Data Dump'!$Q:$Q,'IT FEED'!L$2) -> 6 | M5: =COUNTIFS('Incident Data Dump'!$H:$H,'IT FEED'!$B5,'Incident Data Dump'!$Q:$Q,'IT FEED'!M$2) -> 1 | N5: =SUBTOTAL(9,K5:M5) -> 10 | O5: =COUNTIFS('Incident Data Dump'!$H:$H,'IT FEED'!$B5,'Incident Data Dump'!$Q:$Q,'IT FEED'!O$2) -> 1 | P5: =COUNTIFS('Incident Data Dump'!$H:$H,'IT FEED'!$B5,'Incident Data Dump'!$Q:$Q,'IT FEED'!P$2) -> 7 | Q5: =COUNTIFS('Incident Data Dump'!$H:$H,'IT FEED'!$B5,'Incident Data Dump'!$Q:$Q,'IT FEED'!Q$2) -> 4 | R5: =SUBTOTAL(9,O5:Q5) -> 12 | S5: =SUBTOTAL(9,C5:R5) -> 35 | T5: =COUNTIFS('Incident Data Dump'!$H:$H,'IT FEED'!$B5,'Incident Data Dump'!$Q:$Q,'IT FEED'!T$2) -> 3 | U5: =COUNTIFS('Incident Data Dump'!$H:$H,'IT FEED'!$B5,'Incident Data Dump'!$Q:$Q,'IT FEED'!U$2) -> 7 | V5: =COUNTIFS('Incident Data Dump'!$H:$H,'IT FEED'!$B5,'Incident Data Dump'!$Q:$Q,'IT FEED'!V$2) -> 1 | W5: =SUBTOTAL(9,T5:V5) -> 11 | X5: =COUNTIFS('Incident Data Dump'!$H:$H,'IT FEED'!$B5,'Incident Data Dump'!$Q:$Q,'IT FEED'!X$2) -> 5 | Y5: =COUNTIFS('Incident Data Dump'!$H:$H,'IT FEED'!$B5,'Incident Data Dump'!$Q:$Q,'IT FEED'!Y$2) -> 8 | Z5: =COUNTIFS('Incident Data Dump'!$H:$H,'IT FEED'!$B5,'Incident Data Dump'!$Q:$Q,'IT FEED'!Z$2) -> 9 | AA5: =SUBTOTAL(9,X5:Z5) -> 22 | AB5: =COUNTIFS('Incident Data Dump'!$H:$H,'IT FEED'!$B5,'Incident Data Dump'!$Q:$Q,'IT FEED'!AB$2) -> 4 | AC5: =COUNTIFS('Incident Data Dump'!$H:$H,'IT FEED'!$B5,'Incident Data Dump'!$Q:$Q,'IT FEED'!AC$2) -> 4 | AD5: =COUNTIFS('Incident Data Dump'!$H:$H,'IT FEED'!$B5,'Incident Data Dump'!$Q:$Q,'IT FEED'!AD$2) -> 8 | AE5: =SUBTOTAL(9,AB5:AD5) -> 16 | AF5: =COUNTIFS('Incident Data Dump'!$H:$H,'IT FEED'!$B5,'Incident Data Dump'!$Q:$Q,'IT FEED'!AF$2) -> 0 | AG5: =COUNTIFS('Incident Data Dump'!$H:$H,'IT FEED'!$B5,'Incident Data Dump'!$Q:$Q,'IT FEED'!AG$2) -> 3 | AH5: =COUNTIFS('Incident Data Dump'!$H:$H,'IT FEED'!$B5,'Incident Data Dump'!$Q:$Q,'IT FEED'!AH$2) -> 0 | AI5: =SUBTOTAL(9,AF5:AH5) -> 3 | AJ5: =SUBTOTAL(9,T5:AI5) -> 52
A6: Spotlight DC | B6: Team Member Injury | C6: =COUNTIFS('Incident Data Dump'!$P:$P,'IT FEED'!$A$6,'Incident Data Dump'!$H:$H,'IT FEED'!$B6,'Incident Data Dump'!$Q:$Q,'IT FEED'!C$2) -> 1 | D6: =COUNTIFS('Incident Data Dump'!$P:$P,'IT FEED'!$A$6,'Incident Data Dump'!$H:$H,'IT FEED'!$B6,'Incident Data Dump'!$Q:$Q,'IT FEED'!D$2) -> 0 | E6: =COUNTIFS('Incident Data Dump'!$P:$P,'IT FEED'!$A$6,'Incident Data Dump'!$H:$H,'IT FEED'!$B6,'Incident Data Dump'!$Q:$Q,'IT FEED'!E$2) -> 0 | F6: =SUBTOTAL(9,C6:E6) -> 1 | G6: =COUNTIFS('Incident Data Dump'!$P:$P,'IT FEED'!$A$6,'Incident Data Dump'!$H:$H,'IT FEED'!$B6,'Incident Data Dump'!$Q:$Q,'IT FEED'!G$2) -> 0 | H6: =COUNTIFS('Incident Data Dump'!$P:$P,'IT FEED'!$A$6,'Incident Data Dump'!$H:$H,'IT FEED'!$B6,'Incident Data Dump'!$Q:$Q,'IT FEED'!H$2) -> 3 | I6: =COUNTIFS('Incident Data Dump'!$P:$P,'IT FEED'!$A$6,'Incident Data Dump'!$H:$H,'IT FEED'!$B6,'Incident Data Dump'!$Q:$Q,'IT FEED'!I$2) -> 1 | J6: =SUBTOTAL(9,G6:I6) -> 4 | K6: =COUNTIFS('Incident Data Dump'!$P:$P,'IT FEED'!$A$6,'Incident Data Dump'!$H:$H,'IT FEED'!$B6,'Incident Data Dump'!$Q:$Q,'IT FEED'!K$2) -> 1 | L6: =COUNTIFS('Incident Data Dump'!$P:$P,'IT FEED'!$A$6,'Incident Data Dump'!$H:$H,'IT FEED'!$B6,'Incident Data Dump'!$Q:$Q,'IT FEED'!L$2) -> 1 | M6: =COUNTIFS('Incident Data Dump'!$P:$P,'IT FEED'!$A$6,'Incident Data Dump'!$H:$H,'IT FEED'!$B6,'Incident Data Dump'!$Q:$Q,'IT FEED'!M$2) -> 3 | N6: =SUBTOTAL(9,K6:M6) -> 5 | O6: =COUNTIFS('Incident Data Dump'!$P:$P,'IT FEED'!$A$6,'Incident Data Dump'!$H:$H,'IT FEED'!$B6,'Incident Data Dump'!$Q:$Q,'IT FEED'!O$2) -> 0 | P6: =COUNTIFS('Incident Data Dump'!$P:$P,'IT FEED'!$A$6,'Incident Data Dump'!$H:$H,'IT FEED'!$B6,'Incident Data Dump'!$Q:$Q,'IT FEED'!P$2) -> 1 | Q6: =COUNTIFS('Incident Data Dump'!$P:$P,'IT FEED'!$A$6,'Incident Data Dump'!$H:$H,'IT FEED'!$B6,'Incident Data Dump'!$Q:$Q,'IT FEED'!Q$2) -> 0 | R6: =SUBTOTAL(9,O6:Q6) -> 1 | S6: =SUBTOTAL(9,C6:R6) -> 11 | T6: =COUNTIFS('Incident Data Dump'!$P:$P,'IT FEED'!$A$6,'Incident Data Dump'!$H:$H,'IT FEED'!$B6,'Incident Data Dump'!$Q:$Q,'IT FEED'!T$2) -> 1 | U6: =COUNTIFS('Incident Data Dump'!$P:$P,'IT FEED'!$A$6,'Incident Data Dump'!$H:$H,'IT FEED'!$B6,'Incident Data Dump'!$Q:$Q,'IT FEED'!U$2) -> 1 | V6: =COUNTIFS('Incident Data Dump'!$P:$P,'IT FEED'!$A$6,'Incident Data Dump'!$H:$H,'IT FEED'!$B6,'Incident Data Dump'!$Q:$Q,'IT FEED'!V$2) -> 1 | W6: =SUBTOTAL(9,T6:V6) -> 3 | X6: =COUNTIFS('Incident Data Dump'!$P:$P,'IT FEED'!$A$6,'Incident Data Dump'!$H:$H,'IT FEED'!$B6,'Incident Data Dump'!$Q:$Q,'IT FEED'!X$2) -> 0 | Y6: =COUNTIFS('Incident Data Dump'!$P:$P,'IT FEED'!$A$6,'Incident Data Dump'!$H:$H,'IT FEED'!$B6,'Incident Data Dump'!$Q:$Q,'IT FEED'!Y$2) -> 0 | Z6: =COUNTIFS('Incident Data Dump'!$P:$P,'IT FEED'!$A$6,'Incident Data Dump'!$H:$H,'IT FEED'!$B6,'Incident Data Dump'!$Q:$Q,'IT FEED'!Z$2) -> 1 | AA6: =SUBTOTAL(9,X6:Z6) -> 1 | AB6: =COUNTIFS('Incident Data Dump'!$P:$P,'IT FEED'!$A$6,'Incident Data Dump'!$H:$H,'IT FEED'!$B6,'Incident Data Dump'!$Q:$Q,'IT FEED'!AB$2) -> 1 | AC6: =COUNTIFS('Incident Data Dump'!$P:$P,'IT FEED'!$A$6,'Incident Data Dump'!$H:$H,'IT FEED'!$B6,'Incident Data Dump'!$Q:$Q,'IT FEED'!AC$2) -> 0 | AD6: =COUNTIFS('Incident Data Dump'!$P:$P,'IT FEED'!$A$6,'Incident Data Dump'!$H:$H,'IT FEED'!$B6,'Incident Data Dump'!$Q:$Q,'IT FEED'!AD$2) -> 0 | AE6: =SUBTOTAL(9,AB6:AD6) -> 1 | AF6: =COUNTIFS('Incident Data Dump'!$P:$P,'IT FEED'!$A$6,'Incident Data Dump'!$H:$H,'IT FEED'!$B6,'Incident Data Dump'!$Q:$Q,'IT FEED'!AF$2) -> 1 | AG6: =COUNTIFS('Incident Data Dump'!$P:$P,'IT FEED'!$A$6,'Incident Data Dump'!$H:$H,'IT FEED'!$B6,'Incident Data Dump'!$Q:$Q,'IT FEED'!AG$2) -> 1 | AH6: =COUNTIFS('Incident Data Dump'!$P:$P,'IT FEED'!$A$6,'Incident Data Dump'!$H:$H,'IT FEED'!$B6,'Incident Data Dump'!$Q:$Q,'IT FEED'!AH$2) -> 0 | AI6: =SUBTOTAL(9,AF6:AH6) -> 2 | AJ6: =SUBTOTAL(9,T6:AI6) -> 7
B7: Safety Near Miss | C7: =COUNTIFS('Incident Data Dump'!$P:$P,'IT FEED'!$A$6,'Incident Data Dump'!$H:$H,'IT FEED'!$B7,'Incident Data Dump'!$Q:$Q,'IT FEED'!C$2) -> 0 | D7: =COUNTIFS('Incident Data Dump'!$P:$P,'IT FEED'!$A$6,'Incident Data Dump'!$H:$H,'IT FEED'!$B7,'Incident Data Dump'!$Q:$Q,'IT FEED'!D$2) -> 1 | E7: =COUNTIFS('Incident Data Dump'!$P:$P,'IT FEED'!$A$6,'Incident Data Dump'!$H:$H,'IT FEED'!$B7,'Incident Data Dump'!$Q:$Q,'IT FEED'!E$2) -> 3 | F7: =SUBTOTAL(9,C7:E7) -> 4 | G7: =COUNTIFS('Incident Data Dump'!$P:$P,'IT FEED'!$A$6,'Incident Data Dump'!$H:$H,'IT FEED'!$B7,'Incident Data Dump'!$Q:$Q,'IT FEED'!G$2) -> 1 | H7: =COUNTIFS('Incident Data Dump'!$P:$P,'IT FEED'!$A$6,'Incident Data Dump'!$H:$H,'IT FEED'!$B7,'Incident Data Dump'!$Q:$Q,'IT FEED'!H$2) -> 2 | I7: =COUNTIFS('Incident Data Dump'!$P:$P,'IT FEED'!$A$6,'Incident Data Dump'!$H:$H,'IT FEED'!$B7,'Incident Data Dump'!$Q:$Q,'IT FEED'!I$2) -> 0 | J7: =SUBTOTAL(9,G7:I7) -> 3 | K7: =COUNTIFS('Incident Data Dump'!$P:$P,'IT FEED'!$A$6,'Incident Data Dump'!$H:$H,'IT FEED'!$B7,'Incident Data Dump'!$Q:$Q,'IT FEED'!K$2) -> 2 | L7: =COUNTIFS('Incident Data Dump'!$P:$P,'IT FEED'!$A$6,'Incident Data Dump'!$H:$H,'IT FEED'!$B7,'Incident Data Dump'!$Q:$Q,'IT FEED'!L$2) -> 1 | M7: =COUNTIFS('Incident Data Dump'!$P:$P,'IT FEED'!$A$6,'Incident Data Dump'!$H:$H,'IT FEED'!$B7,'Incident Data Dump'!$Q:$Q,'IT FEED'!M$2) -> 0 | N7: =SUBTOTAL(9,K7:M7) -> 3 | O7: =COUNTIFS('Incident Data Dump'!$P:$P,'IT FEED'!$A$6,'Incident Data Dump'!$H:$H,'IT FEED'!$B7,'Incident Data Dump'!$Q:$Q,'IT FEED'!O$2) -> 2 | P7: =COUNTIFS('Incident Data Dump'!$P:$P,'IT FEED'!$A$6,'Incident Data Dump'!$H:$H,'IT FEED'!$B7,'Incident Data Dump'!$Q:$Q,'IT FEED'!P$2) -> 0 | Q7: =COUNTIFS('Incident Data Dump'!$P:$P,'IT FEED'!$A$6,'Incident Data Dump'!$H:$H,'IT FEED'!$B7,'Incident Data Dump'!$Q:$Q,'IT FEED'!Q$2) -> 2 | R7: =SUBTOTAL(9,O7:Q7) -> 4 | S7: =SUBTOTAL(9,C7:R7) -> 14 | T7: =COUNTIFS('Incident Data Dump'!$P:$P,'IT FEED'!$A$6,'Incident Data Dump'!$H:$H,'IT FEED'!$B7,'Incident Data Dump'!$Q:$Q,'IT FEED'!T$2) -> 0 | U7: =COUNTIFS('Incident Data Dump'!$P:$P,'IT FEED'!$A$6,'Incident Data Dump'!$H:$H,'IT FEED'!$B7,'Incident Data Dump'!$Q:$Q,'IT FEED'!U$2) -> 5 | V7: =COUNTIFS('Incident Data Dump'!$P:$P,'IT FEED'!$A$6,'Incident Data Dump'!$H:$H,'IT FEED'!$B7,'Incident Data Dump'!$Q:$Q,'IT FEED'!V$2) -> 0 | W7: =SUBTOTAL(9,T7:V7) -> 5 | X7: =COUNTIFS('Incident Data Dump'!$P:$P,'IT FEED'!$A$6,'Incident Data Dump'!$H:$H,'IT FEED'!$B7,'Incident Data Dump'!$Q:$Q,'IT FEED'!X$2) -> 1 | Y7: =COUNTIFS('Incident Data Dump'!$P:$P,'IT FEED'!$A$6,'Incident Data Dump'!$H:$H,'IT FEED'!$B7,'Incident Data Dump'!$Q:$Q,'IT FEED'!Y$2) -> 3 | Z7: =COUNTIFS('Incident Data Dump'!$P:$P,'IT FEED'!$A$6,'Incident Data Dump'!$H:$H,'IT FEED'!$B7,'Incident Data Dump'!$Q:$Q,'IT FEED'!Z$2) -> 0 | AA7: =SUBTOTAL(9,X7:Z7) -> 4 | AB7: =COUNTIFS('Incident Data Dump'!$P:$P,'IT FEED'!$A$6,'Incident Data Dump'!$H:$H,'IT FEED'!$B7,'Incident Data Dump'!$Q:$Q,'IT FEED'!AB$2) -> 3 | AC7: =COUNTIFS('Incident Data Dump'!$P:$P,'IT FEED'!$A$6,'Incident Data Dump'!$H:$H,'IT FEED'!$B7,'Incident Data Dump'!$Q:$Q,'IT FEED'!AC$2) -> 3 | AD7: =COUNTIFS('Incident Data Dump'!$P:$P,'IT FEED'!$A$6,'Incident Data Dump'!$H:$H,'IT FEED'!$B7,'Incident Data Dump'!$Q:$Q,'IT FEED'!AD$2) -> 1 | AE7: =SUBTOTAL(9,AB7:AD7) -> 7 | AF7: =COUNTIFS('Incident Data Dump'!$P:$P,'IT FEED'!$A$6,'Incident Data Dump'!$H:$H,'IT FEED'!$B7,'Incident Data Dump'!$Q:$Q,'IT FEED'!AF$2) -> 4 | AG7: =COUNTIFS('Incident Data Dump'!$P:$P,'IT FEED'!$A$6,'Incident Data Dump'!$H:$H,'IT FEED'!$B7,'Incident Data Dump'!$Q:$Q,'IT FEED'!AG$2) -> 2 | AH7: =COUNTIFS('Incident Data Dump'!$P:$P,'IT FEED'!$A$6,'Incident Data Dump'!$H:$H,'IT FEED'!$B7,'Incident Data Dump'!$Q:$Q,'IT FEED'!AH$2) -> 0 | AI7: =SUBTOTAL(9,AF7:AH7) -> 6 | AJ7: =SUBTOTAL(9,T7:AI7) -> 22
B8: Customer / Contractor | C8: =COUNTIFS('Incident Data Dump'!$P:$P,'IT FEED'!$A$6,'Incident Data Dump'!$H:$H,'IT FEED'!$B8,'Incident Data Dump'!$Q:$Q,'IT FEED'!C$2) -> 0 | D8: =COUNTIFS('Incident Data Dump'!$P:$P,'IT FEED'!$A$6,'Incident Data Dump'!$H:$H,'IT FEED'!$B8,'Incident Data Dump'!$Q:$Q,'IT FEED'!D$2) -> 0 | E8: =COUNTIFS('Incident Data Dump'!$P:$P,'IT FEED'!$A$6,'Incident Data Dump'!$H:$H,'IT FEED'!$B8,'Incident Data Dump'!$Q:$Q,'IT FEED'!E$2) -> 0 | F8: =SUBTOTAL(9,C8:E8) -> 0 | G8: =COUNTIFS('Incident Data Dump'!$P:$P,'IT FEED'!$A$6,'Incident Data Dump'!$H:$H,'IT FEED'!$B8,'Incident Data Dump'!$Q:$Q,'IT FEED'!G$2) -> 0 | H8: =COUNTIFS('Incident Data Dump'!$P:$P,'IT FEED'!$A$6,'Incident Data Dump'!$H:$H,'IT FEED'!$B8,'Incident Data Dump'!$Q:$Q,'IT FEED'!H$2) -> 0 | I8: =COUNTIFS('Incident Data Dump'!$P:$P,'IT FEED'!$A$6,'Incident Data Dump'!$H:$H,'IT FEED'!$B8,'Incident Data Dump'!$Q:$Q,'IT FEED'!I$2) -> 0 | J8: =SUBTOTAL(9,G8:I8) -> 0 | K8: =COUNTIFS('Incident Data Dump'!$P:$P,'IT FEED'!$A$6,'Incident Data Dump'!$H:$H,'IT FEED'!$B8,'Incident Data Dump'!$Q:$Q,'IT FEED'!K$2) -> 2 | L8: =COUNTIFS('Incident Data Dump'!$P:$P,'IT FEED'!$A$6,'Incident Data Dump'!$H:$H,'IT FEED'!$B8,'Incident Data Dump'!$Q:$Q,'IT FEED'!L$2) -> 6 | M8: =COUNTIFS('Incident Data Dump'!$P:$P,'IT FEED'!$A$6,'Incident Data Dump'!$H:$H,'IT FEED'!$B8,'Incident Data Dump'!$Q:$Q,'IT FEED'!M$2) -> 1 | N8: =SUBTOTAL(9,K8:M8) -> 9 | O8: =COUNTIFS('Incident Data Dump'!$P:$P,'IT FEED'!$A$6,'Incident Data Dump'!$H:$H,'IT FEED'!$B8,'Incident Data Dump'!$Q:$Q,'IT FEED'!O$2) -> 0 | P8: =COUNTIFS('Incident Data Dump'!$P:$P,'IT FEED'!$A$6,'Incident Data Dump'!$H:$H,'IT FEED'!$B8,'Incident Data Dump'!$Q:$Q,'IT FEED'!P$2) -> 5 | Q8: =COUNTIFS('Incident Data Dump'!$P:$P,'IT FEED'!$A$6,'Incident Data Dump'!$H:$H,'IT FEED'!$B8,'Incident Data Dump'!$Q:$Q,'IT FEED'!Q$2) -> 4 | R8: =SUBTOTAL(9,O8:Q8) -> 9 | S8: =SUBTOTAL(9,C8:R8) -> 18 | T8: =COUNTIFS('Incident Data Dump'!$P:$P,'IT FEED'!$A$6,'Incident Data Dump'!$H:$H,'IT FEED'!$B8,'Incident Data Dump'!$Q:$Q,'IT FEED'!T$2) -> 3 | U8: =COUNTIFS('Incident Data Dump'!$P:$P,'IT FEED'!$A$6,'Incident Data Dump'!$H:$H,'IT FEED'!$B8,'Incident Data Dump'!$Q:$Q,'IT FEED'!U$2) -> 6 | V8: =COUNTIFS('Incident Data Dump'!$P:$P,'IT FEED'!$A$6,'Incident Data Dump'!$H:$H,'IT FEED'!$B8,'Incident Data Dump'!$Q:$Q,'IT FEED'!V$2) -> 0 | W8: =SUBTOTAL(9,T8:V8) -> 9 | X8: =COUNTIFS('Incident Data Dump'!$P:$P,'IT FEED'!$A$6,'Incident Data Dump'!$H:$H,'IT FEED'!$B8,'Incident Data Dump'!$Q:$Q,'IT FEED'!X$2) -> 4 | Y8: =COUNTIFS('Incident Data Dump'!$P:$P,'IT FEED'!$A$6,'Incident Data Dump'!$H:$H,'IT FEED'!$B8,'Incident Data Dump'!$Q:$Q,'IT FEED'!Y$2) -> 5 | Z8: =COUNTIFS('Incident Data Dump'!$P:$P,'IT FEED'!$A$6,'Incident Data Dump'!$H:$H,'IT FEED'!$B8,'Incident Data Dump'!$Q:$Q,'IT FEED'!Z$2) -> 6 | AA8: =SUBTOTAL(9,X8:Z8) -> 15 | AB8: =COUNTIFS('Incident Data Dump'!$P:$P,'IT FEED'!$A$6,'Incident Data Dump'!$H:$H,'IT FEED'!$B8,'Incident Data Dump'!$Q:$Q,'IT FEED'!AB$2) -> 3 | AC8: =COUNTIFS('Incident Data Dump'!$P:$P,'IT FEED'!$A$6,'Incident Data Dump'!$H:$H,'IT FEED'!$B8,'Incident Data Dump'!$Q:$Q,'IT FEED'!AC$2) -> 2 | AD8: =COUNTIFS('Incident Data Dump'!$P:$P,'IT FEED'!$A$6,'Incident Data Dump'!$H:$H,'IT FEED'!$B8,'Incident Data Dump'!$Q:$Q,'IT FEED'!AD$2) -> 5 | AE8: =SUBTOTAL(9,AB8:AD8) -> 10 | AF8: =COUNTIFS('Incident Data Dump'!$P:$P,'IT FEED'!$A$6,'Incident Data Dump'!$H:$H,'IT FEED'!$B8,'Incident Data Dump'!$Q:$Q,'IT FEED'!AF$2) -> 0 | AG8: =COUNTIFS('Incident Data Dump'!$P:$P,'IT FEED'!$A$6,'Incident Data Dump'!$H:$H,'IT FEED'!$B8,'Incident Data Dump'!$Q:$Q,'IT FEED'!AG$2) -> 1 | AH8: =COUNTIFS('Incident Data Dump'!$P:$P,'IT FEED'!$A$6,'Incident Data Dump'!$H:$H,'IT FEED'!$B8,'Incident Data Dump'!$Q:$Q,'IT FEED'!AH$2) -> 0 | AI8: =SUBTOTAL(9,AF8:AH8) -> 1 | AJ8: =SUBTOTAL(9,T8:AI8) -> 35
A9: Anaconda DC | B9: Team Member Injury | C9: =COUNTIFS('Incident Data Dump'!$P:$P,'IT FEED'!$A$9,'Incident Data Dump'!$H:$H,'IT FEED'!$B9,'Incident Data Dump'!$Q:$Q,'IT FEED'!C$2) -> 0 | D9: =COUNTIFS('Incident Data Dump'!$P:$P,'IT FEED'!$A$9,'Incident Data Dump'!$H:$H,'IT FEED'!$B9,'Incident Data Dump'!$Q:$Q,'IT FEED'!D$2) -> 4 | E9: =COUNTIFS('Incident Data Dump'!$P:$P,'IT FEED'!$A$9,'Incident Data Dump'!$H:$H,'IT FEED'!$B9,'Incident Data Dump'!$Q:$Q,'IT FEED'!E$2) -> 3 | F9: =SUBTOTAL(9,C9:E9) -> 7 | G9: =COUNTIFS('Incident Data Dump'!$P:$P,'IT FEED'!$A$9,'Incident Data Dump'!$H:$H,'IT FEED'!$B9,'Incident Data Dump'!$Q:$Q,'IT FEED'!G$2) -> 0 | H9: =COUNTIFS('Incident Data Dump'!$P:$P,'IT FEED'!$A$9,'Incident Data Dump'!$H:$H,'IT FEED'!$B9,'Incident Data Dump'!$Q:$Q,'IT FEED'!H$2) -> 2 | I9: =COUNTIFS('Incident Data Dump'!$P:$P,'IT FEED'!$A$9,'Incident Data Dump'!$H:$H,'IT FEED'!$B9,'Incident Data Dump'!$Q:$Q,'IT FEED'!I$2) -> 2 | J9: =SUBTOTAL(9,G9:I9) -> 4 | K9: =COUNTIFS('Incident Data Dump'!$P:$P,'IT FEED'!$A$9,'Incident Data Dump'!$H:$H,'IT FEED'!$B9,'Incident Data Dump'!$Q:$Q,'IT FEED'!K$2) -> 0 | L9: =COUNTIFS('Incident Data Dump'!$P:$P,'IT FEED'!$A$9,'Incident Data Dump'!$H:$H,'IT FEED'!$B9,'Incident Data Dump'!$Q:$Q,'IT FEED'!L$2) -> 0 | M9: =COUNTIFS('Incident Data Dump'!$P:$P,'IT FEED'!$A$9,'Incident Data Dump'!$H:$H,'IT FEED'!$B9,'Incident Data Dump'!$Q:$Q,'IT FEED'!M$2) -> 0 | N9: =SUBTOTAL(9,K9:M9) -> 0 | O9: =COUNTIFS('Incident Data Dump'!$P:$P,'IT FEED'!$A$9,'Incident Data Dump'!$H:$H,'IT FEED'!$B9,'Incident Data Dump'!$Q:$Q,'IT FEED'!O$2) -> 0 | P9: =COUNTIFS('Incident Data Dump'!$P:$P,'IT FEED'!$A$9,'Incident Data Dump'!$H:$H,'IT FEED'!$B9,'Incident Data Dump'!$Q:$Q,'IT FEED'!P$2) -> 1 | Q9: =COUNTIFS('Incident Data Dump'!$P:$P,'IT FEED'!$A$9,'Incident Data Dump'!$H:$H,'IT FEED'!$B9,'Incident Data Dump'!$Q:$Q,'IT FEED'!Q$2) -> 1 | R9: =SUBTOTAL(9,O9:Q9) -> 2 | S9: =SUBTOTAL(9,C9:R9) -> 13 | T9: =COUNTIFS('Incident Data Dump'!$P:$P,'IT FEED'!$A$9,'Incident Data Dump'!$H:$H,'IT FEED'!$B9,'Incident Data Dump'!$Q:$Q,'IT FEED'!T$2) -> 0 | U9: =COUNTIFS('Incident Data Dump'!$P:$P,'IT FEED'!$A$9,'Incident Data Dump'!$H:$H,'IT FEED'!$B9,'Incident Data Dump'!$Q:$Q,'IT FEED'!U$2) -> 0 | V9: =COUNTIFS('Incident Data Dump'!$P:$P,'IT FEED'!$A$9,'Incident Data Dump'!$H:$H,'IT FEED'!$B9,'Incident Data Dump'!$Q:$Q,'IT FEED'!V$2) -> 0 | W9: =SUBTOTAL(9,T9:V9) -> 0 | X9: =COUNTIFS('Incident Data Dump'!$P:$P,'IT FEED'!$A$9,'Incident Data Dump'!$H:$H,'IT FEED'!$B9,'Incident Data Dump'!$Q:$Q,'IT FEED'!X$2) -> 0 | Y9: =COUNTIFS('Incident Data Dump'!$P:$P,'IT FEED'!$A$9,'Incident Data Dump'!$H:$H,'IT FEED'!$B9,'Incident Data Dump'!$Q:$Q,'IT FEED'!Y$2) -> 0 | Z9: =COUNTIFS('Incident Data Dump'!$P:$P,'IT FEED'!$A$9,'Incident Data Dump'!$H:$H,'IT FEED'!$B9,'Incident Data Dump'!$Q:$Q,'IT FEED'!Z$2) -> 0 | AA9: =SUBTOTAL(9,X9:Z9) -> 0 | AB9: =COUNTIFS('Incident Data Dump'!$P:$P,'IT FEED'!$A$9,'Incident Data Dump'!$H:$H,'IT FEED'!$B9,'Incident Data Dump'!$Q:$Q,'IT FEED'!AB$2) -> 0 | AC9: =COUNTIFS('Incident Data Dump'!$P:$P,'IT FEED'!$A$9,'Incident Data Dump'!$H:$H,'IT FEED'!$B9,'Incident Data Dump'!$Q:$Q,'IT FEED'!AC$2) -> 0 | AD9: =COUNTIFS('Incident Data Dump'!$P:$P,'IT FEED'!$A$9,'Incident Data Dump'!$H:$H,'IT FEED'!$B9,'Incident Data Dump'!$Q:$Q,'IT FEED'!AD$2) -> 0 | AE9: =SUBTOTAL(9,AB9:AD9) -> 0 | AF9: =COUNTIFS('Incident Data Dump'!$P:$P,'IT FEED'!$A$9,'Incident Data Dump'!$H:$H,'IT FEED'!$B9,'Incident Data Dump'!$Q:$Q,'IT FEED'!AF$2) -> 0 | AG9: =COUNTIFS('Incident Data Dump'!$P:$P,'IT FEED'!$A$9,'Incident Data Dump'!$H:$H,'IT FEED'!$B9,'Incident Data Dump'!$Q:$Q,'IT FEED'!AG$2) -> 0 | AH9: =COUNTIFS('Incident Data Dump'!$P:$P,'IT FEED'!$A$9,'Incident Data Dump'!$H:$H,'IT FEED'!$B9,'Incident Data Dump'!$Q:$Q,'IT FEED'!AH$2) -> 0 | AI9: =SUBTOTAL(9,AF9:AH9) -> 0 | AJ9: =SUBTOTAL(9,T9:AI9) -> 0
B10: Safety Near Miss | C10: =COUNTIFS('Incident Data Dump'!$P:$P,'IT FEED'!$A$9,'Incident Data Dump'!$H:$H,'IT FEED'!$B10,'Incident Data Dump'!$Q:$Q,'IT FEED'!C$2) -> 4 | D10: =COUNTIFS('Incident Data Dump'!$P:$P,'IT FEED'!$A$9,'Incident Data Dump'!$H:$H,'IT FEED'!$B10,'Incident Data Dump'!$Q:$Q,'IT FEED'!D$2) -> 5 | E10: =COUNTIFS('Incident Data Dump'!$P:$P,'IT FEED'!$A$9,'Incident Data Dump'!$H:$H,'IT FEED'!$B10,'Incident Data Dump'!$Q:$Q,'IT FEED'!E$2) -> 4 | F10: =SUBTOTAL(9,C10:E10) -> 13 | G10: =COUNTIFS('Incident Data Dump'!$P:$P,'IT FEED'!$A$9,'Incident Data Dump'!$H:$H,'IT FEED'!$B10,'Incident Data Dump'!$Q:$Q,'IT FEED'!G$2) -> 8 | H10: =COUNTIFS('Incident Data Dump'!$P:$P,'IT FEED'!$A$9,'Incident Data Dump'!$H:$H,'IT FEED'!$B10,'Incident Data Dump'!$Q:$Q,'IT FEED'!H$2) -> 3 | I10: =COUNTIFS('Incident Data Dump'!$P:$P,'IT FEED'!$A$9,'Incident Data Dump'!$H:$H,'IT FEED'!$B10,'Incident Data Dump'!$Q:$Q,'IT FEED'!I$2) -> 3 | J10: =SUBTOTAL(9,G10:I10) -> 14 | K10: =COUNTIFS('Incident Data Dump'!$P:$P,'IT FEED'!$A$9,'Incident Data Dump'!$H:$H,'IT FEED'!$B10,'Incident Data Dump'!$Q:$Q,'IT FEED'!K$2) -> 0 | L10: =COUNTIFS('Incident Data Dump'!$P:$P,'IT FEED'!$A$9,'Incident Data Dump'!$H:$H,'IT FEED'!$B10,'Incident Data Dump'!$Q:$Q,'IT FEED'!L$2) -> 0 | M10: =COUNTIFS('Incident Data Dump'!$P:$P,'IT FEED'!$A$9,'Incident Data Dump'!$H:$H,'IT FEED'!$B10,'Incident Data Dump'!$Q:$Q,'IT FEED'!M$2) -> 0 | N10: =SUBTOTAL(9,K10:M10) -> 0 | O10: =COUNTIFS('Incident Data Dump'!$P:$P,'IT FEED'!$A$9,'Incident Data Dump'!$H:$H,'IT FEED'!$B10,'Incident Data Dump'!$Q:$Q,'IT FEED'!O$2) -> 0 | P10: =COUNTIFS('Incident Data Dump'!$P:$P,'IT FEED'!$A$9,'Incident Data Dump'!$H:$H,'IT FEED'!$B10,'Incident Data Dump'!$Q:$Q,'IT FEED'!P$2) -> 0 | Q10: =COUNTIFS('Incident Data Dump'!$P:$P,'IT FEED'!$A$9,'Incident Data Dump'!$H:$H,'IT FEED'!$B10,'Incident Data Dump'!$Q:$Q,'IT FEED'!Q$2) -> 0 | R10: =SUBTOTAL(9,O10:Q10) -> 0 | S10: =SUBTOTAL(9,C10:R10) -> 27 | T10: =COUNTIFS('Incident Data Dump'!$P:$P,'IT FEED'!$A$9,'Incident Data Dump'!$H:$H,'IT FEED'!$B10,'Incident Data Dump'!$Q:$Q,'IT FEED'!T$2) -> 1 | U10: =COUNTIFS('Incident Data Dump'!$P:$P,'IT FEED'!$A$9,'Incident Data Dump'!$H:$H,'IT FEED'!$B10,'Incident Data Dump'!$Q:$Q,'IT FEED'!U$2) -> 1 | V10: =COUNTIFS('Incident Data Dump'!$P:$P,'IT FEED'!$A$9,'Incident Data Dump'!$H:$H,'IT FEED'!$B10,'Incident Data Dump'!$Q:$Q,'IT FEED'!V$2) -> 0 | W10: =SUBTOTAL(9,T10:V10) -> 2 | X10: =COUNTIFS('Incident Data Dump'!$P:$P,'IT FEED'!$A$9,'Incident Data Dump'!$H:$H,'IT FEED'!$B10,'Incident Data Dump'!$Q:$Q,'IT FEED'!X$2) -> 0 | Y10: =COUNTIFS('Incident Data Dump'!$P:$P,'IT FEED'!$A$9,'Incident Data Dump'!$H:$H,'IT FEED'!$B10,'Incident Data Dump'!$Q:$Q,'IT FEED'!Y$2) -> 1 | Z10: =COUNTIFS('Incident Data Dump'!$P:$P,'IT FEED'!$A$9,'Incident Data Dump'!$H:$H,'IT FEED'!$B10,'Incident Data Dump'!$Q:$Q,'IT FEED'!Z$2) -> 0 | AA10: =SUBTOTAL(9,X10:Z10) -> 1 | AB10: =COUNTIFS('Incident Data Dump'!$P:$P,'IT FEED'!$A$9,'Incident Data Dump'!$H:$H,'IT FEED'!$B10,'Incident Data Dump'!$Q:$Q,'IT FEED'!AB$2) -> 1 | AC10: =COUNTIFS('Incident Data Dump'!$P:$P,'IT FEED'!$A$9,'Incident Data Dump'!$H:$H,'IT FEED'!$B10,'Incident Data Dump'!$Q:$Q,'IT FEED'!AC$2) -> 0 | AD10: =COUNTIFS('Incident Data Dump'!$P:$P,'IT FEED'!$A$9,'Incident Data Dump'!$H:$H,'IT FEED'!$B10,'Incident Data Dump'!$Q:$Q,'IT FEED'!AD$2) -> 0 | AE10: =SUBTOTAL(9,AB10:AD10) -> 1 | AF10: =COUNTIFS('Incident Data Dump'!$P:$P,'IT FEED'!$A$9,'Incident Data Dump'!$H:$H,'IT FEED'!$B10,'Incident Data Dump'!$Q:$Q,'IT FEED'!AF$2) -> 0 | AG10: =COUNTIFS('Incident Data Dump'!$P:$P,'IT FEED'!$A$9,'Incident Data Dump'!$H:$H,'IT FEED'!$B10,'Incident Data Dump'!$Q:$Q,'IT FEED'!AG$2) -> 0 | AH10: =COUNTIFS('Incident Data Dump'!$P:$P,'IT FEED'!$A$9,'Incident Data Dump'!$H:$H,'IT FEED'!$B10,'Incident Data Dump'!$Q:$Q,'IT FEED'!AH$2) -> 0 | AI10: =SUBTOTAL(9,AF10:AH10) -> 0 | AJ10: =SUBTOTAL(9,T10:AI10) -> 4
