Workbook

Sheet CA Report_APR FY25
B2: Customer Aggression | D2: Spotlight AU Stores | J2: Anaconda Stores | P2: Harris Scarfe Stores | V2: Brands Total
D3: STORE FEED | E3: STORE FEED | F3: STORE FEED | G3: STORE FEED | H3: STORE FEED | J3: STORE FEED | K3: STORE FEED | L3: STORE FEED | M3: STORE FEED | N3: STORE FEED | P3: STORE FEED | Q3: STORE FEED | R3: STORE FEED | S3: STORE FEED | T3: STORE FEED | V3: STORE FEED | W3: STORE FEED | X3: STORE FEED | Y3: STORE FEED | Z3: STORE FEED
D4: FY24 | F4: FY25 | J4: FY24 | L4: FY25 | P4: FY24 | R4: FY25 | V4: FY24 | X4: FY25
D5: =D6&", "&D4 -> MAY, FY24 | E5: =D6&", "&D4 -> MAY, FY24 | F5: =F6&", "&F4 -> MAY, FY25 | G5: =F6&", "&F4 -> MAY, FY25 | J5: =J6&", "&J4 -> MAY, FY24 | K5: =J6&", "&J4 -> MAY, FY24 | L5: =L6&", "&L4 -> MAY, FY25 | M5: =L6&", "&L4 -> MAY, FY25 | P5: =P6&", "&P4 -> MAY, FY24 | Q5: =P6&", "&P4 -> MAY, FY24 | R5: =R6&", "&R4 -> MAY, FY25 | S5: =R6&", "&R4 -> MAY, FY25 | V5: =V6&", "&V4 -> MAY, FY24 | W5: =V6&", "&V4 -> MAY, FY24 | X5: =X6&", "&X4 -> MAY, FY25 | Y5: =X6&", "&X4 -> MAY, FY25
B6: Incident Types | D6: MAY | E6: YTD | F6: MAY | G6: YTD | H6: VAR | J6: MAY | K6: YTD | L6: MAY | M6: YTD | N6: VAR | P6: MAY | Q6: YTD | R6: MAY | S6: YTD | T6: VAR | V6: MAY | W6: YTD | X6: MAY | Y6: YTD | Z6: VAR
B7: Security Risk | D7: {=_xlfn.XLOOKUP($B7,INDIRECT("'"&D$3&"'!"&"$B3:$B5"),_xlfn.XLOOKUP(D$5,INDIRECT("'"&D$3&"'!"&"$C2:$AZ2"),INDIRECT("'"&D$3&"'!"&"$C3:$AZ5")))} -> 8 | E7: {=_xlfn.XLOOKUP(E$6&" "&$B7,INDIRECT("'"&E$3&"'!"&"$B9:$B11"),_xlfn.XLOOKUP(E$5,INDIRECT("'"&E$3&"'!"&"$C2:$AZ2"),INDIRECT("'"&E$3&"'!"&"$C9:$AZ11")))} -> 39 | F7: {=_xlfn.XLOOKUP($B7,INDIRECT("'"&F$3&"'!"&"$B3:$B5"),_xlfn.XLOOKUP(F$5,INDIRECT("'"&F$3&"'!"&"$C2:$AZ2"),INDIRECT("'"&F$3&"'!"&"$C3:$AZ5")))} -> 4 | G7: {=_xlfn.XLOOKUP(G$6&" "&$B7,INDIRECT("'"&G$3&"'!"&"$B9:$B11"),_xlfn.XLOOKUP(G$5,INDIRECT("'"&G$3&"'!"&"$C2:$AZ2"),INDIRECT("'"&G$3&"'!"&"$C9:$AZ11")))} -> 61 | H7: =G7-E7 -> 22 | J7: {=_xlfn.XLOOKUP($B7,INDIRECT("'"&J$3&"'!"&"$B15:$B17"),_xlfn.XLOOKUP(J$5,INDIRECT("'"&J$3&"'!"&"$C2:$AZ2"),INDIRECT("'"&J$3&"'!"&"$C15:$AZ17")))} -> 7 | K7: {=_xlfn.XLOOKUP(K$6&" "&$B7,INDIRECT("'"&K$3&"'!"&"$B21:$B23"),_xlfn.XLOOKUP(K$5,INDIRECT("'"&K$3&"'!"&"$C2:$AZ2"),INDIRECT("'"&K$3&"'!"&"$C21:$AZ23")))} -> 39 | L7: {=_xlfn.XLOOKUP($B7,INDIRECT("'"&L$3&"'!"&"$B15:$B17"),_xlfn.XLOOKUP(L$5,INDIRECT("'"&L$3&"'!"&"$C2:$AZ2"),INDIRECT("'"&L$3&"'!"&"$C15:$AZ17")))} -> 5 | M7: {=_xlfn.XLOOKUP(M$6&" "&$B7,INDIRECT("'"&M$3&"'!"&"$B21:$B23"),_xlfn.XLOOKUP(M$5,INDIRECT("'"&M$3&"'!"&"$C2:$AZ2"),INDIRECT("'"&M$3&"'!"&"$C21:$AZ23")))} -> 70 | N7: =M7-K7 -> 31 | P7: {=_xlfn.XLOOKUP($B7,INDIRECT("'"&P$3&"'!"&"$B27:$B29"),_xlfn.XLOOKUP(P$5,INDIRECT("'"&P$3&"'!"&"$C2:$AZ2"),INDIRECT("'"&P$3&"'!"&"$C27:$AZ29")))} -> 4 | Q7: {=_xlfn.XLOOKUP(Q$6&" "&$B7,INDIRECT("'"&Q$3&"'!"&"$B33:$B35"),_xlfn.XLOOKUP(Q$5,INDIRECT("'"&Q$3&"'!"&"$C2:$AZ2"),INDIRECT("'"&Q$3&"'!"&"$C33:$AZ35")))} -> 28 | R7: {=_xlfn.XLOOKUP($B7,INDIRECT("'"&R$3&"'!"&"$B27:$B29"),_xlfn.XLOOKUP(R$5,INDIRECT("'"&R$3&"'!"&"$C2:$AZ2"),INDIRECT("'"&R$3&"'!"&"$C27:$AZ29")))} -> 3 | S7: {=_xlfn.XLOOKUP(S$6&" "&$B7,INDIRECT("'"&S$3&"'!"&"$B33:$B35"),_xlfn.XLOOKUP(S$5,INDIRECT("'"&S$3&"'!"&"$C2:$AZ2"),INDIRECT("'"&S$3&"'!"&"$C33:$AZ35")))} -> 48 | T7: =S7-Q7 -> 20 | V7: =D7+J7+P7 -> 19 | W7: =E7+K7+Q7 -> 106 | X7: =F7+L7+R7 -> 12 | Y7: =G7+M7+S7 -> 179 | Z7: =Y7-W7 -> 73
B8: Team Member Injury | D8: {=_xlfn.XLOOKUP($B8,INDIRECT("'"&D$3&"'!"&"$B3:$B5"),_xlfn.XLOOKUP(D$5,INDIRECT("'"&D$3&"'!"&"$C2:$AZ2"),INDIRECT("'"&D$3&"'!"&"$C3:$AZ5")))} -> 0 | E8: {=_xlfn.XLOOKUP(E$6&" "&$B8,INDIRECT("'"&E$3&"'!"&"$B9:$B11"),_xlfn.XLOOKUP(E$5,INDIRECT("'"&E$3&"'!"&"$C2:$AZ2"),INDIRECT("'"&E$3&"'!"&"$C9:$AZ11")))} -> 0 | F8: {=_xlfn.XLOOKUP($B8,INDIRECT("'"&F$3&"'!"&"$B3:$B5"),_xlfn.XLOOKUP(F$5,INDIRECT("'"&F$3&"'!"&"$C2:$AZ2"),INDIRECT("'"&F$3&"'!"&"$C3:$AZ5")))} -> 2 | G8: {=_xlfn.XLOOKUP(G$6&" "&$B8,INDIRECT("'"&G$3&"'!"&"$B9:$B11"),_xlfn.XLOOKUP(G$5,INDIRECT("'"&G$3&"'!"&"$C2:$AZ2"),INDIRECT("'"&G$3&"'!"&"$C9:$AZ11")))} -> 8 | H8: =G8-E8 -> 8 | J8: {=_xlfn.XLOOKUP($B8,INDIRECT("'"&J$3&"'!"&"$B15:$B17"),_xlfn.XLOOKUP(J$5,INDIRECT("'"&J$3&"'!"&"$C2:$AZ2"),INDIRECT("'"&J$3&"'!"&"$C15:$AZ17")))} -> 0 | K8: {=_xlfn.XLOOKUP(K$6&" "&$B8,INDIRECT("'"&K$3&"'!"&"$B21:$B23"),_xlfn.XLOOKUP(K$5,INDIRECT("'"&K$3&"'!"&"$C2:$AZ2"),INDIRECT("'"&K$3&"'!"&"$C21:$AZ23")))} -> 0 | L8: {=_xlfn.XLOOKUP($B8,INDIRECT("'"&L$3&"'!"&"$B15:$B17"),_xlfn.XLOOKUP(L$5,INDIRECT("'"&L$3&"'!"&"$C2:$AZ2"),INDIRECT("'"&L$3&"'!"&"$C15:$AZ17")))} -> 0 | M8: {=_xlfn.XLOOKUP(M$6&" "&$B8,INDIRECT("'"&M$3&"'!"&"$B21:$B23"),_xlfn.XLOOKUP(M$5,INDIRECT("'"&M$3&"'!"&"$C2:$AZ2"),INDIRECT("'"&M$3&"'!"&"$C21:$AZ23")))} -> 2 | N8: =M8-K8 -> 2 | P8: {=_xlfn.XLOOKUP($B8,INDIRECT("'"&P$3&"'!"&"$B27:$B29"),_xlfn.XLOOKUP(P$5,INDIRECT("'"&P$3&"'!"&"$C2:$AZ2"),INDIRECT("'"&P$3&"'!"&"$C27:$AZ29")))} -> 0 | Q8: {=_xlfn.XLOOKUP(Q$6&" "&$B8,INDIRECT("'"&Q$3&"'!"&"$B33:$B35"),_xlfn.XLOOKUP(Q$5,INDIRECT("'"&Q$3&"'!"&"$C2:$AZ2"),INDIRECT("'"&Q$3&"'!"&"$C33:$AZ35")))} -> 0 | R8: {=_xlfn.XLOOKUP($B8,INDIRECT("'"&R$3&"'!"&"$B27:$B29"),_xlfn.XLOOKUP(R$5,INDIRECT("'"&R$3&"'!"&"$C2:$AZ2"),INDIRECT("'"&R$3&"'!"&"$C27:$AZ29")))} -> 0 | S8: {=_xlfn.XLOOKUP(S$6&" "&$B8,INDIRECT("'"&S$3&"'!"&"$B33:$B35"),_xlfn.XLOOKUP(S$5,INDIRECT("'"&S$3&"'!"&"$C2:$AZ2"),INDIRECT("'"&S$3&"'!"&"$C33:$AZ35")))} -> 2 | T8: =S8-Q8 -> 2 | V8: =D8+J8+P8 -> 0 | W8: =E8+K8+Q8 -> 0 | X8: =F8+L8+R8 -> 2 | Y8: =G8+M8+S8 -> 12 | Z8: =Y8-W8 -> 12
B9: PsychoSocial | D9: {=_xlfn.XLOOKUP($B9,INDIRECT("'"&D$3&"'!"&"$B3:$B5"),_xlfn.XLOOKUP(D$5,INDIRECT("'"&D$3&"'!"&"$C2:$AZ2"),INDIRECT("'"&D$3&"'!"&"$C3:$AZ5")))} -> 0 | E9: {=_xlfn.XLOOKUP(E$6&" "&$B9,INDIRECT("'"&E$3&"'!"&"$B9:$B11"),_xlfn.XLOOKUP(E$5,INDIRECT("'"&E$3&"'!"&"$C2:$AZ2"),INDIRECT("'"&E$3&"'!"&"$C9:$AZ11")))} -> 0 | F9: {=_xlfn.XLOOKUP($B9,INDIRECT("'"&F$3&"'!"&"$B3:$B5"),_xlfn.XLOOKUP(F$5,INDIRECT("'"&F$3&"'!"&"$C2:$AZ2"),INDIRECT("'"&F$3&"'!"&"$C3:$AZ5")))} -> 0 | G9: {=_xlfn.XLOOKUP(G$6&" "&$B9,INDIRECT("'"&G$3&"'!"&"$B9:$B11"),_xlfn.XLOOKUP(G$5,INDIRECT("'"&G$3&"'!"&"$C2:$AZ2"),INDIRECT("'"&G$3&"'!"&"$C9:$AZ11")))} -> 4 | H9: =G9-E9 -> 4 | J9: {=_xlfn.XLOOKUP($B9,INDIRECT("'"&J$3&"'!"&"$B15:$B17"),_xlfn.XLOOKUP(J$5,INDIRECT("'"&J$3&"'!"&"$C2:$AZ2"),INDIRECT("'"&J$3&"'!"&"$C15:$AZ17")))} -> 0 | K9: {=_xlfn.XLOOKUP(K$6&" "&$B9,INDIRECT("'"&K$3&"'!"&"$B21:$B23"),_xlfn.XLOOKUP(K$5,INDIRECT("'"&K$3&"'!"&"$C2:$AZ2"),INDIRECT("'"&K$3&"'!"&"$C21:$AZ23")))} -> 0 | L9: {=_xlfn.XLOOKUP($B9,INDIRECT("'"&L$3&"'!"&"$B15:$B17"),_xlfn.XLOOKUP(L$5,INDIRECT("'"&L$3&"'!"&"$C2:$AZ2"),INDIRECT("'"&L$3&"'!"&"$C15:$AZ17")))} -> 0 | M9: {=_xlfn.XLOOKUP(M$6&" "&$B9,INDIRECT("'"&M$3&"'!"&"$B21:$B23"),_xlfn.XLOOKUP(M$5,INDIRECT("'"&M$3&"'!"&"$C2:$AZ2"),INDIRECT("'"&M$3&"'!"&"$C21:$AZ23")))} -> 1 | N9: =M9-K9 -> 1 | P9: {=_xlfn.XLOOKUP($B9,INDIRECT("'"&P$3&"'!"&"$B27:$B29"),_xlfn.XLOOKUP(P$5,INDIRECT("'"&P$3&"'!"&"$C2:$AZ2"),INDIRECT("'"&P$3&"'!"&"$C27:$AZ29")))} -> 0 | Q9: {=_xlfn.XLOOKUP(Q$6&" "&$B9,INDIRECT("'"&Q$3&"'!"&"$B33:$B35"),_xlfn.XLOOKUP(Q$5,INDIRECT("'"&Q$3&"'!"&"$C2:$AZ2"),INDIRECT("'"&Q$3&"'!"&"$C33:$AZ35")))} -> 0 | R9: {=_xlfn.XLOOKUP($B9,INDIRECT("'"&R$3&"'!"&"$B27:$B29"),_xlfn.XLOOKUP(R$5,INDIRECT("'"&R$3&"'!"&"$C2:$AZ2"),INDIRECT("'"&R$3&"'!"&"$C27:$AZ29")))} -> 0 | S9: {=_xlfn.XLOOKUP(S$6&" "&$B9,INDIRECT("'"&S$3&"'!"&"$B33:$B35"),_xlfn.XLOOKUP(S$5,INDIRECT("'"&S$3&"'!"&"$C2:$AZ2"),INDIRECT("'"&S$3&"'!"&"$C33:$AZ35")))} -> 4 | T9: =S9-Q9 -> 4 | V9: =D9+J9+P9 -> 0 | W9: =E9+K9+Q9 -> 0 | X9: =F9+L9+R9 -> 0 | Y9: =G9+M9+S9 -> 9 | Z9: =Y9-W9 -> 9
B10: Grand Total | D10: =SUM(D7:D9) -> 8 | E10: =SUM(E7:E9) -> 39 | F10: =SUM(F7:F9) -> 6 | G10: =SUM(G7:G9) -> 73 | H10: =G10-E10 -> 34 | J10: =SUM(J7:J9) -> 7 | K10: =SUM(K7:K9) -> 39 | L10: =SUM(L7:L9) -> 5 | M10: =SUM(M7:M9) -> 73 | N10: =M10-K10 -> 34 | P10: =SUM(P7:P9) -> 4 | Q10: =SUM(Q7:Q9) -> 28 | R10: =SUM(R7:R9) -> 3 | S10: =SUM(S7:S9) -> 54 | T10: =S10-Q10 -> 26 | V10: =SUM(V7:V9) -> 19 | W10: =SUM(W7:W9) -> 106 | X10: =SUM(X7:X9) -> 14 | Y10: =SUM(Y7:Y9) -> 200 | Z10: =Y10-W10 -> 94
B12: *Var denotes the Variance in YTD Columns

Sheet CA REPORT_12-month Graphs

Sheet STORE FEED
A1: Performance Measures | B1: Brand | C1: FY24 | T1: FY25
B2: Spotlight AU | C2: ="JUL, "&C1 -> JUL, FY24 | D2: ="AUG, "&C1 -> AUG, FY24 | E2: ="SEP, "&C1 -> SEP, FY24 | F2: ="Q1, "&C1 -> Q1, FY24 | G2: ="OCT, "&C1 -> OCT, FY24 | H2: ="NOV, "&C1 -> NOV, FY24 | I2: ="DEC, "&C1 -> DEC, FY24 | J2: ="Q2, "&C1 -> Q2, FY24 | K2: ="JAN, "&C1 -> JAN, FY24 | L2: ="FEB, "&C1 -> FEB, FY24 | M2: ="MAR, "&C1 -> MAR, FY24 | N2: ="Q3, "&C1 -> Q3, FY24 | O2: ="APR, "&C1 -> APR, FY24 | P2: ="MAY, "&C1 -> MAY, FY24 | Q2: ="JUN, "&C1 -> JUN, FY24 | R2: ="Q4, "&C1 -> Q4, FY24 | S2: ="Full Year, "&C1 -> Full Year, FY24 | T2: ="JUL, "&T1 -> JUL, FY25 | U2: ="AUG, "&T1 -> AUG, FY25 | V2: ="SEP, "&T1 -> SEP, FY25 | W2: ="Q1, "&T1 -> Q1, FY25 | X2: ="OCT, "&T1 -> OCT, FY25 | Y2: ="NOV, "&T1 -> NOV, FY25 | Z2: ="DEC, "&T1 -> DEC, FY25 | AA2: ="Q2, "&T1 -> Q2, FY25 | AB2: ="JAN, "&T1 -> JAN, FY25 | AC2: ="FEB, "&T1 -> FEB, FY25 | AD2: ="MAR, "&T1 -> MAR, FY25 | AE2: ="Q3, "&T1 -> Q3, FY25 | AF2: ="APR, "&T1 -> APR, FY25 | AG2: ="MAY, "&T1 -> MAY, FY25 | AH2: ="JUN, "&T1 -> JUN, FY25 | AI2: ="Q4, "&T1 -> Q4, FY25 | AJ2: ="Full Year, "&T1 -> Full Year, FY25
A3: Customer Aggression | B3: Security Risk | C3: =COUNTIFS('Sec_Risk DataDump'!$J:$J,'STORE FEED'!$B$2,'Sec_Risk DataDump'!$L:$L,'STORE FEED'!C$2) -> 3 | D3: =COUNTIFS('Sec_Risk DataDump'!$J:$J,'STORE FEED'!$B$2,'Sec_Risk DataDump'!$L:$L,'STORE FEED'!D$2) -> 7 | E3: =COUNTIFS('Sec_Risk DataDump'!$J:$J,'STORE FEED'!$B$2,'Sec_Risk DataDump'!$L:$L,'STORE FEED'!E$2) -> 3 | F3: =SUBTOTAL(9,C3:E3) -> 13 | G3: =COUNTIFS('Sec_Risk DataDump'!$J:$J,'STORE FEED'!$B$2,'Sec_Risk DataDump'!$L:$L,'STORE FEED'!G$2) -> 2 | H3: =COUNTIFS('Sec_Risk DataDump'!$J:$J,'STORE FEED'!$B$2,'Sec_Risk DataDump'!$L:$L,'STORE FEED'!H$2) -> 0 | I3: =COUNTIFS('Sec_Risk DataDump'!$J:$J,'STORE FEED'!$B$2,'Sec_Risk DataDump'!$L:$L,'STORE FEED'!I$2) -> 4 | J3: =SUBTOTAL(9,G3:I3) -> 6 | K3: =COUNTIFS('Sec_Risk DataDump'!$J:$J,'STORE FEED'!$B$2,'Sec_Risk DataDump'!$L:$L,'STORE FEED'!K$2) -> 1 | L3: =COUNTIFS('Sec_Risk DataDump'!$J:$J,'STORE FEED'!$B$2,'Sec_Risk DataDump'!$L:$L,'STORE FEED'!L$2) -> 5 | M3: =COUNTIFS('Sec_Risk DataDump'!$J:$J,'STORE FEED'!$B$2,'Sec_Risk DataDump'!$L:$L,'STORE FEED'!M$2) -> 3 | N3: =SUBTOTAL(9,K3:M3) -> 9 | O3: =COUNTIFS('Sec_Risk DataDump'!$J:$J,'STORE FEED'!$B$2,'Sec_Risk DataDump'!$L:$L,'STORE FEED'!O$2) -> 3 | P3: =COUNTIFS('Sec_Risk DataDump'!$J:$J,'STORE FEED'!$B$2,'Sec_Risk DataDump'!$L:$L,'STORE FEED'!P$2) -> 8 | Q3: =COUNTIFS('Sec_Risk DataDump'!$J:$J,'STORE FEED'!$B$2,'Sec_Risk DataDump'!$L:$L,'STORE FEED'!Q$2) -> 11 | R3: =SUBTOTAL(9,O3:Q3) -> 22 | S3: =SUBTOTAL(9,C3:R3) -> 50 | T3: =COUNTIFS('Sec_Risk DataDump'!$J:$J,'STORE FEED'!$B$2,'Sec_Risk DataDump'!$L:$L,'STORE FEED'!T$2) -> 4 | U3: =COUNTIFS('Sec_Risk DataDump'!$J:$J,'STORE FEED'!$B$2,'Sec_Risk DataDump'!$L:$L,'STORE FEED'!U$2) -> 4 | V3: =COUNTIFS('Sec_Risk DataDump'!$J:$J,'STORE FEED'!$B$2,'Sec_Risk DataDump'!$L:$L,'STORE FEED'!V$2) -> 4 | W3: =SUBTOTAL(9,T3:V3) -> 12 | X3: =COUNTIFS('Sec_Risk DataDump'!$J:$J,'STORE FEED'!$B$2,'Sec_Risk DataDump'!$L:$L,'STORE FEED'!X$2) -> 2 | Y3: =COUNTIFS('Sec_Risk DataDump'!$J:$J,'STORE FEED'!$B$2,'Sec_Risk DataDump'!$L:$L,'STORE FEED'!Y$2) -> 7 | Z3: =COUNTIFS('Sec_Risk DataDump'!$J:$J,'STORE FEED'!$B$2,'Sec_Risk DataDump'!$L:$L,'STORE FEED'!Z$2) -> 9 | AA3: =SUBTOTAL(9,X3:Z3) -> 18 | AB3: =COUNTIFS('Sec_Risk DataDump'!$J:$J,'STORE FEED'!$B$2,'Sec_Risk DataDump'!$L:$L,'STORE FEED'!AB$2) -> 4 | AC3: =COUNTIFS('Sec_Risk DataDump'!$J:$J,'STORE FEED'!$B$2,'Sec_Risk DataDump'!$L:$L,'STORE FEED'!AC$2) -> 10 | AD3: =COUNTIFS('Sec_Risk DataDump'!$J:$J,'STORE FEED'!$B$2,'Sec_Risk DataDump'!$L:$L,'STORE FEED'!AD$2) -> 8 | AE3: =SUBTOTAL(9,AB3:AD3) -> 22 | AF3: =COUNTIFS('Sec_Risk DataDump'!$J:$J,'STORE FEED'!$B$2,'Sec_Risk DataDump'!$L:$L,'STORE FEED'!AF$2) -> 5 | AG3: =COUNTIFS('Sec_Risk DataDump'!$J:$J,'STORE FEED'!$B$2,'Sec_Risk DataDump'!$L:$L,'STORE FEED'!AG$2) -> 4 | AH3: =COUNTIFS('Sec_Risk DataDump'!$J:$J,'STORE FEED'!$B$2,'Sec_Risk DataDump'!$L:$L,'STORE FEED'!AH$2) -> 0 | AI3: =SUBTOTAL(9,AF3:AH3) -> 9 | AJ3: =SUBTOTAL(9,T3:AI3) -> 61
B4: Team Member Injury | C4: =COUNTIFS('TMJ DataDump'!$J:$J,'STORE FEED'!$B$2,'TMJ DataDump'!$L:$L,'STORE FEED'!C$2) -> 0 | D4: =COUNTIFS('TMJ DataDump'!$J:$J,'STORE FEED'!$B$2,'TMJ DataDump'!$L:$L,'STORE FEED'!D$2) -> 0 | E4: =COUNTIFS('TMJ DataDump'!$J:$J,'STORE FEED'!$B$2,'TMJ DataDump'!$L:$L,'STORE FEED'!E$2) -> 0 | F4: =SUBTOTAL(9,C4:E4) -> 0 | G4: =COUNTIFS('TMJ DataDump'!$J:$J,'STORE FEED'!$B$2,'TMJ DataDump'!$L:$L,'STORE FEED'!G$2) -> 0 | H4: =COUNTIFS('TMJ DataDump'!$J:$J,'STORE FEED'!$B$2,'TMJ DataDump'!$L:$L,'STORE FEED'!H$2) -> 0 | I4: =COUNTIFS('TMJ DataDump'!$J:$J,'STORE FEED'!$B$2,'TMJ DataDump'!$L:$L,'STORE FEED'!I$2) -> 0 | J4: =SUBTOTAL(9,G4:I4) -> 0 | K4: =COUNTIFS('TMJ DataDump'!$J:$J,'STORE FEED'!$B$2,'TMJ DataDump'!$L:$L,'STORE FEED'!K$2) -> 0 | L4: =COUNTIFS('TMJ DataDump'!$J:$J,'STORE FEED'!$B$2,'TMJ DataDump'!$L:$L,'STORE FEED'!L$2) -> 0 | M4: =COUNTIFS('TMJ DataDump'!$J:$J,'STORE FEED'!$B$2,'TMJ DataDump'!$L:$L,'STORE FEED'!M$2) -> 0 | N4: =SUBTOTAL(9,K4:M4) -> 0 | O4: =COUNTIFS('TMJ DataDump'!$J:$J,'STORE FEED'!$B$2,'TMJ DataDump'!$L:$L,'STORE FEED'!O$2) -> 0 | P4: =COUNTIFS('TMJ DataDump'!$J:$J,'STORE FEED'!$B$2,'TMJ DataDump'!$L:$L,'STORE FEED'!P$2) -> 0 | Q4: =COUNTIFS('TMJ DataDump'!$J:$J,'STORE FEED'!$B$2,'TMJ DataDump'!$L:$L,'STORE FEED'!Q$2) -> 0 | R4: =SUBTOTAL(9,O4:Q4) -> 0 | S4: =SUBTOTAL(9,C4:R4) -> 0 | T4: =COUNTIFS('TMJ DataDump'!$J:$J,'STORE FEED'!$B$2,'TMJ DataDump'!$L:$L,'STORE FEED'!T$2) -> 0 | U4: =COUNTIFS('TMJ DataDump'!$J:$J,'STORE FEED'!$B$2,'TMJ DataDump'!$L:$L,'STORE FEED'!U$2) -> 0 | V4: =COUNTIFS('TMJ DataDump'!$J:$J,'STORE FEED'!$B$2,'TMJ DataDump'!$L:$L,'STORE FEED'!V$2) -> 0 | W4: =SUBTOTAL(9,T4:V4) -> 0 | X4: =COUNTIFS('TMJ DataDump'!$J:$J,'STORE FEED'!$B$2,'TMJ DataDump'!$L:$L,'STORE FEED'!X$2) -> 4 | Y4: =COUNTIFS('TMJ DataDump'!$J:$J,'STORE FEED'!$B$2,'TMJ DataDump'!$L:$L,'STORE FEED'!Y$2) -> 1 | Z4: =COUNTIFS('TMJ DataDump'!$J:$J,'STORE FEED'!$B$2,'TMJ DataDump'!$L:$L,'STORE FEED'!Z$2) -> 0 | AA4: =SUBTOTAL(9,X4:Z4) -> 5 | AB4: =COUNTIFS('TMJ DataDump'!$J:$J,'STORE FEED'!$B$2,'TMJ DataDump'!$L:$L,'STORE FEED'!AB$2) -> 0 | AC4: =COUNTIFS('TMJ DataDump'!$J:$J,'STORE FEED'!$B$2,'TMJ DataDump'!$L:$L,'STORE FEED'!AC$2) -> 0 | AD4: =COUNTIFS('TMJ DataDump'!$J:$J,'STORE FEED'!$B$2,'TMJ DataDump'!$L:$L,'STORE FEED'!AD$2) -> 0 | AE4: =SUBTOTAL(9,AB4:AD4) -> 0 | AF4: =COUNTIFS('TMJ DataDump'!$J:$J,'STORE FEED'!$B$2,'TMJ DataDump'!$L:$L,'STORE FEED'!AF$2) -> 1 | AG4: =COUNTIFS('TMJ DataDump'!$J:$J,'STORE FEED'!$B$2,'TMJ DataDump'!$L:$L,'STORE FEED'!AG$2) -> 2 | AH4: =COUNTIFS('TMJ DataDump'!$J:$J,'STORE FEED'!$B$2,'TMJ DataDump'!$L:$L,'STORE FEED'!AH$2) -> 0 | AI4: =SUBTOTAL(9,AF4:AH4) -> 3 | AJ4: =SUBTOTAL(9,T4:AI4) -> 8
B5: PsychoSocial | C5: =COUNTIFS('PsychoSocial DataDump'!$K:$K,'STORE FEED'!$B$2,'PsychoSocial DataDump'!$M:$M,'STORE FEED'!C$2) -> 0 | D5: =COUNTIFS('PsychoSocial DataDump'!$K:$K,'STORE FEED'!$B$2,'PsychoSocial DataDump'!$M:$M,'STORE FEED'!D$2) -> 0 | E5: =COUNTIFS('PsychoSocial DataDump'!$K:$K,'STORE FEED'!$B$2,'PsychoSocial DataDump'!$M:$M,'STORE FEED'!E$2) -> 0 | F5: =SUBTOTAL(9,C5:E5) -> 0 | G5: =COUNTIFS('PsychoSocial DataDump'!$K:$K,'STORE FEED'!$B$2,'PsychoSocial DataDump'!$M:$M,'STORE FEED'!G$2) -> 0 | H5: =COUNTIFS('PsychoSocial DataDump'!$K:$K,'STORE FEED'!$B$2,'PsychoSocial DataDump'!$M:$M,'STORE FEED'!H$2) -> 0 | I5: =COUNTIFS('PsychoSocial DataDump'!$K:$K,'STORE FEED'!$B$2,'PsychoSocial DataDump'!$M:$M,'STORE FEED'!I$2) -> 0 | J5: =SUBTOTAL(9,G5:I5) -> 0 | K5: =COUNTIFS('PsychoSocial DataDump'!$K:$K,'STORE FEED'!$B$2,'PsychoSocial DataDump'!$M:$M,'STORE FEED'!K$2) -> 0 | L5: =COUNTIFS('PsychoSocial DataDump'!$K:$K,'STORE FEED'!$B$2,'PsychoSocial DataDump'!$M:$M,'STORE FEED'!L$2) -> 0 | M5: =COUNTIFS('PsychoSocial DataDump'!$K:$K,'STORE FEED'!$B$2,'PsychoSocial DataDump'!$M:$M,'STORE FEED'!M$2) -> 0 | N5: =SUBTOTAL(9,K5:M5) -> 0 | O5: =COUNTIFS('PsychoSocial DataDump'!$K:$K,'STORE FEED'!$B$2,'PsychoSocial DataDump'!$M:$M,'STORE FEED'!O$2) -> 0 | P5: =COUNTIFS('PsychoSocial DataDump'!$K:$K,'STORE FEED'!$B$2,'PsychoSocial DataDump'!$M:$M,'STORE FEED'!P$2) -> 0 | Q5: =COUNTIFS('PsychoSocial DataDump'!$K:$K,'STORE FEED'!$B$2,'PsychoSocial DataDump'!$M:$M,'STORE FEED'!Q$2) -> 0 | R5: =SUBTOTAL(9,O5:Q5) -> 0 | S5: =SUBTOTAL(9,C5:R5) -> 0 | T5: =COUNTIFS('PsychoSocial DataDump'!$K:$K,'STORE FEED'!$B$2,'PsychoSocial DataDump'!$M:$M,'STORE FEED'!T$2) -> 0 | U5: =COUNTIFS('PsychoSocial DataDump'!$K:$K,'STORE FEED'!$B$2,'PsychoSocial DataDump'!$M:$M,'STORE FEED'!U$2) -> 0 | V5: =COUNTIFS('PsychoSocial DataDump'!$K:$K,'STORE FEED'!$B$2,'PsychoSocial DataDump'!$M:$M,'STORE FEED'!V$2) -> 0 | W5: =SUBTOTAL(9,T5:V5) -> 0 | X5: =COUNTIFS('PsychoSocial DataDump'!$K:$K,'STORE FEED'!$B$2,'PsychoSocial DataDump'!$M:$M,'STORE FEED'!X$2) -> 0 | Y5: =COUNTIFS('PsychoSocial DataDump'!$K:$K,'STORE FEED'!$B$2,'PsychoSocial DataDump'!$M:$M,'STORE FEED'!Y$2) -> 0 | Z5: =COUNTIFS('PsychoSocial DataDump'!$K:$K,'STORE FEED'!$B$2,'PsychoSocial DataDump'!$M:$M,'STORE FEED'!Z$2) -> 0 | AA5: =SUBTOTAL(9,X5:Z5) -> 0 | AB5: =COUNTIFS('PsychoSocial DataDump'!$K:$K,'STORE FEED'!$B$2,'PsychoSocial DataDump'!$M:$M,'STORE FEED'!AB$2) -> 0 | AC5: =COUNTIFS('PsychoSocial DataDump'!$K:$K,'STORE FEED'!$B$2,'PsychoSocial DataDump'!$M:$M,'STORE FEED'!AC$2) -> 2 | AD5: =COUNTIFS('PsychoSocial DataDump'!$K:$K,'STORE FEED'!$B$2,'PsychoSocial DataDump'!$M:$M,'STORE FEED'!AD$2) -> 1 | AE5: =SUBTOTAL(9,AB5:AD5) -> 3 | AF5: =COUNTIFS('PsychoSocial DataDump'!$K:$K,'STORE FEED'!$B$2,'PsychoSocial DataDump'!$M:$M,'STORE FEED'!AF$2) -> 1 | AG5: =COUNTIFS('PsychoSocial DataDump'!$K:$K,'STORE FEED'!$B$2,'PsychoSocial DataDump'!$M:$M,'STORE FEED'!AG$2) -> 0 | AH5: =COUNTIFS('PsychoSocial DataDump'!$K:$K,'STORE FEED'!$B$2,'PsychoSocial DataDump'!$M:$M,'STORE FEED'!AH$2) -> 0 | AI5: =SUBTOTAL(9,AF5:AH5) -> 1 | AJ5: =SUBTOTAL(9,T5:AI5) -> 4
B6: Grand Total | C6: =SUM(C3:C5) -> 3 | D6: =SUM(D3:D5) -> 7 | E6: =SUM(E3:E5) -> 3 | F6: =SUM(F3:F5) -> 13 | G6: =SUM(G3:G5) -> 2 | H6: =SUM(H3:H5) -> 0 | I6: =SUM(I3:I5) -> 4 | J6: =SUM(J3:J5) -> 6 | ... AJ6: =SUM(AJ3:AJ5) -> 73
B8: Spotlight AU
A9: YTD Customer Aggression | B9: YTD Security Risk | C9: =SUBTOTAL(9,$C3:C3) -> 3 | D9: =SUBTOTAL(9,$C3:D3) -> 10 | E9: =SUBTOTAL(9,$C3:E3) -> 13 | F9: =SUBTOTAL(9,$C3:F3) -> 13 | G9: =SUBTOTAL(9,$C3:G3) -> 15 | H9: =SUBTOTAL(9,$C3:H3) -> 15 | I9: =SUBTOTAL(9,$C3:I3) -> 19 | J9: =SUBTOTAL(9,$C3:J3) -> 19 | ... S9: =SUBTOTAL(9,$C3:S3) -> 50 | T9: =SUBTOTAL(9,$T3:T3) -> 4 | U9: =SUBTOTAL(9,$T3:U3) -> 8 | V9: =SUBTOTAL(9,$T3:V3) -> 12 | W9: =SUBTOTAL(9,$T3:W3) -> 12 | X9: =SUBTOTAL(9,$T3:X3) -> 14 | Y9: =SUBTOTAL(9,$T3:Y3) -> 21 | Z9: =SUBTOTAL(9,$T3:Z3) -> 30 | AA9: =SUBTOTAL(9,$T3:AA3) -> 30 | ... AJ9: =SUBTOTAL(9,$T3:AJ3) -> 61
B10: YTD Team Member Injury | C10: =SUBTOTAL(9,$C4:C4) -> 0 | D10: =SUBTOTAL(9,$C4:D4) -> 0 | E10: =SUBTOTAL(9,$C4:E4) -> 0 | F10: =SUBTOTAL(9,$C4:F4) -> 0 | G10: =SUBTOTAL(9,$C4:G4) -> 0 | H10: =SUBTOTAL(9,$C4:H4) -> 0 | I10: =SUBTOTAL(9,$C4:I4) -> 0 | J10: =SUBTOTAL(9,$C4:J4) -> 0 | ... S10: =SUBTOTAL(9,$C4:S4) -> 0 | T10: =SUBTOTAL(9,$T4:T4) -> 0 | U10: =SUBTOTAL(9,$T4:U4) -> 0 | V10: =SUBTOTAL(9,$T4:V4) -> 0 | W10: =SUBTOTAL(9,$T4:W4) -> 0 | X10: =SUBTOTAL(9,$T4:X4) -> 4 | Y10: =SUBTOTAL(9,$T4:Y4) -> 5 | Z10: =SUBTOTAL(9,$T4:Z4) -> 5 | AA10: =SUBTOTAL(9,$T4:AA4) -> 5 | ... AJ10: =SUBTOTAL(9,$T4:AJ4) -> 8
B11: YTD PsychoSocial | C11: =SUBTOTAL(9,$C5:C5) -> 0 | D11: =SUBTOTAL(9,$C5:D5) -> 0 | E11: =SUBTOTAL(9,$C5:E5) -> 0 | F11: =SUBTOTAL(9,$C5:F5) -> 0 | G11: =SUBTOTAL(9,$C5:G5) -> 0 | H11: =SUBTOTAL(9,$C5:H5) -> 0 | I11: =SUBTOTAL(9,$C5:I5) -> 0 | J11: =SUBTOTAL(9,$C5:J5) -> 0 | ... S11: =SUBTOTAL(9,$C5:S5) -> 0 | T11: =SUBTOTAL(9,$T5:T5) -> 0 | U11: =SUBTOTAL(9,$T5:U5) -> 0 | V11: =SUBTOTAL(9,$T5:V5) -> 0 | W11: =SUBTOTAL(9,$T5:W5) -> 0 | X11: =SUBTOTAL(9,$T5:X5) -> 0 | Y11: =SUBTOTAL(9,$T5:Y5) -> 0 | Z11: =SUBTOTAL(9,$T5:Z5) -> 0 | AA11: =SUBTOTAL(9,$T5:AA5) -> 0 | ... AJ11: =SUBTOTAL(9,$T5:AJ5) -> 4
B14: Anaconda
A15: Customer Aggression | B15: Security Risk | C15: =COUNTIFS('Sec_Risk DataDump'!$J:$J,'STORE FEED'!$B$14,'Sec_Risk DataDump'!$L:$L,'STORE FEED'!C$2) -> 2 | D15: =COUNTIFS('Sec_Risk DataDump'!$J:$J,'STORE FEED'!$B$14,'Sec_Risk DataDump'!$L:$L,'STORE FEED'!D$2) -> 0 | E15: =COUNTIFS('Sec_Risk DataDump'!$J:$J,'STORE FEED'!$B$14,'Sec_Risk DataDump'!$L:$L,'STORE FEED'!E$2) -> 1 | F15: =SUBTOTAL(9,C15:E15) -> 3 | G15: =COUNTIFS('Sec_Risk DataDump'!$J:$J,'STORE FEED'!$B$14,'Sec_Risk DataDump'!$L:$L,'STORE FEED'!G$2) -> 2 | H15: =COUNTIFS('Sec_Risk DataDump'!$J:$J,'STORE FEED'!$B$14,'Sec_Risk DataDump'!$L:$L,'STORE FEED'!H$2) -> 4 | I15: =COUNTIFS('Sec_Risk DataDump'!$J:$J,'STORE FEED'!$B$14,'Sec_Risk DataDump'!$L:$L,'STORE FEED'!I$2) -> 7 | J15: =SUBTOTAL(9,G15:I15) -> 13 | K15: =COUNTIFS('Sec_Risk DataDump'!$J:$J,'STORE FEED'!$B$14,'Sec_Risk DataDump'!$L:$L,'STORE FEED'!K$2) -> 7 | L15: =COUNTIFS('Sec_Risk DataDump'!$J:$J,'STORE FEED'!$B$14,'Sec_Risk DataDump'!$L:$L,'STORE FEED'!L$2) -> 1 | M15: =COUNTIFS('Sec_Risk DataDump'!$J:$J,'STORE FEED'!$B$14,'Sec_Risk DataDump'!$L:$L,'STORE FEED'!M$2) -> 3 | N15: =SUBTOTAL(9,K15:M15) -> 11 | O15: =COUNTIFS('Sec_Risk DataDump'!$J:$J,'STORE FEED'!$B$14,'Sec_Risk DataDump'!$L:$L,'STORE FEED'!O$2) -> 5 | P15: =COUNTIFS('Sec_Risk DataDump'!$J:$J,'STORE FEED'!$B$14,'Sec_Risk DataDump'!$L:$L,'STORE FEED'!P$2) -> 7 | Q15: =COUNTIFS('Sec_Risk DataDump'!$J:$J,'STORE FEED'!$B$14,'Sec_Risk DataDump'!$L:$L,'STORE FEED'!Q$2) -> 11 | R15: =SUBTOTAL(9,O15:Q15) -> 23 | S15: =SUBTOTAL(9,C15:R15) -> 50 | T15: =COUNTIFS('Sec_Risk DataDump'!$J:$J,'STORE FEED'!$B$14,'Sec_Risk DataDump'!$L:$L,'STORE FEED'!T$2) -> 13 | U15: =COUNTIFS('Sec_Risk DataDump'!$J:$J,'STORE FEED'!$B$14,'Sec_Risk DataDump'!$L:$L,'STORE FEED'!U$2) -> 20 | V15: =COUNTIFS('Sec_Risk DataDump'!$J:$J,'STORE FEED'!$B$14,'Sec_Risk DataDump'!$L:$L,'STORE FEED'!V$2) -> 3 | W15: =SUBTOTAL(9,T15:V15) -> 36 | X15: =COUNTIFS('Sec_Risk DataDump'!$J:$J,'STORE FEED'!$B$14,'Sec_Risk DataDump'!$L:$L,'STORE FEED'!X$2) -> 2 | Y15: =COUNTIFS('Sec_Risk DataDump'!$J:$J,'STORE FEED'!$B$14,'Sec_Risk DataDump'!$L:$L,'STORE FEED'!Y$2) -> 5 | Z15: =COUNTIFS('Sec_Risk DataDump'!$J:$J,'STORE FEED'!$B$14,'Sec_Risk DataDump'!$L:$L,'STORE FEED'!Z$2) -> 4 | AA15: =SUBTOTAL(9,X15:Z15) -> 11 | AB15: =COUNTIFS('Sec_Risk DataDump'!$J:$J,'STORE FEED'!$B$14,'Sec_Risk DataDump'!$L:$L,'STORE FEED'!AB$2) -> 1 | AC15: =COUNTIFS('Sec_Risk DataDump'!$J:$J,'STORE FEED'!$B$14,'Sec_Risk DataDump'!$L:$L,'STORE FEED'!AC$2) -> 9 | AD15: =COUNTIFS('Sec_Risk DataDump'!$J:$J,'STORE FEED'!$B$14,'Sec_Risk DataDump'!$L:$L,'STORE FEED'!AD$2) -> 3 | AE15: =SUBTOTAL(9,AB15:AD15) -> 13 | AF15: =COUNTIFS('Sec_Risk DataDump'!$J:$J,'STORE FEED'!$B$14,'Sec_Risk DataDump'!$L:$L,'STORE FEED'!AF$2) -> 5 | AG15: =COUNTIFS('Sec_Risk DataDump'!$J:$J,'STORE FEED'!$B$14,'Sec_Risk DataDump'!$L:$L,'STORE FEED'!AG$2) -> 5 | AH15: =COUNTIFS('Sec_Risk DataDump'!$J:$J,'STORE FEED'!$B$14,'Sec_Risk DataDump'!$L:$L,'STORE FEED'!AH$2) -> 0 | AI15: =SUBTOTAL(9,AF15:AH15) -> 10 | AJ15: =SUBTOTAL(9,T15:AI15) -> 70
B16: Team Member Injury | C16: =COUNTIFS('TMJ DataDump'!$J:$J,'STORE FEED'!$B$14,'TMJ DataDump'!$L:$L,'STORE FEED'!C$2) -> 0 | D16: =COUNTIFS('TMJ DataDump'!$J:$J,'STORE FEED'!$B$14,'TMJ DataDump'!$L:$L,'STORE FEED'!D$2) -> 0 | E16: =COUNTIFS('TMJ DataDump'!$J:$J,'STORE FEED'!$B$14,'TMJ DataDump'!$L:$L,'STORE FEED'!E$2) -> 0 | F16: =SUBTOTAL(9,C16:E16) -> 0 | G16: =COUNTIFS('TMJ DataDump'!$J:$J,'STORE FEED'!$B$14,'TMJ DataDump'!$L:$L,'STORE FEED'!G$2) -> 0 | H16: =COUNTIFS('TMJ DataDump'!$J:$J,'STORE FEED'!$B$14,'TMJ DataDump'!$L:$L,'STORE FEED'!H$2) -> 0 | I16: =COUNTIFS('TMJ DataDump'!$J:$J,'STORE FEED'!$B$14,'TMJ DataDump'!$L:$L,'STORE FEED'!I$2) -> 0 | J16: =SUBTOTAL(9,G16:I16) -> 0 | K16: =COUNTIFS('TMJ DataDump'!$J:$J,'STORE FEED'!$B$14,'TMJ DataDump'!$L:$L,'STORE FEED'!K$2) -> 0 | L16: =COUNTIFS('TMJ DataDump'!$J:$J,'STORE FEED'!$B$14,'TMJ DataDump'!$L:$L,'STORE FEED'!L$2) -> 0 | M16: =COUNTIFS('TMJ DataDump'!$J:$J,'STORE FEED'!$B$14,'TMJ DataDump'!$L:$L,'STORE FEED'!M$2) -> 0 | N16: =SUBTOTAL(9,K16:M16) -> 0 | O16: =COUNTIFS('TMJ DataDump'!$J:$J,'STORE FEED'!$B$14,'TMJ DataDump'!$L:$L,'STORE FEED'!O$2) -> 0 | P16: =COUNTIFS('TMJ DataDump'!$J:$J,'STORE FEED'!$B$14,'TMJ DataDump'!$L:$L,'STORE FEED'!P$2) -> 0 | Q16: =COUNTIFS('TMJ DataDump'!$J:$J,'STORE FEED'!$B$14,'TMJ DataDump'!$L:$L,'STORE FEED'!Q$2) -> 0 | R16: =SUBTOTAL(9,O16:Q16) -> 0 | S16: =SUBTOTAL(9,C16:R16) -> 0 | T16: =COUNTIFS('TMJ DataDump'!$J:$J,'STORE FEED'!$B$14,'TMJ DataDump'!$L:$L,'STORE FEED'!T$2) -> 0 | U16: =COUNTIFS('TMJ DataDump'!$J:$J,'STORE FEED'!$B$14,'TMJ DataDump'!$L:$L,'STORE FEED'!U$2) -> 0 | V16: =COUNTIFS('TMJ DataDump'!$J:$J,'STORE FEED'!$B$14,'TMJ DataDump'!$L:$L,'STORE FEED'!V$2) -> 0 | W16: =SUBTOTAL(9,T16:V16) -> 0 | X16: =COUNTIFS('TMJ DataDump'!$J:$J,'STORE FEED'!$B$14,'TMJ DataDump'!$L:$L,'STORE FEED'!X$2) -> 0 | Y16: =COUNTIFS('TMJ DataDump'!$J:$J,'STORE FEED'!$B$14,'TMJ DataDump'!$L:$L,'STORE FEED'!Y$2) -> 0 | Z16: =COUNTIFS('TMJ DataDump'!$J:$J,'STORE FEED'!$B$14,'TMJ DataDump'!$L:$L,'STORE FEED'!Z$2) -> 2 | AA16: =SUBTOTAL(9,X16:Z16) -> 2 | AB16: =COUNTIFS('TMJ DataDump'!$J:$J,'STORE FEED'!$B$14,'TMJ DataDump'!$L:$L,'STORE FEED'!AB$2) -> 0 | AC16: =COUNTIFS('TMJ DataDump'!$J:$J,'STORE FEED'!$B$14,'TMJ DataDump'!$L:$L,'STORE FEED'!AC$2) -> 0 | AD16: =COUNTIFS('TMJ DataDump'!$J:$J,'STORE FEED'!$B$14,'TMJ DataDump'!$L:$L,'STORE FEED'!AD$2) -> 0 | AE16: =SUBTOTAL(9,AB16:AD16) -> 0 | AF16: =COUNTIFS('TMJ DataDump'!$J:$J,'STORE FEED'!$B$14,'TMJ DataDump'!$L:$L,'STORE FEED'!AF$2) -> 0 | AG16: =COUNTIFS('TMJ DataDump'!$J:$J,'STORE FEED'!$B$14,'TMJ DataDump'!$L:$L,'STORE FEED'!AG$2) -> 0 | AH16: =COUNTIFS('TMJ DataDump'!$J:$J,'STORE FEED'!$B$14,'TMJ DataDump'!$L:$L,'STORE FEED'!AH$2) -> 0 | AI16: =SUBTOTAL(9,AF16:AH16) -> 0 | AJ16: =SUBTOTAL(9,T16:AI16) -> 2
B17: PsychoSocial | C17: =COUNTIFS('PsychoSocial DataDump'!$K:$K,'STORE FEED'!$B$14,'PsychoSocial DataDump'!$M:$M,'STORE FEED'!C$2) -> 0 | D17: =COUNTIFS('PsychoSocial DataDump'!$K:$K,'STORE FEED'!$B$14,'PsychoSocial DataDump'!$M:$M,'STORE FEED'!D$2) -> 0 | E17: =COUNTIFS('PsychoSocial DataDump'!$K:$K,'STORE FEED'!$B$14,'PsychoSocial DataDump'!$M:$M,'STORE FEED'!E$2) -> 0 | F17: =SUBTOTAL(9,C17:E17) -> 0 | G17: =COUNTIFS('PsychoSocial DataDump'!$K:$K,'STORE FEED'!$B$14,'PsychoSocial DataDump'!$M:$M,'STORE FEED'!G$2) -> 0 | H17: =COUNTIFS('PsychoSocial DataDump'!$K:$K,'STORE FEED'!$B$14,'PsychoSocial DataDump'!$M:$M,'STORE FEED'!H$2) -> 0 | I17: =COUNTIFS('PsychoSocial DataDump'!$K:$K,'STORE FEED'!$B$14,'PsychoSocial DataDump'!$M:$M,'STORE FEED'!I$2) -> 0 | J17: =SUBTOTAL(9,G17:I17) -> 0 | K17: =COUNTIFS('PsychoSocial DataDump'!$K:$K,'STORE FEED'!$B$14,'PsychoSocial DataDump'!$M:$M,'STORE FEED'!K$2) -> 0 | L17: =COUNTIFS('PsychoSocial DataDump'!$K:$K,'STORE FEED'!$B$14,'PsychoSocial DataDump'!$M:$M,'STORE FEED'!L$2) -> 0 | M17: =COUNTIFS('PsychoSocial DataDump'!$K:$K,'STORE FEED'!$B$14,'PsychoSocial DataDump'!$M:$M,'STORE FEED'!M$2) -> 0 | N17: =SUBTOTAL(9,K17:M17) -> 0 | O17: =COUNTIFS('PsychoSocial DataDump'!$K:$K,'STORE FEED'!$B$14,'PsychoSocial DataDump'!$M:$M,'STORE FEED'!O$2) -> 0 | P17: =COUNTIFS('PsychoSocial DataDump'!$K:$K,'STORE FEED'!$B$14,'PsychoSocial DataDump'!$M:$M,'STORE FEED'!P$2) -> 0 | Q17: =COUNTIFS('PsychoSocial DataDump'!$K:$K,'STORE FEED'!$B$14,'PsychoSocial DataDump'!$M:$M,'STORE FEED'!Q$2) -> 0 | R17: =SUBTOTAL(9,O17:Q17) -> 0 | S17: =SUBTOTAL(9,C17:R17) -> 0 | T17: =COUNTIFS('PsychoSocial DataDump'!$K:$K,'STORE FEED'!$B$14,'PsychoSocial DataDump'!$M:$M,'STORE FEED'!T$2) -> 0 | U17: =COUNTIFS('PsychoSocial DataDump'!$K:$K,'STORE FEED'!$B$14,'PsychoSocial DataDump'!$M:$M,'STORE FEED'!U$2) -> 0 | V17: =COUNTIFS('PsychoSocial DataDump'!$K:$K,'STORE FEED'!$B$14,'PsychoSocial DataDump'!$M:$M,'STORE FEED'!V$2) -> 0 | W17: =SUBTOTAL(9,T17:V17) -> 0 | X17: =COUNTIFS('PsychoSocial DataDump'!$K:$K,'STORE FEED'!$B$14,'PsychoSocial DataDump'!$M:$M,'STORE FEED'!X$2) -> 0 | Y17: =COUNTIFS('PsychoSocial DataDump'!$K:$K,'STORE FEED'!$B$14,'PsychoSocial DataDump'!$M:$M,'STORE FEED'!Y$2) -> 0 | Z17: =COUNTIFS('PsychoSocial DataDump'!$K:$K,'STORE FEED'!$B$14,'PsychoSocial DataDump'!$M:$M,'STORE FEED'!Z$2) -> 0 | AA17: =SUBTOTAL(9,X17:Z17) -> 0 | AB17: =COUNTIFS('PsychoSocial DataDump'!$K:$K,'STORE FEED'!$B$14,'PsychoSocial DataDump'!$M:$M,'STORE FEED'!AB$2) -> 0 | AC17: =COUNTIFS('PsychoSocial DataDump'!$K:$K,'STORE FEED'!$B$14,'PsychoSocial DataDump'!$M:$M,'STORE FEED'!AC$2) -> 0 | AD17: =COUNTIFS('PsychoSocial DataDump'!$K:$K,'STORE FEED'!$B$14,'PsychoSocial DataDump'!$M:$M,'STORE FEED'!AD$2) -> 0 | AE17: =SUBTOTAL(9,AB17:AD17) -> 0 | AF17: =COUNTIFS('PsychoSocial DataDump'!$K:$K,'STORE FEED'!$B$14,'PsychoSocial DataDump'!$M:$M,'STORE FEED'!AF$2) -> 1 | AG17: =COUNTIFS('PsychoSocial DataDump'!$K:$K,'STORE FEED'!$B$14,'PsychoSocial DataDump'!$M:$M,'STORE FEED'!AG$2) -> 0 | AH17: =COUNTIFS('PsychoSocial DataDump'!$K:$K,'STORE FEED'!$B$14,'PsychoSocial DataDump'!$M:$M,'STORE FEED'!AH$2) -> 0 | AI17: =SUBTOTAL(9,AF17:AH17) -> 1 | AJ17: =SUBTOTAL(9,T17:AI17) -> 1
B18: Grand Total | C18: =SUM(C15:C17) -> 2 | D18: =SUM(D15:D17) -> 0 | E18: =SUM(E15:E17) -> 1 | F18: =SUM(F15:F17) -> 3 | G18: =SUM(G15:G17) -> 2 | H18: =SUM(H15:H17) -> 4 | I18: =SUM(I15:I17) -> 7 | J18: =SUM(J15:J17) -> 13 | ... AJ18: =SUM(AJ15:AJ17) -> 73
B20: Anaconda
A21: YTD Customer Aggression | B21: YTD Security Risk | C21: =SUBTOTAL(9,$C15:C15) -> 2 | D21: =SUBTOTAL(9,$C15:D15) -> 2 | E21: =SUBTOTAL(9,$C15:E15) -> 3 | F21: =SUBTOTAL(9,$C15:F15) -> 3 | G21: =SUBTOTAL(9,$C15:G15) -> 5 | H21: =SUBTOTAL(9,$C15:H15) -> 9 | I21: =SUBTOTAL(9,$C15:I15) -> 16 | J21: =SUBTOTAL(9,$C15:J15) -> 16 | ... S21: =SUBTOTAL(9,$C15:S15) -> 50 | T21: =SUBTOTAL(9,$T15:T15) -> 13 | U21: =SUBTOTAL(9,$T15:U15) -> 33 | V21: =SUBTOTAL(9,$T15:V15) -> 36 | W21: =SUBTOTAL(9,$T15:W15) -> 36 | X21: =SUBTOTAL(9,$T15:X15) -> 38 | Y21: =SUBTOTAL(9,$T15:Y15) -> 43 | Z21: =SUBTOTAL(9,$T15:Z15) -> 47 | AA21: =SUBTOTAL(9,$T15:AA15) -> 47 | ... AJ21: =SUBTOTAL(9,$T15:AJ15) -> 70
B22: YTD Team Member Injury | C22: =SUBTOTAL(9,$C16:C16) -> 0 | D22: =SUBTOTAL(9,$C16:D16) -> 0 | E22: =SUBTOTAL(9,$C16:E16) -> 0 | F22: =SUBTOTAL(9,$C16:F16) -> 0 | G22: =SUBTOTAL(9,$C16:G16) -> 0 | H22: =SUBTOTAL(9,$C16:H16) -> 0 | I22: =SUBTOTAL(9,$C16:I16) -> 0 | J22: =SUBTOTAL(9,$C16:J16) -> 0 | ... S22: =SUBTOTAL(9,$C16:S16) -> 0 | T22: =SUBTOTAL(9,$T16:T16) -> 0 | U22: =SUBTOTAL(9,$T16:U16) -> 0 | V22: =SUBTOTAL(9,$T16:V16) -> 0 | W22: =SUBTOTAL(9,$T16:W16) -> 0 | X22: =SUBTOTAL(9,$T16:X16) -> 0 | Y22: =SUBTOTAL(9,$T16:Y16) -> 0 | Z22: =SUBTOTAL(9,$T16:Z16) -> 2 | AA22: =SUBTOTAL(9,$T16:AA16) -> 2 | ... AJ22: =SUBTOTAL(9,$T16:AJ16) -> 2
B23: YTD PsychoSocial | C23: =SUBTOTAL(9,$C17:C17) -> 0 | D23: =SUBTOTAL(9,$C17:D17) -> 0 | E23: =SUBTOTAL(9,$C17:E17) -> 0 | F23: =SUBTOTAL(9,$C17:F17) -> 0 | G23: =SUBTOTAL(9,$C17:G17) -> 0 | H23: =SUBTOTAL(9,$C17:H17) -> 0 | I23: =SUBTOTAL(9,$C17:I17) -> 0 | J23: =SUBTOTAL(9,$C17:J17) -> 0 | ... S23: =SUBTOTAL(9,$C17:S17) -> 0 | T23: =SUBTOTAL(9,$T17:T17) -> 0 | U23: =SUBTOTAL(9,$T17:U17) -> 0 | V23: =SUBTOTAL(9,$T17:V17) -> 0 | W23: =SUBTOTAL(9,$T17:W17) -> 0 | X23: =SUBTOTAL(9,$T17:X17) -> 0 | Y23: =SUBTOTAL(9,$T17:Y17) -> 0 | Z23: =SUBTOTAL(9,$T17:Z17) -> 0 | AA23: =SUBTOTAL(9,$T17:AA17) -> 0 | ... AJ23: =SUBTOTAL(9,$T17:AJ17) -> 1
B26: Harris Scarfe
A27: Customer Aggression | B27: Security Risk | C27: =COUNTIFS('Sec_Risk DataDump'!$J:$J,'STORE FEED'!$B$26,'Sec_Risk DataDump'!$L:$L,'STORE FEED'!C$2) -> 5 | D27: =COUNTIFS('Sec_Risk DataDump'!$J:$J,'STORE FEED'!$B$26,'Sec_Risk DataDump'!$L:$L,'STORE FEED'!D$2) -> 0 | E27: =COUNTIFS('Sec_Risk DataDump'!$J:$J,'STORE FEED'!$B$26,'Sec_Risk DataDump'!$L:$L,'STORE FEED'!E$2) -> 2 | F27: =SUBTOTAL(9,C27:E27) -> 7 | G27: =COUNTIFS('Sec_Risk DataDump'!$J:$J,'STORE FEED'!$B$26,'Sec_Risk DataDump'!$L:$L,'STORE FEED'!G$2) -> 1 | H27: =COUNTIFS('Sec_Risk DataDump'!$J:$J,'STORE FEED'!$B$26,'Sec_Risk DataDump'!$L:$L,'STORE FEED'!H$2) -> 4 | I27: =COUNTIFS('Sec_Risk DataDump'!$J:$J,'STORE FEED'!$B$26,'Sec_Risk DataDump'!$L:$L,'STORE FEED'!I$2) -> 4 | J27: =SUBTOTAL(9,G27:I27) -> 9 | K27: =COUNTIFS('Sec_Risk DataDump'!$J:$J,'STORE FEED'!$B$26,'Sec_Risk DataDump'!$L:$L,'STORE FEED'!K$2) -> 0 | L27: =COUNTIFS('Sec_Risk DataDump'!$J:$J,'STORE FEED'!$B$26,'Sec_Risk DataDump'!$L:$L,'STORE FEED'!L$2) -> 4 | M27: =COUNTIFS('Sec_Risk DataDump'!$J:$J,'STORE FEED'!$B$26,'Sec_Risk DataDump'!$L:$L,'STORE FEED'!M$2) -> 3 | N27: =SUBTOTAL(9,K27:M27) -> 7 | O27: =COUNTIFS('Sec_Risk DataDump'!$J:$J,'STORE FEED'!$B$26,'Sec_Risk DataDump'!$L:$L,'STORE FEED'!O$2) -> 1 | P27: =COUNTIFS('Sec_Risk DataDump'!$J:$J,'STORE FEED'!$B$26,'Sec_Risk DataDump'!$L:$L,'STORE FEED'!P$2) -> 4 | Q27: =COUNTIFS('Sec_Risk DataDump'!$J:$J,'STORE FEED'!$B$26,'Sec_Risk DataDump'!$L:$L,'STORE FEED'!Q$2) -> 6 | R27: =SUBTOTAL(9,O27:Q27) -> 11 | S27: =SUBTOTAL(9,C27:R27) -> 34 | T27: =COUNTIFS('Sec_Risk DataDump'!$J:$J,'STORE FEED'!$B$26,'Sec_Risk DataDump'!$L:$L,'STORE FEED'!T$2) -> 3 | U27: =COUNTIFS('Sec_Risk DataDump'!$J:$J,'STORE FEED'!$B$26,'Sec_Risk DataDump'!$L:$L,'STORE FEED'!U$2) -> 10 | V27: =COUNTIFS('Sec_Risk DataDump'!$J:$J,'STORE FEED'!$B$26,'Sec_Risk DataDump'!$L:$L,'STORE FEED'!V$2) -> 8 | W27: =SUBTOTAL(9,T27:V27) -> 21 | X27: =COUNTIFS('Sec_Risk DataDump'!$J:$J,'STORE FEED'!$B$26,'Sec_Risk DataDump'!$L:$L,'STORE FEED'!X$2) -> 6 | Y27: =COUNTIFS('Sec_Risk DataDump'!$J:$J,'STORE FEED'!$B$26,'Sec_Risk DataDump'!$L:$L,'STORE FEED'!Y$2) -> 6 | Z27: =COUNTIFS('Sec_Risk DataDump'!$J:$J,'STORE FEED'!$B$26,'Sec_Risk DataDump'!$L:$L,'STORE FEED'!Z$2) -> 4 | AA27: =SUBTOTAL(9,X27:Z27) -> 16 | AB27: =COUNTIFS('Sec_Risk DataDump'!$J:$J,'STORE FEED'!$B$26,'Sec_Risk DataDump'!$L:$L,'STORE FEED'!AB$2) -> 2 | AC27: =COUNTIFS('Sec_Risk DataDump'!$J:$J,'STORE FEED'!$B$26,'Sec_Risk DataDump'!$L:$L,'STORE FEED'!AC$2) -> 1 | AD27: =COUNTIFS('Sec_Risk DataDump'!$J:$J,'STORE FEED'!$B$26,'Sec_Risk DataDump'!$L:$L,'STORE FEED'!AD$2) -> 1 | AE27: =SUBTOTAL(9,AB27:AD27) -> 4 | AF27: =COUNTIFS('Sec_Risk DataDump'!$J:$J,'STORE FEED'!$B$26,'Sec_Risk DataDump'!$L:$L,'STORE FEED'!AF$2) -> 4 | AG27: =COUNTIFS('Sec_Risk DataDump'!$J:$J,'STORE FEED'!$B$26,'Sec_Risk DataDump'!$L:$L,'STORE FEED'!AG$2) -> 3 | AH27: =COUNTIFS('Sec_Risk DataDump'!$J:$J,'STORE FEED'!$B$26,'Sec_Risk DataDump'!$L:$L,'STORE FEED'!AH$2) -> 0 | AI27: =SUBTOTAL(9,AF27:AH27) -> 7 | AJ27: =SUBTOTAL(9,T27:AI27) -> 48
B28: Team Member Injury | C28: =COUNTIFS('TMJ DataDump'!$J:$J,'STORE FEED'!$B$26,'TMJ DataDump'!$L:$L,'STORE FEED'!C$2) -> 0 | D28: =COUNTIFS('TMJ DataDump'!$J:$J,'STORE FEED'!$B$26,'TMJ DataDump'!$L:$L,'STORE FEED'!D$2) -> 0 | E28: =COUNTIFS('TMJ DataDump'!$J:$J,'STORE FEED'!$B$26,'TMJ DataDump'!$L:$L,'STORE FEED'!E$2) -> 0 | F28: =SUBTOTAL(9,C28:E28) -> 0 | G28: =COUNTIFS('TMJ DataDump'!$J:$J,'STORE FEED'!$B$26,'TMJ DataDump'!$L:$L,'STORE FEED'!G$2) -> 0 | H28: =COUNTIFS('TMJ DataDump'!$J:$J,'STORE FEED'!$B$26,'TMJ DataDump'!$L:$L,'STORE FEED'!H$2) -> 0 | I28: =COUNTIFS('TMJ DataDump'!$J:$J,'STORE FEED'!$B$26,'TMJ DataDump'!$L:$L,'STORE FEED'!I$2) -> 0 | J28: =SUBTOTAL(9,G28:I28) -> 0 | K28: =COUNTIFS('TMJ DataDump'!$J:$J,'STORE FEED'!$B$26,'TMJ DataDump'!$L:$L,'STORE FEED'!K$2) -> 0 | L28: =COUNTIFS('TMJ DataDump'!$J:$J,'STORE FEED'!$B$26,'TMJ DataDump'!$L:$L,'STORE FEED'!L$2) -> 0 | M28: =COUNTIFS('TMJ DataDump'!$J:$J,'STORE FEED'!$B$26,'TMJ DataDump'!$L:$L,'STORE FEED'!M$2) -> 0 | N28: =SUBTOTAL(9,K28:M28) -> 0 | O28: =COUNTIFS('TMJ DataDump'!$J:$J,'STORE FEED'!$B$26,'TMJ DataDump'!$L:$L,'STORE FEED'!O$2) -> 0 | P28: =COUNTIFS('TMJ DataDump'!$J:$J,'STORE FEED'!$B$26,'TMJ DataDump'!$L:$L,'STORE FEED'!P$2) -> 0 | Q28: =COUNTIFS('TMJ DataDump'!$J:$J,'STORE FEED'!$B$26,'TMJ DataDump'!$L:$L,'STORE FEED'!Q$2) -> 0 | R28: =SUBTOTAL(9,O28:Q28) -> 0 | S28: =SUBTOTAL(9,C28:R28) -> 0 | T28: =COUNTIFS('TMJ DataDump'!$J:$J,'STORE FEED'!$B$26,'TMJ DataDump'!$L:$L,'STORE FEED'!T$2) -> 0 | U28: =COUNTIFS('TMJ DataDump'!$J:$J,'STORE FEED'!$B$26,'TMJ DataDump'!$L:$L,'STORE FEED'!U$2) -> 0 | V28: =COUNTIFS('TMJ DataDump'!$J:$J,'STORE FEED'!$B$26,'TMJ DataDump'!$L:$L,'STORE FEED'!V$2) -> 0 | W28: =SUBTOTAL(9,T28:V28) -> 0 | X28: =COUNTIFS('TMJ DataDump'!$J:$J,'STORE FEED'!$B$26,'TMJ DataDump'!$L:$L,'STORE FEED'!X$2) -> 0 | Y28: =COUNTIFS('TMJ DataDump'!$J:$J,'STORE FEED'!$B$26,'TMJ DataDump'!$L:$L,'STORE FEED'!Y$2) -> 0 | Z28: =COUNTIFS('TMJ DataDump'!$J:$J,'STORE FEED'!$B$26,'TMJ DataDump'!$L:$L,'STORE FEED'!Z$2) -> 0 | AA28: =SUBTOTAL(9,X28:Z28) -> 0 | AB28: =COUNTIFS('TMJ DataDump'!$J:$J,'STORE FEED'!$B$26,'TMJ DataDump'!$L:$L,'STORE FEED'!AB$2) -> 0 | AC28: =COUNTIFS('TMJ DataDump'!$J:$J,'STORE FEED'!$B$26,'TMJ DataDump'!$L:$L,'STORE FEED'!AC$2) -> 0 | AD28: =COUNTIFS('TMJ DataDump'!$J:$J,'STORE FEED'!$B$26,'TMJ DataDump'!$L:$L,'STORE FEED'!AD$2) -> 1 | AE28: =SUBTOTAL(9,AB28:AD28) -> 1 | AF28: =COUNTIFS('TMJ DataDump'!$J:$J,'STORE FEED'!$B$26,'TMJ DataDump'!$L:$L,'STORE FEED'!AF$2) -> 1 | AG28: =COUNTIFS('TMJ DataDump'!$J:$J,'STORE FEED'!$B$26,'TMJ DataDump'!$L:$L,'STORE FEED'!AG$2) -> 0 | AH28: =COUNTIFS('TMJ DataDump'!$J:$J,'STORE FEED'!$B$26,'TMJ DataDump'!$L:$L,'STORE FEED'!AH$2) -> 0 | AI28: =SUBTOTAL(9,AF28:AH28) -> 1 | AJ28: =SUBTOTAL(9,T28:AI28) -> 2
B29: PsychoSocial | C29: =COUNTIFS('PsychoSocial DataDump'!$K:$K,'STORE FEED'!$B$26,'PsychoSocial DataDump'!$M:$M,'STORE FEED'!C$2) -> 0 | D29: =COUNTIFS('PsychoSocial DataDump'!$K:$K,'STORE FEED'!$B$26,'PsychoSocial DataDump'!$M:$M,'STORE FEED'!D$2) -> 0 | E29: =COUNTIFS('PsychoSocial DataDump'!$K:$K,'STORE FEED'!$B$26,'PsychoSocial DataDump'!$M:$M,'STORE FEED'!E$2) -> 0 | F29: =SUBTOTAL(9,C29:E29) -> 0 | G29: =COUNTIFS('PsychoSocial DataDump'!$K:$K,'STORE FEED'!$B$26,'PsychoSocial DataDump'!$M:$M,'STORE FEED'!G$2) -> 0 | H29: =COUNTIFS('PsychoSocial DataDump'!$K:$K,'STORE FEED'!$B$26,'PsychoSocial DataDump'!$M:$M,'STORE FEED'!H$2) -> 0 | I29: =COUNTIFS('PsychoSocial DataDump'!$K:$K,'STORE FEED'!$B$26,'PsychoSocial DataDump'!$M:$M,'STORE FEED'!I$2) -> 0 | J29: =SUBTOTAL(9,G29:I29) -> 0 | K29: =COUNTIFS('PsychoSocial DataDump'!$K:$K,'STORE FEED'!$B$26,'PsychoSocial DataDump'!$M:$M,'STORE FEED'!K$2) -> 0 | L29: =COUNTIFS('PsychoSocial DataDump'!$K:$K,'STORE FEED'!$B$26,'PsychoSocial DataDump'!$M:$M,'STORE FEED'!L$2) -> 0 | M29: =COUNTIFS('PsychoSocial DataDump'!$K:$K,'STORE FEED'!$B$26,'PsychoSocial DataDump'!$M:$M,'STORE FEED'!M$2) -> 0 | N29: =SUBTOTAL(9,K29:M29) -> 0 | O29: =COUNTIFS('PsychoSocial DataDump'!$K:$K,'STORE FEED'!$B$26,'PsychoSocial DataDump'!$M:$M,'STORE FEED'!O$2) -> 0 | P29: =COUNTIFS('PsychoSocial DataDump'!$K:$K,'STORE FEED'!$B$26,'PsychoSocial DataDump'!$M:$M,'STORE FEED'!P$2) -> 0 | Q29: =COUNTIFS('PsychoSocial DataDump'!$K:$K,'STORE FEED'!$B$26,'PsychoSocial DataDump'!$M:$M,'STORE FEED'!Q$2) -> 0 | R29: =SUBTOTAL(9,O29:Q29) -> 0 | S29: =SUBTOTAL(9,C29:R29) -> 0 | T29: =COUNTIFS('PsychoSocial DataDump'!$K:$K,'STORE FEED'!$B$26,'PsychoSocial DataDump'!$M:$M,'STORE FEED'!T$2) -> 0 | U29: =COUNTIFS('PsychoSocial DataDump'!$K:$K,'STORE FEED'!$B$26,'PsychoSocial DataDump'!$M:$M,'STORE FEED'!U$2) -> 1 | V29: =COUNTIFS('PsychoSocial DataDump'!$K:$K,'STORE FEED'!$B$26,'PsychoSocial DataDump'!$M:$M,'STORE FEED'!V$2) -> 0 | W29: =SUBTOTAL(9,T29:V29) -> 1 | X29: =COUNTIFS('PsychoSocial DataDump'!$K:$K,'STORE FEED'!$B$26,'PsychoSocial DataDump'!$M:$M,'STORE FEED'!X$2) -> 0 | Y29: =COUNTIFS('PsychoSocial DataDump'!$K:$K,'STORE FEED'!$B$26,'PsychoSocial DataDump'!$M:$M,'STORE FEED'!Y$2) -> 0 | Z29: =COUNTIFS('PsychoSocial DataDump'!$K:$K,'STORE FEED'!$B$26,'PsychoSocial DataDump'!$M:$M,'STORE FEED'!Z$2) -> 0 | AA29: =SUBTOTAL(9,X29:Z29) -> 0 | AB29: =COUNTIFS('PsychoSocial DataDump'!$K:$K,'STORE FEED'!$B$26,'PsychoSocial DataDump'!$M:$M,'STORE FEED'!AB$2) -> 0 | AC29: =COUNTIFS('PsychoSocial DataDump'!$K:$K,'STORE FEED'!$B$26,'PsychoSocial DataDump'!$M:$M,'STORE FEED'!AC$2) -> 0 | AD29: =COUNTIFS('PsychoSocial DataDump'!$K:$K,'STORE FEED'!$B$26,'PsychoSocial DataDump'!$M:$M,'STORE FEED'!AD$2) -> 1 | AE29: =SUBTOTAL(9,AB29:AD29) -> 1 | AF29: =COUNTIFS('PsychoSocial DataDump'!$K:$K,'STORE FEED'!$B$26,'PsychoSocial DataDump'!$M:$M,'STORE FEED'!AF$2) -> 2 | AG29: =COUNTIFS('PsychoSocial DataDump'!$K:$K,'STORE FEED'!$B$26,'PsychoSocial DataDump'!$M:$M,'STORE FEED'!AG$2) -> 0 | AH29: =COUNTIFS('PsychoSocial DataDump'!$K:$K,'STORE FEED'!$B$26,'PsychoSocial DataDump'!$M:$M,'STORE FEED'!AH$2) -> 0 | AI29: =SUBTOTAL(9,AF29:AH29) -> 2 | AJ29: =SUBTOTAL(9,T29:AI29) -> 4
B30: Grand Total | C30: =SUM(C27:C29) -> 5 | D30: =SUM(D27:D29) -> 0 | E30: =SUM(E27:E29) -> 2 | F30: =SUM(F27:F29) -> 7 | G30: =SUM(G27:G29) -> 1 | H30: =SUM(H27:H29) -> 4 | I30: =SUM(I27:I29) -> 4 | J30: =SUM(J27:J29) -> 9 | ... AJ30: =SUM(AJ27:AJ29) -> 54
B32: Harris Scarfe
A33: YTD Customer Aggression | B33: YTD Security Risk | C33: =SUBTOTAL(9,$C27:C27) -> 5 | D33: =SUBTOTAL(9,$C27:D27) -> 5 | E33: =SUBTOTAL(9,$C27:E27) -> 7 | F33: =SUBTOTAL(9,$C27:F27) -> 7 | G33: =SUBTOTAL(9,$C27:G27) -> 8 | H33: =SUBTOTAL(9,$C27:H27) -> 12 | I33: =SUBTOTAL(9,$C27:I27) -> 16 | J33: =SUBTOTAL(9,$C27:J27) -> 16 | ... S33: =SUBTOTAL(9,$C27:S27) -> 34 | T33: =SUBTOTAL(9,$T27:T27) -> 3 | U33: =SUBTOTAL(9,$T27:U27) -> 13 | V33: =SUBTOTAL(9,$T27:V27) -> 21 | W33: =SUBTOTAL(9,$T27:W27) -> 21 | X33: =SUBTOTAL(9,$T27:X27) -> 27 | Y33: =SUBTOTAL(9,$T27:Y27) -> 33 | Z33: =SUBTOTAL(9,$T27:Z27) -> 37 | AA33: =SUBTOTAL(9,$T27:AA27) -> 37 | ... AJ33: =SUBTOTAL(9,$T27:AJ27) -> 48
B34: YTD Team Member Injury | C34: =SUBTOTAL(9,$C28:C28) -> 0 | D34: =SUBTOTAL(9,$C28:D28) -> 0 | E34: =SUBTOTAL(9,$C28:E28) -> 0 | F34: =SUBTOTAL(9,$C28:F28) -> 0 | G34: =SUBTOTAL(9,$C28:G28) -> 0 | H34: =SUBTOTAL(9,$C28:H28) -> 0 | I34: =SUBTOTAL(9,$C28:I28) -> 0 | J34: =SUBTOTAL(9,$C28:J28) -> 0 | ... S34: =SUBTOTAL(9,$C28:S28) -> 0 | T34: =SUBTOTAL(9,$T28:T28) -> 0 | U34: =SUBTOTAL(9,$T28:U28) -> 0 | V34: =SUBTOTAL(9,$T28:V28) -> 0 | W34: =SUBTOTAL(9,$T28:W28) -> 0 | X34: =SUBTOTAL(9,$T28:X28) -> 0 | Y34: =SUBTOTAL(9,$T28:Y28) -> 0 | Z34: =SUBTOTAL(9,$T28:Z28) -> 0 | AA34: =SUBTOTAL(9,$T28:AA28) -> 0 | ... AJ34: =SUBTOTAL(9,$T28:AJ28) -> 2
B35: YTD PsychoSocial | C35: =SUBTOTAL(9,$C29:C29) -> 0 | D35: =SUBTOTAL(9,$C29:D29) -> 0 | E35: =SUBTOTAL(9,$C29:E29) -> 0 | F35: =SUBTOTAL(9,$C29:F29) -> 0 | G35: =SUBTOTAL(9,$C29:G29) -> 0 | H35: =SUBTOTAL(9,$C29:H29) -> 0 | I35: =SUBTOTAL(9,$C29:I29) -> 0 | J35: =SUBTOTAL(9,$C29:J29) -> 0 | ... S35: =SUBTOTAL(9,$C29:S29) -> 0 | T35: =SUBTOTAL(9,$T29:T29) -> 0 | U35: =SUBTOTAL(9,$T29:U29) -> 1 | V35: =SUBTOTAL(9,$T29:V29) -> 1 | W35: =SUBTOTAL(9,$T29:W29) -> 1 | X35: =SUBTOTAL(9,$T29:X29) -> 1 | Y35: =SUBTOTAL(9,$T29:Y29) -> 1 | Z35: =SUBTOTAL(9,$T29:Z29) -> 1 | AA35: =SUBTOTAL(9,$T29:AA29) -> 1 | ... AJ35: =SUBTOTAL(9,$T29:AJ29) -> 4

Sheet PsychoSocial DataDump
A1: Unique ID | B1: Created At | C1: Date and Time of the Incident: | D1: Created By | E1: Incident Type: | F1: Psychosocial Classification: | G1: Record Location | H1: Record Organization | I1: Cause of this complaint | J1: Region | K1: Company | L1: Class | M1: Fiscal Month | N1: Fiscal Quarter
A2: INC9237 | B2: 45535.542 | C2: 45535.512 | D2: VINCENT GERACE | E2: Psychosocial | F2: Customer Aggression | G2: HS2033 EASTLAND | H2: HARRIS SCARFE PTY LTD VICTORIA | I2: Other | J2: =VLOOKUP(G2,'STORE LOOKUP'!$C:$G,2,0) -> VIC | K2: =VLOOKUP(G2,'STORE LOOKUP'!$C:$G,4,0) -> Harris Scarfe | L2: =VLOOKUP(G2,'STORE LOOKUP'!$C:$G,5,0) -> Store | M2: =VLOOKUP(C2,'FIN CAL LOOKUP'!A:J,7,1) -> AUG, FY25 | N2: =VLOOKUP(C2,'FIN CAL LOOKUP'!A:J,10,1) -> Q1, FY25
A3: INC11465 | B3: 45694.563 | C3: 45694.546 | D3: CHRISTINE BARLOW | E3: Psychosocial | F3: Customer Aggression | G3: S113 SOUTH MORANG | H3: Spotlight VICTORIA | I3: Disability / impairment | J3: =VLOOKUP(G3,'STORE LOOKUP'!$C:$G,2,0) -> VIC West | K3: =VLOOKUP(G3,'STORE LOOKUP'!$C:$G,4,0) -> Spotlight AU | L3: =VLOOKUP(G3,'STORE LOOKUP'!$C:$G,5,0) -> Store | M3: =VLOOKUP(C3,'FIN CAL LOOKUP'!A:J,7,1) -> FEB, FY25 | N3: =VLOOKUP(C3,'FIN CAL LOOKUP'!A:J,10,1) -> Q3, FY25
A4: INC11871 | B4: 45722.617 | C4: 45716.614 | D4: SHERIEN CATTERALL | E4: Psychosocial | F4: Customer Aggression | G4: S011 LAUNCESTON | H4: Spotlight TASMANIA | I4: Customer Interaction | J4: =VLOOKUP(G4,'STORE LOOKUP'!$C:$G,2,0) -> QLD Central / TAS | K4: =VLOOKUP(G4,'STORE LOOKUP'!$C:$G,4,0) -> Spotlight AU | L4: =VLOOKUP(G4,'STORE LOOKUP'!$C:$G,5,0) -> Store | M4: =VLOOKUP(C4,'FIN CAL LOOKUP'!A:J,7,1) -> FEB, FY25 | N4: =VLOOKUP(C4,'FIN CAL LOOKUP'!A:J,10,1) -> Q3, FY25
A5: INC12002 | B5: 45733.543 | C5: 45732.528 | D5: KIMBERLY YOUNG | E5: Psychosocial | F5: Customer Aggression | G5: S014 BAYSWATER | H5: Spotlight VICTORIA | I5: Customer Interaction | J5: =VLOOKUP(G5,'STORE LOOKUP'!$C:$G,2,0) -> VIC East | K5: =VLOOKUP(G5,'STORE LOOKUP'!$C:$G,4,0) -> Spotlight AU | L5: =VLOOKUP(G5,'STORE LOOKUP'!$C:$G,5,0) -> Store | M5: =VLOOKUP(C5,'FIN CAL LOOKUP'!A:J,7,1) -> MAR, FY25 | N5: =VLOOKUP(C5,'FIN CAL LOOKUP'!A:J,10,1) -> Q3, FY25
A6: INC12005 | B6: 45733.606 | C6: 45733.542 | D6: LYNDA GOLDFINCH | E6: Psychosocial | F6: Customer Aggression | G6: HS4042 CAMBRIDGE | H6: HARRIS SCARFE PTY LTD TASMANIA | I6: Customer Interaction | J6: =VLOOKUP(G6,'STORE LOOKUP'!$C:$G,2,0) -> SA/TAS | K6: =VLOOKUP(G6,'STORE LOOKUP'!$C:$G,4,0) -> Harris Scarfe | L6: =VLOOKUP(G6,'STORE LOOKUP'!$C:$G,5,0) -> Store | M6: =VLOOKUP(C6,'FIN CAL LOOKUP'!A:J,7,1) -> MAR, FY25 | N6: =VLOOKUP(C6,'FIN CAL LOOKUP'!A:J,10,1) -> Q3, FY25
A7: INC12464 | B7: 45761.619 | C7: 45760.448 | D7: AMANDA STYLES | E7: Psychosocial | F7: Customer Aggression | G7: HS1011 MARION | H7: HARRIS SCARFE PTY LTD SOUTH AUSTRALIA | I7: Customer Interaction | J7: =VLOOKUP(G7,'STORE LOOKUP'!$C:$G,2,0) -> SA/TAS | K7: =VLOOKUP(G7,'STORE LOOKUP'!$C:$G,4,0) -> Harris Scarfe | L7: =VLOOKUP(G7,'STORE LOOKUP'!$C:$G,5,0) -> Store | M7: =VLOOKUP(C7,'FIN CAL LOOKUP'!A:J,7,1) -> APR, FY25 | N7: =VLOOKUP(C7,'FIN CAL LOOKUP'!A:J,10,1) -> Q4, FY25
A8: INC12492 | B8: 45763.436 | C8: 45763.385 | D8: AMANDA STYLES | E8: Psychosocial | F8: Customer Aggression | G8: HS1011 MARION | H8: HARRIS SCARFE PTY LTD SOUTH AUSTRALIA | I8: Customer Interaction | J8: =VLOOKUP(G8,'STORE LOOKUP'!$C:$G,2,0) -> SA/TAS | K8: =VLOOKUP(G8,'STORE LOOKUP'!$C:$G,4,0) -> Harris Scarfe | L8: =VLOOKUP(G8,'STORE LOOKUP'!$C:$G,5,0) -> Store | M8: =VLOOKUP(C8,'FIN CAL LOOKUP'!A:J,7,1) -> APR, FY25 | N8: =VLOOKUP(C8,'FIN CAL LOOKUP'!A:J,10,1) -> Q4, FY25
A9: INC12577 | B9: 45769.729 | C9: 45769.701 | D9: LUKE SOUTHWELL | E9: Psychosocial | F9: Customer Aggression | G9: A038 Toowoomba | H9: Anaconda QUEENSLAND | I9: Race / ethnicity | J9: =VLOOKUP(G9,'STORE LOOKUP'!$C:$G,2,0) -> QLD NW / NT | K9: =VLOOKUP(G9,'STORE LOOKUP'!$C:$G,4,0) -> Anaconda | L9: =VLOOKUP(G9,'STORE LOOKUP'!$C:$G,5,0) -> Store | M9: =VLOOKUP(C9,'FIN CAL LOOKUP'!A:J,7,1) -> APR, FY25 | N9: =VLOOKUP(C9,'FIN CAL LOOKUP'!A:J,10,1) -> Q4, FY25
A10: INC12659 | B10: 45776.428 | C10: 45773.542 | D10: KARIN CHURCH | E10: Psychosocial | F10: Customer Aggression | G10: S046 MACKAY | H10: Spotlight QUEENSLAND | I10: Customer Interaction | J10: =VLOOKUP(G10,'STORE LOOKUP'!$C:$G,2,0) -> QLD North | K10: =VLOOKUP(G10,'STORE LOOKUP'!$C:$G,4,0) -> Spotlight AU | L10: =VLOOKUP(G10,'STORE LOOKUP'!$C:$G,5,0) -> Store | M10: =VLOOKUP(C10,'FIN CAL LOOKUP'!A:J,7,1) -> APR, FY25 | N10: =VLOOKUP(C10,'FIN CAL LOOKUP'!A:J,10,1) -> Q4, FY25

Sheet Sec_Risk DataDump
A1: Unique ID | B1: Created At | C1: Date and Time of the Incident: | D1: Created By | E1: Incident Type: | F1: Security Category: | G1: Record Location | H1: Record Organization | I1: Region | J1: Company | K1: Class | L1: Fiscal Month | M1: Fiscal Quarter
A2: INC0780 | B2: 44962.428 | C2: 44961.701 | D2: NATALIE BRUHN | E2: Security / Risk | F2: Threatening / Unsocial / Aggressive Behaviour | G2: A047 North Lakes | H2: Anaconda QUEENSLAND | I2: =VLOOKUP(G2,'STORE LOOKUP'!$C:$G,2,0) -> QLD Central | J2: =VLOOKUP(G2,'STORE LOOKUP'!$C:$G,4,0) -> Anaconda | K2: =VLOOKUP(G2,'STORE LOOKUP'!$C:$G,5,0) -> Store | L2: =VLOOKUP(C2,'FIN CAL LOOKUP'!A:J,7,1) -> FEB, FY23 | M2: =VLOOKUP(C2,'FIN CAL LOOKUP'!A:J,10,1) -> Q3, FY23
A3: INC0998 | B3: 44989.503 | C3: 44988.66 | D3: COREY REICHSTEIN | E3: Security / Risk | F3: Threatening / Unsocial / Aggressive Behaviour | G3: A043 Darwin | H3: Anaconda NORTHERN TERRITORY | I3: =VLOOKUP(G3,'STORE LOOKUP'!$C:$G,2,0) -> QLD NW / NT | J3: =VLOOKUP(G3,'STORE LOOKUP'!$C:$G,4,0) -> Anaconda | K3: =VLOOKUP(G3,'STORE LOOKUP'!$C:$G,5,0) -> Store | L3: =VLOOKUP(C3,'FIN CAL LOOKUP'!A:J,7,1) -> MAR, FY23 | M3: =VLOOKUP(C3,'FIN CAL LOOKUP'!A:J,10,1) -> Q3, FY23
A4: INC1189 | B4: 45013.62 | C4: 45013.566 | D4: TANYA AL-CHAHER | E4: Security / Risk | F4: Threatening / Unsocial / Aggressive Behaviour | G4: S044 MUNNO PARA | H4: Spotlight SOUTH AUSTRALIA | I4: =VLOOKUP(G4,'STORE LOOKUP'!$C:$G,2,0) -> SA/NT | J4: =VLOOKUP(G4,'STORE LOOKUP'!$C:$G,4,0) -> Spotlight AU | K4: =VLOOKUP(G4,'STORE LOOKUP'!$C:$G,5,0) -> Store | L4: =VLOOKUP(C4,'FIN CAL LOOKUP'!A:J,7,1) -> APR, FY23 | M4: =VLOOKUP(C4,'FIN CAL LOOKUP'!A:J,10,1) -> Q4, FY23
A5: INC1203 | B5: 45014.569 | C5: 45013.542 | D5: COREY REICHSTEIN | E5: Security / Risk | F5: Threatening / Unsocial / Aggressive Behaviour | G5: A043 Darwin | H5: Anaconda NORTHERN TERRITORY | I5: =VLOOKUP(G5,'STORE LOOKUP'!$C:$G,2,0) -> QLD NW / NT | J5: =VLOOKUP(G5,'STORE LOOKUP'!$C:$G,4,0) -> Anaconda | K5: =VLOOKUP(G5,'STORE LOOKUP'!$C:$G,5,0) -> Store | L5: =VLOOKUP(C5,'FIN CAL LOOKUP'!A:J,7,1) -> APR, FY23 | M5: =VLOOKUP(C5,'FIN CAL LOOKUP'!A:J,10,1) -> Q4, FY23
A6: INC1281 | B6: 45021.459 | C6: 45018.675 | D6: MICHAEL MILLS | E6: Security / Risk | F6: Threatening / Unsocial / Aggressive Behaviour | G6: A016 Morayfield | H6: Anaconda QUEENSLAND | I6: =VLOOKUP(G6,'STORE LOOKUP'!$C:$G,2,0) -> QLD Central | J6: =VLOOKUP(G6,'STORE LOOKUP'!$C:$G,4,0) -> Anaconda | K6: =VLOOKUP(G6,'STORE LOOKUP'!$C:$G,5,0) -> Store | L6: =VLOOKUP(C6,'FIN CAL LOOKUP'!A:J,7,1) -> APR, FY23 | M6: =VLOOKUP(C6,'FIN CAL LOOKUP'!A:J,10,1) -> Q4, FY23
A7: INC1324 | B7: 45022.624 | C7: 45022.597 | D7: BRITTANY DAVIDSON | E7: Security / Risk | F7: Threatening / Unsocial / Aggressive Behaviour | G7: A035 Ballarat | H7: Anaconda VICTORIA | I7: =VLOOKUP(G7,'STORE LOOKUP'!$C:$G,2,0) -> VIC North / East | J7: =VLOOKUP(G7,'STORE LOOKUP'!$C:$G,4,0) -> Anaconda | K7: =VLOOKUP(G7,'STORE LOOKUP'!$C:$G,5,0) -> Store | L7: =VLOOKUP(C7,'FIN CAL LOOKUP'!A:J,7,1) -> APR, FY23 | M7: =VLOOKUP(C7,'FIN CAL LOOKUP'!A:J,10,1) -> Q4, FY23
A8: INC1381 | B8: 45029.545 | C8: 45026.688 | D8: CHELSEA HARDING | E8: Security / Risk | F8: Threatening / Unsocial / Aggressive Behaviour | G8: S057 DARWIN | H8: Spotlight NORTHERN TERRITORY | I8: =VLOOKUP(G8,'STORE LOOKUP'!$C:$G,2,0) -> SA/NT | J8: =VLOOKUP(G8,'STORE LOOKUP'!$C:$G,4,0) -> Spotlight AU | K8: =VLOOKUP(G8,'STORE LOOKUP'!$C:$G,5,0) -> Store | L8: =VLOOKUP(C8,'FIN CAL LOOKUP'!A:J,7,1) -> APR, FY23 | M8: =VLOOKUP(C8,'FIN CAL LOOKUP'!A:J,10,1) -> Q4, FY23
A9: INC1382 | B9: 45029.56 | C9: 45029.514 | D9: MATHEW ARMISTEAD | E9: Security / Risk | F9: Threatening / Unsocial / Aggressive Behaviour | G9: A013 Frankston | H9: Anaconda VICTORIA | I9: =VLOOKUP(G9,'STORE LOOKUP'!$C:$G,2,0) -> VIC North / East | J9: =VLOOKUP(G9,'STORE LOOKUP'!$C:$G,4,0) -> Anaconda | K9: =VLOOKUP(G9,'STORE LOOKUP'!$C:$G,5,0) -> Store | L9: =VLOOKUP(C9,'FIN CAL LOOKUP'!A:J,7,1) -> APR, FY23 | M9: =VLOOKUP(C9,'FIN CAL LOOKUP'!A:J,10,1) -> Q4, FY23
A10: INC1391 | B10: 45030.358 | C10: 45029.642 | D10: Jessica Blackhall | E10: Security / Risk | F10: Threatening / Unsocial / Aggressive Behaviour | G10: HS4041 MOONAH | H10: Shared Services VICTORIA | I10: =VLOOKUP(G10,'STORE LOOKUP'!$C:$G,2,0) -> SA/TAS | J10: =VLOOKUP(G10,'STORE LOOKUP'!$C:$G,4,0) -> Harris Scarfe | K10: =VLOOKUP(G10,'STORE LOOKUP'!$C:$G,5,0) -> Store | L10: =VLOOKUP(C10,'FIN CAL LOOKUP'!A:J,7,1) -> APR, FY23 | M10: =VLOOKUP(C10,'FIN CAL LOOKUP'!A:J,10,1) -> Q4, FY23
A11: INC1399 | B11: 45030.632 | C11: 45030.507 | D11: ANTONY FLETCHER | E11: Security / Risk | F11: Threatening / Unsocial / Aggressive Behaviour | G11: S063 CANNINGTON | H11: Spotlight WESTERN AUSTRALIA | I11: =VLOOKUP(G11,'STORE LOOKUP'!$C:$G,2,0) -> WA | J11: =VLOOKUP(G11,'STORE LOOKUP'!$C:$G,4,0) -> Spotlight AU | K11: =VLOOKUP(G11,'STORE LOOKUP'!$C:$G,5,0) -> Store | L11: =VLOOKUP(C11,'FIN CAL LOOKUP'!A:J,7,1) -> APR, FY23 | M11: =VLOOKUP(C11,'FIN CAL LOOKUP'!A:J,10,1) -> Q4, FY23
A12: INC1449 | B12: 45035.631 | C12: 45035.583 | D12: SCOTT BUTCHER | E12: Security / Risk | F12: Threatening / Unsocial / Aggressive Behaviour | G12: HS9095 CHERMSIDE | H12: HARRIS SCARFE PTY LTD QUEENSLAND | I12: =VLOOKUP(G12,'STORE LOOKUP'!$C:$G,2,0) -> QLD | J12: =VLOOKUP(G12,'STORE LOOKUP'!$C:$G,4,0) -> Harris Scarfe | K12: =VLOOKUP(G12,'STORE LOOKUP'!$C:$G,5,0) -> Store | L12: =VLOOKUP(C12,'FIN CAL LOOKUP'!A:J,7,1) -> APR, FY23 | M12: =VLOOKUP(C12,'FIN CAL LOOKUP'!A:J,10,1) -> Q4, FY23
A13: INC1469 | B13: 45037.574 | C13: 45037.385 | D13: LAURA FAZLDEEN | E13: Security / Risk | F13: Threatening / Unsocial / Aggressive Behaviour | G13: S094 CAIRNS | H13: Spotlight QUEENSLAND | I13: =VLOOKUP(G13,'STORE LOOKUP'!$C:$G,2,0) -> QLD North | J13: =VLOOKUP(G13,'STORE LOOKUP'!$C:$G,4,0) -> Spotlight AU | K13: =VLOOKUP(G13,'STORE LOOKUP'!$C:$G,5,0) -> Store | L13: =VLOOKUP(C13,'FIN CAL LOOKUP'!A:J,7,1) -> APR, FY23 | M13: =VLOOKUP(C13,'FIN CAL LOOKUP'!A:J,10,1) -> Q4, FY23
... A358: INC13146 | B358: 45809.69 | C358: 45809.665 | D358: MELISSA MOROZOV | E358: Security / Risk | F358: Threatening / Unsocial / Aggressive Behaviour | G358: A020 Preston | H358: Anaconda VICTORIA | I358: =VLOOKUP(G358,'STORE LOOKUP'!$C:$G,2,0) -> VIC West / TAS | J358: =VLOOKUP(G358,'STORE LOOKUP'!$C:$G,4,0) -> Anaconda | K358: =VLOOKUP(G358,'STORE LOOKUP'!$C:$G,5,0) -> Store | L358: =VLOOKUP(C358,'FIN CAL LOOKUP'!A:J,7,1) -> MAY, FY25 | M358: =VLOOKUP(C358,'FIN CAL LOOKUP'!A:J,10,1) -> Q4, FY25

Sheet TMJ DataDump
A1: Parent Record: Uniq ID | B1: Created At | C1: Date and Time of the Incident | D1: Created By | E1: Injury Type | F1: Injury Nature | G1: Parent Record: Record Location | H1: Parent Record: Record Organization | I1: Region | J1: Company | K1: Class | L1: Fiscal Month | M1: Fiscal Quarter
A2: INC10009 | B2: 45589.824 | C2: 45589.691 | D2: SAMARA SOLLY | E2: Customer Aggression | F2: Other | G2: S044 MUNNO PARA | H2: Spotlight SOUTH AUSTRALIA | I2: =VLOOKUP(G2,'STORE LOOKUP'!$C:$G,2,0) -> SA/NT | J2: =VLOOKUP(G2,'STORE LOOKUP'!$C:$G,4,0) -> Spotlight AU | K2: =VLOOKUP(G2,'STORE LOOKUP'!$C:$G,5,0) -> Store | L2: =VLOOKUP(C2,'FIN CAL LOOKUP'!A:J,7,1) -> OCT, FY25 | M2: =VLOOKUP(C2,'FIN CAL LOOKUP'!A:J,10,1) -> Q2, FY25
A3: INC10010 | B3: 45589.836 | C3: 45589.691 | D3: SAMARA SOLLY | E3: Customer Aggression | F3: Other | G3: S044 MUNNO PARA | H3: Spotlight SOUTH AUSTRALIA | I3: =VLOOKUP(G3,'STORE LOOKUP'!$C:$G,2,0) -> SA/NT | J3: =VLOOKUP(G3,'STORE LOOKUP'!$C:$G,4,0) -> Spotlight AU | K3: =VLOOKUP(G3,'STORE LOOKUP'!$C:$G,5,0) -> Store | L3: =VLOOKUP(C3,'FIN CAL LOOKUP'!A:J,7,1) -> OCT, FY25 | M3: =VLOOKUP(C3,'FIN CAL LOOKUP'!A:J,10,1) -> Q2, FY25
A4: INC10019 | B4: 45591.512 | C4: 45589.667 | D4: RAZIA ALI | E4: Customer Aggression | F4: Psychological Factors | G4: S125 WETHERILL PARK | H4: Spotlight NEW SOUTH WALES | I4: =VLOOKUP(G4,'STORE LOOKUP'!$C:$G,2,0) -> NSW South / ACT | J4: =VLOOKUP(G4,'STORE LOOKUP'!$C:$G,4,0) -> Spotlight AU | K4: =VLOOKUP(G4,'STORE LOOKUP'!$C:$G,5,0) -> Store | L4: =VLOOKUP(C4,'FIN CAL LOOKUP'!A:J,7,1) -> OCT, FY25 | M4: =VLOOKUP(C4,'FIN CAL LOOKUP'!A:J,10,1) -> Q2, FY25
A5: INC10072 | B5: 45593.557 | C5: 45592.708 | D5: DEBRA CHESTERFIELD | E5: Customer Aggression | F5: Bruise/Pain/Soreness | G5: S071 CHRISTCHURCH | H5: Spotlight NZ NEW ZEALAND | I5: =VLOOKUP(G5,'STORE LOOKUP'!$C:$G,2,0) -> New Zealand South | J5: =VLOOKUP(G5,'STORE LOOKUP'!$C:$G,4,0) -> Spotlight NZ | K5: =VLOOKUP(G5,'STORE LOOKUP'!$C:$G,5,0) -> Store | L5: =VLOOKUP(C5,'FIN CAL LOOKUP'!A:J,7,1) -> OCT, FY25 | M5: =VLOOKUP(C5,'FIN CAL LOOKUP'!A:J,10,1) -> Q2, FY25
A6: INC10043 | B6: 45593.56 | C6: 45589.688 | D6: ANGELA GEORGIESKA | E6: Customer Aggression | F6: Psychological Factors | G6: S044 MUNNO PARA | H6: Spotlight SOUTH AUSTRALIA | I6: =VLOOKUP(G6,'STORE LOOKUP'!$C:$G,2,0) -> SA/NT | J6: =VLOOKUP(G6,'STORE LOOKUP'!$C:$G,4,0) -> Spotlight AU | K6: =VLOOKUP(G6,'STORE LOOKUP'!$C:$G,5,0) -> Store | L6: =VLOOKUP(C6,'FIN CAL LOOKUP'!A:J,7,1) -> OCT, FY25 | M6: =VLOOKUP(C6,'FIN CAL LOOKUP'!A:J,10,1) -> Q2, FY25
A7: INC10114 | B7: 45596.47 | C7: 45596.451 | D7: SUSAN O'CONNELL | E7: Customer Aggression | F7: Psychological Factors | G7: S098 BURNSIDE | H7: Spotlight VICTORIA | I7: =VLOOKUP(G7,'STORE LOOKUP'!$C:$G,2,0) -> VIC West | J7: =VLOOKUP(G7,'STORE LOOKUP'!$C:$G,4,0) -> Spotlight AU | K7: =VLOOKUP(G7,'STORE LOOKUP'!$C:$G,5,0) -> Store | L7: =VLOOKUP(C7,'FIN CAL LOOKUP'!A:J,7,1) -> NOV, FY25 | M7: =VLOOKUP(C7,'FIN CAL LOOKUP'!A:J,10,1) -> Q2, FY25
A8: INC10916 | B8: 45654.652 | C8: 45654.572 | D8: THOMAS NADER | E8: Customer Aggression | F8: Cut/Abrasion, Other | G8: A023 West Gosford | H8: Anaconda NEW SOUTH WALES | I8: =VLOOKUP(G8,'STORE LOOKUP'!$C:$G,2,0) -> NSW North | J8: =VLOOKUP(G8,'STORE LOOKUP'!$C:$G,4,0) -> Anaconda | K8: =VLOOKUP(G8,'STORE LOOKUP'!$C:$G,5,0) -> Store | L8: =VLOOKUP(C8,'FIN CAL LOOKUP'!A:J,7,1) -> DEC, FY25 | M8: =VLOOKUP(C8,'FIN CAL LOOKUP'!A:J,10,1) -> Q2, FY25
A9: INC10919 | B9: 45654.69 | C9: 45654.572 | D9: THOMAS NADER | E9: Customer Aggression | F9: Bruise/Pain/Soreness, Cut/Abrasion, Sprain/Strain | G9: A023 West Gosford | H9: Anaconda NEW SOUTH WALES | I9: =VLOOKUP(G9,'STORE LOOKUP'!$C:$G,2,0) -> NSW North | J9: =VLOOKUP(G9,'STORE LOOKUP'!$C:$G,4,0) -> Anaconda | K9: =VLOOKUP(G9,'STORE LOOKUP'!$C:$G,5,0) -> Store | L9: =VLOOKUP(C9,'FIN CAL LOOKUP'!A:J,7,1) -> DEC, FY25 | M9: =VLOOKUP(C9,'FIN CAL LOOKUP'!A:J,10,1) -> Q2, FY25
A10: INC12252 | B10: 45748.457 | C10: 45745.429 | D10: ARGO D'ALOIA | E10: Customer Aggression | F10: Psychological Factors | G10: HS1005 ELIZABETH | H10: HARRIS SCARFE PTY LTD SOUTH AUSTRALIA | I10: =VLOOKUP(G10,'STORE LOOKUP'!$C:$G,2,0) -> SA/TAS | J10: =VLOOKUP(G10,'STORE LOOKUP'!$C:$G,4,0) -> Harris Scarfe | K10: =VLOOKUP(G10,'STORE LOOKUP'!$C:$G,5,0) -> Store | L10: =VLOOKUP(C10,'FIN CAL LOOKUP'!A:J,7,1) -> MAR, FY25 | M10: =VLOOKUP(C10,'FIN CAL LOOKUP'!A:J,10,1) -> Q3, FY25
A11: INC12345 | B11: 45754.651 | C11: 45753.625 | D11: LYNDAL PHILLIPS | E11: Customer Aggression | F11: Other | G11: S110 FRANKSTON | H11: Spotlight VICTORIA | I11: =VLOOKUP(G11,'STORE LOOKUP'!$C:$G,2,0) -> VIC East | J11: =VLOOKUP(G11,'STORE LOOKUP'!$C:$G,4,0) -> Spotlight AU | K11: =VLOOKUP(G11,'STORE LOOKUP'!$C:$G,5,0) -> Store | L11: =VLOOKUP(C11,'FIN CAL LOOKUP'!A:J,7,1) -> APR, FY25 | M11: =VLOOKUP(C11,'FIN CAL LOOKUP'!A:J,10,1) -> Q4, FY25
A12: INC12608 | B12: 45771.611 | C12: 45771.566 | D12: PETER RIGGS | E12: Customer Aggression | F12: Bruise/Pain/Soreness | G12: HS2020 FOREST HILL | H12: HARRIS SCARFE PTY LTD VICTORIA | I12: =VLOOKUP(G12,'STORE LOOKUP'!$C:$G,2,0) -> VIC | J12: =VLOOKUP(G12,'STORE LOOKUP'!$C:$G,4,0) -> Harris Scarfe | K12: =VLOOKUP(G12,'STORE LOOKUP'!$C:$G,5,0) -> Store | L12: =VLOOKUP(C12,'FIN CAL LOOKUP'!A:J,7,1) -> APR, FY25 | M12: =VLOOKUP(C12,'FIN CAL LOOKUP'!A:J,10,1) -> Q4, FY25
