Workbook

Sheet MLA REPORT_Monthly View
B2: Mandatory Learning Activity | D2: Mandatory Learning Activities - Booked | J2: Mandatory Learning Activities - In Progress | P2: Mandatory Learning Activities - Complete | V2: Mandatory Learning Activities - Month
D3: MLA FEED 2 | E3: MLA FEED 2 | F3: MLA FEED 2 | G3: MLA FEED 2 | H3: MLA FEED 2 | J3: MLA FEED 2 | K3: MLA FEED 2 | L3: MLA FEED 2 | M3: MLA FEED 2 | N3: MLA FEED 2 | P3: MLA FEED 2 | Q3: MLA FEED 2 | R3: MLA FEED 2 | S3: MLA FEED 2 | T3: MLA FEED 2 | V3: MLA FEED | W3: MLA FEED | X3: MLA FEED | Y3: MLA FEED | Z3: MLA FEED
D4: FY24 | F4: FY25 | J4: FY24 | L4: FY25 | P4: FY24 | R4: FY25 | V4: FY24 | X4: FY25
D5: =D6&", "&D4 -> MAY, FY24 | E5: =D6&", "&D4 -> MAY, FY24 | F5: =F6&", "&F4 -> MAY, FY25 | G5: =F6&", "&F4 -> MAY, FY25 | J5: =J6&", "&J4 -> MAY, FY24 | K5: =J6&", "&J4 -> MAY, FY24 | L5: =L6&", "&L4 -> MAY, FY25 | M5: =L6&", "&L4 -> MAY, FY25 | P5: =P6&", "&P4 -> MAY, FY24 | Q5: =P6&", "&P4 -> MAY, FY24 | R5: =R6&", "&R4 -> MAY, FY25 | S5: =R6&", "&R4 -> MAY, FY25 | V5: =V6&", "&V4 -> MAY, FY24 | W5: =V6&", "&V4 -> MAY, FY24 | X5: =X6&", "&X4 -> MAY, FY25 | Y5: =X6&", "&X4 -> MAY, FY25
B6: Shared Services, FFM, SPG | D6: MAY | E6: YTD | F6: MAY | G6: YTD | H6: VAR | J6: MAY | K6: YTD | L6: MAY | M6: YTD | N6: VAR | P6: MAY | Q6: YTD | R6: MAY | S6: YTD | T6: VAR | V6: MAY | W6: YTD | X6: MAY | Y6: YTD | Z6: VAR
B7: Bullying, Harassment and Discrimination - Module 1 | D7: {=_xlfn.XLOOKUP($B7,INDIRECT("'"&D$3&"'!"&"$B3:$B14"),_xlfn.XLOOKUP(D$5,INDIRECT("'"&D$3&"'!"&"$C2:$AZ2"),INDIRECT("'"&D$3&"'!"&"$C3:$AZ14")))} -> 0 | E7: {=_xlfn.XLOOKUP(E$6&" "&$B7,INDIRECT("'"&E$3&"'!"&"$B17:$B28"),_xlfn.XLOOKUP(E$5,INDIRECT("'"&E$3&"'!"&"$C2:$AZ2"),INDIRECT("'"&E$3&"'!"&"$C17:$AZ28")))} -> 0 | F7: {=_xlfn.XLOOKUP($B7,INDIRECT("'"&F$3&"'!"&"$B3:$B14"),_xlfn.XLOOKUP(F$5,INDIRECT("'"&F$3&"'!"&"$C2:$AZ2"),INDIRECT("'"&F$3&"'!"&"$C3:$AZ14")))} -> 1 | G7: {=_xlfn.XLOOKUP(G$6&" "&$B7,INDIRECT("'"&G$3&"'!"&"$B17:$B28"),_xlfn.XLOOKUP(G$5,INDIRECT("'"&G$3&"'!"&"$C2:$AZ2"),INDIRECT("'"&G$3&"'!"&"$C17:$AZ28")))} -> 5 | H7: =G7-E7 -> 5 | J7: {=_xlfn.XLOOKUP($B7,INDIRECT("'"&J$3&"'!"&"$B32:$B43"),_xlfn.XLOOKUP(J$5,INDIRECT("'"&J$3&"'!"&"$C2:$AZ2"),INDIRECT("'"&J$3&"'!"&"$C32:$AZ43")))} -> 0 | K7: {=_xlfn.XLOOKUP(K$6&" "&$B7,INDIRECT("'"&K$3&"'!"&"$B46:$B57"),_xlfn.XLOOKUP(K$5,INDIRECT("'"&K$3&"'!"&"$C2:$AZ2"),INDIRECT("'"&K$3&"'!"&"$C46:$AZ57")))} -> 0 | L7: {=_xlfn.XLOOKUP($B7,INDIRECT("'"&L$3&"'!"&"$B32:$B43"),_xlfn.XLOOKUP(L$5,INDIRECT("'"&L$3&"'!"&"$C2:$AZ2"),INDIRECT("'"&L$3&"'!"&"$C32:$AZ43")))} -> 0 | M7: {=_xlfn.XLOOKUP(M$6&" "&$B7,INDIRECT("'"&M$3&"'!"&"$B46:$B57"),_xlfn.XLOOKUP(M$5,INDIRECT("'"&M$3&"'!"&"$C2:$AZ2"),INDIRECT("'"&M$3&"'!"&"$C46:$AZ57")))} -> 0 | N7: =M7-K7 -> 0 | P7: {=_xlfn.XLOOKUP($B7,INDIRECT("'"&P$3&"'!"&"$B61:$B72"),_xlfn.XLOOKUP(P$5,INDIRECT("'"&P$3&"'!"&"$C2:$AZ2"),INDIRECT("'"&P$3&"'!"&"$C61:$AZ72")))} -> 8 | Q7: {=_xlfn.XLOOKUP(Q$6&" "&$B7,INDIRECT("'"&Q$3&"'!"&"$B75:$B86"),_xlfn.XLOOKUP(Q$5,INDIRECT("'"&Q$3&"'!"&"$C2:$AZ2"),INDIRECT("'"&Q$3&"'!"&"$C75:$AZ86")))} -> 69 | R7: {=_xlfn.XLOOKUP($B7,INDIRECT("'"&R$3&"'!"&"$B61:$B72"),_xlfn.XLOOKUP(R$5,INDIRECT("'"&R$3&"'!"&"$C2:$AZ2"),INDIRECT("'"&R$3&"'!"&"$C61:$AZ72")))} -> 9 | S7: {=_xlfn.XLOOKUP(S$6&" "&$B7,INDIRECT("'"&S$3&"'!"&"$B75:$B86"),_xlfn.XLOOKUP(S$5,INDIRECT("'"&S$3&"'!"&"$C2:$AZ2"),INDIRECT("'"&S$3&"'!"&"$C75:$AZ86")))} -> 92 | T7: =S7-Q7 -> 23 | V7: {=_xlfn.XLOOKUP($B7,INDIRECT("'"&V$3&"'!"&"$B3:$B14"),_xlfn.XLOOKUP(V$5,INDIRECT("'"&V$3&"'!"&"$C2:$AZ2"),INDIRECT("'"&V$3&"'!"&"$C3:$AZ14")))} -> 8 | W7: {=_xlfn.XLOOKUP(W$6&" "&$B7,INDIRECT("'"&W$3&"'!"&"$B16:$B27"),_xlfn.XLOOKUP(W$5,INDIRECT("'"&W$3&"'!"&"$C2:$AZ2"),INDIRECT("'"&W$3&"'!"&"$C16:$AZ27")))} -> 69 | X7: {=_xlfn.XLOOKUP($B7,INDIRECT("'"&X$3&"'!"&"$B3:$B14"),_xlfn.XLOOKUP(X$5,INDIRECT("'"&X$3&"'!"&"$C2:$AZ2"),INDIRECT("'"&X$3&"'!"&"$C3:$AZ14")))} -> 10 | Y7: {=_xlfn.XLOOKUP(Y$6&" "&$B7,INDIRECT("'"&Y$3&"'!"&"$B16:$B27"),_xlfn.XLOOKUP(Y$5,INDIRECT("'"&Y$3&"'!"&"$C2:$AZ2"),INDIRECT("'"&Y$3&"'!"&"$C16:$AZ27")))} -> 97 | Z7: =Y7-W7 -> 28
B8: Bullying, Harassment and Discrimination - Module 2 | D8: {=_xlfn.XLOOKUP($B8,INDIRECT("'"&D$3&"'!"&"$B3:$B14"),_xlfn.XLOOKUP(D$5,INDIRECT("'"&D$3&"'!"&"$C2:$AZ2"),INDIRECT("'"&D$3&"'!"&"$C3:$AZ14")))} -> 0 | E8: {=_xlfn.XLOOKUP(E$6&" "&$B8,INDIRECT("'"&E$3&"'!"&"$B17:$B28"),_xlfn.XLOOKUP(E$5,INDIRECT("'"&E$3&"'!"&"$C2:$AZ2"),INDIRECT("'"&E$3&"'!"&"$C17:$AZ28")))} -> 0 | F8: {=_xlfn.XLOOKUP($B8,INDIRECT("'"&F$3&"'!"&"$B3:$B14"),_xlfn.XLOOKUP(F$5,INDIRECT("'"&F$3&"'!"&"$C2:$AZ2"),INDIRECT("'"&F$3&"'!"&"$C3:$AZ14")))} -> 1 | G8: {=_xlfn.XLOOKUP(G$6&" "&$B8,INDIRECT("'"&G$3&"'!"&"$B17:$B28"),_xlfn.XLOOKUP(G$5,INDIRECT("'"&G$3&"'!"&"$C2:$AZ2"),INDIRECT("'"&G$3&"'!"&"$C17:$AZ28")))} -> 5 | H8: =G8-E8 -> 5 | J8: {=_xlfn.XLOOKUP($B8,INDIRECT("'"&J$3&"'!"&"$B32:$B43"),_xlfn.XLOOKUP(J$5,INDIRECT("'"&J$3&"'!"&"$C2:$AZ2"),INDIRECT("'"&J$3&"'!"&"$C32:$AZ43")))} -> 0 | K8: {=_xlfn.XLOOKUP(K$6&" "&$B8,INDIRECT("'"&K$3&"'!"&"$B46:$B57"),_xlfn.XLOOKUP(K$5,INDIRECT("'"&K$3&"'!"&"$C2:$AZ2"),INDIRECT("'"&K$3&"'!"&"$C46:$AZ57")))} -> 0 | L8: {=_xlfn.XLOOKUP($B8,INDIRECT("'"&L$3&"'!"&"$B32:$B43"),_xlfn.XLOOKUP(L$5,INDIRECT("'"&L$3&"'!"&"$C2:$AZ2"),INDIRECT("'"&L$3&"'!"&"$C32:$AZ43")))} -> 0 | M8: {=_xlfn.XLOOKUP(M$6&" "&$B8,INDIRECT("'"&M$3&"'!"&"$B46:$B57"),_xlfn.XLOOKUP(M$5,INDIRECT("'"&M$3&"'!"&"$C2:$AZ2"),INDIRECT("'"&M$3&"'!"&"$C46:$AZ57")))} -> 0 | N8: =M8-K8 -> 0 | P8: {=_xlfn.XLOOKUP($B8,INDIRECT("'"&P$3&"'!"&"$B61:$B72"),_xlfn.XLOOKUP(P$5,INDIRECT("'"&P$3&"'!"&"$C2:$AZ2"),INDIRECT("'"&P$3&"'!"&"$C61:$AZ72")))} -> 9 | Q8: {=_xlfn.XLOOKUP(Q$6&" "&$B8,INDIRECT("'"&Q$3&"'!"&"$B75:$B86"),_xlfn.XLOOKUP(Q$5,INDIRECT("'"&Q$3&"'!"&"$C2:$AZ2"),INDIRECT("'"&Q$3&"'!"&"$C75:$AZ86")))} -> 74 | R8: {=_xlfn.XLOOKUP($B8,INDIRECT("'"&R$3&"'!"&"$B61:$B72"),_xlfn.XLOOKUP(R$5,INDIRECT("'"&R$3&"'!"&"$C2:$AZ2"),INDIRECT("'"&R$3&"'!"&"$C61:$AZ72")))} -> 9 | S8: {=_xlfn.XLOOKUP(S$6&" "&$B8,INDIRECT("'"&S$3&"'!"&"$B75:$B86"),_xlfn.XLOOKUP(S$5,INDIRECT("'"&S$3&"'!"&"$C2:$AZ2"),INDIRECT("'"&S$3&"'!"&"$C75:$AZ86")))} -> 91 | T8: =S8-Q8 -> 17 | V8: {=_xlfn.XLOOKUP($B8,INDIRECT("'"&V$3&"'!"&"$B3:$B14"),_xlfn.XLOOKUP(V$5,INDIRECT("'"&V$3&"'!"&"$C2:$AZ2"),INDIRECT("'"&V$3&"'!"&"$C3:$AZ14")))} -> 9 | W8: {=_xlfn.XLOOKUP(W$6&" "&$B8,INDIRECT("'"&W$3&"'!"&"$B16:$B27"),_xlfn.XLOOKUP(W$5,INDIRECT("'"&W$3&"'!"&"$C2:$AZ2"),INDIRECT("'"&W$3&"'!"&"$C16:$AZ27")))} -> 74 | X8: {=_xlfn.XLOOKUP($B8,INDIRECT("'"&X$3&"'!"&"$B3:$B14"),_xlfn.XLOOKUP(X$5,INDIRECT("'"&X$3&"'!"&"$C2:$AZ2"),INDIRECT("'"&X$3&"'!"&"$C3:$AZ14")))} -> 10 | Y8: {=_xlfn.XLOOKUP(Y$6&" "&$B8,INDIRECT("'"&Y$3&"'!"&"$B16:$B27"),_xlfn.XLOOKUP(Y$5,INDIRECT("'"&Y$3&"'!"&"$C2:$AZ2"),INDIRECT("'"&Y$3&"'!"&"$C16:$AZ27")))} -> 96 | Z8: =Y8-W8 -> 22
B9: Bullying, Harassment and Discrimination for Team Leaders/Line Managers | D9: {=_xlfn.XLOOKUP($B9,INDIRECT("'"&D$3&"'!"&"$B3:$B14"),_xlfn.XLOOKUP(D$5,INDIRECT("'"&D$3&"'!"&"$C2:$AZ2"),INDIRECT("'"&D$3&"'!"&"$C3:$AZ14")))} -> 0 | E9: {=_xlfn.XLOOKUP(E$6&" "&$B9,INDIRECT("'"&E$3&"'!"&"$B17:$B28"),_xlfn.XLOOKUP(E$5,INDIRECT("'"&E$3&"'!"&"$C2:$AZ2"),INDIRECT("'"&E$3&"'!"&"$C17:$AZ28")))} -> 0 | F9: {=_xlfn.XLOOKUP($B9,INDIRECT("'"&F$3&"'!"&"$B3:$B14"),_xlfn.XLOOKUP(F$5,INDIRECT("'"&F$3&"'!"&"$C2:$AZ2"),INDIRECT("'"&F$3&"'!"&"$C3:$AZ14")))} -> 0 | G9: {=_xlfn.XLOOKUP(G$6&" "&$B9,INDIRECT("'"&G$3&"'!"&"$B17:$B28"),_xlfn.XLOOKUP(G$5,INDIRECT("'"&G$3&"'!"&"$C2:$AZ2"),INDIRECT("'"&G$3&"'!"&"$C17:$AZ28")))} -> 0 | H9: =G9-E9 -> 0 | J9: {=_xlfn.XLOOKUP($B9,INDIRECT("'"&J$3&"'!"&"$B32:$B43"),_xlfn.XLOOKUP(J$5,INDIRECT("'"&J$3&"'!"&"$C2:$AZ2"),INDIRECT("'"&J$3&"'!"&"$C32:$AZ43")))} -> 0 | K9: {=_xlfn.XLOOKUP(K$6&" "&$B9,INDIRECT("'"&K$3&"'!"&"$B46:$B57"),_xlfn.XLOOKUP(K$5,INDIRECT("'"&K$3&"'!"&"$C2:$AZ2"),INDIRECT("'"&K$3&"'!"&"$C46:$AZ57")))} -> 0 | L9: {=_xlfn.XLOOKUP($B9,INDIRECT("'"&L$3&"'!"&"$B32:$B43"),_xlfn.XLOOKUP(L$5,INDIRECT("'"&L$3&"'!"&"$C2:$AZ2"),INDIRECT("'"&L$3&"'!"&"$C32:$AZ43")))} -> 0 | M9: {=_xlfn.XLOOKUP(M$6&" "&$B9,INDIRECT("'"&M$3&"'!"&"$B46:$B57"),_xlfn.XLOOKUP(M$5,INDIRECT("'"&M$3&"'!"&"$C2:$AZ2"),INDIRECT("'"&M$3&"'!"&"$C46:$AZ57")))} -> 0 | N9: =M9-K9 -> 0 | P9: {=_xlfn.XLOOKUP($B9,INDIRECT("'"&P$3&"'!"&"$B61:$B72"),_xlfn.XLOOKUP(P$5,INDIRECT("'"&P$3&"'!"&"$C2:$AZ2"),INDIRECT("'"&P$3&"'!"&"$C61:$AZ72")))} -> 0 | Q9: {=_xlfn.XLOOKUP(Q$6&" "&$B9,INDIRECT("'"&Q$3&"'!"&"$B75:$B86"),_xlfn.XLOOKUP(Q$5,INDIRECT("'"&Q$3&"'!"&"$C2:$AZ2"),INDIRECT("'"&Q$3&"'!"&"$C75:$AZ86")))} -> 3 | R9: {=_xlfn.XLOOKUP($B9,INDIRECT("'"&R$3&"'!"&"$B61:$B72"),_xlfn.XLOOKUP(R$5,INDIRECT("'"&R$3&"'!"&"$C2:$AZ2"),INDIRECT("'"&R$3&"'!"&"$C61:$AZ72")))} -> 0 | S9: {=_xlfn.XLOOKUP(S$6&" "&$B9,INDIRECT("'"&S$3&"'!"&"$B75:$B86"),_xlfn.XLOOKUP(S$5,INDIRECT("'"&S$3&"'!"&"$C2:$AZ2"),INDIRECT("'"&S$3&"'!"&"$C75:$AZ86")))} -> 6 | T9: =S9-Q9 -> 3 | V9: {=_xlfn.XLOOKUP($B9,INDIRECT("'"&V$3&"'!"&"$B3:$B14"),_xlfn.XLOOKUP(V$5,INDIRECT("'"&V$3&"'!"&"$C2:$AZ2"),INDIRECT("'"&V$3&"'!"&"$C3:$AZ14")))} -> 0 | W9: {=_xlfn.XLOOKUP(W$6&" "&$B9,INDIRECT("'"&W$3&"'!"&"$B16:$B27"),_xlfn.XLOOKUP(W$5,INDIRECT("'"&W$3&"'!"&"$C2:$AZ2"),INDIRECT("'"&W$3&"'!"&"$C16:$AZ27")))} -> 3 | X9: {=_xlfn.XLOOKUP($B9,INDIRECT("'"&X$3&"'!"&"$B3:$B14"),_xlfn.XLOOKUP(X$5,INDIRECT("'"&X$3&"'!"&"$C2:$AZ2"),INDIRECT("'"&X$3&"'!"&"$C3:$AZ14")))} -> 0 | Y9: {=_xlfn.XLOOKUP(Y$6&" "&$B9,INDIRECT("'"&Y$3&"'!"&"$B16:$B27"),_xlfn.XLOOKUP(Y$5,INDIRECT("'"&Y$3&"'!"&"$C2:$AZ2"),INDIRECT("'"&Y$3&"'!"&"$C16:$AZ27")))} -> 6 | Z9: =Y9-W9 -> 3
B10: Cyber Security Awareness - Business Email Compromise Scams | D10: {=_xlfn.XLOOKUP($B10,INDIRECT("'"&D$3&"'!"&"$B3:$B14"),_xlfn.XLOOKUP(D$5,INDIRECT("'"&D$3&"'!"&"$C2:$AZ2"),INDIRECT("'"&D$3&"'!"&"$C3:$AZ14")))} -> 0 | E10: {=_xlfn.XLOOKUP(E$6&" "&$B10,INDIRECT("'"&E$3&"'!"&"$B17:$B28"),_xlfn.XLOOKUP(E$5,INDIRECT("'"&E$3&"'!"&"$C2:$AZ2"),INDIRECT("'"&E$3&"'!"&"$C17:$AZ28")))} -> 100 | F10: {=_xlfn.XLOOKUP($B10,INDIRECT("'"&F$3&"'!"&"$B3:$B14"),_xlfn.XLOOKUP(F$5,INDIRECT("'"&F$3&"'!"&"$C2:$AZ2"),INDIRECT("'"&F$3&"'!"&"$C3:$AZ14")))} -> 28 | G10: {=_xlfn.XLOOKUP(G$6&" "&$B10,INDIRECT("'"&G$3&"'!"&"$B17:$B28"),_xlfn.XLOOKUP(G$5,INDIRECT("'"&G$3&"'!"&"$C2:$AZ2"),INDIRECT("'"&G$3&"'!"&"$C17:$AZ28")))} -> 61 | H10: =G10-E10 -> -39 | J10: {=_xlfn.XLOOKUP($B10,INDIRECT("'"&J$3&"'!"&"$B32:$B43"),_xlfn.XLOOKUP(J$5,INDIRECT("'"&J$3&"'!"&"$C2:$AZ2"),INDIRECT("'"&J$3&"'!"&"$C32:$AZ43")))} -> 0 | K10: {=_xlfn.XLOOKUP(K$6&" "&$B10,INDIRECT("'"&K$3&"'!"&"$B46:$B57"),_xlfn.XLOOKUP(K$5,INDIRECT("'"&K$3&"'!"&"$C2:$AZ2"),INDIRECT("'"&K$3&"'!"&"$C46:$AZ57")))} -> 1 | L10: {=_xlfn.XLOOKUP($B10,INDIRECT("'"&L$3&"'!"&"$B32:$B43"),_xlfn.XLOOKUP(L$5,INDIRECT("'"&L$3&"'!"&"$C2:$AZ2"),INDIRECT("'"&L$3&"'!"&"$C32:$AZ43")))} -> 0 | M10: {=_xlfn.XLOOKUP(M$6&" "&$B10,INDIRECT("'"&M$3&"'!"&"$B46:$B57"),_xlfn.XLOOKUP(M$5,INDIRECT("'"&M$3&"'!"&"$C2:$AZ2"),INDIRECT("'"&M$3&"'!"&"$C46:$AZ57")))} -> 5 | N10: =M10-K10 -> 4 | P10: {=_xlfn.XLOOKUP($B10,INDIRECT("'"&P$3&"'!"&"$B61:$B72"),_xlfn.XLOOKUP(P$5,INDIRECT("'"&P$3&"'!"&"$C2:$AZ2"),INDIRECT("'"&P$3&"'!"&"$C61:$AZ72")))} -> 61 | Q10: {=_xlfn.XLOOKUP(Q$6&" "&$B10,INDIRECT("'"&Q$3&"'!"&"$B75:$B86"),_xlfn.XLOOKUP(Q$5,INDIRECT("'"&Q$3&"'!"&"$C2:$AZ2"),INDIRECT("'"&Q$3&"'!"&"$C75:$AZ86")))} -> 117 | R10: {=_xlfn.XLOOKUP($B10,INDIRECT("'"&R$3&"'!"&"$B61:$B72"),_xlfn.XLOOKUP(R$5,INDIRECT("'"&R$3&"'!"&"$C2:$AZ2"),INDIRECT("'"&R$3&"'!"&"$C61:$AZ72")))} -> 60 | S10: {=_xlfn.XLOOKUP(S$6&" "&$B10,INDIRECT("'"&S$3&"'!"&"$B75:$B86"),_xlfn.XLOOKUP(S$5,INDIRECT("'"&S$3&"'!"&"$C2:$AZ2"),INDIRECT("'"&S$3&"'!"&"$C75:$AZ86")))} -> 188 | T10: =S10-Q10 -> 71 | V10: {=_xlfn.XLOOKUP($B10,INDIRECT("'"&V$3&"'!"&"$B3:$B14"),_xlfn.XLOOKUP(V$5,INDIRECT("'"&V$3&"'!"&"$C2:$AZ2"),INDIRECT("'"&V$3&"'!"&"$C3:$AZ14")))} -> 61 | W10: {=_xlfn.XLOOKUP(W$6&" "&$B10,INDIRECT("'"&W$3&"'!"&"$B16:$B27"),_xlfn.XLOOKUP(W$5,INDIRECT("'"&W$3&"'!"&"$C2:$AZ2"),INDIRECT("'"&W$3&"'!"&"$C16:$AZ27")))} -> 218 | X10: {=_xlfn.XLOOKUP($B10,INDIRECT("'"&X$3&"'!"&"$B3:$B14"),_xlfn.XLOOKUP(X$5,INDIRECT("'"&X$3&"'!"&"$C2:$AZ2"),INDIRECT("'"&X$3&"'!"&"$C3:$AZ14")))} -> 88 | Y10: {=_xlfn.XLOOKUP(Y$6&" "&$B10,INDIRECT("'"&Y$3&"'!"&"$B16:$B27"),_xlfn.XLOOKUP(Y$5,INDIRECT("'"&Y$3&"'!"&"$C2:$AZ2"),INDIRECT("'"&Y$3&"'!"&"$C16:$AZ27")))} -> 254 | Z10: =Y10-W10 -> 36
B11: Cyber Security Awareness - Introduction | D11: {=_xlfn.XLOOKUP($B11,INDIRECT("'"&D$3&"'!"&"$B3:$B14"),_xlfn.XLOOKUP(D$5,INDIRECT("'"&D$3&"'!"&"$C2:$AZ2"),INDIRECT("'"&D$3&"'!"&"$C3:$AZ14")))} -> 0 | E11: {=_xlfn.XLOOKUP(E$6&" "&$B11,INDIRECT("'"&E$3&"'!"&"$B17:$B28"),_xlfn.XLOOKUP(E$5,INDIRECT("'"&E$3&"'!"&"$C2:$AZ2"),INDIRECT("'"&E$3&"'!"&"$C17:$AZ28")))} -> 89 | F11: {=_xlfn.XLOOKUP($B11,INDIRECT("'"&F$3&"'!"&"$B3:$B14"),_xlfn.XLOOKUP(F$5,INDIRECT("'"&F$3&"'!"&"$C2:$AZ2"),INDIRECT("'"&F$3&"'!"&"$C3:$AZ14")))} -> 24 | G11: {=_xlfn.XLOOKUP(G$6&" "&$B11,INDIRECT("'"&G$3&"'!"&"$B17:$B28"),_xlfn.XLOOKUP(G$5,INDIRECT("'"&G$3&"'!"&"$C2:$AZ2"),INDIRECT("'"&G$3&"'!"&"$C17:$AZ28")))} -> 57 | H11: =G11-E11 -> -32 | J11: {=_xlfn.XLOOKUP($B11,INDIRECT("'"&J$3&"'!"&"$B32:$B43"),_xlfn.XLOOKUP(J$5,INDIRECT("'"&J$3&"'!"&"$C2:$AZ2"),INDIRECT("'"&J$3&"'!"&"$C32:$AZ43")))} -> 0 | K11: {=_xlfn.XLOOKUP(K$6&" "&$B11,INDIRECT("'"&K$3&"'!"&"$B46:$B57"),_xlfn.XLOOKUP(K$5,INDIRECT("'"&K$3&"'!"&"$C2:$AZ2"),INDIRECT("'"&K$3&"'!"&"$C46:$AZ57")))} -> 2 | L11: {=_xlfn.XLOOKUP($B11,INDIRECT("'"&L$3&"'!"&"$B32:$B43"),_xlfn.XLOOKUP(L$5,INDIRECT("'"&L$3&"'!"&"$C2:$AZ2"),INDIRECT("'"&L$3&"'!"&"$C32:$AZ43")))} -> 0 | M11: {=_xlfn.XLOOKUP(M$6&" "&$B11,INDIRECT("'"&M$3&"'!"&"$B46:$B57"),_xlfn.XLOOKUP(M$5,INDIRECT("'"&M$3&"'!"&"$C2:$AZ2"),INDIRECT("'"&M$3&"'!"&"$C46:$AZ57")))} -> 3 | N11: =M11-K11 -> 1 | P11: {=_xlfn.XLOOKUP($B11,INDIRECT("'"&P$3&"'!"&"$B61:$B72"),_xlfn.XLOOKUP(P$5,INDIRECT("'"&P$3&"'!"&"$C2:$AZ2"),INDIRECT("'"&P$3&"'!"&"$C61:$AZ72")))} -> 62 | Q11: {=_xlfn.XLOOKUP(Q$6&" "&$B11,INDIRECT("'"&Q$3&"'!"&"$B75:$B86"),_xlfn.XLOOKUP(Q$5,INDIRECT("'"&Q$3&"'!"&"$C2:$AZ2"),INDIRECT("'"&Q$3&"'!"&"$C75:$AZ86")))} -> 125 | R11: {=_xlfn.XLOOKUP($B11,INDIRECT("'"&R$3&"'!"&"$B61:$B72"),_xlfn.XLOOKUP(R$5,INDIRECT("'"&R$3&"'!"&"$C2:$AZ2"),INDIRECT("'"&R$3&"'!"&"$C61:$AZ72")))} -> 66 | S11: {=_xlfn.XLOOKUP(S$6&" "&$B11,INDIRECT("'"&S$3&"'!"&"$B75:$B86"),_xlfn.XLOOKUP(S$5,INDIRECT("'"&S$3&"'!"&"$C2:$AZ2"),INDIRECT("'"&S$3&"'!"&"$C75:$AZ86")))} -> 196 | T11: =S11-Q11 -> 71 | V11: {=_xlfn.XLOOKUP($B11,INDIRECT("'"&V$3&"'!"&"$B3:$B14"),_xlfn.XLOOKUP(V$5,INDIRECT("'"&V$3&"'!"&"$C2:$AZ2"),INDIRECT("'"&V$3&"'!"&"$C3:$AZ14")))} -> 62 | W11: {=_xlfn.XLOOKUP(W$6&" "&$B11,INDIRECT("'"&W$3&"'!"&"$B16:$B27"),_xlfn.XLOOKUP(W$5,INDIRECT("'"&W$3&"'!"&"$C2:$AZ2"),INDIRECT("'"&W$3&"'!"&"$C16:$AZ27")))} -> 216 | X11: {=_xlfn.XLOOKUP($B11,INDIRECT("'"&X$3&"'!"&"$B3:$B14"),_xlfn.XLOOKUP(X$5,INDIRECT("'"&X$3&"'!"&"$C2:$AZ2"),INDIRECT("'"&X$3&"'!"&"$C3:$AZ14")))} -> 90 | Y11: {=_xlfn.XLOOKUP(Y$6&" "&$B11,INDIRECT("'"&Y$3&"'!"&"$B16:$B27"),_xlfn.XLOOKUP(Y$5,INDIRECT("'"&Y$3&"'!"&"$C2:$AZ2"),INDIRECT("'"&Y$3&"'!"&"$C16:$AZ27")))} -> 256 | Z11: =Y11-W11 -> 40
B12: Cyber Security Awareness - Malicious Links | D12: {=_xlfn.XLOOKUP($B12,INDIRECT("'"&D$3&"'!"&"$B3:$B14"),_xlfn.XLOOKUP(D$5,INDIRECT("'"&D$3&"'!"&"$C2:$AZ2"),INDIRECT("'"&D$3&"'!"&"$C3:$AZ14")))} -> 0 | E12: {=_xlfn.XLOOKUP(E$6&" "&$B12,INDIRECT("'"&E$3&"'!"&"$B17:$B28"),_xlfn.XLOOKUP(E$5,INDIRECT("'"&E$3&"'!"&"$C2:$AZ2"),INDIRECT("'"&E$3&"'!"&"$C17:$AZ28")))} -> 102 | F12: {=_xlfn.XLOOKUP($B12,INDIRECT("'"&F$3&"'!"&"$B3:$B14"),_xlfn.XLOOKUP(F$5,INDIRECT("'"&F$3&"'!"&"$C2:$AZ2"),INDIRECT("'"&F$3&"'!"&"$C3:$AZ14")))} -> 27 | G12: {=_xlfn.XLOOKUP(G$6&" "&$B12,INDIRECT("'"&G$3&"'!"&"$B17:$B28"),_xlfn.XLOOKUP(G$5,INDIRECT("'"&G$3&"'!"&"$C2:$AZ2"),INDIRECT("'"&G$3&"'!"&"$C17:$AZ28")))} -> 60 | H12: =G12-E12 -> -42 | J12: {=_xlfn.XLOOKUP($B12,INDIRECT("'"&J$3&"'!"&"$B32:$B43"),_xlfn.XLOOKUP(J$5,INDIRECT("'"&J$3&"'!"&"$C2:$AZ2"),INDIRECT("'"&J$3&"'!"&"$C32:$AZ43")))} -> 0 | K12: {=_xlfn.XLOOKUP(K$6&" "&$B12,INDIRECT("'"&K$3&"'!"&"$B46:$B57"),_xlfn.XLOOKUP(K$5,INDIRECT("'"&K$3&"'!"&"$C2:$AZ2"),INDIRECT("'"&K$3&"'!"&"$C46:$AZ57")))} -> 0 | L12: {=_xlfn.XLOOKUP($B12,INDIRECT("'"&L$3&"'!"&"$B32:$B43"),_xlfn.XLOOKUP(L$5,INDIRECT("'"&L$3&"'!"&"$C2:$AZ2"),INDIRECT("'"&L$3&"'!"&"$C32:$AZ43")))} -> 0 | M12: {=_xlfn.XLOOKUP(M$6&" "&$B12,INDIRECT("'"&M$3&"'!"&"$B46:$B57"),_xlfn.XLOOKUP(M$5,INDIRECT("'"&M$3&"'!"&"$C2:$AZ2"),INDIRECT("'"&M$3&"'!"&"$C46:$AZ57")))} -> 3 | N12: =M12-K12 -> 3 | P12: {=_xlfn.XLOOKUP($B12,INDIRECT("'"&P$3&"'!"&"$B61:$B72"),_xlfn.XLOOKUP(P$5,INDIRECT("'"&P$3&"'!"&"$C2:$AZ2"),INDIRECT("'"&P$3&"'!"&"$C61:$AZ72")))} -> 59 | Q12: {=_xlfn.XLOOKUP(Q$6&" "&$B12,INDIRECT("'"&Q$3&"'!"&"$B75:$B86"),_xlfn.XLOOKUP(Q$5,INDIRECT("'"&Q$3&"'!"&"$C2:$AZ2"),INDIRECT("'"&Q$3&"'!"&"$C75:$AZ86")))} -> 118 | R12: {=_xlfn.XLOOKUP($B12,INDIRECT("'"&R$3&"'!"&"$B61:$B72"),_xlfn.XLOOKUP(R$5,INDIRECT("'"&R$3&"'!"&"$C2:$AZ2"),INDIRECT("'"&R$3&"'!"&"$C61:$AZ72")))} -> 64 | S12: {=_xlfn.XLOOKUP(S$6&" "&$B12,INDIRECT("'"&S$3&"'!"&"$B75:$B86"),_xlfn.XLOOKUP(S$5,INDIRECT("'"&S$3&"'!"&"$C2:$AZ2"),INDIRECT("'"&S$3&"'!"&"$C75:$AZ86")))} -> 187 | T12: =S12-Q12 -> 69 | V12: {=_xlfn.XLOOKUP($B12,INDIRECT("'"&V$3&"'!"&"$B3:$B14"),_xlfn.XLOOKUP(V$5,INDIRECT("'"&V$3&"'!"&"$C2:$AZ2"),INDIRECT("'"&V$3&"'!"&"$C3:$AZ14")))} -> 59 | W12: {=_xlfn.XLOOKUP(W$6&" "&$B12,INDIRECT("'"&W$3&"'!"&"$B16:$B27"),_xlfn.XLOOKUP(W$5,INDIRECT("'"&W$3&"'!"&"$C2:$AZ2"),INDIRECT("'"&W$3&"'!"&"$C16:$AZ27")))} -> 220 | X12: {=_xlfn.XLOOKUP($B12,INDIRECT("'"&X$3&"'!"&"$B3:$B14"),_xlfn.XLOOKUP(X$5,INDIRECT("'"&X$3&"'!"&"$C2:$AZ2"),INDIRECT("'"&X$3&"'!"&"$C3:$AZ14")))} -> 91 | Y12: {=_xlfn.XLOOKUP(Y$6&" "&$B12,INDIRECT("'"&Y$3&"'!"&"$B16:$B27"),_xlfn.XLOOKUP(Y$5,INDIRECT("'"&Y$3&"'!"&"$C2:$AZ2"),INDIRECT("'"&Y$3&"'!"&"$C16:$AZ27")))} -> 250 | Z12: =Y12-W12 -> 30
B13: Cyber Security Awareness - Surfing the Web | D13: {=_xlfn.XLOOKUP($B13,INDIRECT("'"&D$3&"'!"&"$B3:$B14"),_xlfn.XLOOKUP(D$5,INDIRECT("'"&D$3&"'!"&"$C2:$AZ2"),INDIRECT("'"&D$3&"'!"&"$C3:$AZ14")))} -> 0 | E13: {=_xlfn.XLOOKUP(E$6&" "&$B13,INDIRECT("'"&E$3&"'!"&"$B17:$B28"),_xlfn.XLOOKUP(E$5,INDIRECT("'"&E$3&"'!"&"$C2:$AZ2"),INDIRECT("'"&E$3&"'!"&"$C17:$AZ28")))} -> 108 | F13: {=_xlfn.XLOOKUP($B13,INDIRECT("'"&F$3&"'!"&"$B3:$B14"),_xlfn.XLOOKUP(F$5,INDIRECT("'"&F$3&"'!"&"$C2:$AZ2"),INDIRECT("'"&F$3&"'!"&"$C3:$AZ14")))} -> 26 | G13: {=_xlfn.XLOOKUP(G$6&" "&$B13,INDIRECT("'"&G$3&"'!"&"$B17:$B28"),_xlfn.XLOOKUP(G$5,INDIRECT("'"&G$3&"'!"&"$C2:$AZ2"),INDIRECT("'"&G$3&"'!"&"$C17:$AZ28")))} -> 62 | H13: =G13-E13 -> -46 | J13: {=_xlfn.XLOOKUP($B13,INDIRECT("'"&J$3&"'!"&"$B32:$B43"),_xlfn.XLOOKUP(J$5,INDIRECT("'"&J$3&"'!"&"$C2:$AZ2"),INDIRECT("'"&J$3&"'!"&"$C32:$AZ43")))} -> 1 | K13: {=_xlfn.XLOOKUP(K$6&" "&$B13,INDIRECT("'"&K$3&"'!"&"$B46:$B57"),_xlfn.XLOOKUP(K$5,INDIRECT("'"&K$3&"'!"&"$C2:$AZ2"),INDIRECT("'"&K$3&"'!"&"$C46:$AZ57")))} -> 1 | L13: {=_xlfn.XLOOKUP($B13,INDIRECT("'"&L$3&"'!"&"$B32:$B43"),_xlfn.XLOOKUP(L$5,INDIRECT("'"&L$3&"'!"&"$C2:$AZ2"),INDIRECT("'"&L$3&"'!"&"$C32:$AZ43")))} -> 0 | M13: {=_xlfn.XLOOKUP(M$6&" "&$B13,INDIRECT("'"&M$3&"'!"&"$B46:$B57"),_xlfn.XLOOKUP(M$5,INDIRECT("'"&M$3&"'!"&"$C2:$AZ2"),INDIRECT("'"&M$3&"'!"&"$C46:$AZ57")))} -> 3 | N13: =M13-K13 -> 2 | P13: {=_xlfn.XLOOKUP($B13,INDIRECT("'"&P$3&"'!"&"$B61:$B72"),_xlfn.XLOOKUP(P$5,INDIRECT("'"&P$3&"'!"&"$C2:$AZ2"),INDIRECT("'"&P$3&"'!"&"$C61:$AZ72")))} -> 58 | Q13: {=_xlfn.XLOOKUP(Q$6&" "&$B13,INDIRECT("'"&Q$3&"'!"&"$B75:$B86"),_xlfn.XLOOKUP(Q$5,INDIRECT("'"&Q$3&"'!"&"$C2:$AZ2"),INDIRECT("'"&Q$3&"'!"&"$C75:$AZ86")))} -> 115 | R13: {=_xlfn.XLOOKUP($B13,INDIRECT("'"&R$3&"'!"&"$B61:$B72"),_xlfn.XLOOKUP(R$5,INDIRECT("'"&R$3&"'!"&"$C2:$AZ2"),INDIRECT("'"&R$3&"'!"&"$C61:$AZ72")))} -> 59 | S13: {=_xlfn.XLOOKUP(S$6&" "&$B13,INDIRECT("'"&S$3&"'!"&"$B75:$B86"),_xlfn.XLOOKUP(S$5,INDIRECT("'"&S$3&"'!"&"$C2:$AZ2"),INDIRECT("'"&S$3&"'!"&"$C75:$AZ86")))} -> 180 | T13: =S13-Q13 -> 65 | V13: {=_xlfn.XLOOKUP($B13,INDIRECT("'"&V$3&"'!"&"$B3:$B14"),_xlfn.XLOOKUP(V$5,INDIRECT("'"&V$3&"'!"&"$C2:$AZ2"),INDIRECT("'"&V$3&"'!"&"$C3:$AZ14")))} -> 59 | W13: {=_xlfn.XLOOKUP(W$6&" "&$B13,INDIRECT("'"&W$3&"'!"&"$B16:$B27"),_xlfn.XLOOKUP(W$5,INDIRECT("'"&W$3&"'!"&"$C2:$AZ2"),INDIRECT("'"&W$3&"'!"&"$C16:$AZ27")))} -> 224 | X13: {=_xlfn.XLOOKUP($B13,INDIRECT("'"&X$3&"'!"&"$B3:$B14"),_xlfn.XLOOKUP(X$5,INDIRECT("'"&X$3&"'!"&"$C2:$AZ2"),INDIRECT("'"&X$3&"'!"&"$C3:$AZ14")))} -> 85 | Y13: {=_xlfn.XLOOKUP(Y$6&" "&$B13,INDIRECT("'"&Y$3&"'!"&"$B16:$B27"),_xlfn.XLOOKUP(Y$5,INDIRECT("'"&Y$3&"'!"&"$C2:$AZ2"),INDIRECT("'"&Y$3&"'!"&"$C16:$AZ27")))} -> 245 | Z13: =Y13-W13 -> 21
B14: Cyber Security Toolkit | D14: {=_xlfn.XLOOKUP($B14,INDIRECT("'"&D$3&"'!"&"$B3:$B14"),_xlfn.XLOOKUP(D$5,INDIRECT("'"&D$3&"'!"&"$C2:$AZ2"),INDIRECT("'"&D$3&"'!"&"$C3:$AZ14")))} -> 0 | E14: {=_xlfn.XLOOKUP(E$6&" "&$B14,INDIRECT("'"&E$3&"'!"&"$B17:$B28"),_xlfn.XLOOKUP(E$5,INDIRECT("'"&E$3&"'!"&"$C2:$AZ2"),INDIRECT("'"&E$3&"'!"&"$C17:$AZ28")))} -> 111 | F14: {=_xlfn.XLOOKUP($B14,INDIRECT("'"&F$3&"'!"&"$B3:$B14"),_xlfn.XLOOKUP(F$5,INDIRECT("'"&F$3&"'!"&"$C2:$AZ2"),INDIRECT("'"&F$3&"'!"&"$C3:$AZ14")))} -> 25 | G14: {=_xlfn.XLOOKUP(G$6&" "&$B14,INDIRECT("'"&G$3&"'!"&"$B17:$B28"),_xlfn.XLOOKUP(G$5,INDIRECT("'"&G$3&"'!"&"$C2:$AZ2"),INDIRECT("'"&G$3&"'!"&"$C17:$AZ28")))} -> 63 | H14: =G14-E14 -> -48 | J14: {=_xlfn.XLOOKUP($B14,INDIRECT("'"&J$3&"'!"&"$B32:$B43"),_xlfn.XLOOKUP(J$5,INDIRECT("'"&J$3&"'!"&"$C2:$AZ2"),INDIRECT("'"&J$3&"'!"&"$C32:$AZ43")))} -> 0 | K14: {=_xlfn.XLOOKUP(K$6&" "&$B14,INDIRECT("'"&K$3&"'!"&"$B46:$B57"),_xlfn.XLOOKUP(K$5,INDIRECT("'"&K$3&"'!"&"$C2:$AZ2"),INDIRECT("'"&K$3&"'!"&"$C46:$AZ57")))} -> 0 | L14: {=_xlfn.XLOOKUP($B14,INDIRECT("'"&L$3&"'!"&"$B32:$B43"),_xlfn.XLOOKUP(L$5,INDIRECT("'"&L$3&"'!"&"$C2:$AZ2"),INDIRECT("'"&L$3&"'!"&"$C32:$AZ43")))} -> 0 | M14: {=_xlfn.XLOOKUP(M$6&" "&$B14,INDIRECT("'"&M$3&"'!"&"$B46:$B57"),_xlfn.XLOOKUP(M$5,INDIRECT("'"&M$3&"'!"&"$C2:$AZ2"),INDIRECT("'"&M$3&"'!"&"$C46:$AZ57")))} -> 0 | N14: =M14-K14 -> 0 | P14: {=_xlfn.XLOOKUP($B14,INDIRECT("'"&P$3&"'!"&"$B61:$B72"),_xlfn.XLOOKUP(P$5,INDIRECT("'"&P$3&"'!"&"$C2:$AZ2"),INDIRECT("'"&P$3&"'!"&"$C61:$AZ72")))} -> 57 | Q14: {=_xlfn.XLOOKUP(Q$6&" "&$B14,INDIRECT("'"&Q$3&"'!"&"$B75:$B86"),_xlfn.XLOOKUP(Q$5,INDIRECT("'"&Q$3&"'!"&"$C2:$AZ2"),INDIRECT("'"&Q$3&"'!"&"$C75:$AZ86")))} -> 113 | R14: {=_xlfn.XLOOKUP($B14,INDIRECT("'"&R$3&"'!"&"$B61:$B72"),_xlfn.XLOOKUP(R$5,INDIRECT("'"&R$3&"'!"&"$C2:$AZ2"),INDIRECT("'"&R$3&"'!"&"$C61:$AZ72")))} -> 63 | S14: {=_xlfn.XLOOKUP(S$6&" "&$B14,INDIRECT("'"&S$3&"'!"&"$B75:$B86"),_xlfn.XLOOKUP(S$5,INDIRECT("'"&S$3&"'!"&"$C2:$AZ2"),INDIRECT("'"&S$3&"'!"&"$C75:$AZ86")))} -> 194 | T14: =S14-Q14 -> 81 | V14: {=_xlfn.XLOOKUP($B14,INDIRECT("'"&V$3&"'!"&"$B3:$B14"),_xlfn.XLOOKUP(V$5,INDIRECT("'"&V$3&"'!"&"$C2:$AZ2"),INDIRECT("'"&V$3&"'!"&"$C3:$AZ14")))} -> 57 | W14: {=_xlfn.XLOOKUP(W$6&" "&$B14,INDIRECT("'"&W$3&"'!"&"$B16:$B27"),_xlfn.XLOOKUP(W$5,INDIRECT("'"&W$3&"'!"&"$C2:$AZ2"),INDIRECT("'"&W$3&"'!"&"$C16:$AZ27")))} -> 224 | X14: {=_xlfn.XLOOKUP($B14,INDIRECT("'"&X$3&"'!"&"$B3:$B14"),_xlfn.XLOOKUP(X$5,INDIRECT("'"&X$3&"'!"&"$C2:$AZ2"),INDIRECT("'"&X$3&"'!"&"$C3:$AZ14")))} -> 88 | Y14: {=_xlfn.XLOOKUP(Y$6&" "&$B14,INDIRECT("'"&Y$3&"'!"&"$B16:$B27"),_xlfn.XLOOKUP(Y$5,INDIRECT("'"&Y$3&"'!"&"$C2:$AZ2"),INDIRECT("'"&Y$3&"'!"&"$C16:$AZ27")))} -> 257 | Z14: =Y14-W14 -> 33
B15: Flexible Working Guidelines | D15: {=_xlfn.XLOOKUP($B15,INDIRECT("'"&D$3&"'!"&"$B3:$B14"),_xlfn.XLOOKUP(D$5,INDIRECT("'"&D$3&"'!"&"$C2:$AZ2"),INDIRECT("'"&D$3&"'!"&"$C3:$AZ14")))} -> 0 | E15: {=_xlfn.XLOOKUP(E$6&" "&$B15,INDIRECT("'"&E$3&"'!"&"$B17:$B28"),_xlfn.XLOOKUP(E$5,INDIRECT("'"&E$3&"'!"&"$C2:$AZ2"),INDIRECT("'"&E$3&"'!"&"$C17:$AZ28")))} -> 0 | F15: {=_xlfn.XLOOKUP($B15,INDIRECT("'"&F$3&"'!"&"$B3:$B14"),_xlfn.XLOOKUP(F$5,INDIRECT("'"&F$3&"'!"&"$C2:$AZ2"),INDIRECT("'"&F$3&"'!"&"$C3:$AZ14")))} -> 1 | G15: {=_xlfn.XLOOKUP(G$6&" "&$B15,INDIRECT("'"&G$3&"'!"&"$B17:$B28"),_xlfn.XLOOKUP(G$5,INDIRECT("'"&G$3&"'!"&"$C2:$AZ2"),INDIRECT("'"&G$3&"'!"&"$C17:$AZ28")))} -> 4 | H15: =G15-E15 -> 4 | J15: {=_xlfn.XLOOKUP($B15,INDIRECT("'"&J$3&"'!"&"$B32:$B43"),_xlfn.XLOOKUP(J$5,INDIRECT("'"&J$3&"'!"&"$C2:$AZ2"),INDIRECT("'"&J$3&"'!"&"$C32:$AZ43")))} -> 0 | K15: {=_xlfn.XLOOKUP(K$6&" "&$B15,INDIRECT("'"&K$3&"'!"&"$B46:$B57"),_xlfn.XLOOKUP(K$5,INDIRECT("'"&K$3&"'!"&"$C2:$AZ2"),INDIRECT("'"&K$3&"'!"&"$C46:$AZ57")))} -> 0 | L15: {=_xlfn.XLOOKUP($B15,INDIRECT("'"&L$3&"'!"&"$B32:$B43"),_xlfn.XLOOKUP(L$5,INDIRECT("'"&L$3&"'!"&"$C2:$AZ2"),INDIRECT("'"&L$3&"'!"&"$C32:$AZ43")))} -> 0 | M15: {=_xlfn.XLOOKUP(M$6&" "&$B15,INDIRECT("'"&M$3&"'!"&"$B46:$B57"),_xlfn.XLOOKUP(M$5,INDIRECT("'"&M$3&"'!"&"$C2:$AZ2"),INDIRECT("'"&M$3&"'!"&"$C46:$AZ57")))} -> 2 | N15: =M15-K15 -> 2 | P15: {=_xlfn.XLOOKUP($B15,INDIRECT("'"&P$3&"'!"&"$B61:$B72"),_xlfn.XLOOKUP(P$5,INDIRECT("'"&P$3&"'!"&"$C2:$AZ2"),INDIRECT("'"&P$3&"'!"&"$C61:$AZ72")))} -> 9 | Q15: {=_xlfn.XLOOKUP(Q$6&" "&$B15,INDIRECT("'"&Q$3&"'!"&"$B75:$B86"),_xlfn.XLOOKUP(Q$5,INDIRECT("'"&Q$3&"'!"&"$C2:$AZ2"),INDIRECT("'"&Q$3&"'!"&"$C75:$AZ86")))} -> 47 | R15: {=_xlfn.XLOOKUP($B15,INDIRECT("'"&R$3&"'!"&"$B61:$B72"),_xlfn.XLOOKUP(R$5,INDIRECT("'"&R$3&"'!"&"$C2:$AZ2"),INDIRECT("'"&R$3&"'!"&"$C61:$AZ72")))} -> 10 | S15: {=_xlfn.XLOOKUP(S$6&" "&$B15,INDIRECT("'"&S$3&"'!"&"$B75:$B86"),_xlfn.XLOOKUP(S$5,INDIRECT("'"&S$3&"'!"&"$C2:$AZ2"),INDIRECT("'"&S$3&"'!"&"$C75:$AZ86")))} -> 83 | T15: =S15-Q15 -> 36 | V15: {=_xlfn.XLOOKUP($B15,INDIRECT("'"&V$3&"'!"&"$B3:$B14"),_xlfn.XLOOKUP(V$5,INDIRECT("'"&V$3&"'!"&"$C2:$AZ2"),INDIRECT("'"&V$3&"'!"&"$C3:$AZ14")))} -> 9 | W15: {=_xlfn.XLOOKUP(W$6&" "&$B15,INDIRECT("'"&W$3&"'!"&"$B16:$B27"),_xlfn.XLOOKUP(W$5,INDIRECT("'"&W$3&"'!"&"$C2:$AZ2"),INDIRECT("'"&W$3&"'!"&"$C16:$AZ27")))} -> 47 | X15: {=_xlfn.XLOOKUP($B15,INDIRECT("'"&X$3&"'!"&"$B3:$B14"),_xlfn.XLOOKUP(X$5,INDIRECT("'"&X$3&"'!"&"$C2:$AZ2"),INDIRECT("'"&X$3&"'!"&"$C3:$AZ14")))} -> 11 | Y15: {=_xlfn.XLOOKUP(Y$6&" "&$B15,INDIRECT("'"&Y$3&"'!"&"$B16:$B27"),_xlfn.XLOOKUP(Y$5,INDIRECT("'"&Y$3&"'!"&"$C2:$AZ2"),INDIRECT("'"&Y$3&"'!"&"$C16:$AZ27")))} -> 89 | Z15: =Y15-W15 -> 42
B16: Getting to know SGH | D16: {=_xlfn.XLOOKUP($B16,INDIRECT("'"&D$3&"'!"&"$B3:$B14"),_xlfn.XLOOKUP(D$5,INDIRECT("'"&D$3&"'!"&"$C2:$AZ2"),INDIRECT("'"&D$3&"'!"&"$C3:$AZ14")))} -> 0 | E16: {=_xlfn.XLOOKUP(E$6&" "&$B16,INDIRECT("'"&E$3&"'!"&"$B17:$B28"),_xlfn.XLOOKUP(E$5,INDIRECT("'"&E$3&"'!"&"$C2:$AZ2"),INDIRECT("'"&E$3&"'!"&"$C17:$AZ28")))} -> 0 | F16: {=_xlfn.XLOOKUP($B16,INDIRECT("'"&F$3&"'!"&"$B3:$B14"),_xlfn.XLOOKUP(F$5,INDIRECT("'"&F$3&"'!"&"$C2:$AZ2"),INDIRECT("'"&F$3&"'!"&"$C3:$AZ14")))} -> 1 | G16: {=_xlfn.XLOOKUP(G$6&" "&$B16,INDIRECT("'"&G$3&"'!"&"$B17:$B28"),_xlfn.XLOOKUP(G$5,INDIRECT("'"&G$3&"'!"&"$C2:$AZ2"),INDIRECT("'"&G$3&"'!"&"$C17:$AZ28")))} -> 6 | H16: =G16-E16 -> 6 | J16: {=_xlfn.XLOOKUP($B16,INDIRECT("'"&J$3&"'!"&"$B32:$B43"),_xlfn.XLOOKUP(J$5,INDIRECT("'"&J$3&"'!"&"$C2:$AZ2"),INDIRECT("'"&J$3&"'!"&"$C32:$AZ43")))} -> 0 | K16: {=_xlfn.XLOOKUP(K$6&" "&$B16,INDIRECT("'"&K$3&"'!"&"$B46:$B57"),_xlfn.XLOOKUP(K$5,INDIRECT("'"&K$3&"'!"&"$C2:$AZ2"),INDIRECT("'"&K$3&"'!"&"$C46:$AZ57")))} -> 0 | L16: {=_xlfn.XLOOKUP($B16,INDIRECT("'"&L$3&"'!"&"$B32:$B43"),_xlfn.XLOOKUP(L$5,INDIRECT("'"&L$3&"'!"&"$C2:$AZ2"),INDIRECT("'"&L$3&"'!"&"$C32:$AZ43")))} -> 0 | M16: {=_xlfn.XLOOKUP(M$6&" "&$B16,INDIRECT("'"&M$3&"'!"&"$B46:$B57"),_xlfn.XLOOKUP(M$5,INDIRECT("'"&M$3&"'!"&"$C2:$AZ2"),INDIRECT("'"&M$3&"'!"&"$C46:$AZ57")))} -> 0 | N16: =M16-K16 -> 0 | P16: {=_xlfn.XLOOKUP($B16,INDIRECT("'"&P$3&"'!"&"$B61:$B72"),_xlfn.XLOOKUP(P$5,INDIRECT("'"&P$3&"'!"&"$C2:$AZ2"),INDIRECT("'"&P$3&"'!"&"$C61:$AZ72")))} -> 11 | Q16: {=_xlfn.XLOOKUP(Q$6&" "&$B16,INDIRECT("'"&Q$3&"'!"&"$B75:$B86"),_xlfn.XLOOKUP(Q$5,INDIRECT("'"&Q$3&"'!"&"$C2:$AZ2"),INDIRECT("'"&Q$3&"'!"&"$C75:$AZ86")))} -> 67 | R16: {=_xlfn.XLOOKUP($B16,INDIRECT("'"&R$3&"'!"&"$B61:$B72"),_xlfn.XLOOKUP(R$5,INDIRECT("'"&R$3&"'!"&"$C2:$AZ2"),INDIRECT("'"&R$3&"'!"&"$C61:$AZ72")))} -> 14 | S16: {=_xlfn.XLOOKUP(S$6&" "&$B16,INDIRECT("'"&S$3&"'!"&"$B75:$B86"),_xlfn.XLOOKUP(S$5,INDIRECT("'"&S$3&"'!"&"$C2:$AZ2"),INDIRECT("'"&S$3&"'!"&"$C75:$AZ86")))} -> 99 | T16: =S16-Q16 -> 32 | V16: {=_xlfn.XLOOKUP($B16,INDIRECT("'"&V$3&"'!"&"$B3:$B14"),_xlfn.XLOOKUP(V$5,INDIRECT("'"&V$3&"'!"&"$C2:$AZ2"),INDIRECT("'"&V$3&"'!"&"$C3:$AZ14")))} -> 11 | W16: {=_xlfn.XLOOKUP(W$6&" "&$B16,INDIRECT("'"&W$3&"'!"&"$B16:$B27"),_xlfn.XLOOKUP(W$5,INDIRECT("'"&W$3&"'!"&"$C2:$AZ2"),INDIRECT("'"&W$3&"'!"&"$C16:$AZ27")))} -> 67 | X16: {=_xlfn.XLOOKUP($B16,INDIRECT("'"&X$3&"'!"&"$B3:$B14"),_xlfn.XLOOKUP(X$5,INDIRECT("'"&X$3&"'!"&"$C2:$AZ2"),INDIRECT("'"&X$3&"'!"&"$C3:$AZ14")))} -> 15 | Y16: {=_xlfn.XLOOKUP(Y$6&" "&$B16,INDIRECT("'"&Y$3&"'!"&"$B16:$B27"),_xlfn.XLOOKUP(Y$5,INDIRECT("'"&Y$3&"'!"&"$C2:$AZ2"),INDIRECT("'"&Y$3&"'!"&"$C16:$AZ27")))} -> 105 | Z16: =Y16-W16 -> 38
B17: Health and Safety Begins with You | D17: {=_xlfn.XLOOKUP($B17,INDIRECT("'"&D$3&"'!"&"$B3:$B14"),_xlfn.XLOOKUP(D$5,INDIRECT("'"&D$3&"'!"&"$C2:$AZ2"),INDIRECT("'"&D$3&"'!"&"$C3:$AZ14")))} -> 0 | E17: {=_xlfn.XLOOKUP(E$6&" "&$B17,INDIRECT("'"&E$3&"'!"&"$B17:$B28"),_xlfn.XLOOKUP(E$5,INDIRECT("'"&E$3&"'!"&"$C2:$AZ2"),INDIRECT("'"&E$3&"'!"&"$C17:$AZ28")))} -> 0 | F17: {=_xlfn.XLOOKUP($B17,INDIRECT("'"&F$3&"'!"&"$B3:$B14"),_xlfn.XLOOKUP(F$5,INDIRECT("'"&F$3&"'!"&"$C2:$AZ2"),INDIRECT("'"&F$3&"'!"&"$C3:$AZ14")))} -> 1 | G17: {=_xlfn.XLOOKUP(G$6&" "&$B17,INDIRECT("'"&G$3&"'!"&"$B17:$B28"),_xlfn.XLOOKUP(G$5,INDIRECT("'"&G$3&"'!"&"$C2:$AZ2"),INDIRECT("'"&G$3&"'!"&"$C17:$AZ28")))} -> 5 | H17: =G17-E17 -> 5 | J17: {=_xlfn.XLOOKUP($B17,INDIRECT("'"&J$3&"'!"&"$B32:$B43"),_xlfn.XLOOKUP(J$5,INDIRECT("'"&J$3&"'!"&"$C2:$AZ2"),INDIRECT("'"&J$3&"'!"&"$C32:$AZ43")))} -> 0 | K17: {=_xlfn.XLOOKUP(K$6&" "&$B17,INDIRECT("'"&K$3&"'!"&"$B46:$B57"),_xlfn.XLOOKUP(K$5,INDIRECT("'"&K$3&"'!"&"$C2:$AZ2"),INDIRECT("'"&K$3&"'!"&"$C46:$AZ57")))} -> 0 | L17: {=_xlfn.XLOOKUP($B17,INDIRECT("'"&L$3&"'!"&"$B32:$B43"),_xlfn.XLOOKUP(L$5,INDIRECT("'"&L$3&"'!"&"$C2:$AZ2"),INDIRECT("'"&L$3&"'!"&"$C32:$AZ43")))} -> 1 | M17: {=_xlfn.XLOOKUP(M$6&" "&$B17,INDIRECT("'"&M$3&"'!"&"$B46:$B57"),_xlfn.XLOOKUP(M$5,INDIRECT("'"&M$3&"'!"&"$C2:$AZ2"),INDIRECT("'"&M$3&"'!"&"$C46:$AZ57")))} -> 4 | N17: =M17-K17 -> 4 | P17: {=_xlfn.XLOOKUP($B17,INDIRECT("'"&P$3&"'!"&"$B61:$B72"),_xlfn.XLOOKUP(P$5,INDIRECT("'"&P$3&"'!"&"$C2:$AZ2"),INDIRECT("'"&P$3&"'!"&"$C61:$AZ72")))} -> 10 | Q17: {=_xlfn.XLOOKUP(Q$6&" "&$B17,INDIRECT("'"&Q$3&"'!"&"$B75:$B86"),_xlfn.XLOOKUP(Q$5,INDIRECT("'"&Q$3&"'!"&"$C2:$AZ2"),INDIRECT("'"&Q$3&"'!"&"$C75:$AZ86")))} -> 89 | R17: {=_xlfn.XLOOKUP($B17,INDIRECT("'"&R$3&"'!"&"$B61:$B72"),_xlfn.XLOOKUP(R$5,INDIRECT("'"&R$3&"'!"&"$C2:$AZ2"),INDIRECT("'"&R$3&"'!"&"$C61:$AZ72")))} -> 16 | S17: {=_xlfn.XLOOKUP(S$6&" "&$B17,INDIRECT("'"&S$3&"'!"&"$B75:$B86"),_xlfn.XLOOKUP(S$5,INDIRECT("'"&S$3&"'!"&"$C2:$AZ2"),INDIRECT("'"&S$3&"'!"&"$C75:$AZ86")))} -> 101 | T17: =S17-Q17 -> 12 | V17: {=_xlfn.XLOOKUP($B17,INDIRECT("'"&V$3&"'!"&"$B3:$B14"),_xlfn.XLOOKUP(V$5,INDIRECT("'"&V$3&"'!"&"$C2:$AZ2"),INDIRECT("'"&V$3&"'!"&"$C3:$AZ14")))} -> 10 | W17: {=_xlfn.XLOOKUP(W$6&" "&$B17,INDIRECT("'"&W$3&"'!"&"$B16:$B27"),_xlfn.XLOOKUP(W$5,INDIRECT("'"&W$3&"'!"&"$C2:$AZ2"),INDIRECT("'"&W$3&"'!"&"$C16:$AZ27")))} -> 89 | X17: {=_xlfn.XLOOKUP($B17,INDIRECT("'"&X$3&"'!"&"$B3:$B14"),_xlfn.XLOOKUP(X$5,INDIRECT("'"&X$3&"'!"&"$C2:$AZ2"),INDIRECT("'"&X$3&"'!"&"$C3:$AZ14")))} -> 18 | Y17: {=_xlfn.XLOOKUP(Y$6&" "&$B17,INDIRECT("'"&Y$3&"'!"&"$B16:$B27"),_xlfn.XLOOKUP(Y$5,INDIRECT("'"&Y$3&"'!"&"$C2:$AZ2"),INDIRECT("'"&Y$3&"'!"&"$C16:$AZ27")))} -> 110 | Z17: =Y17-W17 -> 21
B18: Technology Usage - PCI Compliance | D18: {=_xlfn.XLOOKUP($B18,INDIRECT("'"&D$3&"'!"&"$B3:$B14"),_xlfn.XLOOKUP(D$5,INDIRECT("'"&D$3&"'!"&"$C2:$AZ2"),INDIRECT("'"&D$3&"'!"&"$C3:$AZ14")))} -> 0 | E18: {=_xlfn.XLOOKUP(E$6&" "&$B18,INDIRECT("'"&E$3&"'!"&"$B17:$B28"),_xlfn.XLOOKUP(E$5,INDIRECT("'"&E$3&"'!"&"$C2:$AZ2"),INDIRECT("'"&E$3&"'!"&"$C17:$AZ28")))} -> 0 | F18: {=_xlfn.XLOOKUP($B18,INDIRECT("'"&F$3&"'!"&"$B3:$B14"),_xlfn.XLOOKUP(F$5,INDIRECT("'"&F$3&"'!"&"$C2:$AZ2"),INDIRECT("'"&F$3&"'!"&"$C3:$AZ14")))} -> 7 | G18: {=_xlfn.XLOOKUP(G$6&" "&$B18,INDIRECT("'"&G$3&"'!"&"$B17:$B28"),_xlfn.XLOOKUP(G$5,INDIRECT("'"&G$3&"'!"&"$C2:$AZ2"),INDIRECT("'"&G$3&"'!"&"$C17:$AZ28")))} -> 12 | H18: =G18-E18 -> 12 | J18: {=_xlfn.XLOOKUP($B18,INDIRECT("'"&J$3&"'!"&"$B32:$B43"),_xlfn.XLOOKUP(J$5,INDIRECT("'"&J$3&"'!"&"$C2:$AZ2"),INDIRECT("'"&J$3&"'!"&"$C32:$AZ43")))} -> 0 | K18: {=_xlfn.XLOOKUP(K$6&" "&$B18,INDIRECT("'"&K$3&"'!"&"$B46:$B57"),_xlfn.XLOOKUP(K$5,INDIRECT("'"&K$3&"'!"&"$C2:$AZ2"),INDIRECT("'"&K$3&"'!"&"$C46:$AZ57")))} -> 0 | L18: {=_xlfn.XLOOKUP($B18,INDIRECT("'"&L$3&"'!"&"$B32:$B43"),_xlfn.XLOOKUP(L$5,INDIRECT("'"&L$3&"'!"&"$C2:$AZ2"),INDIRECT("'"&L$3&"'!"&"$C32:$AZ43")))} -> 0 | M18: {=_xlfn.XLOOKUP(M$6&" "&$B18,INDIRECT("'"&M$3&"'!"&"$B46:$B57"),_xlfn.XLOOKUP(M$5,INDIRECT("'"&M$3&"'!"&"$C2:$AZ2"),INDIRECT("'"&M$3&"'!"&"$C46:$AZ57")))} -> 0 | N18: =M18-K18 -> 0 | P18: {=_xlfn.XLOOKUP($B18,INDIRECT("'"&P$3&"'!"&"$B61:$B72"),_xlfn.XLOOKUP(P$5,INDIRECT("'"&P$3&"'!"&"$C2:$AZ2"),INDIRECT("'"&P$3&"'!"&"$C61:$AZ72")))} -> 10 | Q18: {=_xlfn.XLOOKUP(Q$6&" "&$B18,INDIRECT("'"&Q$3&"'!"&"$B75:$B86"),_xlfn.XLOOKUP(Q$5,INDIRECT("'"&Q$3&"'!"&"$C2:$AZ2"),INDIRECT("'"&Q$3&"'!"&"$C75:$AZ86")))} -> 55 | R18: {=_xlfn.XLOOKUP($B18,INDIRECT("'"&R$3&"'!"&"$B61:$B72"),_xlfn.XLOOKUP(R$5,INDIRECT("'"&R$3&"'!"&"$C2:$AZ2"),INDIRECT("'"&R$3&"'!"&"$C61:$AZ72")))} -> 14 | S18: {=_xlfn.XLOOKUP(S$6&" "&$B18,INDIRECT("'"&S$3&"'!"&"$B75:$B86"),_xlfn.XLOOKUP(S$5,INDIRECT("'"&S$3&"'!"&"$C2:$AZ2"),INDIRECT("'"&S$3&"'!"&"$C75:$AZ86")))} -> 88 | T18: =S18-Q18 -> 33 | V18: {=_xlfn.XLOOKUP($B18,INDIRECT("'"&V$3&"'!"&"$B3:$B14"),_xlfn.XLOOKUP(V$5,INDIRECT("'"&V$3&"'!"&"$C2:$AZ2"),INDIRECT("'"&V$3&"'!"&"$C3:$AZ14")))} -> 10 | W18: {=_xlfn.XLOOKUP(W$6&" "&$B18,INDIRECT("'"&W$3&"'!"&"$B16:$B27"),_xlfn.XLOOKUP(W$5,INDIRECT("'"&W$3&"'!"&"$C2:$AZ2"),INDIRECT("'"&W$3&"'!"&"$C16:$AZ27")))} -> 55 | X18: {=_xlfn.XLOOKUP($B18,INDIRECT("'"&X$3&"'!"&"$B3:$B14"),_xlfn.XLOOKUP(X$5,INDIRECT("'"&X$3&"'!"&"$C2:$AZ2"),INDIRECT("'"&X$3&"'!"&"$C3:$AZ14")))} -> 21 | Y18: {=_xlfn.XLOOKUP(Y$6&" "&$B18,INDIRECT("'"&Y$3&"'!"&"$B16:$B27"),_xlfn.XLOOKUP(Y$5,INDIRECT("'"&Y$3&"'!"&"$C2:$AZ2"),INDIRECT("'"&Y$3&"'!"&"$C16:$AZ27")))} -> 100 | Z18: =Y18-W18 -> 45
B19: *Var denotes the Variance in YTD Columns

Sheet Pivot_StatusByModule
A1: Fiscal Month | B1: (Multiple Items)
A3: Count of Learning Activity Title | B3: Column Labels
A4: Row Labels | B4: Booked | C4: Complete | D4: In progress | E4: Grand Total
A5: Bullying, Harassment and Discrimination - Module 1 | B5: 5 | C5: 92 | E5: 97
A6: Bullying, Harassment and Discrimination - Module 2 | B6: 5 | C6: 91 | E6: 96
A7: Bullying, Harassment and Discrimination for Team Leaders/Line Managers | C7: 6 | E7: 6
A8: Flexible Working Guidelines | B8: 4 | C8: 83 | D8: 2 | E8: 89
A9: Getting to know SGH | B9: 6 | C9: 99 | E9: 105
A10: Health and Safety Begins with You | B10: 5 | C10: 101 | D10: 4 | E10: 110
A11: Technology Usage - PCI Compliance | B11: 12 | C11: 88 | E11: 100
A12: Cyber Security Awareness - Business Email Compromise Scams | B12: 61 | C12: 188 | D12: 5 | E12: 254
A13: Cyber Security Awareness - Introduction | B13: 57 | C13: 196 | D13: 3 | E13: 256
A14: Cyber Security Awareness - Malicious Links | B14: 60 | C14: 187 | D14: 3 | E14: 250
A15: Cyber Security Awareness - Surfing the Web | B15: 62 | C15: 180 | D15: 3 | E15: 245
A16: Cyber Security Toolkit | B16: 63 | C16: 194 | E16: 257
A17: Grand Total | B17: 340 | C17: 1505 | D17: 20 | E17: 1865
B22: Complete | C22: Booked | D22: In progress
A23: Bullying, Harassment and Discrimination - Module 1 | B23: =GETPIVOTDATA("Learning Activity Title",$A$3,"Learning Activity Title","Bullying, Harassment and Discrimination - Module 1","Activity status","Complete") -> 92 | C23: =GETPIVOTDATA("Learning Activity Title",$A$3,"Learning Activity Title","Bullying, Harassment and Discrimination - Module 1","Activity status","Booked") -> 5 | D23: =GETPIVOTDATA("Learning Activity Title",$A$3,"Learning Activity Title","Bullying, Harassment and Discrimination - Module 1","Activity status","In progress") -> 0
B25: Complete | C25: Booked | D25: In progress
A26: Bullying, Harassment and Discrimination - Module 2 | B26: =GETPIVOTDATA("Learning Activity Title",$A$3,"Learning Activity Title","Bullying, Harassment and Discrimination - Module 2","Activity status","Complete") -> 91 | C26: =GETPIVOTDATA("Learning Activity Title",$A$3,"Learning Activity Title","Bullying, Harassment and Discrimination - Module 2","Activity status","Booked") -> 5 | D26: =GETPIVOTDATA("Learning Activity Title",$A$3,"Learning Activity Title","Bullying, Harassment and Discrimination - Module 2","Activity status","In progress") -> 0
B28: Complete | C28: Booked | D28: In progress
A29: Bullying, Harassment and Discrimination for Team Leaders/Line Managers | B29: =GETPIVOTDATA("Learning Activity Title",$A$3,"Learning Activity Title","Bullying, Harassment and Discrimination for Team Leaders/Line Managers","Activity status","Complete") -> 6 | C29: =GETPIVOTDATA("Learning Activity Title",$A$3,"Learning Activity Title","Bullying, Harassment and Discrimination for Team Leaders/Line Managers","Activity status","Booked") -> 0 | D29: =GETPIVOTDATA("Learning Activity Title",$A$3,"Learning Activity Title","Bullying, Harassment and Discrimination for Team Leaders/Line Managers","Activity status","In progress") -> 0
B31: Complete | C31: Booked | D31: In progress
A32: Flexible Working Guidelines | B32: =GETPIVOTDATA("Learning Activity Title",$A$3,"Learning Activity Title","Flexible Working Guidelines","Activity status","Complete") -> 83 | C32: =GETPIVOTDATA("Learning Activity Title",$A$3,"Learning Activity Title","Flexible Working Guidelines","Activity status","Booked") -> 4 | D32: =GETPIVOTDATA("Learning Activity Title",$A$3,"Learning Activity Title","Flexible Working Guidelines","Activity status","In progress") -> 2
B34: Complete | C34: Booked | D34: In progress
A35: Getting to know SGH | B35: =GETPIVOTDATA("Learning Activity Title",$A$3,"Learning Activity Title","Getting to know SGH","Activity status","Complete") -> 99 | C35: =GETPIVOTDATA("Learning Activity Title",$A$3,"Learning Activity Title","Getting to know SGH","Activity status","Booked") -> 6 | D35: =GETPIVOTDATA("Learning Activity Title",$A$3,"Learning Activity Title","Getting to know SGH","Activity status","In progress") -> 0
B37: Complete | C37: Booked | D37: In progress
A38: Health and Safety Begins with You | B38: =GETPIVOTDATA("Learning Activity Title",$A$3,"Learning Activity Title","Health and Safety Begins with You","Activity status","Complete") -> 101 | C38: =GETPIVOTDATA("Learning Activity Title",$A$3,"Learning Activity Title","Health and Safety Begins with You","Activity status","Booked") -> 5 | D38: =GETPIVOTDATA("Learning Activity Title",$A$3,"Learning Activity Title","Health and Safety Begins with You","Activity status","In progress") -> 4
B40: Complete | C40: Booked | D40: In progress
A41: Technology Usage - PCI Compliance | B41: =GETPIVOTDATA("Learning Activity Title",$A$3,"Learning Activity Title","Technology Usage - PCI Compliance","Activity status","Complete") -> 88 | C41: =GETPIVOTDATA("Learning Activity Title",$A$3,"Learning Activity Title","Technology Usage - PCI Compliance","Activity status","Booked") -> 12 | D41: =GETPIVOTDATA("Learning Activity Title",$A$3,"Learning Activity Title","Technology Usage - PCI Compliance","Activity status","In progress") -> 0
B43: Complete | C43: Booked | D43: In progress
A44: Cyber Security Awareness - Business Email Compromise Scams | B44: =GETPIVOTDATA("Learning Activity Title",$A$3,"Learning Activity Title","Cyber Security Awareness - Business Email Compromise Scams","Activity status","Complete") -> 188 | C44: =GETPIVOTDATA("Learning Activity Title",$A$3,"Learning Activity Title","Cyber Security Awareness - Business Email Compromise Scams","Activity status","Booked") -> 61 | D44: =GETPIVOTDATA("Learning Activity Title",$A$3,"Learning Activity Title","Cyber Security Awareness - Business Email Compromise Scams","Activity status","In progress") -> 5
B46: Complete | C46: Booked | D46: In progress
A47: Cyber Security Awareness - Introduction | B47: =GETPIVOTDATA("Learning Activity Title",$A$3,"Learning Activity Title","Cyber Security Awareness - Introduction","Activity status","Complete") -> 196 | C47: =GETPIVOTDATA("Learning Activity Title",$A$3,"Learning Activity Title","Cyber Security Awareness - Introduction","Activity status","Booked") -> 57 | D47: =GETPIVOTDATA("Learning Activity Title",$A$3,"Learning Activity Title","Cyber Security Awareness - Introduction","Activity status","In progress") -> 3
B49: Complete | C49: Booked | D49: In progress
A50: Cyber Security Awareness - Malicious Links | B50: =GETPIVOTDATA("Learning Activity Title",$A$3,"Learning Activity Title","Cyber Security Awareness - Malicious Links","Activity status","Complete") -> 187 | C50: =GETPIVOTDATA("Learning Activity Title",$A$3,"Learning Activity Title","Cyber Security Awareness - Malicious Links","Activity status","Booked") -> 60 | D50: =GETPIVOTDATA("Learning Activity Title",$A$3,"Learning Activity Title","Cyber Security Awareness - Malicious Links","Activity status","In progress") -> 3
B52: Complete | C52: Booked | D52: In progress
A53: Cyber Security Awareness - Surfing the Web | B53: =GETPIVOTDATA("Learning Activity Title",$A$3,"Learning Activity Title","Cyber Security Awareness - Surfing the Web","Activity status","Complete") -> 180 | C53: =GETPIVOTDATA("Learning Activity Title",$A$3,"Learning Activity Title","Cyber Security Awareness - Surfing the Web","Activity status","Booked") -> 62 | D53: =GETPIVOTDATA("Learning Activity Title",$A$3,"Learning Activity Title","Cyber Security Awareness - Surfing the Web","Activity status","In progress") -> 3
B55: Complete | C55: Booked | D55: In progress
A56: Cyber Security Toolkit | B56: =GETPIVOTDATA("Learning Activity Title",$A$3,"Learning Activity Title","Cyber Security Toolkit","Activity status","Complete") -> 194 | C56: =GETPIVOTDATA("Learning Activity Title",$A$3,"Learning Activity Title","Cyber Security Toolkit","Activity status","Booked") -> 63 | D56: =GETPIVOTDATA("Learning Activity Title",$A$3,"Learning Activity Title","Cyber Security Toolkit","Activity status","In progress") -> 0

Sheet PieCharts_Modules

Sheet Pivot_StatusByBrand
A1: Fiscal Month | B1: (Multiple Items)
A3: Count of Learning Activity Title | B3: Column Labels
A4: Row Labels | B4: Booked | C4: Complete | D4: In progress | E4: Grand Total
A5: ANALYTICS & INSIGHTS | B5: 22 | C5: 16 | E5: 38
A6: eCommerce Management | B6: 34 | C6: 165 | D6: 1 | E6: 200
A7: Finance | C7: 5 | E7: 5
A8: HR MANAGEMENT | B8: 38 | C8: 160 | D8: 5 | E8: 203
A9: IT | B9: 115 | C9: 272 | D9: 2 | E9: 389
A10: Marketing | B10: 48 | C10: 298 | D10: 5 | E10: 351
A11: Property | B11: 16 | C11: 133 | D11: 1 | E11: 150
A12: SG AVIATION TM | C12: 12 | E12: 12
A13: SPG DEV | C13: 22 | E13: 22
A14: SS Finance | B14: 39 | C14: 215 | D14: 2 | E14: 256
A15: Supply Chain | B15: 21 | C15: 109 | E15: 130
A16: Grand Total | B16: 333 | C16: 1407 | D16: 16 | E16: 1756
B22: Complete | C22: Booked | D22: In progress
A23: ANALYTICS & INSIGHTS | B23: =GETPIVOTDATA("Learning Activity Title",$A$3,"Brand/Function","ANALYTICS & INSIGHTS","Activity status","Complete") -> 16 | C23: =GETPIVOTDATA("Learning Activity Title",$A$3,"Brand/Function","ANALYTICS & INSIGHTS","Activity status","Booked") -> 22 | D23: =GETPIVOTDATA("Learning Activity Title",$A$3,"Brand/Function","ANALYTICS & INSIGHTS","Activity status","In progress") -> 0
B25: Complete | C25: Booked | D25: In progress
A26: eCommerce Management | B26: =GETPIVOTDATA("Learning Activity Title",$A$3,"Brand/Function","eCommerce Management","Activity status","Complete") -> 165 | C26: =GETPIVOTDATA("Learning Activity Title",$A$3,"Brand/Function","eCommerce Management","Activity status","Booked") -> 34 | D26: =GETPIVOTDATA("Learning Activity Title",$A$3,"Brand/Function","eCommerce Management","Activity status","In progress") -> 1
B28: Complete | C28: Booked | D28: In progress
A29: Finance | B29: =GETPIVOTDATA("Learning Activity Title",$A$3,"Brand/Function","Finance","Activity status","Complete") -> 5 | C29: =GETPIVOTDATA("Learning Activity Title",$A$3,"Brand/Function","Finance","Activity status","Booked") -> 0 | D29: =GETPIVOTDATA("Learning Activity Title",$A$3,"Brand/Function","Finance","Activity status","In progress") -> 0
B31: Complete | C31: Booked | D31: In progress
A32: HR MANAGEMENT | B32: =GETPIVOTDATA("Learning Activity Title",$A$3,"Brand/Function","HR MANAGEMENT","Activity status","Complete") -> 160 | C32: =GETPIVOTDATA("Learning Activity Title",$A$3,"Brand/Function","HR MANAGEMENT","Activity status","Booked") -> 38 | D32: =GETPIVOTDATA("Learning Activity Title",$A$3,"Brand/Function","HR MANAGEMENT","Activity status","In progress") -> 5
B34: Complete | C34: Booked | D34: In progress
A35: IT | B35: =GETPIVOTDATA("Learning Activity Title",$A$3,"Brand/Function","IT","Activity status","Complete") -> 272 | C35: =GETPIVOTDATA("Learning Activity Title",$A$3,"Brand/Function","IT","Activity status","Booked") -> 115 | D35: =GETPIVOTDATA("Learning Activity Title",$A$3,"Brand/Function","IT","Activity status","In progress") -> 2
B37: Complete | C37: Booked | D37: In progress
A38: Marketing | B38: =GETPIVOTDATA("Learning Activity Title",$A$3,"Brand/Function","Marketing","Activity status","Complete") -> 298 | C38: =GETPIVOTDATA("Learning Activity Title",$A$3,"Brand/Function","Marketing","Activity status","Booked") -> 48 | D38: =GETPIVOTDATA("Learning Activity Title",$A$3,"Brand/Function","Marketing","Activity status","In progress") -> 5
B40: Complete | C40: Booked | D40: In progress
A41: Property | B41: =GETPIVOTDATA("Learning Activity Title",$A$3,"Brand/Function","Property","Activity status","Complete") -> 133 | C41: =GETPIVOTDATA("Learning Activity Title",$A$3,"Brand/Function","Property","Activity status","Booked") -> 16 | D41: =GETPIVOTDATA("Learning Activity Title",$A$3,"Brand/Function","Property","Activity status","In progress") -> 1
B43: Complete | C43: Booked | D43: In progress
A44: SG AVIATION TM | B44: =GETPIVOTDATA("Learning Activity Title",$A$3,"Brand/Function","SG AVIATION TM","Activity status","Complete") -> 12 | C44: =GETPIVOTDATA("Learning Activity Title",$A$3,"Brand/Function","SG AVIATION TM","Activity status","Booked") -> 0 | D44: =GETPIVOTDATA("Learning Activity Title",$A$3,"Brand/Function","SG AVIATION TM","Activity status","In progress") -> 0
B46: Complete | C46: Booked | D46: In progress
A47: SPG DEV | B47: =GETPIVOTDATA("Learning Activity Title",$A$3,"Brand/Function","SPG DEV","Activity status","Complete") -> 22 | C47: =GETPIVOTDATA("Learning Activity Title",$A$3,"Brand/Function","SPG DEV","Activity status","Booked") -> 0 | D47: =GETPIVOTDATA("Learning Activity Title",$A$3,"Brand/Function","SPG DEV","Activity status","In progress") -> 0
B49: Complete | C49: Booked | D49: In progress
A50: SS Finance | B50: =GETPIVOTDATA("Learning Activity Title",$A$3,"Brand/Function","SS Finance","Activity status","Complete") -> 215 | C50: =GETPIVOTDATA("Learning Activity Title",$A$3,"Brand/Function","SS Finance","Activity status","Booked") -> 39 | D50: =GETPIVOTDATA("Learning Activity Title",$A$3,"Brand/Function","SS Finance","Activity status","In progress") -> 2
B52: Complete | C52: Booked | D52: In progress
A53: Supply Chain | B53: =GETPIVOTDATA("Learning Activity Title",$A$3,"Brand/Function","Supply Chain","Activity status","Complete") -> 109 | C53: =GETPIVOTDATA("Learning Activity Title",$A$3,"Brand/Function","Supply Chain","Activity status","Booked") -> 21 | D53: =GETPIVOTDATA("Learning Activity Title",$A$3,"Brand/Function","Supply Chain","Activity status","In progress") -> 0

Sheet PieCharts_Brands

Sheet MLA FEED
B1: Mandatory Learning Activity | C1: FY24 | T1: FY25
B2: Shared Services, FFM, SPG | C2: ="JUL, "&C1 -> JUL, FY24 | D2: ="AUG, "&C1 -> AUG, FY24 | E2: ="SEP, "&C1 -> SEP, FY24 | F2: ="Q1, "&C1 -> Q1, FY24 | G2: ="OCT, "&C1 -> OCT, FY24 | H2: ="NOV, "&C1 -> NOV, FY24 | I2: ="DEC, "&C1 -> DEC, FY24 | J2: ="Q2, "&C1 -> Q2, FY24 | K2: ="JAN, "&C1 -> JAN, FY24 | L2: ="FEB, "&C1 -> FEB, FY24 | M2: ="MAR, "&C1 -> MAR, FY24 | N2: ="Q3, "&C1 -> Q3, FY24 | O2: ="APR, "&C1 -> APR, FY24 | P2: ="MAY, "&C1 -> MAY, FY24 | Q2: ="JUN, "&C1 -> JUN, FY24 | R2: ="Q4, "&C1 -> Q4, FY24 | S2: ="Full Year, "&C1 -> Full Year, FY24 | T2: ="JUL, "&T1 -> JUL, FY25 | U2: ="AUG, "&T1 -> AUG, FY25 | V2: ="SEP, "&T1 -> SEP, FY25 | W2: ="Q1, "&T1 -> Q1, FY25 | X2: ="OCT, "&T1 -> OCT, FY25 | Y2: ="NOV, "&T1 -> NOV, FY25 | Z2: ="DEC, "&T1 -> DEC, FY25 | AA2: ="Q2, "&T1 -> Q2, FY25 | AB2: ="JAN, "&T1 -> JAN, FY25 | AC2: ="FEB, "&T1 -> FEB, FY25 | AD2: ="MAR, "&T1 -> MAR, FY25 | AE2: ="Q3, "&T1 -> Q3, FY25 | AF2: ="APR, "&T1 -> APR, FY25 | AG2: ="MAY, "&T1 -> MAY, FY25 | AH2: ="JUN, "&T1 -> JUN, FY25 | AI2: ="Q4, "&T1 -> Q4, FY25 | AJ2: ="Full Year, "&T1 -> Full Year, FY25
A3: Mandatory Learning Activity | B3: Bullying, Harassment and Discrimination - Module 1 | C3: =COUNTIFS('MLA Data Dump'!$H:$H,'MLA FEED'!$B3,'MLA Data Dump'!$M:$M,'MLA FEED'!C$2) -> 5 | D3: =COUNTIFS('MLA Data Dump'!$H:$H,'MLA FEED'!$B3,'MLA Data Dump'!$M:$M,'MLA FEED'!D$2) -> 17 | E3: =COUNTIFS('MLA Data Dump'!$H:$H,'MLA FEED'!$B3,'MLA Data Dump'!$M:$M,'MLA FEED'!E$2) -> 0 | F3: =SUBTOTAL(9,C3:E3) -> 22 | G3: =COUNTIFS('MLA Data Dump'!$H:$H,'MLA FEED'!$B3,'MLA Data Dump'!$M:$M,'MLA FEED'!G$2) -> 3 | H3: =COUNTIFS('MLA Data Dump'!$H:$H,'MLA FEED'!$B3,'MLA Data Dump'!$M:$M,'MLA FEED'!H$2) -> 2 | I3: =COUNTIFS('MLA Data Dump'!$H:$H,'MLA FEED'!$B3,'MLA Data Dump'!$M:$M,'MLA FEED'!I$2) -> 7 | J3: =SUBTOTAL(9,G3:I3) -> 12 | K3: =COUNTIFS('MLA Data Dump'!$H:$H,'MLA FEED'!$B3,'MLA Data Dump'!$M:$M,'MLA FEED'!K$2) -> 4 | L3: =COUNTIFS('MLA Data Dump'!$H:$H,'MLA FEED'!$B3,'MLA Data Dump'!$M:$M,'MLA FEED'!L$2) -> 5 | M3: =COUNTIFS('MLA Data Dump'!$H:$H,'MLA FEED'!$B3,'MLA Data Dump'!$M:$M,'MLA FEED'!M$2) -> 3 | N3: =SUBTOTAL(9,K3:M3) -> 12 | O3: =COUNTIFS('MLA Data Dump'!$H:$H,'MLA FEED'!$B3,'MLA Data Dump'!$M:$M,'MLA FEED'!O$2) -> 15 | P3: =COUNTIFS('MLA Data Dump'!$H:$H,'MLA FEED'!$B3,'MLA Data Dump'!$M:$M,'MLA FEED'!P$2) -> 8 | Q3: =COUNTIFS('MLA Data Dump'!$H:$H,'MLA FEED'!$B3,'MLA Data Dump'!$M:$M,'MLA FEED'!Q$2) -> 9 | R3: =SUBTOTAL(9,O3:Q3) -> 32 | S3: =SUBTOTAL(9,C3:R3) -> 78 | T3: =COUNTIFS('MLA Data Dump'!$H:$H,'MLA FEED'!$B3,'MLA Data Dump'!$M:$M,'MLA FEED'!T$2) -> 9 | U3: =COUNTIFS('MLA Data Dump'!$H:$H,'MLA FEED'!$B3,'MLA Data Dump'!$M:$M,'MLA FEED'!U$2) -> 10 | V3: =COUNTIFS('MLA Data Dump'!$H:$H,'MLA FEED'!$B3,'MLA Data Dump'!$M:$M,'MLA FEED'!V$2) -> 6 | W3: =SUBTOTAL(9,T3:V3) -> 25 | X3: =COUNTIFS('MLA Data Dump'!$H:$H,'MLA FEED'!$B3,'MLA Data Dump'!$M:$M,'MLA FEED'!X$2) -> 3 | Y3: =COUNTIFS('MLA Data Dump'!$H:$H,'MLA FEED'!$B3,'MLA Data Dump'!$M:$M,'MLA FEED'!Y$2) -> 11 | Z3: =COUNTIFS('MLA Data Dump'!$H:$H,'MLA FEED'!$B3,'MLA Data Dump'!$M:$M,'MLA FEED'!Z$2) -> 4 | AA3: =SUBTOTAL(9,X3:Z3) -> 18 | AB3: =COUNTIFS('MLA Data Dump'!$H:$H,'MLA FEED'!$B3,'MLA Data Dump'!$M:$M,'MLA FEED'!AB$2) -> 6 | AC3: =COUNTIFS('MLA Data Dump'!$H:$H,'MLA FEED'!$B3,'MLA Data Dump'!$M:$M,'MLA FEED'!AC$2) -> 16 | AD3: =COUNTIFS('MLA Data Dump'!$H:$H,'MLA FEED'!$B3,'MLA Data Dump'!$M:$M,'MLA FEED'!AD$2) -> 14 | AE3: =SUBTOTAL(9,AB3:AD3) -> 36 | AF3: =COUNTIFS('MLA Data Dump'!$H:$H,'MLA FEED'!$B3,'MLA Data Dump'!$M:$M,'MLA FEED'!AF$2) -> 8 | AG3: =COUNTIFS('MLA Data Dump'!$H:$H,'MLA FEED'!$B3,'MLA Data Dump'!$M:$M,'MLA FEED'!AG$2) -> 10 | AH3: =COUNTIFS('MLA Data Dump'!$H:$H,'MLA FEED'!$B3,'MLA Data Dump'!$M:$M,'MLA FEED'!AH$2) -> 0 | AI3: =SUBTOTAL(9,AF3:AH3) -> 18 | AJ3: =SUBTOTAL(9,T3:AI3) -> 97
B4: Bullying, Harassment and Discrimination - Module 2 | C4: =COUNTIFS('MLA Data Dump'!$H:$H,'MLA FEED'!$B4,'MLA Data Dump'!$M:$M,'MLA FEED'!C$2) -> 8 | D4: =COUNTIFS('MLA Data Dump'!$H:$H,'MLA FEED'!$B4,'MLA Data Dump'!$M:$M,'MLA FEED'!D$2) -> 19 | E4: =COUNTIFS('MLA Data Dump'!$H:$H,'MLA FEED'!$B4,'MLA Data Dump'!$M:$M,'MLA FEED'!E$2) -> 1 | F4: =SUBTOTAL(9,C4:E4) -> 28 | G4: =COUNTIFS('MLA Data Dump'!$H:$H,'MLA FEED'!$B4,'MLA Data Dump'!$M:$M,'MLA FEED'!G$2) -> 3 | H4: =COUNTIFS('MLA Data Dump'!$H:$H,'MLA FEED'!$B4,'MLA Data Dump'!$M:$M,'MLA FEED'!H$2) -> 1 | I4: =COUNTIFS('MLA Data Dump'!$H:$H,'MLA FEED'!$B4,'MLA Data Dump'!$M:$M,'MLA FEED'!I$2) -> 7 | J4: =SUBTOTAL(9,G4:I4) -> 11 | K4: =COUNTIFS('MLA Data Dump'!$H:$H,'MLA FEED'!$B4,'MLA Data Dump'!$M:$M,'MLA FEED'!K$2) -> 4 | L4: =COUNTIFS('MLA Data Dump'!$H:$H,'MLA FEED'!$B4,'MLA Data Dump'!$M:$M,'MLA FEED'!L$2) -> 5 | M4: =COUNTIFS('MLA Data Dump'!$H:$H,'MLA FEED'!$B4,'MLA Data Dump'!$M:$M,'MLA FEED'!M$2) -> 3 | N4: =SUBTOTAL(9,K4:M4) -> 12 | O4: =COUNTIFS('MLA Data Dump'!$H:$H,'MLA FEED'!$B4,'MLA Data Dump'!$M:$M,'MLA FEED'!O$2) -> 14 | P4: =COUNTIFS('MLA Data Dump'!$H:$H,'MLA FEED'!$B4,'MLA Data Dump'!$M:$M,'MLA FEED'!P$2) -> 9 | Q4: =COUNTIFS('MLA Data Dump'!$H:$H,'MLA FEED'!$B4,'MLA Data Dump'!$M:$M,'MLA FEED'!Q$2) -> 9 | R4: =SUBTOTAL(9,O4:Q4) -> 32 | S4: =SUBTOTAL(9,C4:R4) -> 83 | T4: =COUNTIFS('MLA Data Dump'!$H:$H,'MLA FEED'!$B4,'MLA Data Dump'!$M:$M,'MLA FEED'!T$2) -> 11 | U4: =COUNTIFS('MLA Data Dump'!$H:$H,'MLA FEED'!$B4,'MLA Data Dump'!$M:$M,'MLA FEED'!U$2) -> 10 | V4: =COUNTIFS('MLA Data Dump'!$H:$H,'MLA FEED'!$B4,'MLA Data Dump'!$M:$M,'MLA FEED'!V$2) -> 6 | W4: =SUBTOTAL(9,T4:V4) -> 27 | X4: =COUNTIFS('MLA Data Dump'!$H:$H,'MLA FEED'!$B4,'MLA Data Dump'!$M:$M,'MLA FEED'!X$2) -> 3 | Y4: =COUNTIFS('MLA Data Dump'!$H:$H,'MLA FEED'!$B4,'MLA Data Dump'!$M:$M,'MLA FEED'!Y$2) -> 11 | Z4: =COUNTIFS('MLA Data Dump'!$H:$H,'MLA FEED'!$B4,'MLA Data Dump'!$M:$M,'MLA FEED'!Z$2) -> 4 | AA4: =SUBTOTAL(9,X4:Z4) -> 18 | AB4: =COUNTIFS('MLA Data Dump'!$H:$H,'MLA FEED'!$B4,'MLA Data Dump'!$M:$M,'MLA FEED'!AB$2) -> 5 | AC4: =COUNTIFS('MLA Data Dump'!$H:$H,'MLA FEED'!$B4,'MLA Data Dump'!$M:$M,'MLA FEED'!AC$2) -> 15 | AD4: =COUNTIFS('MLA Data Dump'!$H:$H,'MLA FEED'!$B4,'MLA Data Dump'!$M:$M,'MLA FEED'!AD$2) -> 14 | AE4: =SUBTOTAL(9,AB4:AD4) -> 34 | AF4: =COUNTIFS('MLA Data Dump'!$H:$H,'MLA FEED'!$B4,'MLA Data Dump'!$M:$M,'MLA FEED'!AF$2) -> 7 | AG4: =COUNTIFS('MLA Data Dump'!$H:$H,'MLA FEED'!$B4,'MLA Data Dump'!$M:$M,'MLA FEED'!AG$2) -> 10 | AH4: =COUNTIFS('MLA Data Dump'!$H:$H,'MLA FEED'!$B4,'MLA Data Dump'!$M:$M,'MLA FEED'!AH$2) -> 0 | AI4: =SUBTOTAL(9,AF4:AH4) -> 17 | AJ4: =SUBTOTAL(9,T4:AI4) -> 96
B5: Bullying, Harassment and Discrimination for Team Leaders/Line Managers | C5: =COUNTIFS('MLA Data Dump'!$H:$H,'MLA FEED'!$B5,'MLA Data Dump'!$M:$M,'MLA FEED'!C$2) -> 2 | D5: =COUNTIFS('MLA Data Dump'!$H:$H,'MLA FEED'!$B5,'MLA Data Dump'!$M:$M,'MLA FEED'!D$2) -> 0 | E5: =COUNTIFS('MLA Data Dump'!$H:$H,'MLA FEED'!$B5,'MLA Data Dump'!$M:$M,'MLA FEED'!E$2) -> 0 | F5: =SUBTOTAL(9,C5:E5) -> 2 | G5: =COUNTIFS('MLA Data Dump'!$H:$H,'MLA FEED'!$B5,'MLA Data Dump'!$M:$M,'MLA FEED'!G$2) -> 1 | H5: =COUNTIFS('MLA Data Dump'!$H:$H,'MLA FEED'!$B5,'MLA Data Dump'!$M:$M,'MLA FEED'!H$2) -> 0 | I5: =COUNTIFS('MLA Data Dump'!$H:$H,'MLA FEED'!$B5,'MLA Data Dump'!$M:$M,'MLA FEED'!I$2) -> 0 | J5: =SUBTOTAL(9,G5:I5) -> 1 | K5: =COUNTIFS('MLA Data Dump'!$H:$H,'MLA FEED'!$B5,'MLA Data Dump'!$M:$M,'MLA FEED'!K$2) -> 0 | L5: =COUNTIFS('MLA Data Dump'!$H:$H,'MLA FEED'!$B5,'MLA Data Dump'!$M:$M,'MLA FEED'!L$2) -> 0 | M5: =COUNTIFS('MLA Data Dump'!$H:$H,'MLA FEED'!$B5,'MLA Data Dump'!$M:$M,'MLA FEED'!M$2) -> 0 | N5: =SUBTOTAL(9,K5:M5) -> 0 | O5: =COUNTIFS('MLA Data Dump'!$H:$H,'MLA FEED'!$B5,'MLA Data Dump'!$M:$M,'MLA FEED'!O$2) -> 0 | P5: =COUNTIFS('MLA Data Dump'!$H:$H,'MLA FEED'!$B5,'MLA Data Dump'!$M:$M,'MLA FEED'!P$2) -> 0 | Q5: =COUNTIFS('MLA Data Dump'!$H:$H,'MLA FEED'!$B5,'MLA Data Dump'!$M:$M,'MLA FEED'!Q$2) -> 0 | R5: =SUBTOTAL(9,O5:Q5) -> 0 | S5: =SUBTOTAL(9,C5:R5) -> 3 | T5: =COUNTIFS('MLA Data Dump'!$H:$H,'MLA FEED'!$B5,'MLA Data Dump'!$M:$M,'MLA FEED'!T$2) -> 1 | U5: =COUNTIFS('MLA Data Dump'!$H:$H,'MLA FEED'!$B5,'MLA Data Dump'!$M:$M,'MLA FEED'!U$2) -> 0 | V5: =COUNTIFS('MLA Data Dump'!$H:$H,'MLA FEED'!$B5,'MLA Data Dump'!$M:$M,'MLA FEED'!V$2) -> 0 | W5: =SUBTOTAL(9,T5:V5) -> 1 | X5: =COUNTIFS('MLA Data Dump'!$H:$H,'MLA FEED'!$B5,'MLA Data Dump'!$M:$M,'MLA FEED'!X$2) -> 0 | Y5: =COUNTIFS('MLA Data Dump'!$H:$H,'MLA FEED'!$B5,'MLA Data Dump'!$M:$M,'MLA FEED'!Y$2) -> 0 | Z5: =COUNTIFS('MLA Data Dump'!$H:$H,'MLA FEED'!$B5,'MLA Data Dump'!$M:$M,'MLA FEED'!Z$2) -> 0 | AA5: =SUBTOTAL(9,X5:Z5) -> 0 | AB5: =COUNTIFS('MLA Data Dump'!$H:$H,'MLA FEED'!$B5,'MLA Data Dump'!$M:$M,'MLA FEED'!AB$2) -> 0 | AC5: =COUNTIFS('MLA Data Dump'!$H:$H,'MLA FEED'!$B5,'MLA Data Dump'!$M:$M,'MLA FEED'!AC$2) -> 5 | AD5: =COUNTIFS('MLA Data Dump'!$H:$H,'MLA FEED'!$B5,'MLA Data Dump'!$M:$M,'MLA FEED'!AD$2) -> 0 | AE5: =SUBTOTAL(9,AB5:AD5) -> 5 | AF5: =COUNTIFS('MLA Data Dump'!$H:$H,'MLA FEED'!$B5,'MLA Data Dump'!$M:$M,'MLA FEED'!AF$2) -> 0 | AG5: =COUNTIFS('MLA Data Dump'!$H:$H,'MLA FEED'!$B5,'MLA Data Dump'!$M:$M,'MLA FEED'!AG$2) -> 0 | AH5: =COUNTIFS('MLA Data Dump'!$H:$H,'MLA FEED'!$B5,'MLA Data Dump'!$M:$M,'MLA FEED'!AH$2) -> 0 | AI5: =SUBTOTAL(9,AF5:AH5) -> 0 | AJ5: =SUBTOTAL(9,T5:AI5) -> 6
B6: Cyber Security Awareness - Business Email Compromise Scams | C6: =COUNTIFS('MLA Data Dump'!$H:$H,'MLA FEED'!$B6,'MLA Data Dump'!$M:$M,'MLA FEED'!C$2) -> 0 | D6: =COUNTIFS('MLA Data Dump'!$H:$H,'MLA FEED'!$B6,'MLA Data Dump'!$M:$M,'MLA FEED'!D$2) -> 0 | E6: =COUNTIFS('MLA Data Dump'!$H:$H,'MLA FEED'!$B6,'MLA Data Dump'!$M:$M,'MLA FEED'!E$2) -> 0 | F6: =SUBTOTAL(9,C6:E6) -> 0 | G6: =COUNTIFS('MLA Data Dump'!$H:$H,'MLA FEED'!$B6,'MLA Data Dump'!$M:$M,'MLA FEED'!G$2) -> 0 | H6: =COUNTIFS('MLA Data Dump'!$H:$H,'MLA FEED'!$B6,'MLA Data Dump'!$M:$M,'MLA FEED'!H$2) -> 0 | I6: =COUNTIFS('MLA Data Dump'!$H:$H,'MLA FEED'!$B6,'MLA Data Dump'!$M:$M,'MLA FEED'!I$2) -> 0 | J6: =SUBTOTAL(9,G6:I6) -> 0 | K6: =COUNTIFS('MLA Data Dump'!$H:$H,'MLA FEED'!$B6,'MLA Data Dump'!$M:$M,'MLA FEED'!K$2) -> 1 | L6: =COUNTIFS('MLA Data Dump'!$H:$H,'MLA FEED'!$B6,'MLA Data Dump'!$M:$M,'MLA FEED'!L$2) -> 0 | M6: =COUNTIFS('MLA Data Dump'!$H:$H,'MLA FEED'!$B6,'MLA Data Dump'!$M:$M,'MLA FEED'!M$2) -> 114 | N6: =SUBTOTAL(9,K6:M6) -> 115 | O6: =COUNTIFS('MLA Data Dump'!$H:$H,'MLA FEED'!$B6,'MLA Data Dump'!$M:$M,'MLA FEED'!O$2) -> 42 | P6: =COUNTIFS('MLA Data Dump'!$H:$H,'MLA FEED'!$B6,'MLA Data Dump'!$M:$M,'MLA FEED'!P$2) -> 61 | Q6: =COUNTIFS('MLA Data Dump'!$H:$H,'MLA FEED'!$B6,'MLA Data Dump'!$M:$M,'MLA FEED'!Q$2) -> 36 | R6: =SUBTOTAL(9,O6:Q6) -> 139 | S6: =SUBTOTAL(9,C6:R6) -> 254 | T6: =COUNTIFS('MLA Data Dump'!$H:$H,'MLA FEED'!$B6,'MLA Data Dump'!$M:$M,'MLA FEED'!T$2) -> 22 | U6: =COUNTIFS('MLA Data Dump'!$H:$H,'MLA FEED'!$B6,'MLA Data Dump'!$M:$M,'MLA FEED'!U$2) -> 20 | V6: =COUNTIFS('MLA Data Dump'!$H:$H,'MLA FEED'!$B6,'MLA Data Dump'!$M:$M,'MLA FEED'!V$2) -> 6 | W6: =SUBTOTAL(9,T6:V6) -> 48 | X6: =COUNTIFS('MLA Data Dump'!$H:$H,'MLA FEED'!$B6,'MLA Data Dump'!$M:$M,'MLA FEED'!X$2) -> 14 | Y6: =COUNTIFS('MLA Data Dump'!$H:$H,'MLA FEED'!$B6,'MLA Data Dump'!$M:$M,'MLA FEED'!Y$2) -> 9 | Z6: =COUNTIFS('MLA Data Dump'!$H:$H,'MLA FEED'!$B6,'MLA Data Dump'!$M:$M,'MLA FEED'!Z$2) -> 6 | AA6: =SUBTOTAL(9,X6:Z6) -> 29 | AB6: =COUNTIFS('MLA Data Dump'!$H:$H,'MLA FEED'!$B6,'MLA Data Dump'!$M:$M,'MLA FEED'!AB$2) -> 6 | AC6: =COUNTIFS('MLA Data Dump'!$H:$H,'MLA FEED'!$B6,'MLA Data Dump'!$M:$M,'MLA FEED'!AC$2) -> 13 | AD6: =COUNTIFS('MLA Data Dump'!$H:$H,'MLA FEED'!$B6,'MLA Data Dump'!$M:$M,'MLA FEED'!AD$2) -> 31 | AE6: =SUBTOTAL(9,AB6:AD6) -> 50 | AF6: =COUNTIFS('MLA Data Dump'!$H:$H,'MLA FEED'!$B6,'MLA Data Dump'!$M:$M,'MLA FEED'!AF$2) -> 39 | AG6: =COUNTIFS('MLA Data Dump'!$H:$H,'MLA FEED'!$B6,'MLA Data Dump'!$M:$M,'MLA FEED'!AG$2) -> 88 | AH6: =COUNTIFS('MLA Data Dump'!$H:$H,'MLA FEED'!$B6,'MLA Data Dump'!$M:$M,'MLA FEED'!AH$2) -> 0 | AI6: =SUBTOTAL(9,AF6:AH6) -> 127 | AJ6: =SUBTOTAL(9,T6:AI6) -> 254
