Workbook

Sheet ANA SIT REPORT - APR
E2: Total Booking - Working in Store
E3: ANA FEED | F3: ANA FEED | G3: ANA FEED | H3: ANA FEED | I3: ANA FEED
E4: FY24 | G4: FY25
E5: =E6&", "&E4 -> MAY, FY24 | F5: =E6&", "&E4 -> MAY, FY24 | G5: =G6&", "&G4 -> MAY, FY25 | H5: =G6&", "&G4 -> MAY, FY25
B6: Store Name | C6: Store Description | E6: MAY | F6: YTD | G6: MAY | H6: YTD | I6: VAR
B7: A050 | C7: Anaconda Albury | E7: {=_xlfn.XLOOKUP($B7,INDIRECT("'"&E$3&"'!"&"$A3:$A35"),_xlfn.XLOOKUP(E$5,INDIRECT("'"&E$3&"'!"&"$C2:$AZ2"),INDIRECT("'"&E$3&"'!"&"$C3:$AZ35")))} -> 0 | F7: {=_xlfn.XLOOKUP($B7,INDIRECT("'"&F$3&"'!"&"$A39:$A71"),_xlfn.XLOOKUP(F$5,INDIRECT("'"&F$3&"'!"&"$C2:$AZ2"),INDIRECT("'"&F$3&"'!"&"$C39:$AZ71")))} -> 2 | G7: {=_xlfn.XLOOKUP($B7,INDIRECT("'"&G$3&"'!"&"$A3:$A35"),_xlfn.XLOOKUP(G$5,INDIRECT("'"&G$3&"'!"&"$C2:$AZ2"),INDIRECT("'"&G$3&"'!"&"$C3:$AZ35")))} -> 0 | H7: {=_xlfn.XLOOKUP($B7,INDIRECT("'"&H$3&"'!"&"$A39:$A71"),_xlfn.XLOOKUP(H$5,INDIRECT("'"&H$3&"'!"&"$C2:$AZ2"),INDIRECT("'"&H$3&"'!"&"$C39:$AZ71")))} -> 1 | I7: =H7-F7 -> -1
B8: A002 | C8: Anaconda Ashmore | E8: {=_xlfn.XLOOKUP($B8,INDIRECT("'"&E$3&"'!"&"$A3:$A35"),_xlfn.XLOOKUP(E$5,INDIRECT("'"&E$3&"'!"&"$C2:$AZ2"),INDIRECT("'"&E$3&"'!"&"$C3:$AZ35")))} -> 0 | F8: {=_xlfn.XLOOKUP($B8,INDIRECT("'"&F$3&"'!"&"$A39:$A71"),_xlfn.XLOOKUP(F$5,INDIRECT("'"&F$3&"'!"&"$C2:$AZ2"),INDIRECT("'"&F$3&"'!"&"$C39:$AZ71")))} -> 0 | G8: {=_xlfn.XLOOKUP($B8,INDIRECT("'"&G$3&"'!"&"$A3:$A35"),_xlfn.XLOOKUP(G$5,INDIRECT("'"&G$3&"'!"&"$C2:$AZ2"),INDIRECT("'"&G$3&"'!"&"$C3:$AZ35")))} -> 0 | H8: {=_xlfn.XLOOKUP($B8,INDIRECT("'"&H$3&"'!"&"$A39:$A71"),_xlfn.XLOOKUP(H$5,INDIRECT("'"&H$3&"'!"&"$C2:$AZ2"),INDIRECT("'"&H$3&"'!"&"$C39:$AZ71")))} -> 0 | I8: =H8-F8 -> 0
B9: A035 | C9: Anaconda Ballarat | E9: {=_xlfn.XLOOKUP($B9,INDIRECT("'"&E$3&"'!"&"$A3:$A35"),_xlfn.XLOOKUP(E$5,INDIRECT("'"&E$3&"'!"&"$C2:$AZ2"),INDIRECT("'"&E$3&"'!"&"$C3:$AZ35")))} -> 0 | F9: {=_xlfn.XLOOKUP($B9,INDIRECT("'"&F$3&"'!"&"$A39:$A71"),_xlfn.XLOOKUP(F$5,INDIRECT("'"&F$3&"'!"&"$C2:$AZ2"),INDIRECT("'"&F$3&"'!"&"$C39:$AZ71")))} -> 0 | G9: {=_xlfn.XLOOKUP($B9,INDIRECT("'"&G$3&"'!"&"$A3:$A35"),_xlfn.XLOOKUP(G$5,INDIRECT("'"&G$3&"'!"&"$C2:$AZ2"),INDIRECT("'"&G$3&"'!"&"$C3:$AZ35")))} -> 1 | H9: {=_xlfn.XLOOKUP($B9,INDIRECT("'"&H$3&"'!"&"$A39:$A71"),_xlfn.XLOOKUP(H$5,INDIRECT("'"&H$3&"'!"&"$C2:$AZ2"),INDIRECT("'"&H$3&"'!"&"$C39:$AZ71")))} -> 2 | I9: =H9-F9 -> 2
B10: A001 | C10: Anaconda Bayswater | E10: {=_xlfn.XLOOKUP($B10,INDIRECT("'"&E$3&"'!"&"$A3:$A35"),_xlfn.XLOOKUP(E$5,INDIRECT("'"&E$3&"'!"&"$C2:$AZ2"),INDIRECT("'"&E$3&"'!"&"$C3:$AZ35")))} -> 0 | F10: {=_xlfn.XLOOKUP($B10,INDIRECT("'"&F$3&"'!"&"$A39:$A71"),_xlfn.XLOOKUP(F$5,INDIRECT("'"&F$3&"'!"&"$C2:$AZ2"),INDIRECT("'"&F$3&"'!"&"$C39:$AZ71")))} -> 5 | G10: {=_xlfn.XLOOKUP($B10,INDIRECT("'"&G$3&"'!"&"$A3:$A35"),_xlfn.XLOOKUP(G$5,INDIRECT("'"&G$3&"'!"&"$C2:$AZ2"),INDIRECT("'"&G$3&"'!"&"$C3:$AZ35")))} -> 1 | H10: {=_xlfn.XLOOKUP($B10,INDIRECT("'"&H$3&"'!"&"$A39:$A71"),_xlfn.XLOOKUP(H$5,INDIRECT("'"&H$3&"'!"&"$C2:$AZ2"),INDIRECT("'"&H$3&"'!"&"$C39:$AZ71")))} -> 5 | I10: =H10-F10 -> 0
B11: A021 | C11: Anaconda Bendigo | E11: {=_xlfn.XLOOKUP($B11,INDIRECT("'"&E$3&"'!"&"$A3:$A35"),_xlfn.XLOOKUP(E$5,INDIRECT("'"&E$3&"'!"&"$C2:$AZ2"),INDIRECT("'"&E$3&"'!"&"$C3:$AZ35")))} -> 0 | F11: {=_xlfn.XLOOKUP($B11,INDIRECT("'"&F$3&"'!"&"$A39:$A71"),_xlfn.XLOOKUP(F$5,INDIRECT("'"&F$3&"'!"&"$C2:$AZ2"),INDIRECT("'"&F$3&"'!"&"$C39:$AZ71")))} -> 0 | G11: {=_xlfn.XLOOKUP($B11,INDIRECT("'"&G$3&"'!"&"$A3:$A35"),_xlfn.XLOOKUP(G$5,INDIRECT("'"&G$3&"'!"&"$C2:$AZ2"),INDIRECT("'"&G$3&"'!"&"$C3:$AZ35")))} -> 0 | H11: {=_xlfn.XLOOKUP($B11,INDIRECT("'"&H$3&"'!"&"$A39:$A71"),_xlfn.XLOOKUP(H$5,INDIRECT("'"&H$3&"'!"&"$C2:$AZ2"),INDIRECT("'"&H$3&"'!"&"$C39:$AZ71")))} -> 2 | I11: =H11-F11 -> 2
B12: A041 | C12: Anaconda Box Hill | E12: {=_xlfn.XLOOKUP($B12,INDIRECT("'"&E$3&"'!"&"$A3:$A35"),_xlfn.XLOOKUP(E$5,INDIRECT("'"&E$3&"'!"&"$C2:$AZ2"),INDIRECT("'"&E$3&"'!"&"$C3:$AZ35")))} -> 0 | F12: {=_xlfn.XLOOKUP($B12,INDIRECT("'"&F$3&"'!"&"$A39:$A71"),_xlfn.XLOOKUP(F$5,INDIRECT("'"&F$3&"'!"&"$C2:$AZ2"),INDIRECT("'"&F$3&"'!"&"$C39:$AZ71")))} -> 2 | G12: {=_xlfn.XLOOKUP($B12,INDIRECT("'"&G$3&"'!"&"$A3:$A35"),_xlfn.XLOOKUP(G$5,INDIRECT("'"&G$3&"'!"&"$C2:$AZ2"),INDIRECT("'"&G$3&"'!"&"$C3:$AZ35")))} -> 1 | H12: {=_xlfn.XLOOKUP($B12,INDIRECT("'"&H$3&"'!"&"$A39:$A71"),_xlfn.XLOOKUP(H$5,INDIRECT("'"&H$3&"'!"&"$C2:$AZ2"),INDIRECT("'"&H$3&"'!"&"$C39:$AZ71")))} -> 2 | I12: =H12-F12 -> 0
B13: A071 | C13: Anaconda Bunbury | E13: {=_xlfn.XLOOKUP($B13,INDIRECT("'"&E$3&"'!"&"$A3:$A35"),_xlfn.XLOOKUP(E$5,INDIRECT("'"&E$3&"'!"&"$C2:$AZ2"),INDIRECT("'"&E$3&"'!"&"$C3:$AZ35")))} -> 0 | F13: {=_xlfn.XLOOKUP($B13,INDIRECT("'"&F$3&"'!"&"$A39:$A71"),_xlfn.XLOOKUP(F$5,INDIRECT("'"&F$3&"'!"&"$C2:$AZ2"),INDIRECT("'"&F$3&"'!"&"$C39:$AZ71")))} -> 0 | G13: {=_xlfn.XLOOKUP($B13,INDIRECT("'"&G$3&"'!"&"$A3:$A35"),_xlfn.XLOOKUP(G$5,INDIRECT("'"&G$3&"'!"&"$C2:$AZ2"),INDIRECT("'"&G$3&"'!"&"$C3:$AZ35")))} -> 0 | H13: {=_xlfn.XLOOKUP($B13,INDIRECT("'"&H$3&"'!"&"$A39:$A71"),_xlfn.XLOOKUP(H$5,INDIRECT("'"&H$3&"'!"&"$C2:$AZ2"),INDIRECT("'"&H$3&"'!"&"$C39:$AZ71")))} -> 0 | I13: =H13-F13 -> 0
B14: A037 | C14: Anaconda Cairns | E14: {=_xlfn.XLOOKUP($B14,INDIRECT("'"&E$3&"'!"&"$A3:$A35"),_xlfn.XLOOKUP(E$5,INDIRECT("'"&E$3&"'!"&"$C2:$AZ2"),INDIRECT("'"&E$3&"'!"&"$C3:$AZ35")))} -> 0 | F14: {=_xlfn.XLOOKUP($B14,INDIRECT("'"&F$3&"'!"&"$A39:$A71"),_xlfn.XLOOKUP(F$5,INDIRECT("'"&F$3&"'!"&"$C2:$AZ2"),INDIRECT("'"&F$3&"'!"&"$C39:$AZ71")))} -> 0 | G14: {=_xlfn.XLOOKUP($B14,INDIRECT("'"&G$3&"'!"&"$A3:$A35"),_xlfn.XLOOKUP(G$5,INDIRECT("'"&G$3&"'!"&"$C2:$AZ2"),INDIRECT("'"&G$3&"'!"&"$C3:$AZ35")))} -> 0 | H14: {=_xlfn.XLOOKUP($B14,INDIRECT("'"&H$3&"'!"&"$A39:$A71"),_xlfn.XLOOKUP(H$5,INDIRECT("'"&H$3&"'!"&"$C2:$AZ2"),INDIRECT("'"&H$3&"'!"&"$C39:$AZ71")))} -> 0 | I14: =H14-F14 -> 0
B15: A062 | C15: Anaconda Campbelltown | E15: {=_xlfn.XLOOKUP($B15,INDIRECT("'"&E$3&"'!"&"$A3:$A35"),_xlfn.XLOOKUP(E$5,INDIRECT("'"&E$3&"'!"&"$C2:$AZ2"),INDIRECT("'"&E$3&"'!"&"$C3:$AZ35")))} -> 0 | F15: {=_xlfn.XLOOKUP($B15,INDIRECT("'"&F$3&"'!"&"$A39:$A71"),_xlfn.XLOOKUP(F$5,INDIRECT("'"&F$3&"'!"&"$C2:$AZ2"),INDIRECT("'"&F$3&"'!"&"$C39:$AZ71")))} -> 0 | G15: {=_xlfn.XLOOKUP($B15,INDIRECT("'"&G$3&"'!"&"$A3:$A35"),_xlfn.XLOOKUP(G$5,INDIRECT("'"&G$3&"'!"&"$C2:$AZ2"),INDIRECT("'"&G$3&"'!"&"$C3:$AZ35")))} -> 0 | H15: {=_xlfn.XLOOKUP($B15,INDIRECT("'"&H$3&"'!"&"$A39:$A71"),_xlfn.XLOOKUP(H$5,INDIRECT("'"&H$3&"'!"&"$C2:$AZ2"),INDIRECT("'"&H$3&"'!"&"$C39:$AZ71")))} -> 0 | I15: =H15-F15 -> 0
B16: A006 | C16: Anaconda Chullora | E16: {=_xlfn.XLOOKUP($B16,INDIRECT("'"&E$3&"'!"&"$A3:$A35"),_xlfn.XLOOKUP(E$5,INDIRECT("'"&E$3&"'!"&"$C2:$AZ2"),INDIRECT("'"&E$3&"'!"&"$C3:$AZ35")))} -> 0 | F16: {=_xlfn.XLOOKUP($B16,INDIRECT("'"&F$3&"'!"&"$A39:$A71"),_xlfn.XLOOKUP(F$5,INDIRECT("'"&F$3&"'!"&"$C2:$AZ2"),INDIRECT("'"&F$3&"'!"&"$C39:$AZ71")))} -> 0 | G16: {=_xlfn.XLOOKUP($B16,INDIRECT("'"&G$3&"'!"&"$A3:$A35"),_xlfn.XLOOKUP(G$5,INDIRECT("'"&G$3&"'!"&"$C2:$AZ2"),INDIRECT("'"&G$3&"'!"&"$C3:$AZ35")))} -> 0 | H16: {=_xlfn.XLOOKUP($B16,INDIRECT("'"&H$3&"'!"&"$A39:$A71"),_xlfn.XLOOKUP(H$5,INDIRECT("'"&H$3&"'!"&"$C2:$AZ2"),INDIRECT("'"&H$3&"'!"&"$C39:$AZ71")))} -> 0 | I16: =H16-F16 -> 0
B17: A052 | C17: Anaconda Epping | E17: {=_xlfn.XLOOKUP($B17,INDIRECT("'"&E$3&"'!"&"$A3:$A35"),_xlfn.XLOOKUP(E$5,INDIRECT("'"&E$3&"'!"&"$C2:$AZ2"),INDIRECT("'"&E$3&"'!"&"$C3:$AZ35")))} -> 0 | F17: {=_xlfn.XLOOKUP($B17,INDIRECT("'"&F$3&"'!"&"$A39:$A71"),_xlfn.XLOOKUP(F$5,INDIRECT("'"&F$3&"'!"&"$C2:$AZ2"),INDIRECT("'"&F$3&"'!"&"$C39:$AZ71")))} -> 5 | G17: {=_xlfn.XLOOKUP($B17,INDIRECT("'"&G$3&"'!"&"$A3:$A35"),_xlfn.XLOOKUP(G$5,INDIRECT("'"&G$3&"'!"&"$C2:$AZ2"),INDIRECT("'"&G$3&"'!"&"$C3:$AZ35")))} -> 0 | H17: {=_xlfn.XLOOKUP($B17,INDIRECT("'"&H$3&"'!"&"$A39:$A71"),_xlfn.XLOOKUP(H$5,INDIRECT("'"&H$3&"'!"&"$C2:$AZ2"),INDIRECT("'"&H$3&"'!"&"$C39:$AZ71")))} -> 2 | I17: =H17-F17 -> -3
B18: A004 | C18: Anaconda Everton Park | E18: {=_xlfn.XLOOKUP($B18,INDIRECT("'"&E$3&"'!"&"$A3:$A35"),_xlfn.XLOOKUP(E$5,INDIRECT("'"&E$3&"'!"&"$C2:$AZ2"),INDIRECT("'"&E$3&"'!"&"$C3:$AZ35")))} -> 0 | F18: {=_xlfn.XLOOKUP($B18,INDIRECT("'"&F$3&"'!"&"$A39:$A71"),_xlfn.XLOOKUP(F$5,INDIRECT("'"&F$3&"'!"&"$C2:$AZ2"),INDIRECT("'"&F$3&"'!"&"$C39:$AZ71")))} -> 0 | G18: {=_xlfn.XLOOKUP($B18,INDIRECT("'"&G$3&"'!"&"$A3:$A35"),_xlfn.XLOOKUP(G$5,INDIRECT("'"&G$3&"'!"&"$C2:$AZ2"),INDIRECT("'"&G$3&"'!"&"$C3:$AZ35")))} -> 0 | H18: {=_xlfn.XLOOKUP($B18,INDIRECT("'"&H$3&"'!"&"$A39:$A71"),_xlfn.XLOOKUP(H$5,INDIRECT("'"&H$3&"'!"&"$C2:$AZ2"),INDIRECT("'"&H$3&"'!"&"$C39:$AZ71")))} -> 1 | I18: =H18-F18 -> 1
... B39: A040 | C39: Anaconda Watergardens | E39: {=_xlfn.XLOOKUP($B39,INDIRECT("'"&E$3&"'!"&"$A3:$A35"),_xlfn.XLOOKUP(E$5,INDIRECT("'"&E$3&"'!"&"$C2:$AZ2"),INDIRECT("'"&E$3&"'!"&"$C3:$AZ35")))} -> 0 | F39: {=_xlfn.XLOOKUP($B39,INDIRECT("'"&F$3&"'!"&"$A39:$A71"),_xlfn.XLOOKUP(F$5,INDIRECT("'"&F$3&"'!"&"$C2:$AZ2"),INDIRECT("'"&F$3&"'!"&"$C39:$AZ71")))} -> 4 | G39: {=_xlfn.XLOOKUP($B39,INDIRECT("'"&G$3&"'!"&"$A3:$A35"),_xlfn.XLOOKUP(G$5,INDIRECT("'"&G$3&"'!"&"$C2:$AZ2"),INDIRECT("'"&G$3&"'!"&"$C3:$AZ35")))} -> 0 | H39: {=_xlfn.XLOOKUP($B39,INDIRECT("'"&H$3&"'!"&"$A39:$A71"),_xlfn.XLOOKUP(H$5,INDIRECT("'"&H$3&"'!"&"$C2:$AZ2"),INDIRECT("'"&H$3&"'!"&"$C39:$AZ71")))} -> 4 | I39: =H39-F39 -> 0
B40: Grand Total | E40: =SUM(E7:E39) -> 1 | F40: =SUM(F7:F39) -> 69 | G40: =SUM(G7:G39) -> 9 | H40: =SUM(H7:H39) -> 85 | I40: =SUM(I7:I39) -> 16
B41: *Var denotes the Variance in YTD Columns

Sheet HS SIT REPORT - APR
E2: Total Booking - Working in Store
E3: HS FEED | F3: HS FEED | G3: HS FEED | H3: HS FEED | I3: HS FEED
E4: FY24 | G4: FY25
E5: =E6&", "&E4 -> MAY, FY24 | F5: =E6&", "&E4 -> MAY, FY24 | G5: =G6&", "&G4 -> MAY, FY25 | H5: =G6&", "&G4 -> MAY, FY25
B6: Store Name | C6: Store Description | E6: MAY | F6: YTD | G6: MAY | H6: YTD | I6: VAR
B7: HS2027 | C7: Harris Scarfe Airport West | E7: {=_xlfn.XLOOKUP($B7,INDIRECT("'"&E$3&"'!"&"$A3:$A36"),_xlfn.XLOOKUP(E$5,INDIRECT("'"&E$3&"'!"&"$C2:$AZ2"),INDIRECT("'"&E$3&"'!"&"$C3:$AZ36")))} -> 0 | F7: {=_xlfn.XLOOKUP($B7,INDIRECT("'"&F$3&"'!"&"$A40:$A73"),_xlfn.XLOOKUP(F$5,INDIRECT("'"&F$3&"'!"&"$C2:$AZ2"),INDIRECT("'"&F$3&"'!"&"$C40:$AZ73")))} -> 12 | G7: {=_xlfn.XLOOKUP($B7,INDIRECT("'"&G$3&"'!"&"$A3:$A36"),_xlfn.XLOOKUP(G$5,INDIRECT("'"&G$3&"'!"&"$C2:$AZ2"),INDIRECT("'"&G$3&"'!"&"$C3:$AZ36")))} -> 1 | H7: {=_xlfn.XLOOKUP($B7,INDIRECT("'"&H$3&"'!"&"$A40:$A73"),_xlfn.XLOOKUP(H$5,INDIRECT("'"&H$3&"'!"&"$C2:$AZ2"),INDIRECT("'"&H$3&"'!"&"$C40:$AZ73")))} -> 5 | I7: =H7-F7 -> -7
B8: HS1004 | C8: Harris Scarfe Arndale | E8: {=_xlfn.XLOOKUP($B8,INDIRECT("'"&E$3&"'!"&"$A3:$A36"),_xlfn.XLOOKUP(E$5,INDIRECT("'"&E$3&"'!"&"$C2:$AZ2"),INDIRECT("'"&E$3&"'!"&"$C3:$AZ36")))} -> 0 | F8: {=_xlfn.XLOOKUP($B8,INDIRECT("'"&F$3&"'!"&"$A40:$A73"),_xlfn.XLOOKUP(F$5,INDIRECT("'"&F$3&"'!"&"$C2:$AZ2"),INDIRECT("'"&F$3&"'!"&"$C40:$AZ73")))} -> 0 | G8: {=_xlfn.XLOOKUP($B8,INDIRECT("'"&G$3&"'!"&"$A3:$A36"),_xlfn.XLOOKUP(G$5,INDIRECT("'"&G$3&"'!"&"$C2:$AZ2"),INDIRECT("'"&G$3&"'!"&"$C3:$AZ36")))} -> 0 | H8: {=_xlfn.XLOOKUP($B8,INDIRECT("'"&H$3&"'!"&"$A40:$A73"),_xlfn.XLOOKUP(H$5,INDIRECT("'"&H$3&"'!"&"$C2:$AZ2"),INDIRECT("'"&H$3&"'!"&"$C40:$AZ73")))} -> 0 | I8: =H8-F8 -> 0
B9: HS2059 | C9: Harris Scarfe Bairnsdale | E9: {=_xlfn.XLOOKUP($B9,INDIRECT("'"&E$3&"'!"&"$A3:$A36"),_xlfn.XLOOKUP(E$5,INDIRECT("'"&E$3&"'!"&"$C2:$AZ2"),INDIRECT("'"&E$3&"'!"&"$C3:$AZ36")))} -> 0 | F9: {=_xlfn.XLOOKUP($B9,INDIRECT("'"&F$3&"'!"&"$A40:$A73"),_xlfn.XLOOKUP(F$5,INDIRECT("'"&F$3&"'!"&"$C2:$AZ2"),INDIRECT("'"&F$3&"'!"&"$C40:$AZ73")))} -> 1 | G9: {=_xlfn.XLOOKUP($B9,INDIRECT("'"&G$3&"'!"&"$A3:$A36"),_xlfn.XLOOKUP(G$5,INDIRECT("'"&G$3&"'!"&"$C2:$AZ2"),INDIRECT("'"&G$3&"'!"&"$C3:$AZ36")))} -> 0 | H9: {=_xlfn.XLOOKUP($B9,INDIRECT("'"&H$3&"'!"&"$A40:$A73"),_xlfn.XLOOKUP(H$5,INDIRECT("'"&H$3&"'!"&"$C2:$AZ2"),INDIRECT("'"&H$3&"'!"&"$C40:$AZ73")))} -> 0 | I9: =H9-F9 -> -1
B10: HS2019 | C10: Harris Scarfe Ballarat | E10: {=_xlfn.XLOOKUP($B10,INDIRECT("'"&E$3&"'!"&"$A3:$A36"),_xlfn.XLOOKUP(E$5,INDIRECT("'"&E$3&"'!"&"$C2:$AZ2"),INDIRECT("'"&E$3&"'!"&"$C3:$AZ36")))} -> 0 | F10: {=_xlfn.XLOOKUP($B10,INDIRECT("'"&F$3&"'!"&"$A40:$A73"),_xlfn.XLOOKUP(F$5,INDIRECT("'"&F$3&"'!"&"$C2:$AZ2"),INDIRECT("'"&F$3&"'!"&"$C40:$AZ73")))} -> 0 | G10: {=_xlfn.XLOOKUP($B10,INDIRECT("'"&G$3&"'!"&"$A3:$A36"),_xlfn.XLOOKUP(G$5,INDIRECT("'"&G$3&"'!"&"$C2:$AZ2"),INDIRECT("'"&G$3&"'!"&"$C3:$AZ36")))} -> 0 | H10: {=_xlfn.XLOOKUP($B10,INDIRECT("'"&H$3&"'!"&"$A40:$A73"),_xlfn.XLOOKUP(H$5,INDIRECT("'"&H$3&"'!"&"$C2:$AZ2"),INDIRECT("'"&H$3&"'!"&"$C40:$AZ73")))} -> 0 | I10: =H10-F10 -> 0
B11: HS5054 | C11: Harris Scarfe Blacktown | E11: {=_xlfn.XLOOKUP($B11,INDIRECT("'"&E$3&"'!"&"$A3:$A36"),_xlfn.XLOOKUP(E$5,INDIRECT("'"&E$3&"'!"&"$C2:$AZ2"),INDIRECT("'"&E$3&"'!"&"$C3:$AZ36")))} -> 0 | F11: {=_xlfn.XLOOKUP($B11,INDIRECT("'"&F$3&"'!"&"$A40:$A73"),_xlfn.XLOOKUP(F$5,INDIRECT("'"&F$3&"'!"&"$C2:$AZ2"),INDIRECT("'"&F$3&"'!"&"$C40:$AZ73")))} -> 1 | G11: {=_xlfn.XLOOKUP($B11,INDIRECT("'"&G$3&"'!"&"$A3:$A36"),_xlfn.XLOOKUP(G$5,INDIRECT("'"&G$3&"'!"&"$C2:$AZ2"),INDIRECT("'"&G$3&"'!"&"$C3:$AZ36")))} -> 0 | H11: {=_xlfn.XLOOKUP($B11,INDIRECT("'"&H$3&"'!"&"$A40:$A73"),_xlfn.XLOOKUP(H$5,INDIRECT("'"&H$3&"'!"&"$C2:$AZ2"),INDIRECT("'"&H$3&"'!"&"$C40:$AZ73")))} -> 0 | I11: =H11-F11 -> -1
B12: HS2042 | C12: Harris Scarfe Carnegie | E12: {=_xlfn.XLOOKUP($B12,INDIRECT("'"&E$3&"'!"&"$A3:$A36"),_xlfn.XLOOKUP(E$5,INDIRECT("'"&E$3&"'!"&"$C2:$AZ2"),INDIRECT("'"&E$3&"'!"&"$C3:$AZ36")))} -> 0 | F12: {=_xlfn.XLOOKUP($B12,INDIRECT("'"&F$3&"'!"&"$A40:$A73"),_xlfn.XLOOKUP(F$5,INDIRECT("'"&F$3&"'!"&"$C2:$AZ2"),INDIRECT("'"&F$3&"'!"&"$C40:$AZ73")))} -> 0 | G12: {=_xlfn.XLOOKUP($B12,INDIRECT("'"&G$3&"'!"&"$A3:$A36"),_xlfn.XLOOKUP(G$5,INDIRECT("'"&G$3&"'!"&"$C2:$AZ2"),INDIRECT("'"&G$3&"'!"&"$C3:$AZ36")))} -> 0 | H12: {=_xlfn.XLOOKUP($B12,INDIRECT("'"&H$3&"'!"&"$A40:$A73"),_xlfn.XLOOKUP(H$5,INDIRECT("'"&H$3&"'!"&"$C2:$AZ2"),INDIRECT("'"&H$3&"'!"&"$C40:$AZ73")))} -> 1 | I12: =H12-F12 -> 1
B13: HS2054 | C13: Harris Scarfe Chirnside Park | E13: {=_xlfn.XLOOKUP($B13,INDIRECT("'"&E$3&"'!"&"$A3:$A36"),_xlfn.XLOOKUP(E$5,INDIRECT("'"&E$3&"'!"&"$C2:$AZ2"),INDIRECT("'"&E$3&"'!"&"$C3:$AZ36")))} -> 0 | F13: {=_xlfn.XLOOKUP($B13,INDIRECT("'"&F$3&"'!"&"$A40:$A73"),_xlfn.XLOOKUP(F$5,INDIRECT("'"&F$3&"'!"&"$C2:$AZ2"),INDIRECT("'"&F$3&"'!"&"$C40:$AZ73")))} -> 1 | G13: {=_xlfn.XLOOKUP($B13,INDIRECT("'"&G$3&"'!"&"$A3:$A36"),_xlfn.XLOOKUP(G$5,INDIRECT("'"&G$3&"'!"&"$C2:$AZ2"),INDIRECT("'"&G$3&"'!"&"$C3:$AZ36")))} -> 0 | H13: {=_xlfn.XLOOKUP($B13,INDIRECT("'"&H$3&"'!"&"$A40:$A73"),_xlfn.XLOOKUP(H$5,INDIRECT("'"&H$3&"'!"&"$C2:$AZ2"),INDIRECT("'"&H$3&"'!"&"$C40:$AZ73")))} -> 0 | I13: =H13-F13 -> -1
B14: HS2055 | C14: Harris Scarfe Craigieburn | E14: {=_xlfn.XLOOKUP($B14,INDIRECT("'"&E$3&"'!"&"$A3:$A36"),_xlfn.XLOOKUP(E$5,INDIRECT("'"&E$3&"'!"&"$C2:$AZ2"),INDIRECT("'"&E$3&"'!"&"$C3:$AZ36")))} -> 0 | F14: {=_xlfn.XLOOKUP($B14,INDIRECT("'"&F$3&"'!"&"$A40:$A73"),_xlfn.XLOOKUP(F$5,INDIRECT("'"&F$3&"'!"&"$C2:$AZ2"),INDIRECT("'"&F$3&"'!"&"$C40:$AZ73")))} -> 0 | G14: {=_xlfn.XLOOKUP($B14,INDIRECT("'"&G$3&"'!"&"$A3:$A36"),_xlfn.XLOOKUP(G$5,INDIRECT("'"&G$3&"'!"&"$C2:$AZ2"),INDIRECT("'"&G$3&"'!"&"$C3:$AZ36")))} -> 0 | H14: {=_xlfn.XLOOKUP($B14,INDIRECT("'"&H$3&"'!"&"$A40:$A73"),_xlfn.XLOOKUP(H$5,INDIRECT("'"&H$3&"'!"&"$C2:$AZ2"),INDIRECT("'"&H$3&"'!"&"$C40:$AZ73")))} -> 0 | I14: =H14-F14 -> 0
B15: HS2028 | C15: Harris Scarfe Cranbourne Park | E15: {=_xlfn.XLOOKUP($B15,INDIRECT("'"&E$3&"'!"&"$A3:$A36"),_xlfn.XLOOKUP(E$5,INDIRECT("'"&E$3&"'!"&"$C2:$AZ2"),INDIRECT("'"&E$3&"'!"&"$C3:$AZ36")))} -> 0 | F15: {=_xlfn.XLOOKUP($B15,INDIRECT("'"&F$3&"'!"&"$A40:$A73"),_xlfn.XLOOKUP(F$5,INDIRECT("'"&F$3&"'!"&"$C2:$AZ2"),INDIRECT("'"&F$3&"'!"&"$C40:$AZ73")))} -> 0 | G15: {=_xlfn.XLOOKUP($B15,INDIRECT("'"&G$3&"'!"&"$A3:$A36"),_xlfn.XLOOKUP(G$5,INDIRECT("'"&G$3&"'!"&"$C2:$AZ2"),INDIRECT("'"&G$3&"'!"&"$C3:$AZ36")))} -> 0 | H15: {=_xlfn.XLOOKUP($B15,INDIRECT("'"&H$3&"'!"&"$A40:$A73"),_xlfn.XLOOKUP(H$5,INDIRECT("'"&H$3&"'!"&"$C2:$AZ2"),INDIRECT("'"&H$3&"'!"&"$C40:$AZ73")))} -> 0 | I15: =H15-F15 -> 0
B16: HS2057 | C16: Harris Scarfe DC | E16: {=_xlfn.XLOOKUP($B16,INDIRECT("'"&E$3&"'!"&"$A3:$A36"),_xlfn.XLOOKUP(E$5,INDIRECT("'"&E$3&"'!"&"$C2:$AZ2"),INDIRECT("'"&E$3&"'!"&"$C3:$AZ36")))} -> 0 | F16: {=_xlfn.XLOOKUP($B16,INDIRECT("'"&F$3&"'!"&"$A40:$A73"),_xlfn.XLOOKUP(F$5,INDIRECT("'"&F$3&"'!"&"$C2:$AZ2"),INDIRECT("'"&F$3&"'!"&"$C40:$AZ73")))} -> 0 | G16: {=_xlfn.XLOOKUP($B16,INDIRECT("'"&G$3&"'!"&"$A3:$A36"),_xlfn.XLOOKUP(G$5,INDIRECT("'"&G$3&"'!"&"$C2:$AZ2"),INDIRECT("'"&G$3&"'!"&"$C3:$AZ36")))} -> 0 | H16: {=_xlfn.XLOOKUP($B16,INDIRECT("'"&H$3&"'!"&"$A40:$A73"),_xlfn.XLOOKUP(H$5,INDIRECT("'"&H$3&"'!"&"$C2:$AZ2"),INDIRECT("'"&H$3&"'!"&"$C40:$AZ73")))} -> 3 | I16: =H16-F16 -> 3
B17: HS2033 | C17: Harris Scarfe Eastland | E17: {=_xlfn.XLOOKUP($B17,INDIRECT("'"&E$3&"'!"&"$A3:$A36"),_xlfn.XLOOKUP(E$5,INDIRECT("'"&E$3&"'!"&"$C2:$AZ2"),INDIRECT("'"&E$3&"'!"&"$C3:$AZ36")))} -> 0 | F17: {=_xlfn.XLOOKUP($B17,INDIRECT("'"&F$3&"'!"&"$A40:$A73"),_xlfn.XLOOKUP(F$5,INDIRECT("'"&F$3&"'!"&"$C2:$AZ2"),INDIRECT("'"&F$3&"'!"&"$C40:$AZ73")))} -> 3 | G17: {=_xlfn.XLOOKUP($B17,INDIRECT("'"&G$3&"'!"&"$A3:$A36"),_xlfn.XLOOKUP(G$5,INDIRECT("'"&G$3&"'!"&"$C2:$AZ2"),INDIRECT("'"&G$3&"'!"&"$C3:$AZ36")))} -> 0 | H17: {=_xlfn.XLOOKUP($B17,INDIRECT("'"&H$3&"'!"&"$A40:$A73"),_xlfn.XLOOKUP(H$5,INDIRECT("'"&H$3&"'!"&"$C2:$AZ2"),INDIRECT("'"&H$3&"'!"&"$C40:$AZ73")))} -> 0 | I17: =H17-F17 -> -3
B18: HS2023 | C18: Harris Scarfe Epping | E18: {=_xlfn.XLOOKUP($B18,INDIRECT("'"&E$3&"'!"&"$A3:$A36"),_xlfn.XLOOKUP(E$5,INDIRECT("'"&E$3&"'!"&"$C2:$AZ2"),INDIRECT("'"&E$3&"'!"&"$C3:$AZ36")))} -> 0 | F18: {=_xlfn.XLOOKUP($B18,INDIRECT("'"&F$3&"'!"&"$A40:$A73"),_xlfn.XLOOKUP(F$5,INDIRECT("'"&F$3&"'!"&"$C2:$AZ2"),INDIRECT("'"&F$3&"'!"&"$C40:$AZ73")))} -> 3 | G18: {=_xlfn.XLOOKUP($B18,INDIRECT("'"&G$3&"'!"&"$A3:$A36"),_xlfn.XLOOKUP(G$5,INDIRECT("'"&G$3&"'!"&"$C2:$AZ2"),INDIRECT("'"&G$3&"'!"&"$C3:$AZ36")))} -> 0 | H18: {=_xlfn.XLOOKUP($B18,INDIRECT("'"&H$3&"'!"&"$A40:$A73"),_xlfn.XLOOKUP(H$5,INDIRECT("'"&H$3&"'!"&"$C2:$AZ2"),INDIRECT("'"&H$3&"'!"&"$C40:$AZ73")))} -> 1 | I18: =H18-F18 -> -2
... B40: HS2017 | C40: Harris Scarfe Woodgrove | E40: {=_xlfn.XLOOKUP($B40,INDIRECT("'"&E$3&"'!"&"$A3:$A36"),_xlfn.XLOOKUP(E$5,INDIRECT("'"&E$3&"'!"&"$C2:$AZ2"),INDIRECT("'"&E$3&"'!"&"$C3:$AZ36")))} -> 0 | F40: {=_xlfn.XLOOKUP($B40,INDIRECT("'"&F$3&"'!"&"$A40:$A73"),_xlfn.XLOOKUP(F$5,INDIRECT("'"&F$3&"'!"&"$C2:$AZ2"),INDIRECT("'"&F$3&"'!"&"$C40:$AZ73")))} -> 1 | G40: {=_xlfn.XLOOKUP($B40,INDIRECT("'"&G$3&"'!"&"$A3:$A36"),_xlfn.XLOOKUP(G$5,INDIRECT("'"&G$3&"'!"&"$C2:$AZ2"),INDIRECT("'"&G$3&"'!"&"$C3:$AZ36")))} -> 0 | H40: {=_xlfn.XLOOKUP($B40,INDIRECT("'"&H$3&"'!"&"$A40:$A73"),_xlfn.XLOOKUP(H$5,INDIRECT("'"&H$3&"'!"&"$C2:$AZ2"),INDIRECT("'"&H$3&"'!"&"$C40:$AZ73")))} -> 4 | I40: =H40-F40 -> 3
B41: Grand Total | E41: =SUM(E7:E40) -> 3 | F41: =SUM(F7:F40) -> 88 | G41: =SUM(G7:G40) -> 7 | H41: =SUM(H7:H40) -> 51 | I41: =SUM(I7:I40) -> -37
B42: *Var denotes the Variance in YTD Columns

Sheet SPL SIT REPORT - APR
E2: Total Booking - Working in Store
E3: SPL FEED | F3: SPL FEED | G3: SPL FEED | H3: SPL FEED | I3: SPL FEED
E4: FY24 | G4: FY25
E5: =E6&", "&E4 -> MAY, FY24 | F5: =E6&", "&E4 -> MAY, FY24 | G5: =G6&", "&G4 -> MAY, FY25 | H5: =G6&", "&G4 -> MAY, FY25
B6: Store Name | C6: Store Description | E6: MAY | F6: YTD | G6: MAY | H6: YTD | I6: VAR
B7: S021 | C7: Spotlight Albury | E7: {=_xlfn.XLOOKUP($B7,INDIRECT("'"&E$3&"'!"&"$A3:$A44"),_xlfn.XLOOKUP(E$5,INDIRECT("'"&E$3&"'!"&"$C2:$AZ2"),INDIRECT("'"&E$3&"'!"&"$C3:$AZ44")))} -> 0 | F7: {=_xlfn.XLOOKUP($B7,INDIRECT("'"&F$3&"'!"&"$A48:$A89"),_xlfn.XLOOKUP(F$5,INDIRECT("'"&F$3&"'!"&"$C2:$AZ2"),INDIRECT("'"&F$3&"'!"&"$C48:$AZ89")))} -> 0 | G7: {=_xlfn.XLOOKUP($B7,INDIRECT("'"&G$3&"'!"&"$A3:$A44"),_xlfn.XLOOKUP(G$5,INDIRECT("'"&G$3&"'!"&"$C2:$AZ2"),INDIRECT("'"&G$3&"'!"&"$C3:$AZ44")))} -> 0 | H7: {=_xlfn.XLOOKUP($B7,INDIRECT("'"&H$3&"'!"&"$A48:$A89"),_xlfn.XLOOKUP(H$5,INDIRECT("'"&H$3&"'!"&"$C2:$AZ2"),INDIRECT("'"&H$3&"'!"&"$C48:$AZ89")))} -> 0 | I7: =H7-F7 -> 0
B8: S013 | C8: Spotlight Ballarat | E8: {=_xlfn.XLOOKUP($B8,INDIRECT("'"&E$3&"'!"&"$A3:$A44"),_xlfn.XLOOKUP(E$5,INDIRECT("'"&E$3&"'!"&"$C2:$AZ2"),INDIRECT("'"&E$3&"'!"&"$C3:$AZ44")))} -> 0 | F8: {=_xlfn.XLOOKUP($B8,INDIRECT("'"&F$3&"'!"&"$A48:$A89"),_xlfn.XLOOKUP(F$5,INDIRECT("'"&F$3&"'!"&"$C2:$AZ2"),INDIRECT("'"&F$3&"'!"&"$C48:$AZ89")))} -> 1 | G8: {=_xlfn.XLOOKUP($B8,INDIRECT("'"&G$3&"'!"&"$A3:$A44"),_xlfn.XLOOKUP(G$5,INDIRECT("'"&G$3&"'!"&"$C2:$AZ2"),INDIRECT("'"&G$3&"'!"&"$C3:$AZ44")))} -> 0 | H8: {=_xlfn.XLOOKUP($B8,INDIRECT("'"&H$3&"'!"&"$A48:$A89"),_xlfn.XLOOKUP(H$5,INDIRECT("'"&H$3&"'!"&"$C2:$AZ2"),INDIRECT("'"&H$3&"'!"&"$C48:$AZ89")))} -> 0 | I8: =H8-F8 -> -1
B9: S014 | C9: Spotlight Bayswater | E9: {=_xlfn.XLOOKUP($B9,INDIRECT("'"&E$3&"'!"&"$A3:$A44"),_xlfn.XLOOKUP(E$5,INDIRECT("'"&E$3&"'!"&"$C2:$AZ2"),INDIRECT("'"&E$3&"'!"&"$C3:$AZ44")))} -> 0 | F9: {=_xlfn.XLOOKUP($B9,INDIRECT("'"&F$3&"'!"&"$A48:$A89"),_xlfn.XLOOKUP(F$5,INDIRECT("'"&F$3&"'!"&"$C2:$AZ2"),INDIRECT("'"&F$3&"'!"&"$C48:$AZ89")))} -> 3 | G9: {=_xlfn.XLOOKUP($B9,INDIRECT("'"&G$3&"'!"&"$A3:$A44"),_xlfn.XLOOKUP(G$5,INDIRECT("'"&G$3&"'!"&"$C2:$AZ2"),INDIRECT("'"&G$3&"'!"&"$C3:$AZ44")))} -> 0 | H9: {=_xlfn.XLOOKUP($B9,INDIRECT("'"&H$3&"'!"&"$A48:$A89"),_xlfn.XLOOKUP(H$5,INDIRECT("'"&H$3&"'!"&"$C2:$AZ2"),INDIRECT("'"&H$3&"'!"&"$C48:$AZ89")))} -> 2 | I9: =H9-F9 -> -1
B10: S026 | C10: Spotlight Bendigo | E10: {=_xlfn.XLOOKUP($B10,INDIRECT("'"&E$3&"'!"&"$A3:$A44"),_xlfn.XLOOKUP(E$5,INDIRECT("'"&E$3&"'!"&"$C2:$AZ2"),INDIRECT("'"&E$3&"'!"&"$C3:$AZ44")))} -> 0 | F10: {=_xlfn.XLOOKUP($B10,INDIRECT("'"&F$3&"'!"&"$A48:$A89"),_xlfn.XLOOKUP(F$5,INDIRECT("'"&F$3&"'!"&"$C2:$AZ2"),INDIRECT("'"&F$3&"'!"&"$C48:$AZ89")))} -> 0 | G10: {=_xlfn.XLOOKUP($B10,INDIRECT("'"&G$3&"'!"&"$A3:$A44"),_xlfn.XLOOKUP(G$5,INDIRECT("'"&G$3&"'!"&"$C2:$AZ2"),INDIRECT("'"&G$3&"'!"&"$C3:$AZ44")))} -> 0 | H10: {=_xlfn.XLOOKUP($B10,INDIRECT("'"&H$3&"'!"&"$A48:$A89"),_xlfn.XLOOKUP(H$5,INDIRECT("'"&H$3&"'!"&"$C2:$AZ2"),INDIRECT("'"&H$3&"'!"&"$C48:$AZ89")))} -> 0 | I10: =H10-F10 -> 0
B11: S002 | C11: Spotlight Box Hill | E11: {=_xlfn.XLOOKUP($B11,INDIRECT("'"&E$3&"'!"&"$A3:$A44"),_xlfn.XLOOKUP(E$5,INDIRECT("'"&E$3&"'!"&"$C2:$AZ2"),INDIRECT("'"&E$3&"'!"&"$C3:$AZ44")))} -> 3 | F11: {=_xlfn.XLOOKUP($B11,INDIRECT("'"&F$3&"'!"&"$A48:$A89"),_xlfn.XLOOKUP(F$5,INDIRECT("'"&F$3&"'!"&"$C2:$AZ2"),INDIRECT("'"&F$3&"'!"&"$C48:$AZ89")))} -> 11 | G11: {=_xlfn.XLOOKUP($B11,INDIRECT("'"&G$3&"'!"&"$A3:$A44"),_xlfn.XLOOKUP(G$5,INDIRECT("'"&G$3&"'!"&"$C2:$AZ2"),INDIRECT("'"&G$3&"'!"&"$C3:$AZ44")))} -> 1 | H11: {=_xlfn.XLOOKUP($B11,INDIRECT("'"&H$3&"'!"&"$A48:$A89"),_xlfn.XLOOKUP(H$5,INDIRECT("'"&H$3&"'!"&"$C2:$AZ2"),INDIRECT("'"&H$3&"'!"&"$C48:$AZ89")))} -> 8 | I11: =H11-F11 -> -3
B12: S084 | C12: Spotlight Bunbury | E12: {=_xlfn.XLOOKUP($B12,INDIRECT("'"&E$3&"'!"&"$A3:$A44"),_xlfn.XLOOKUP(E$5,INDIRECT("'"&E$3&"'!"&"$C2:$AZ2"),INDIRECT("'"&E$3&"'!"&"$C3:$AZ44")))} -> 0 | F12: {=_xlfn.XLOOKUP($B12,INDIRECT("'"&F$3&"'!"&"$A48:$A89"),_xlfn.XLOOKUP(F$5,INDIRECT("'"&F$3&"'!"&"$C2:$AZ2"),INDIRECT("'"&F$3&"'!"&"$C48:$AZ89")))} -> 0 | G12: {=_xlfn.XLOOKUP($B12,INDIRECT("'"&G$3&"'!"&"$A3:$A44"),_xlfn.XLOOKUP(G$5,INDIRECT("'"&G$3&"'!"&"$C2:$AZ2"),INDIRECT("'"&G$3&"'!"&"$C3:$AZ44")))} -> 0 | H12: {=_xlfn.XLOOKUP($B12,INDIRECT("'"&H$3&"'!"&"$A48:$A89"),_xlfn.XLOOKUP(H$5,INDIRECT("'"&H$3&"'!"&"$C2:$AZ2"),INDIRECT("'"&H$3&"'!"&"$C48:$AZ89")))} -> 0 | I12: =H12-F12 -> 0
B13: S069 | C13: Spotlight Bundaberg | E13: {=_xlfn.XLOOKUP($B13,INDIRECT("'"&E$3&"'!"&"$A3:$A44"),_xlfn.XLOOKUP(E$5,INDIRECT("'"&E$3&"'!"&"$C2:$AZ2"),INDIRECT("'"&E$3&"'!"&"$C3:$AZ44")))} -> 0 | F13: {=_xlfn.XLOOKUP($B13,INDIRECT("'"&F$3&"'!"&"$A48:$A89"),_xlfn.XLOOKUP(F$5,INDIRECT("'"&F$3&"'!"&"$C2:$AZ2"),INDIRECT("'"&F$3&"'!"&"$C48:$AZ89")))} -> 0 | G13: {=_xlfn.XLOOKUP($B13,INDIRECT("'"&G$3&"'!"&"$A3:$A44"),_xlfn.XLOOKUP(G$5,INDIRECT("'"&G$3&"'!"&"$C2:$AZ2"),INDIRECT("'"&G$3&"'!"&"$C3:$AZ44")))} -> 0 | H13: {=_xlfn.XLOOKUP($B13,INDIRECT("'"&H$3&"'!"&"$A48:$A89"),_xlfn.XLOOKUP(H$5,INDIRECT("'"&H$3&"'!"&"$C2:$AZ2"),INDIRECT("'"&H$3&"'!"&"$C48:$AZ89")))} -> 0 | I13: =H13-F13 -> 0
B14: S098 | C14: Spotlight Burnside | E14: {=_xlfn.XLOOKUP($B14,INDIRECT("'"&E$3&"'!"&"$A3:$A44"),_xlfn.XLOOKUP(E$5,INDIRECT("'"&E$3&"'!"&"$C2:$AZ2"),INDIRECT("'"&E$3&"'!"&"$C3:$AZ44")))} -> 0 | F14: {=_xlfn.XLOOKUP($B14,INDIRECT("'"&F$3&"'!"&"$A48:$A89"),_xlfn.XLOOKUP(F$5,INDIRECT("'"&F$3&"'!"&"$C2:$AZ2"),INDIRECT("'"&F$3&"'!"&"$C48:$AZ89")))} -> 2 | G14: {=_xlfn.XLOOKUP($B14,INDIRECT("'"&G$3&"'!"&"$A3:$A44"),_xlfn.XLOOKUP(G$5,INDIRECT("'"&G$3&"'!"&"$C2:$AZ2"),INDIRECT("'"&G$3&"'!"&"$C3:$AZ44")))} -> 0 | H14: {=_xlfn.XLOOKUP($B14,INDIRECT("'"&H$3&"'!"&"$A48:$A89"),_xlfn.XLOOKUP(H$5,INDIRECT("'"&H$3&"'!"&"$C2:$AZ2"),INDIRECT("'"&H$3&"'!"&"$C48:$AZ89")))} -> 4 | I14: =H14-F14 -> 2
B15: S037 | C15: Spotlight Campbelltown | E15: {=_xlfn.XLOOKUP($B15,INDIRECT("'"&E$3&"'!"&"$A3:$A44"),_xlfn.XLOOKUP(E$5,INDIRECT("'"&E$3&"'!"&"$C2:$AZ2"),INDIRECT("'"&E$3&"'!"&"$C3:$AZ44")))} -> 0 | F15: {=_xlfn.XLOOKUP($B15,INDIRECT("'"&F$3&"'!"&"$A48:$A89"),_xlfn.XLOOKUP(F$5,INDIRECT("'"&F$3&"'!"&"$C2:$AZ2"),INDIRECT("'"&F$3&"'!"&"$C48:$AZ89")))} -> 1 | G15: {=_xlfn.XLOOKUP($B15,INDIRECT("'"&G$3&"'!"&"$A3:$A44"),_xlfn.XLOOKUP(G$5,INDIRECT("'"&G$3&"'!"&"$C2:$AZ2"),INDIRECT("'"&G$3&"'!"&"$C3:$AZ44")))} -> 0 | H15: {=_xlfn.XLOOKUP($B15,INDIRECT("'"&H$3&"'!"&"$A48:$A89"),_xlfn.XLOOKUP(H$5,INDIRECT("'"&H$3&"'!"&"$C2:$AZ2"),INDIRECT("'"&H$3&"'!"&"$C48:$AZ89")))} -> 0 | I15: =H15-F15 -> -1
B16: S088 | C16: Spotlight Castle Hill | E16: {=_xlfn.XLOOKUP($B16,INDIRECT("'"&E$3&"'!"&"$A3:$A44"),_xlfn.XLOOKUP(E$5,INDIRECT("'"&E$3&"'!"&"$C2:$AZ2"),INDIRECT("'"&E$3&"'!"&"$C3:$AZ44")))} -> 0 | F16: {=_xlfn.XLOOKUP($B16,INDIRECT("'"&F$3&"'!"&"$A48:$A89"),_xlfn.XLOOKUP(F$5,INDIRECT("'"&F$3&"'!"&"$C2:$AZ2"),INDIRECT("'"&F$3&"'!"&"$C48:$AZ89")))} -> 1 | G16: {=_xlfn.XLOOKUP($B16,INDIRECT("'"&G$3&"'!"&"$A3:$A44"),_xlfn.XLOOKUP(G$5,INDIRECT("'"&G$3&"'!"&"$C2:$AZ2"),INDIRECT("'"&G$3&"'!"&"$C3:$AZ44")))} -> 0 | H16: {=_xlfn.XLOOKUP($B16,INDIRECT("'"&H$3&"'!"&"$A48:$A89"),_xlfn.XLOOKUP(H$5,INDIRECT("'"&H$3&"'!"&"$C2:$AZ2"),INDIRECT("'"&H$3&"'!"&"$C48:$AZ89")))} -> 0 | I16: =H16-F16 -> -1
B17: S074 | C17: Spotlight Clovercrest | E17: {=_xlfn.XLOOKUP($B17,INDIRECT("'"&E$3&"'!"&"$A3:$A44"),_xlfn.XLOOKUP(E$5,INDIRECT("'"&E$3&"'!"&"$C2:$AZ2"),INDIRECT("'"&E$3&"'!"&"$C3:$AZ44")))} -> 0 | F17: {=_xlfn.XLOOKUP($B17,INDIRECT("'"&F$3&"'!"&"$A48:$A89"),_xlfn.XLOOKUP(F$5,INDIRECT("'"&F$3&"'!"&"$C2:$AZ2"),INDIRECT("'"&F$3&"'!"&"$C48:$AZ89")))} -> 1 | G17: {=_xlfn.XLOOKUP($B17,INDIRECT("'"&G$3&"'!"&"$A3:$A44"),_xlfn.XLOOKUP(G$5,INDIRECT("'"&G$3&"'!"&"$C2:$AZ2"),INDIRECT("'"&G$3&"'!"&"$C3:$AZ44")))} -> 0 | H17: {=_xlfn.XLOOKUP($B17,INDIRECT("'"&H$3&"'!"&"$A48:$A89"),_xlfn.XLOOKUP(H$5,INDIRECT("'"&H$3&"'!"&"$C2:$AZ2"),INDIRECT("'"&H$3&"'!"&"$C48:$AZ89")))} -> 1 | I17: =H17-F17 -> 0
B18: S135 | C18: Spotlight Cranbourne | E18: {=_xlfn.XLOOKUP($B18,INDIRECT("'"&E$3&"'!"&"$A3:$A44"),_xlfn.XLOOKUP(E$5,INDIRECT("'"&E$3&"'!"&"$C2:$AZ2"),INDIRECT("'"&E$3&"'!"&"$C3:$AZ44")))} -> 0 | F18: {=_xlfn.XLOOKUP($B18,INDIRECT("'"&F$3&"'!"&"$A48:$A89"),_xlfn.XLOOKUP(F$5,INDIRECT("'"&F$3&"'!"&"$C2:$AZ2"),INDIRECT("'"&F$3&"'!"&"$C48:$AZ89")))} -> 0 | G18: {=_xlfn.XLOOKUP($B18,INDIRECT("'"&G$3&"'!"&"$A3:$A44"),_xlfn.XLOOKUP(G$5,INDIRECT("'"&G$3&"'!"&"$C2:$AZ2"),INDIRECT("'"&G$3&"'!"&"$C3:$AZ44")))} -> 0 | H18: {=_xlfn.XLOOKUP($B18,INDIRECT("'"&H$3&"'!"&"$A48:$A89"),_xlfn.XLOOKUP(H$5,INDIRECT("'"&H$3&"'!"&"$C2:$AZ2"),INDIRECT("'"&H$3&"'!"&"$C48:$AZ89")))} -> 1 | I18: =H18-F18 -> 1
... B48: S079 | C48: Spotlight West Burleigh | E48: {=_xlfn.XLOOKUP($B48,INDIRECT("'"&E$3&"'!"&"$A3:$A44"),_xlfn.XLOOKUP(E$5,INDIRECT("'"&E$3&"'!"&"$C2:$AZ2"),INDIRECT("'"&E$3&"'!"&"$C3:$AZ44")))} -> 0 | F48: {=_xlfn.XLOOKUP($B48,INDIRECT("'"&F$3&"'!"&"$A48:$A89"),_xlfn.XLOOKUP(F$5,INDIRECT("'"&F$3&"'!"&"$C2:$AZ2"),INDIRECT("'"&F$3&"'!"&"$C48:$AZ89")))} -> 0 | G48: {=_xlfn.XLOOKUP($B48,INDIRECT("'"&G$3&"'!"&"$A3:$A44"),_xlfn.XLOOKUP(G$5,INDIRECT("'"&G$3&"'!"&"$C2:$AZ2"),INDIRECT("'"&G$3&"'!"&"$C3:$AZ44")))} -> 0 | H48: {=_xlfn.XLOOKUP($B48,INDIRECT("'"&H$3&"'!"&"$A48:$A89"),_xlfn.XLOOKUP(H$5,INDIRECT("'"&H$3&"'!"&"$C2:$AZ2"),INDIRECT("'"&H$3&"'!"&"$C48:$AZ89")))} -> 0 | I48: =H48-F48 -> 0
B49: Grand Total | E49: =SUM(E7:E48) -> 10 | F49: =SUM(F7:F48) -> 77 | G49: =SUM(G7:G48) -> 10 | H49: =SUM(H7:H48) -> 58 | I49: =SUM(I7:I48) -> -19
B50: *Var denotes the Variance in YTD Columns

Sheet Pivot Results 1
G1: Fiscal Month | H1: (Multiple Items)
G3: Count of Brand | H3: Column Labels
G4: Row Labels | H4: Booked | I4: Complete | J4: In progress | K4: Grand Total
G5: Ananconda | H5: 13 | I5: 76 | K5: 89
G6: Harris Scarfe | H6: 7 | I6: 47 | K6: 54
G7: Spotlight | H7: 16 | I7: 53 | J7: 1 | K7: 70
G8: Grand Total | H8: 36 | I8: 176 | J8: 1 | K8: 213
A10: Fiscal Month | B10: MAY, FY25 | G10: Fiscal Month | H10: MAY, FY25 | N10: Fiscal Month | O10: MAY, FY25
A12: Count of Brand | B12: Column Labels | G12: Count of Brand | H12: Column Labels | N12: Count of Brand | O12: Column Labels
A13: Row Labels | B13: Booked | C13: Complete | D13: Grand Total | G13: Row Labels | H13: Booked | I13: Complete | J13: Grand Total | N13: Row Labels | O13: Booked | P13: Complete | Q13: Grand Total
A14: Anaconda Ballarat | B14: 1 | D14: 1 | G14: Harris Scarfe Airport West | H14: 1 | J14: 1 | N14: Spotlight Box Hill | O14: 1 | Q14: 1
A15: Anaconda Bayswater | B15: 1 | D15: 1 | G15: Harris Scarfe Highpoint | I15: 1 | J15: 1 | N15: Spotlight Cranegie | P15: 2 | Q15: 2
A16: Anaconda Box Hill | B16: 1 | D16: 1 | G16: Harris Scarfe Spencer Outlet | I16: 4 | J16: 4 | N16: Spotlight Essendon | P16: 1 | Q16: 1
A17: Anaconda Hawthorn East | C17: 1 | D17: 1 | G17: Harris Scarfe Sunbury | I17: 1 | J17: 1 | N17: Spotlight Hoppers Crossing | P17: 1 | Q17: 1
A18: Anaconda Highett | C18: 2 | D18: 2 | G18: Grand Total | H18: 1 | I18: 6 | J18: 7 | N18: Spotlight South Melbourne | O18: 1 | P18: 4 | Q18: 5
A19: Anaconda Preston | C19: 1 | D19: 1 | N19: Grand Total | O19: 2 | P19: 8 | Q19: 10
A20: Anaconda Springvale | B20: 2 | D20: 2
A21: Grand Total | B21: 5 | C21: 4 | D21: 9

Sheet Pivot Results 2
A1: Fiscal Month | B1: (Multiple Items)
A3: Count of Employee number | B3: Column Labels
A4: Row Labels | B4: Booked | C4: Complete | D4: In progress | E4: Grand Total
A5: ANALYTICS & INSIGHTS | C5: 1 | E5: 1
A6: eCommerce Management | B6: 8 | C6: 19 | E6: 27
A7: HR MANAGEMENT | B7: 10 | C7: 25 | D7: 1 | E7: 36
A8: IT | B8: 2 | C8: 35 | E8: 37
A9: Marketing | B9: 9 | C9: 26 | E9: 35
A10: Property | B10: 1 | C10: 8 | E10: 9
A11: SS Finance | B11: 4 | C11: 29 | E11: 33
A12: Supply Chain | C12: 5 | E12: 5
A13: Grand Total | B13: 34 | C13: 148 | D13: 1 | E13: 183

Sheet Monthly Graphs

Sheet ANA FEED
C1: FY24 | T1: FY25
A2: Store Name | B2: Store Description | C2: ="JUL, "&C1 -> JUL, FY24 | D2: ="AUG, "&C1 -> AUG, FY24 | E2: ="SEP, "&C1 -> SEP, FY24 | F2: ="Q1, "&C1 -> Q1, FY24 | G2: ="OCT, "&C1 -> OCT, FY24 | H2: ="NOV, "&C1 -> NOV, FY24 | I2: ="DEC, "&C1 -> DEC, FY24 | J2: ="Q2, "&C1 -> Q2, FY24 | K2: ="JAN, "&C1 -> JAN, FY24 | L2: ="FEB, "&C1 -> FEB, FY24 | M2: ="MAR, "&C1 -> MAR, FY24 | N2: ="Q3, "&C1 -> Q3, FY24 | O2: ="APR, "&C1 -> APR, FY24 | P2: ="MAY, "&C1 -> MAY, FY24 | Q2: ="JUN, "&C1 -> JUN, FY24 | R2: ="Q4, "&C1 -> Q4, FY24 | S2: ="Full Year, "&C1 -> Full Year, FY24 | T2: ="JUL, "&T1 -> JUL, FY25 | U2: ="AUG, "&T1 -> AUG, FY25 | V2: ="SEP, "&T1 -> SEP, FY25 | W2: ="Q1, "&T1 -> Q1, FY25 | X2: ="OCT, "&T1 -> OCT, FY25 | Y2: ="NOV, "&T1 -> NOV, FY25 | Z2: ="DEC, "&T1 -> DEC, FY25 | AA2: ="Q2, "&T1 -> Q2, FY25 | AB2: ="JAN, "&T1 -> JAN, FY25 | AC2: ="FEB, "&T1 -> FEB, FY25 | AD2: ="MAR, "&T1 -> MAR, FY25 | AE2: ="Q3, "&T1 -> Q3, FY25 | AF2: ="APR, "&T1 -> APR, FY25 | AG2: ="MAY, "&T1 -> MAY, FY25 | AH2: ="JUN, "&T1 -> JUN, FY25 | AI2: ="Q4, "&T1 -> Q4, FY25 | AJ2: ="Full Year, "&T1 -> Full Year, FY25
A3: A050 | B3: Anaconda Albury | C3: =COUNTIFS('Data Dump'!$P:$P,'ANA FEED'!$A3,'Data Dump'!$S:$S,'ANA FEED'!C$2) -> 1 | D3: =COUNTIFS('Data Dump'!$P:$P,'ANA FEED'!$A3,'Data Dump'!$S:$S,'ANA FEED'!D$2) -> 0 | E3: =COUNTIFS('Data Dump'!$P:$P,'ANA FEED'!$A3,'Data Dump'!$S:$S,'ANA FEED'!E$2) -> 0 | F3: =SUBTOTAL(9,C3:E3) -> 1 | G3: =COUNTIFS('Data Dump'!$P:$P,'ANA FEED'!$A3,'Data Dump'!$S:$S,'ANA FEED'!G$2) -> 0 | H3: =COUNTIFS('Data Dump'!$P:$P,'ANA FEED'!$A3,'Data Dump'!$S:$S,'ANA FEED'!H$2) -> 0 | I3: =COUNTIFS('Data Dump'!$P:$P,'ANA FEED'!$A3,'Data Dump'!$S:$S,'ANA FEED'!I$2) -> 1 | J3: =SUBTOTAL(9,G3:I3) -> 1 | K3: =COUNTIFS('Data Dump'!$P:$P,'ANA FEED'!$A3,'Data Dump'!$S:$S,'ANA FEED'!K$2) -> 0 | L3: =COUNTIFS('Data Dump'!$P:$P,'ANA FEED'!$A3,'Data Dump'!$S:$S,'ANA FEED'!L$2) -> 0 | M3: =COUNTIFS('Data Dump'!$P:$P,'ANA FEED'!$A3,'Data Dump'!$S:$S,'ANA FEED'!M$2) -> 0 | N3: =SUBTOTAL(9,K3:M3) -> 0 | O3: =COUNTIFS('Data Dump'!$P:$P,'ANA FEED'!$A3,'Data Dump'!$S:$S,'ANA FEED'!O$2) -> 0 | P3: =COUNTIFS('Data Dump'!$P:$P,'ANA FEED'!$A3,'Data Dump'!$S:$S,'ANA FEED'!P$2) -> 0 | Q3: =COUNTIFS('Data Dump'!$P:$P,'ANA FEED'!$A3,'Data Dump'!$S:$S,'ANA FEED'!Q$2) -> 0 | R3: =SUBTOTAL(9,O3:Q3) -> 0 | S3: =SUBTOTAL(9,C3:R3) -> 2 | T3: =COUNTIFS('Data Dump'!$P:$P,'ANA FEED'!$A3,'Data Dump'!$S:$S,'ANA FEED'!T$2) -> 0 | U3: =COUNTIFS('Data Dump'!$P:$P,'ANA FEED'!$A3,'Data Dump'!$S:$S,'ANA FEED'!U$2) -> 0 | V3: =COUNTIFS('Data Dump'!$P:$P,'ANA FEED'!$A3,'Data Dump'!$S:$S,'ANA FEED'!V$2) -> 0 | W3: =SUBTOTAL(9,T3:V3) -> 0 | X3: =COUNTIFS('Data Dump'!$P:$P,'ANA FEED'!$A3,'Data Dump'!$S:$S,'ANA FEED'!X$2) -> 0 | Y3: =COUNTIFS('Data Dump'!$P:$P,'ANA FEED'!$A3,'Data Dump'!$S:$S,'ANA FEED'!Y$2) -> 0 | Z3: =COUNTIFS('Data Dump'!$P:$P,'ANA FEED'!$A3,'Data Dump'!$S:$S,'ANA FEED'!Z$2) -> 1 | AA3: =SUBTOTAL(9,X3:Z3) -> 1 | AB3: =COUNTIFS('Data Dump'!$P:$P,'ANA FEED'!$A3,'Data Dump'!$S:$S,'ANA FEED'!AB$2) -> 0 | AC3: =COUNTIFS('Data Dump'!$P:$P,'ANA FEED'!$A3,'Data Dump'!$S:$S,'ANA FEED'!AC$2) -> 0 | AD3: =COUNTIFS('Data Dump'!$P:$P,'ANA FEED'!$A3,'Data Dump'!$S:$S,'ANA FEED'!AD$2) -> 0 | AE3: =SUBTOTAL(9,AB3:AD3) -> 0 | AF3: =COUNTIFS('Data Dump'!$P:$P,'ANA FEED'!$A3,'Data Dump'!$S:$S,'ANA FEED'!AF$2) -> 0 | AG3: =COUNTIFS('Data Dump'!$P:$P,'ANA FEED'!$A3,'Data Dump'!$S:$S,'ANA FEED'!AG$2) -> 0 | AH3: =COUNTIFS('Data Dump'!$P:$P,'ANA FEED'!$A3,'Data Dump'!$S:$S,'ANA FEED'!AH$2) -> 0 | AI3: =SUBTOTAL(9,AF3:AH3) -> 0 | AJ3: =SUBTOTAL(9,T3:AI3) -> 1
A4: A002 | B4: Anaconda Ashmore | C4: =COUNTIFS('Data Dump'!$P:$P,'ANA FEED'!$A4,'Data Dump'!$S:$S,'ANA FEED'!C$2) -> 0 | D4: =COUNTIFS('Data Dump'!$P:$P,'ANA FEED'!$A4,'Data Dump'!$S:$S,'ANA FEED'!D$2) -> 0 | E4: =COUNTIFS('Data Dump'!$P:$P,'ANA FEED'!$A4,'Data Dump'!$S:$S,'ANA FEED'!E$2) -> 0 | F4: =SUBTOTAL(9,C4:E4) -> 0 | G4: =COUNTIFS('Data Dump'!$P:$P,'ANA FEED'!$A4,'Data Dump'!$S:$S,'ANA FEED'!G$2) -> 0 | H4: =COUNTIFS('Data Dump'!$P:$P,'ANA FEED'!$A4,'Data Dump'!$S:$S,'ANA FEED'!H$2) -> 0 | I4: =COUNTIFS('Data Dump'!$P:$P,'ANA FEED'!$A4,'Data Dump'!$S:$S,'ANA FEED'!I$2) -> 0 | J4: =SUBTOTAL(9,G4:I4) -> 0 | K4: =COUNTIFS('Data Dump'!$P:$P,'ANA FEED'!$A4,'Data Dump'!$S:$S,'ANA FEED'!K$2) -> 0 | L4: =COUNTIFS('Data Dump'!$P:$P,'ANA FEED'!$A4,'Data Dump'!$S:$S,'ANA FEED'!L$2) -> 0 | M4: =COUNTIFS('Data Dump'!$P:$P,'ANA FEED'!$A4,'Data Dump'!$S:$S,'ANA FEED'!M$2) -> 0 | N4: =SUBTOTAL(9,K4:M4) -> 0 | O4: =COUNTIFS('Data Dump'!$P:$P,'ANA FEED'!$A4,'Data Dump'!$S:$S,'ANA FEED'!O$2) -> 0 | P4: =COUNTIFS('Data Dump'!$P:$P,'ANA FEED'!$A4,'Data Dump'!$S:$S,'ANA FEED'!P$2) -> 0 | Q4: =COUNTIFS('Data Dump'!$P:$P,'ANA FEED'!$A4,'Data Dump'!$S:$S,'ANA FEED'!Q$2) -> 0 | R4: =SUBTOTAL(9,O4:Q4) -> 0 | S4: =SUBTOTAL(9,C4:R4) -> 0 | T4: =COUNTIFS('Data Dump'!$P:$P,'ANA FEED'!$A4,'Data Dump'!$S:$S,'ANA FEED'!T$2) -> 0 | U4: =COUNTIFS('Data Dump'!$P:$P,'ANA FEED'!$A4,'Data Dump'!$S:$S,'ANA FEED'!U$2) -> 0 | V4: =COUNTIFS('Data Dump'!$P:$P,'ANA FEED'!$A4,'Data Dump'!$S:$S,'ANA FEED'!V$2) -> 0 | W4: =SUBTOTAL(9,T4:V4) -> 0 | X4: =COUNTIFS('Data Dump'!$P:$P,'ANA FEED'!$A4,'Data Dump'!$S:$S,'ANA FEED'!X$2) -> 0 | Y4: =COUNTIFS('Data Dump'!$P:$P,'ANA FEED'!$A4,'Data Dump'!$S:$S,'ANA FEED'!Y$2) -> 0 | Z4: =COUNTIFS('Data Dump'!$P:$P,'ANA FEED'!$A4,'Data Dump'!$S:$S,'ANA FEED'!Z$2) -> 0 | AA4: =SUBTOTAL(9,X4:Z4) -> 0 | AB4: =COUNTIFS('Data Dump'!$P:$P,'ANA FEED'!$A4,'Data Dump'!$S:$S,'ANA FEED'!AB$2) -> 0 | AC4: =COUNTIFS('Data Dump'!$P:$P,'ANA FEED'!$A4,'Data Dump'!$S:$S,'ANA FEED'!AC$2) -> 0 | AD4: =COUNTIFS('Data Dump'!$P:$P,'ANA FEED'!$A4,'Data Dump'!$S:$S,'ANA FEED'!AD$2) -> 0 | AE4: =SUBTOTAL(9,AB4:AD4) -> 0 | AF4: =COUNTIFS('Data Dump'!$P:$P,'ANA FEED'!$A4,'Data Dump'!$S:$S,'ANA FEED'!AF$2) -> 0 | AG4: =COUNTIFS('Data Dump'!$P:$P,'ANA FEED'!$A4,'Data Dump'!$S:$S,'ANA FEED'!AG$2) -> 0 | AH4: =COUNTIFS('Data Dump'!$P:$P,'ANA FEED'!$A4,'Data Dump'!$S:$S,'ANA FEED'!AH$2) -> 0 | AI4: =SUBTOTAL(9,AF4:AH4) -> 0 | AJ4: =SUBTOTAL(9,T4:AI4) -> 0
A5: A035 | B5: Anaconda Ballarat | C5: =COUNTIFS('Data Dump'!$P:$P,'ANA FEED'!$A5,'Data Dump'!$S:$S,'ANA FEED'!C$2) -> 0 | D5: =COUNTIFS('Data Dump'!$P:$P,'ANA FEED'!$A5,'Data Dump'!$S:$S,'ANA FEED'!D$2) -> 0 | E5: =COUNTIFS('Data Dump'!$P:$P,'ANA FEED'!$A5,'Data Dump'!$S:$S,'ANA FEED'!E$2) -> 0 | F5: =SUBTOTAL(9,C5:E5) -> 0 | G5: =COUNTIFS('Data Dump'!$P:$P,'ANA FEED'!$A5,'Data Dump'!$S:$S,'ANA FEED'!G$2) -> 0 | H5: =COUNTIFS('Data Dump'!$P:$P,'ANA FEED'!$A5,'Data Dump'!$S:$S,'ANA FEED'!H$2) -> 0 | I5: =COUNTIFS('Data Dump'!$P:$P,'ANA FEED'!$A5,'Data Dump'!$S:$S,'ANA FEED'!I$2) -> 0 | J5: =SUBTOTAL(9,G5:I5) -> 0 | K5: =COUNTIFS('Data Dump'!$P:$P,'ANA FEED'!$A5,'Data Dump'!$S:$S,'ANA FEED'!K$2) -> 0 | L5: =COUNTIFS('Data Dump'!$P:$P,'ANA FEED'!$A5,'Data Dump'!$S:$S,'ANA FEED'!L$2) -> 0 | M5: =COUNTIFS('Data Dump'!$P:$P,'ANA FEED'!$A5,'Data Dump'!$S:$S,'ANA FEED'!M$2) -> 0 | N5: =SUBTOTAL(9,K5:M5) -> 0 | O5: =COUNTIFS('Data Dump'!$P:$P,'ANA FEED'!$A5,'Data Dump'!$S:$S,'ANA FEED'!O$2) -> 0 | P5: =COUNTIFS('Data Dump'!$P:$P,'ANA FEED'!$A5,'Data Dump'!$S:$S,'ANA FEED'!P$2) -> 0 | Q5: =COUNTIFS('Data Dump'!$P:$P,'ANA FEED'!$A5,'Data Dump'!$S:$S,'ANA FEED'!Q$2) -> 0 | R5: =SUBTOTAL(9,O5:Q5) -> 0 | S5: =SUBTOTAL(9,C5:R5) -> 0 | T5: =COUNTIFS('Data Dump'!$P:$P,'ANA FEED'!$A5,'Data Dump'!$S:$S,'ANA FEED'!T$2) -> 0 | U5: =COUNTIFS('Data Dump'!$P:$P,'ANA FEED'!$A5,'Data Dump'!$S:$S,'ANA FEED'!U$2) -> 0 | V5: =COUNTIFS('Data Dump'!$P:$P,'ANA FEED'!$A5,'Data Dump'!$S:$S,'ANA FEED'!V$2) -> 0 | W5: =SUBTOTAL(9,T5:V5) -> 0 | X5: =COUNTIFS('Data Dump'!$P:$P,'ANA FEED'!$A5,'Data Dump'!$S:$S,'ANA FEED'!X$2) -> 0 | Y5: =COUNTIFS('Data Dump'!$P:$P,'ANA FEED'!$A5,'Data Dump'!$S:$S,'ANA FEED'!Y$2) -> 0 | Z5: =COUNTIFS('Data Dump'!$P:$P,'ANA FEED'!$A5,'Data Dump'!$S:$S,'ANA FEED'!Z$2) -> 0 | AA5: =SUBTOTAL(9,X5:Z5) -> 0 | AB5: =COUNTIFS('Data Dump'!$P:$P,'ANA FEED'!$A5,'Data Dump'!$S:$S,'ANA FEED'!AB$2) -> 0 | AC5: =COUNTIFS('Data Dump'!$P:$P,'ANA FEED'!$A5,'Data Dump'!$S:$S,'ANA FEED'!AC$2) -> 0 | AD5: =COUNTIFS('Data Dump'!$P:$P,'ANA FEED'!$A5,'Data Dump'!$S:$S,'ANA FEED'!AD$2) -> 0 | AE5: =SUBTOTAL(9,AB5:AD5) -> 0 | AF5: =COUNTIFS('Data Dump'!$P:$P,'ANA FEED'!$A5,'Data Dump'!$S:$S,'ANA FEED'!AF$2) -> 1 | AG5: =COUNTIFS('Data Dump'!$P:$P,'ANA FEED'!$A5,'Data Dump'!$S:$S,'ANA FEED'!AG$2) -> 1 | AH5: =COUNTIFS('Data Dump'!$P:$P,'ANA FEED'!$A5,'Data Dump'!$S:$S,'ANA FEED'!AH$2) -> 0 | AI5: =SUBTOTAL(9,AF5:AH5) -> 2 | AJ5: =SUBTOTAL(9,T5:AI5) -> 2
A6: A001 | B6: Anaconda Bayswater | C6: =COUNTIFS('Data Dump'!$P:$P,'ANA FEED'!$A6,'Data Dump'!$S:$S,'ANA FEED'!C$2) -> 0 | D6: =COUNTIFS('Data Dump'!$P:$P,'ANA FEED'!$A6,'Data Dump'!$S:$S,'ANA FEED'!D$2) -> 0 | E6: =COUNTIFS('Data Dump'!$P:$P,'ANA FEED'!$A6,'Data Dump'!$S:$S,'ANA FEED'!E$2) -> 0 | F6: =SUBTOTAL(9,C6:E6) -> 0 | G6: =COUNTIFS('Data Dump'!$P:$P,'ANA FEED'!$A6,'Data Dump'!$S:$S,'ANA FEED'!G$2) -> 0 | H6: =COUNTIFS('Data Dump'!$P:$P,'ANA FEED'!$A6,'Data Dump'!$S:$S,'ANA FEED'!H$2) -> 0 | I6: =COUNTIFS('Data Dump'!$P:$P,'ANA FEED'!$A6,'Data Dump'!$S:$S,'ANA FEED'!I$2) -> 4 | J6: =SUBTOTAL(9,G6:I6) -> 4 | K6: =COUNTIFS('Data Dump'!$P:$P,'ANA FEED'!$A6,'Data Dump'!$S:$S,'ANA FEED'!K$2) -> 0 | L6: =COUNTIFS('Data Dump'!$P:$P,'ANA FEED'!$A6,'Data Dump'!$S:$S,'ANA FEED'!L$2) -> 0 | M6: =COUNTIFS('Data Dump'!$P:$P,'ANA FEED'!$A6,'Data Dump'!$S:$S,'ANA FEED'!M$2) -> 1 | N6: =SUBTOTAL(9,K6:M6) -> 1 | O6: =COUNTIFS('Data Dump'!$P:$P,'ANA FEED'!$A6,'Data Dump'!$S:$S,'ANA FEED'!O$2) -> 0 | P6: =COUNTIFS('Data Dump'!$P:$P,'ANA FEED'!$A6,'Data Dump'!$S:$S,'ANA FEED'!P$2) -> 0 | Q6: =COUNTIFS('Data Dump'!$P:$P,'ANA FEED'!$A6,'Data Dump'!$S:$S,'ANA FEED'!Q$2) -> 0 | R6: =SUBTOTAL(9,O6:Q6) -> 0 | S6: =SUBTOTAL(9,C6:R6) -> 5 | T6: =COUNTIFS('Data Dump'!$P:$P,'ANA FEED'!$A6,'Data Dump'!$S:$S,'ANA FEED'!T$2) -> 1 | U6: =COUNTIFS('Data Dump'!$P:$P,'ANA FEED'!$A6,'Data Dump'!$S:$S,'ANA FEED'!U$2) -> 0 | V6: =COUNTIFS('Data Dump'!$P:$P,'ANA FEED'!$A6,'Data Dump'!$S:$S,'ANA FEED'!V$2) -> 0 | W6: =SUBTOTAL(9,T6:V6) -> 1 | X6: =COUNTIFS('Data Dump'!$P:$P,'ANA FEED'!$A6,'Data Dump'!$S:$S,'ANA FEED'!X$2) -> 0 | Y6: =COUNTIFS('Data Dump'!$P:$P,'ANA FEED'!$A6,'Data Dump'!$S:$S,'ANA FEED'!Y$2) -> 2 | Z6: =COUNTIFS('Data Dump'!$P:$P,'ANA FEED'!$A6,'Data Dump'!$S:$S,'ANA FEED'!Z$2) -> 1 | AA6: =SUBTOTAL(9,X6:Z6) -> 3 | AB6: =COUNTIFS('Data Dump'!$P:$P,'ANA FEED'!$A6,'Data Dump'!$S:$S,'ANA FEED'!AB$2) -> 0 | AC6: =COUNTIFS('Data Dump'!$P:$P,'ANA FEED'!$A6,'Data Dump'!$S:$S,'ANA FEED'!AC$2) -> 0 | AD6: =COUNTIFS('Data Dump'!$P:$P,'ANA FEED'!$A6,'Data Dump'!$S:$S,'ANA FEED'!AD$2) -> 0 | AE6: =SUBTOTAL(9,AB6:AD6) -> 0 | AF6: =COUNTIFS('Data Dump'!$P:$P,'ANA FEED'!$A6,'Data Dump'!$S:$S,'ANA FEED'!AF$2) -> 0 | AG6: =COUNTIFS('Data Dump'!$P:$P,'ANA FEED'!$A6,'Data Dump'!$S:$S,'ANA FEED'!AG$2) -> 1 | AH6: =COUNTIFS('Data Dump'!$P:$P,'ANA FEED'!$A6,'Data Dump'!$S:$S,'ANA FEED'!AH$2) -> 0 | AI6: =SUBTOTAL(9,AF6:AH6) -> 1 | AJ6: =SUBTOTAL(9,T6:AI6) -> 5
A7: A021 | B7: Anaconda Bendigo | C7: =COUNTIFS('Data Dump'!$P:$P,'ANA FEED'!$A7,'Data Dump'!$S:$S,'ANA FEED'!C$2) -> 0 | D7: =COUNTIFS('Data Dump'!$P:$P,'ANA FEED'!$A7,'Data Dump'!$S:$S,'ANA FEED'!D$2) -> 0 | E7: =COUNTIFS('Data Dump'!$P:$P,'ANA FEED'!$A7,'Data Dump'!$S:$S,'ANA FEED'!E$2) -> 0 | F7: =SUBTOTAL(9,C7:E7) -> 0 | G7: =COUNTIFS('Data Dump'!$P:$P,'ANA FEED'!$A7,'Data Dump'!$S:$S,'ANA FEED'!G$2) -> 0 | H7: =COUNTIFS('Data Dump'!$P:$P,'ANA FEED'!$A7,'Data Dump'!$S:$S,'ANA FEED'!H$2) -> 0 | I7: =COUNTIFS('Data Dump'!$P:$P,'ANA FEED'!$A7,'Data Dump'!$S:$S,'ANA FEED'!I$2) -> 0 | J7: =SUBTOTAL(9,G7:I7) -> 0 | K7: =COUNTIFS('Data Dump'!$P:$P,'ANA FEED'!$A7,'Data Dump'!$S:$S,'ANA FEED'!K$2) -> 0 | L7: =COUNTIFS('Data Dump'!$P:$P,'ANA FEED'!$A7,'Data Dump'!$S:$S,'ANA FEED'!L$2) -> 0 | M7: =COUNTIFS('Data Dump'!$P:$P,'ANA FEED'!$A7,'Data Dump'!$S:$S,'ANA FEED'!M$2) -> 0 | N7: =SUBTOTAL(9,K7:M7) -> 0 | O7: =COUNTIFS('Data Dump'!$P:$P,'ANA FEED'!$A7,'Data Dump'!$S:$S,'ANA FEED'!O$2) -> 0 | P7: =COUNTIFS('Data Dump'!$P:$P,'ANA FEED'!$A7,'Data Dump'!$S:$S,'ANA FEED'!P$2) -> 0 | Q7: =COUNTIFS('Data Dump'!$P:$P,'ANA FEED'!$A7,'Data Dump'!$S:$S,'ANA FEED'!Q$2) -> 0 | R7: =SUBTOTAL(9,O7:Q7) -> 0 | S7: =SUBTOTAL(9,C7:R7) -> 0 | T7: =COUNTIFS('Data Dump'!$P:$P,'ANA FEED'!$A7,'Data Dump'!$S:$S,'ANA FEED'!T$2) -> 0 | U7: =COUNTIFS('Data Dump'!$P:$P,'ANA FEED'!$A7,'Data Dump'!$S:$S,'ANA FEED'!U$2) -> 0 | V7: =COUNTIFS('Data Dump'!$P:$P,'ANA FEED'!$A7,'Data Dump'!$S:$S,'ANA FEED'!V$2) -> 0 | W7: =SUBTOTAL(9,T7:V7) -> 0 | X7: =COUNTIFS('Data Dump'!$P:$P,'ANA FEED'!$A7,'Data Dump'!$S:$S,'ANA FEED'!X$2) -> 0 | Y7: =COUNTIFS('Data Dump'!$P:$P,'ANA FEED'!$A7,'Data Dump'!$S:$S,'ANA FEED'!Y$2) -> 0 | Z7: =COUNTIFS('Data Dump'!$P:$P,'ANA FEED'!$A7,'Data Dump'!$S:$S,'ANA FEED'!Z$2) -> 1 | AA7: =SUBTOTAL(9,X7:Z7) -> 1 | AB7: =COUNTIFS('Data Dump'!$P:$P,'ANA FEED'!$A7,'Data Dump'!$S:$S,'ANA FEED'!AB$2) -> 0 | AC7: =COUNTIFS('Data Dump'!$P:$P,'ANA FEED'!$A7,'Data Dump'!$S:$S,'ANA FEED'!AC$2) -> 1 | AD7: =COUNTIFS('Data Dump'!$P:$P,'ANA FEED'!$A7,'Data Dump'!$S:$S,'ANA FEED'!AD$2) -> 0 | AE7: =SUBTOTAL(9,AB7:AD7) -> 1 | AF7: =COUNTIFS('Data Dump'!$P:$P,'ANA FEED'!$A7,'Data Dump'!$S:$S,'ANA FEED'!AF$2) -> 0 | AG7: =COUNTIFS('Data Dump'!$P:$P,'ANA FEED'!$A7,'Data Dump'!$S:$S,'ANA FEED'!AG$2) -> 0 | AH7: =COUNTIFS('Data Dump'!$P:$P,'ANA FEED'!$A7,'Data Dump'!$S:$S,'ANA FEED'!AH$2) -> 0 | AI7: =SUBTOTAL(9,AF7:AH7) -> 0 | AJ7: =SUBTOTAL(9,T7:AI7) -> 2
A8: A041 | B8: Anaconda Box Hill | C8: =COUNTIFS('Data Dump'!$P:$P,'ANA FEED'!$A8,'Data Dump'!$S:$S,'ANA FEED'!C$2) -> 0 | D8: =COUNTIFS('Data Dump'!$P:$P,'ANA FEED'!$A8,'Data Dump'!$S:$S,'ANA FEED'!D$2) -> 0 | E8: =COUNTIFS('Data Dump'!$P:$P,'ANA FEED'!$A8,'Data Dump'!$S:$S,'ANA FEED'!E$2) -> 0 | F8: =SUBTOTAL(9,C8:E8) -> 0 | G8: =COUNTIFS('Data Dump'!$P:$P,'ANA FEED'!$A8,'Data Dump'!$S:$S,'ANA FEED'!G$2) -> 1 | H8: =COUNTIFS('Data Dump'!$P:$P,'ANA FEED'!$A8,'Data Dump'!$S:$S,'ANA FEED'!H$2) -> 1 | I8: =COUNTIFS('Data Dump'!$P:$P,'ANA FEED'!$A8,'Data Dump'!$S:$S,'ANA FEED'!I$2) -> 0 | J8: =SUBTOTAL(9,G8:I8) -> 2 | K8: =COUNTIFS('Data Dump'!$P:$P,'ANA FEED'!$A8,'Data Dump'!$S:$S,'ANA FEED'!K$2) -> 0 | L8: =COUNTIFS('Data Dump'!$P:$P,'ANA FEED'!$A8,'Data Dump'!$S:$S,'ANA FEED'!L$2) -> 0 | M8: =COUNTIFS('Data Dump'!$P:$P,'ANA FEED'!$A8,'Data Dump'!$S:$S,'ANA FEED'!M$2) -> 0 | N8: =SUBTOTAL(9,K8:M8) -> 0 | O8: =COUNTIFS('Data Dump'!$P:$P,'ANA FEED'!$A8,'Data Dump'!$S:$S,'ANA FEED'!O$2) -> 0 | P8: =COUNTIFS('Data Dump'!$P:$P,'ANA FEED'!$A8,'Data Dump'!$S:$S,'ANA FEED'!P$2) -> 0 | Q8: =COUNTIFS('Data Dump'!$P:$P,'ANA FEED'!$A8,'Data Dump'!$S:$S,'ANA FEED'!Q$2) -> 0 | R8: =SUBTOTAL(9,O8:Q8) -> 0 | S8: =SUBTOTAL(9,C8:R8) -> 2 | T8: =COUNTIFS('Data Dump'!$P:$P,'ANA FEED'!$A8,'Data Dump'!$S:$S,'ANA FEED'!T$2) -> 0 | U8: =COUNTIFS('Data Dump'!$P:$P,'ANA FEED'!$A8,'Data Dump'!$S:$S,'ANA FEED'!U$2) -> 0 | V8: =COUNTIFS('Data Dump'!$P:$P,'ANA FEED'!$A8,'Data Dump'!$S:$S,'ANA FEED'!V$2) -> 0 | W8: =SUBTOTAL(9,T8:V8) -> 0 | X8: =COUNTIFS('Data Dump'!$P:$P,'ANA FEED'!$A8,'Data Dump'!$S:$S,'ANA FEED'!X$2) -> 0 | Y8: =COUNTIFS('Data Dump'!$P:$P,'ANA FEED'!$A8,'Data Dump'!$S:$S,'ANA FEED'!Y$2) -> 1 | Z8: =COUNTIFS('Data Dump'!$P:$P,'ANA FEED'!$A8,'Data Dump'!$S:$S,'ANA FEED'!Z$2) -> 0 | AA8: =SUBTOTAL(9,X8:Z8) -> 1 | AB8: =COUNTIFS('Data Dump'!$P:$P,'ANA FEED'!$A8,'Data Dump'!$S:$S,'ANA FEED'!AB$2) -> 0 | AC8: =COUNTIFS('Data Dump'!$P:$P,'ANA FEED'!$A8,'Data Dump'!$S:$S,'ANA FEED'!AC$2) -> 0 | AD8: =COUNTIFS('Data Dump'!$P:$P,'ANA FEED'!$A8,'Data Dump'!$S:$S,'ANA FEED'!AD$2) -> 0 | AE8: =SUBTOTAL(9,AB8:AD8) -> 0 | AF8: =COUNTIFS('Data Dump'!$P:$P,'ANA FEED'!$A8,'Data Dump'!$S:$S,'ANA FEED'!AF$2) -> 0 | AG8: =COUNTIFS('Data Dump'!$P:$P,'ANA FEED'!$A8,'Data Dump'!$S:$S,'ANA FEED'!AG$2) -> 1 | AH8: =COUNTIFS('Data Dump'!$P:$P,'ANA FEED'!$A8,'Data Dump'!$S:$S,'ANA FEED'!AH$2) -> 1 | AI8: =SUBTOTAL(9,AF8:AH8) -> 2 | AJ8: =SUBTOTAL(9,T8:AI8) -> 3
A9: A071 | B9: Anaconda Bunbury | C9: =COUNTIFS('Data Dump'!$P:$P,'ANA FEED'!$A9,'Data Dump'!$S:$S,'ANA FEED'!C$2) -> 0 | D9: =COUNTIFS('Data Dump'!$P:$P,'ANA FEED'!$A9,'Data Dump'!$S:$S,'ANA FEED'!D$2) -> 0 | E9: =COUNTIFS('Data Dump'!$P:$P,'ANA FEED'!$A9,'Data Dump'!$S:$S,'ANA FEED'!E$2) -> 0 | F9: =SUBTOTAL(9,C9:E9) -> 0 | G9: =COUNTIFS('Data Dump'!$P:$P,'ANA FEED'!$A9,'Data Dump'!$S:$S,'ANA FEED'!G$2) -> 0 | H9: =COUNTIFS('Data Dump'!$P:$P,'ANA FEED'!$A9,'Data Dump'!$S:$S,'ANA FEED'!H$2) -> 0 | I9: =COUNTIFS('Data Dump'!$P:$P,'ANA FEED'!$A9,'Data Dump'!$S:$S,'ANA FEED'!I$2) -> 0 | J9: =SUBTOTAL(9,G9:I9) -> 0 | K9: =COUNTIFS('Data Dump'!$P:$P,'ANA FEED'!$A9,'Data Dump'!$S:$S,'ANA FEED'!K$2) -> 0 | L9: =COUNTIFS('Data Dump'!$P:$P,'ANA FEED'!$A9,'Data Dump'!$S:$S,'ANA FEED'!L$2) -> 0 | M9: =COUNTIFS('Data Dump'!$P:$P,'ANA FEED'!$A9,'Data Dump'!$S:$S,'ANA FEED'!M$2) -> 0 | N9: =SUBTOTAL(9,K9:M9) -> 0 | O9: =COUNTIFS('Data Dump'!$P:$P,'ANA FEED'!$A9,'Data Dump'!$S:$S,'ANA FEED'!O$2) -> 0 | P9: =COUNTIFS('Data Dump'!$P:$P,'ANA FEED'!$A9,'Data Dump'!$S:$S,'ANA FEED'!P$2) -> 0 | Q9: =COUNTIFS('Data Dump'!$P:$P,'ANA FEED'!$A9,'Data Dump'!$S:$S,'ANA FEED'!Q$2) -> 0 | R9: =SUBTOTAL(9,O9:Q9) -> 0 | S9: =SUBTOTAL(9,C9:R9) -> 0 | T9: =COUNTIFS('Data Dump'!$P:$P,'ANA FEED'!$A9,'Data Dump'!$S:$S,'ANA FEED'!T$2) -> 0 | U9: =COUNTIFS('Data Dump'!$P:$P,'ANA FEED'!$A9,'Data Dump'!$S:$S,'ANA FEED'!U$2) -> 0 | V9: =COUNTIFS('Data Dump'!$P:$P,'ANA FEED'!$A9,'Data Dump'!$S:$S,'ANA FEED'!V$2) -> 0 | W9: =SUBTOTAL(9,T9:V9) -> 0 | X9: =COUNTIFS('Data Dump'!$P:$P,'ANA FEED'!$A9,'Data Dump'!$S:$S,'ANA FEED'!X$2) -> 0 | Y9: =COUNTIFS('Data Dump'!$P:$P,'ANA FEED'!$A9,'Data Dump'!$S:$S,'ANA FEED'!Y$2) -> 0 | Z9: =COUNTIFS('Data Dump'!$P:$P,'ANA FEED'!$A9,'Data Dump'!$S:$S,'ANA FEED'!Z$2) -> 0 | AA9: =SUBTOTAL(9,X9:Z9) -> 0 | AB9: =COUNTIFS('Data Dump'!$P:$P,'ANA FEED'!$A9,'Data Dump'!$S:$S,'ANA FEED'!AB$2) -> 0 | AC9: =COUNTIFS('Data Dump'!$P:$P,'ANA FEED'!$A9,'Data Dump'!$S:$S,'ANA FEED'!AC$2) -> 0 | AD9: =COUNTIFS('Data Dump'!$P:$P,'ANA FEED'!$A9,'Data Dump'!$S:$S,'ANA FEED'!AD$2) -> 0 | AE9: =SUBTOTAL(9,AB9:AD9) -> 0 | AF9: =COUNTIFS('Data Dump'!$P:$P,'ANA FEED'!$A9,'Data Dump'!$S:$S,'ANA FEED'!AF$2) -> 0 | AG9: =COUNTIFS('Data Dump'!$P:$P,'ANA FEED'!$A9,'Data Dump'!$S:$S,'ANA FEED'!AG$2) -> 0 | AH9: =COUNTIFS('Data Dump'!$P:$P,'ANA FEED'!$A9,'Data Dump'!$S:$S,'ANA FEED'!AH$2) -> 0 | AI9: =SUBTOTAL(9,AF9:AH9) -> 0 | AJ9: =SUBTOTAL(9,T9:AI9) -> 0
A10: A037 | B10: Anaconda Cairns | C10: =COUNTIFS('Data Dump'!$P:$P,'ANA FEED'!$A10,'Data Dump'!$S:$S,'ANA FEED'!C$2) -> 0 | D10: =COUNTIFS('Data Dump'!$P:$P,'ANA FEED'!$A10,'Data Dump'!$S:$S,'ANA FEED'!D$2) -> 0 | E10: =COUNTIFS('Data Dump'!$P:$P,'ANA FEED'!$A10,'Data Dump'!$S:$S,'ANA FEED'!E$2) -> 0 | F10: =SUBTOTAL(9,C10:E10) -> 0 | G10: =COUNTIFS('Data Dump'!$P:$P,'ANA FEED'!$A10,'Data Dump'!$S:$S,'ANA FEED'!G$2) -> 0 | H10: =COUNTIFS('Data Dump'!$P:$P,'ANA FEED'!$A10,'Data Dump'!$S:$S,'ANA FEED'!H$2) -> 0 | I10: =COUNTIFS('Data Dump'!$P:$P,'ANA FEED'!$A10,'Data Dump'!$S:$S,'ANA FEED'!I$2) -> 0 | J10: =SUBTOTAL(9,G10:I10) -> 0 | K10: =COUNTIFS('Data Dump'!$P:$P,'ANA FEED'!$A10,'Data Dump'!$S:$S,'ANA FEED'!K$2) -> 0 | L10: =COUNTIFS('Data Dump'!$P:$P,'ANA FEED'!$A10,'Data Dump'!$S:$S,'ANA FEED'!L$2) -> 0 | M10: =COUNTIFS('Data Dump'!$P:$P,'ANA FEED'!$A10,'Data Dump'!$S:$S,'ANA FEED'!M$2) -> 0 | N10: =SUBTOTAL(9,K10:M10) -> 0 | O10: =COUNTIFS('Data Dump'!$P:$P,'ANA FEED'!$A10,'Data Dump'!$S:$S,'ANA FEED'!O$2) -> 0 | P10: =COUNTIFS('Data Dump'!$P:$P,'ANA FEED'!$A10,'Data Dump'!$S:$S,'ANA FEED'!P$2) -> 0 | Q10: =COUNTIFS('Data Dump'!$P:$P,'ANA FEED'!$A10,'Data Dump'!$S:$S,'ANA FEED'!Q$2) -> 0 | R10: =SUBTOTAL(9,O10:Q10) -> 0 | S10: =SUBTOTAL(9,C10:R10) -> 0 | T10: =COUNTIFS('Data Dump'!$P:$P,'ANA FEED'!$A10,'Data Dump'!$S:$S,'ANA FEED'!T$2) -> 0 | U10: =COUNTIFS('Data Dump'!$P:$P,'ANA FEED'!$A10,'Data Dump'!$S:$S,'ANA FEED'!U$2) -> 0 | V10: =COUNTIFS('Data Dump'!$P:$P,'ANA FEED'!$A10,'Data Dump'!$S:$S,'ANA FEED'!V$2) -> 0 | W10: =SUBTOTAL(9,T10:V10) -> 0 | X10: =COUNTIFS('Data Dump'!$P:$P,'ANA FEED'!$A10,'Data Dump'!$S:$S,'ANA FEED'!X$2) -> 0 | Y10: =COUNTIFS('Data Dump'!$P:$P,'ANA FEED'!$A10,'Data Dump'!$S:$S,'ANA FEED'!Y$2) -> 0 | Z10: =COUNTIFS('Data Dump'!$P:$P,'ANA FEED'!$A10,'Data Dump'!$S:$S,'ANA FEED'!Z$2) -> 0 | AA10: =SUBTOTAL(9,X10:Z10) -> 0 | AB10: =COUNTIFS('Data Dump'!$P:$P,'ANA FEED'!$A10,'Data Dump'!$S:$S,'ANA FEED'!AB$2) -> 0 | AC10: =COUNTIFS('Data Dump'!$P:$P,'ANA FEED'!$A10,'Data Dump'!$S:$S,'ANA FEED'!AC$2) -> 0 | AD10: =COUNTIFS('Data Dump'!$P:$P,'ANA FEED'!$A10,'Data Dump'!$S:$S,'ANA FEED'!AD$2) -> 0 | AE10: =SUBTOTAL(9,AB10:AD10) -> 0 | AF10: =COUNTIFS('Data Dump'!$P:$P,'ANA FEED'!$A10,'Data Dump'!$S:$S,'ANA FEED'!AF$2) -> 0 | AG10: =COUNTIFS('Data Dump'!$P:$P,'ANA FEED'!$A10,'Data Dump'!$S:$S,'ANA FEED'!AG$2) -> 0 | AH10: =COUNTIFS('Data Dump'!$P:$P,'ANA FEED'!$A10,'Data Dump'!$S:$S,'ANA FEED'!AH$2) -> 0 | AI10: =SUBTOTAL(9,AF10:AH10) -> 0 | AJ10: =SUBTOTAL(9,T10:AI10) -> 0
A11: A062 | B11: Anaconda Campbelltown | C11: =COUNTIFS('Data Dump'!$P:$P,'ANA FEED'!$A11,'Data Dump'!$S:$S,'ANA FEED'!C$2) -> 0 | D11: =COUNTIFS('Data Dump'!$P:$P,'ANA FEED'!$A11,'Data Dump'!$S:$S,'ANA FEED'!D$2) -> 0 | E11: =COUNTIFS('Data Dump'!$P:$P,'ANA FEED'!$A11,'Data Dump'!$S:$S,'ANA FEED'!E$2) -> 0 | F11: =SUBTOTAL(9,C11:E11) -> 0 | G11: =COUNTIFS('Data Dump'!$P:$P,'ANA FEED'!$A11,'Data Dump'!$S:$S,'ANA FEED'!G$2) -> 0 | H11: =COUNTIFS('Data Dump'!$P:$P,'ANA FEED'!$A11,'Data Dump'!$S:$S,'ANA FEED'!H$2) -> 0 | I11: =COUNTIFS('Data Dump'!$P:$P,'ANA FEED'!$A11,'Data Dump'!$S:$S,'ANA FEED'!I$2) -> 0 | J11: =SUBTOTAL(9,G11:I11) -> 0 | K11: =COUNTIFS('Data Dump'!$P:$P,'ANA FEED'!$A11,'Data Dump'!$S:$S,'ANA FEED'!K$2) -> 0 | L11: =COUNTIFS('Data Dump'!$P:$P,'ANA FEED'!$A11,'Data Dump'!$S:$S,'ANA FEED'!L$2) -> 0 | M11: =COUNTIFS('Data Dump'!$P:$P,'ANA FEED'!$A11,'Data Dump'!$S:$S,'ANA FEED'!M$2) -> 0 | N11: =SUBTOTAL(9,K11:M11) -> 0 | O11: =COUNTIFS('Data Dump'!$P:$P,'ANA FEED'!$A11,'Data Dump'!$S:$S,'ANA FEED'!O$2) -> 0 | P11: =COUNTIFS('Data Dump'!$P:$P,'ANA FEED'!$A11,'Data Dump'!$S:$S,'ANA FEED'!P$2) -> 0 | Q11: =COUNTIFS('Data Dump'!$P:$P,'ANA FEED'!$A11,'Data Dump'!$S:$S,'ANA FEED'!Q$2) -> 0 | R11: =SUBTOTAL(9,O11:Q11) -> 0 | S11: =SUBTOTAL(9,C11:R11) -> 0 | T11: =COUNTIFS('Data Dump'!$P:$P,'ANA FEED'!$A11,'Data Dump'!$S:$S,'ANA FEED'!T$2) -> 0 | U11: =COUNTIFS('Data Dump'!$P:$P,'ANA FEED'!$A11,'Data Dump'!$S:$S,'ANA FEED'!U$2) -> 0 | V11: =COUNTIFS('Data Dump'!$P:$P,'ANA FEED'!$A11,'Data Dump'!$S:$S,'ANA FEED'!V$2) -> 0 | W11: =SUBTOTAL(9,T11:V11) -> 0 | X11: =COUNTIFS('Data Dump'!$P:$P,'ANA FEED'!$A11,'Data Dump'!$S:$S,'ANA FEED'!X$2) -> 0 | Y11: =COUNTIFS('Data Dump'!$P:$P,'ANA FEED'!$A11,'Data Dump'!$S:$S,'ANA FEED'!Y$2) -> 0 | Z11: =COUNTIFS('Data Dump'!$P:$P,'ANA FEED'!$A11,'Data Dump'!$S:$S,'ANA FEED'!Z$2) -> 0 | AA11: =SUBTOTAL(9,X11:Z11) -> 0 | AB11: =COUNTIFS('Data Dump'!$P:$P,'ANA FEED'!$A11,'Data Dump'!$S:$S,'ANA FEED'!AB$2) -> 0 | AC11: =COUNTIFS('Data Dump'!$P:$P,'ANA FEED'!$A11,'Data Dump'!$S:$S,'ANA FEED'!AC$2) -> 0 | AD11: =COUNTIFS('Data Dump'!$P:$P,'ANA FEED'!$A11,'Data Dump'!$S:$S,'ANA FEED'!AD$2) -> 0 | AE11: =SUBTOTAL(9,AB11:AD11) -> 0 | AF11: =COUNTIFS('Data Dump'!$P:$P,'ANA FEED'!$A11,'Data Dump'!$S:$S,'ANA FEED'!AF$2) -> 0 | AG11: =COUNTIFS('Data Dump'!$P:$P,'ANA FEED'!$A11,'Data Dump'!$S:$S,'ANA FEED'!AG$2) -> 0 | AH11: =COUNTIFS('Data Dump'!$P:$P,'ANA FEED'!$A11,'Data Dump'!$S:$S,'ANA FEED'!AH$2) -> 0 | AI11: =SUBTOTAL(9,AF11:AH11) -> 0 | AJ11: =SUBTOTAL(9,T11:AI11) -> 0
A12: A006 | B12: Anaconda Chullora | C12: =COUNTIFS('Data Dump'!$P:$P,'ANA FEED'!$A12,'Data Dump'!$S:$S,'ANA FEED'!C$2) -> 0 | D12: =COUNTIFS('Data Dump'!$P:$P,'ANA FEED'!$A12,'Data Dump'!$S:$S,'ANA FEED'!D$2) -> 0 | E12: =COUNTIFS('Data Dump'!$P:$P,'ANA FEED'!$A12,'Data Dump'!$S:$S,'ANA FEED'!E$2) -> 0 | F12: =SUBTOTAL(9,C12:E12) -> 0 | G12: =COUNTIFS('Data Dump'!$P:$P,'ANA FEED'!$A12,'Data Dump'!$S:$S,'ANA FEED'!G$2) -> 0 | H12: =COUNTIFS('Data Dump'!$P:$P,'ANA FEED'!$A12,'Data Dump'!$S:$S,'ANA FEED'!H$2) -> 0 | I12: =COUNTIFS('Data Dump'!$P:$P,'ANA FEED'!$A12,'Data Dump'!$S:$S,'ANA FEED'!I$2) -> 0 | J12: =SUBTOTAL(9,G12:I12) -> 0 | K12: =COUNTIFS('Data Dump'!$P:$P,'ANA FEED'!$A12,'Data Dump'!$S:$S,'ANA FEED'!K$2) -> 0 | L12: =COUNTIFS('Data Dump'!$P:$P,'ANA FEED'!$A12,'Data Dump'!$S:$S,'ANA FEED'!L$2) -> 0 | M12: =COUNTIFS('Data Dump'!$P:$P,'ANA FEED'!$A12,'Data Dump'!$S:$S,'ANA FEED'!M$2) -> 0 | N12: =SUBTOTAL(9,K12:M12) -> 0 | O12: =COUNTIFS('Data Dump'!$P:$P,'ANA FEED'!$A12,'Data Dump'!$S:$S,'ANA FEED'!O$2) -> 0 | P12: =COUNTIFS('Data Dump'!$P:$P,'ANA FEED'!$A12,'Data Dump'!$S:$S,'ANA FEED'!P$2) -> 0 | Q12: =COUNTIFS('Data Dump'!$P:$P,'ANA FEED'!$A12,'Data Dump'!$S:$S,'ANA FEED'!Q$2) -> 0 | R12: =SUBTOTAL(9,O12:Q12) -> 0 | S12: =SUBTOTAL(9,C12:R12) -> 0 | T12: =COUNTIFS('Data Dump'!$P:$P,'ANA FEED'!$A12,'Data Dump'!$S:$S,'ANA FEED'!T$2) -> 0 | U12: =COUNTIFS('Data Dump'!$P:$P,'ANA FEED'!$A12,'Data Dump'!$S:$S,'ANA FEED'!U$2) -> 0 | V12: =COUNTIFS('Data Dump'!$P:$P,'ANA FEED'!$A12,'Data Dump'!$S:$S,'ANA FEED'!V$2) -> 0 | W12: =SUBTOTAL(9,T12:V12) -> 0 | X12: =COUNTIFS('Data Dump'!$P:$P,'ANA FEED'!$A12,'Data Dump'!$S:$S,'ANA FEED'!X$2) -> 0 | Y12: =COUNTIFS('Data Dump'!$P:$P,'ANA FEED'!$A12,'Data Dump'!$S:$S,'ANA FEED'!Y$2) -> 0 | Z12: =COUNTIFS('Data Dump'!$P:$P,'ANA FEED'!$A12,'Data Dump'!$S:$S,'ANA FEED'!Z$2) -> 0 | AA12: =SUBTOTAL(9,X12:Z12) -> 0 | AB12: =COUNTIFS('Data Dump'!$P:$P,'ANA FEED'!$A12,'Data Dump'!$S:$S,'ANA FEED'!AB$2) -> 0 | AC12: =COUNTIFS('Data Dump'!$P:$P,'ANA FEED'!$A12,'Data Dump'!$S:$S,'ANA FEED'!AC$2) -> 0 | AD12: =COUNTIFS('Data Dump'!$P:$P,'ANA FEED'!$A12,'Data Dump'!$S:$S,'ANA FEED'!AD$2) -> 0 | AE12: =SUBTOTAL(9,AB12:AD12) -> 0 | AF12: =COUNTIFS('Data Dump'!$P:$P,'ANA FEED'!$A12,'Data Dump'!$S:$S,'ANA FEED'!AF$2) -> 0 | AG12: =COUNTIFS('Data Dump'!$P:$P,'ANA FEED'!$A12,'Data Dump'!$S:$S,'ANA FEED'!AG$2) -> 0 | AH12: =COUNTIFS('Data Dump'!$P:$P,'ANA FEED'!$A12,'Data Dump'!$S:$S,'ANA FEED'!AH$2) -> 0 | AI12: =SUBTOTAL(9,AF12:AH12) -> 0 | AJ12: =SUBTOTAL(9,T12:AI12) -> 0
A13: A052 | B13: Anaconda Epping | C13: =COUNTIFS('Data Dump'!$P:$P,'ANA FEED'!$A13,'Data Dump'!$S:$S,'ANA FEED'!C$2) -> 0 | D13: =COUNTIFS('Data Dump'!$P:$P,'ANA FEED'!$A13,'Data Dump'!$S:$S,'ANA FEED'!D$2) -> 0 | E13: =COUNTIFS('Data Dump'!$P:$P,'ANA FEED'!$A13,'Data Dump'!$S:$S,'ANA FEED'!E$2) -> 0 | F13: =SUBTOTAL(9,C13:E13) -> 0 | G13: =COUNTIFS('Data Dump'!$P:$P,'ANA FEED'!$A13,'Data Dump'!$S:$S,'ANA FEED'!G$2) -> 2 | H13: =COUNTIFS('Data Dump'!$P:$P,'ANA FEED'!$A13,'Data Dump'!$S:$S,'ANA FEED'!H$2) -> 0 | I13: =COUNTIFS('Data Dump'!$P:$P,'ANA FEED'!$A13,'Data Dump'!$S:$S,'ANA FEED'!I$2) -> 2 | J13: =SUBTOTAL(9,G13:I13) -> 4 | K13: =COUNTIFS('Data Dump'!$P:$P,'ANA FEED'!$A13,'Data Dump'!$S:$S,'ANA FEED'!K$2) -> 0 | L13: =COUNTIFS('Data Dump'!$P:$P,'ANA FEED'!$A13,'Data Dump'!$S:$S,'ANA FEED'!L$2) -> 0 | M13: =COUNTIFS('Data Dump'!$P:$P,'ANA FEED'!$A13,'Data Dump'!$S:$S,'ANA FEED'!M$2) -> 0 | N13: =SUBTOTAL(9,K13:M13) -> 0 | O13: =COUNTIFS('Data Dump'!$P:$P,'ANA FEED'!$A13,'Data Dump'!$S:$S,'ANA FEED'!O$2) -> 1 | P13: =COUNTIFS('Data Dump'!$P:$P,'ANA FEED'!$A13,'Data Dump'!$S:$S,'ANA FEED'!P$2) -> 0 | Q13: =COUNTIFS('Data Dump'!$P:$P,'ANA FEED'!$A13,'Data Dump'!$S:$S,'ANA FEED'!Q$2) -> 0 | R13: =SUBTOTAL(9,O13:Q13) -> 1 | S13: =SUBTOTAL(9,C13:R13) -> 5 | T13: =COUNTIFS('Data Dump'!$P:$P,'ANA FEED'!$A13,'Data Dump'!$S:$S,'ANA FEED'!T$2) -> 0 | U13: =COUNTIFS('Data Dump'!$P:$P,'ANA FEED'!$A13,'Data Dump'!$S:$S,'ANA FEED'!U$2) -> 0 | V13: =COUNTIFS('Data Dump'!$P:$P,'ANA FEED'!$A13,'Data Dump'!$S:$S,'ANA FEED'!V$2) -> 0 | W13: =SUBTOTAL(9,T13:V13) -> 0 | X13: =COUNTIFS('Data Dump'!$P:$P,'ANA FEED'!$A13,'Data Dump'!$S:$S,'ANA FEED'!X$2) -> 0 | Y13: =COUNTIFS('Data Dump'!$P:$P,'ANA FEED'!$A13,'Data Dump'!$S:$S,'ANA FEED'!Y$2) -> 0 | Z13: =COUNTIFS('Data Dump'!$P:$P,'ANA FEED'!$A13,'Data Dump'!$S:$S,'ANA FEED'!Z$2) -> 1 | AA13: =SUBTOTAL(9,X13:Z13) -> 1 | AB13: =COUNTIFS('Data Dump'!$P:$P,'ANA FEED'!$A13,'Data Dump'!$S:$S,'ANA FEED'!AB$2) -> 0 | AC13: =COUNTIFS('Data Dump'!$P:$P,'ANA FEED'!$A13,'Data Dump'!$S:$S,'ANA FEED'!AC$2) -> 0 | AD13: =COUNTIFS('Data Dump'!$P:$P,'ANA FEED'!$A13,'Data Dump'!$S:$S,'ANA FEED'!AD$2) -> 1 | AE13: =SUBTOTAL(9,AB13:AD13) -> 1 | AF13: =COUNTIFS('Data Dump'!$P:$P,'ANA FEED'!$A13,'Data Dump'!$S:$S,'ANA FEED'!AF$2) -> 0 | AG13: =COUNTIFS('Data Dump'!$P:$P,'ANA FEED'!$A13,'Data Dump'!$S:$S,'ANA FEED'!AG$2) -> 0 | AH13: =COUNTIFS('Data Dump'!$P:$P,'ANA FEED'!$A13,'Data Dump'!$S:$S,'ANA FEED'!AH$2) -> 0 | AI13: =SUBTOTAL(9,AF13:AH13) -> 0 | AJ13: =SUBTOTAL(9,T13:AI13) -> 2
